Workbook

Sheet 汇总
A1: 序号 | B1: 工号 | C1: 姓名 | D1: 部门 | E1: 岗位 | F1: 薪资项目 | G1: 金额 | H1: 备注 | K1: 说明
A2: 1 | B2: 341422 | C2: 谭悦 | D2: 考研个性化 | E2: 学习顾问 | F2: 提成奖金 | G2: =业绩核算!AD4 -> 61282.821 | K2: 兵种 | L2: 薪资名称 | M2: 标化薪资项目请选择
A3: 2 | B3: 341422 | C3: 谭悦 | D3: 考研个性化 | E3: 学习顾问 | F3: 转介绍额外激励 | G3: =业绩核算!AF4 -> 576.1584 | K3: 顾问 | L3: 月绩效 | M3: 月度绩效
A4: 3 | B4: 238256 | C4: 赵星火 | D4: 考研个性化 | E4: 学习顾问 | F4: 月度绩效 | G4: =业绩核算!P5 -> 906 | L4: 业绩提点 | M4: 提成奖金
A5: 4 | B5: 238256 | C5: 赵星火 | D5: 考研个性化 | E5: 学习顾问 | F5: 提成奖金 | G5: =业绩核算!AD5 -> 36796.97 | L5: 转介绍额外激励 | M5: 提成奖金
A6: 5 | B6: 238256 | C6: 赵星火 | D6: 考研个性化 | E6: 学习顾问 | F6: 转介绍额外激励 | G6: =业绩核算!AF5 -> 190.1816 | L6: PK赛激励 | M6: 其他业绩奖金
A7: 6 | B7: 404905 | C7: 李涛 | D7: 考研个性化 | E7: 学习顾问 | F7: 月度绩效 | G7: =业绩核算!P6 -> 0 | K7: 特殊项 | L7: 业绩回算正数 | M7: 往月薪资补发
A8: 7 | B8: 404905 | C8: 李涛 | D8: 考研个性化 | E8: 学习顾问 | F8: 提成奖金 | G8: =业绩核算!AD6 -> 35032.62 | L8: 业绩回算负值 | M8: 业绩扣款
A9: 8 | B9: 404905 | C9: 李涛 | D9: 考研个性化 | E9: 学习顾问 | F9: 转介绍额外激励 | G9: =业绩核算!AF6 -> 0
A10: 9 | B10: 675069 | C10: 王志鹏 | D10: 考研个性化 | E10: 学习顾问 | F10: 月度绩效 | G10: 2000 | H10: 保护期全额
A11: 10 | B11: 675069 | C11: 王志鹏 | D11: 考研个性化 | E11: 学习顾问 | F11: 提成奖金 | G11: =业绩核算!AD7 -> 1930.1226

Sheet 业绩核算
A1: 手动填写灰色、蓝色单元格，其他含公式，勿动
A2: 个性化顾问 | D2: 转介绍业绩-30% | H2: 签约率-40% | K2: 日常管理-30% | M2: 月度绩效 | Q2: 基本提成 | AE2: 转介绍提成 | AG2: 提成奖金小计 | AH2: 绩效+提成合计
A3: 月份 | B3: 姓名 | C3: 职级（下滑选择） | D3: 转介绍目标 | E3: 转介绍业绩（净） | F3: 完成率 | G3: 得分 | H3: 目标 | I3: 签约率 | J3: 得分 | K3: 日常管理扣分次数 | L3: 得分 | M3: 总得分 | N3: 绩效基数 | O3: 发放比例 | P3: 绩效发放金额小计 | Q3: 地面现金目标 | R3: 地面现金签约 | S3: 地面退费 | T3: 地面净现金 | U3: 在线现金目标 | V3: 在线现金签约 | W3: 在线退费 | X3: 在线净现金 | Y3: 总现金完成-退费后 | Z3: 现金完成率-退费后 | AA3: 现金完成率-退费前 | AB3: 上月退费后业绩完成率 | AC3: 奖金提点系数 | AD3: 基本提成 | AE3: 转介绍业绩提成比率 | AF3: 转介绍提成
A4: 202604 | B4: 谭悦 | C4: O3 | D4: 60000 | E4: 288079.2 | F4: =IFERROR(E4/D4,"") -> 4.80132 | G4: =IFERROR(IF(F4>=1,30,IF(AND(1>F4,F4>=0.7),F4*30,IF(F4<70,0))),0) -> 30 | H4: 0.25 | I4: 0.2418 | J4: =_xlfn.IFS(I4<H4,(100*40%)-(H4-I4)*100*5,I4>=H4,100*40%) -> 35.9 | K4: 0 | L4: =IF(30-K4<0,0,30-K4) -> 30 | M4: =L4+J4+G4 -> 95.9 | N4: =IFERROR(IF(C4="O1",2000,IF(C4="O2",1000,IF(C4="O3",0,2000))),0) -> 0 | O4: =IF(ISNUMBER(SEARCH("培训",C4)),1,IF(M4>=90,1,IF(M4>=70,1-(90-M4)*0.02,0))) -> 1 | P4: =IF(M4>=90,N4,IF(M4<70,0,IF(AND(90>M4,M4>=70),N4-N4*((90-M4)*0.02)))) -> 0 | Q4: 600000 | R4: 1442510.1 | S4: -215249.85 | T4: =R4+S4 -> 1227260.2 | U4: 0 | V4: 13792.2 | W4: -21811.4 | X4: =V4+W4 -> -8019.2 | Y4: =T4 -> 1227260.2 | Z4: =Y4/Q4 -> 2.0454337 | AA4: =R4/Q4 -> 2.4041835 | AB4: 1.8789381 | AC4: =IF(ISNUMBER(SEARCH("保薪",C4)),IFERROR(IF(Z4<0.7,0%,IF(AND(Z4>=0.7,Z4<1),0.8%,IF(AND(Z4>=1,Z4<1.2),1.2%,IF(Z4>=1.2,2%)))),0),IFERROR(IF(AND(Z4>=1.5,AB4>=0.4),0.05,IF(AND(Z4>=1.5,AB4<0.4),0.04,IF(AND(Z4<1.5,Z4>=1.2),0.04,IF(AND(Z4<1.2,Z4>=1),0.03,IF(AND(Z4<1,Z4>=0.8),0.018,IF(AND(Z4<0.8,Z4>=0.7),0.008,IF(AND(Z4<0.7,AA4>=0.7),0.008,IF(AND(Z4<0.7,AA4<0.7),0)))))))),0)) -> 0.05 | AD4: =Y4*AC4+X4*1% -> 61282.821 | AE4: =IF(F4>=1,0.002,IF(F4<0.7,-0.002,IF(AND(F4>=0.7,F4<1),0))) -> 0.002 | AF4: =E4*(AE4) -> 576.1584 | AG4: =AF4+AD4 -> 61858.979 | AH4: =P4+AG4 -> 61858.979
A5: 202604 | B5: 赵星火 | C5: O2 | D5: 60000 | E5: 95090.8 | F5: =IFERROR(E5/D5,"") -> 1.5848467 | G5: =IFERROR(IF(F5>=1,30,IF(AND(1>F5,F5>=0.7),F5*30,IF(F5<70,0))),0) -> 30 | H5: 0.25 | I5: 0.2206 | J5: =_xlfn.IFS(I5<H5,(100*40%)-(H5-I5)*100*5,I5>=H5,100*40%) -> 25.3 | K5: 0 | L5: =IF(30-K5<0,0,30-K5) -> 30 | M5: =L5+J5+G5 -> 85.3 | N5: =IFERROR(IF(C5="O1",2000,IF(C5="O2",1000,IF(C5="O3",0,2000))),0) -> 1000 | O5: =IF(ISNUMBER(SEARCH("培训",C5)),1,IF(M5>=90,1,IF(M5>=70,1-(90-M5)*0.02,0))) -> 0.906 | P5: =IF(M5>=90,N5,IF(M5<70,0,IF(AND(90>M5,M5>=70),N5-N5*((90-M5)*0.02)))) -> 906 | Q5: 652000 | R5: 984600.1 | S5: -67072.1 | T5: =R5+S5 -> 917528 | U5: 0 | V5: 21675 | W5: -12090 | X5: =V5+W5 -> 9585 | Y5: =T5 -> 917528 | Z5: =Y5/Q5 -> 1.4072515 | AA5: =R5/Q5 -> 1.5101229 | AB5: 0.62490388 | AC5: =IF(ISNUMBER(SEARCH("保薪",C5)),IFERROR(IF(Z5<0.7,0%,IF(AND(Z5>=0.7,Z5<1),0.8%,IF(AND(Z5>=1,Z5<1.2),1.2%,IF(Z5>=1.2,2%)))),0),IFERROR(IF(AND(Z5>=1.5,AB5>=0.4),0.05,IF(AND(Z5>=1.5,AB5<0.4),0.04,IF(AND(Z5<1.5,Z5>=1.2),0.04,IF(AND(Z5<1.2,Z5>=1),0.03,IF(AND(Z5<1,Z5>=0.8),0.018,IF(AND(Z5<0.8,Z5>=0.7),0.008,IF(AND(Z5<0.7,AA5>=0.7),0.008,IF(AND(Z5<0.7,AA5<0.7),0)))))))),0)) -> 0.04 | AD5: =Y5*AC5+X5*1% -> 36796.97 | AE5: =IF(F5>=1,0.002,IF(F5<0.7,-0.002,IF(AND(F5>=0.7,F5<1),0))) -> 0.002 | AF5: =E5*(AE5) -> 190.1816 | AG5: =AF5+AD5 -> 36987.152 | AH5: =P5+AG5 -> 37893.152
A6: 202604 | B6: 李涛 | C6: O1 | D6: 60000 | E6: 0 | F6: =IFERROR(E6/D6,"") -> 0 | G6: =IFERROR(IF(F6>=1,30,IF(AND(1>F6,F6>=0.7),F6*30,IF(F6<70,0))),0) -> 0 | H6: 0.2 | I6: 0.1556 | J6: =_xlfn.IFS(I6<H6,(100*40%)-(H6-I6)*100*5,I6>=H6,100*40%) -> 17.8 | K6: 0 | L6: =IF(30-K6<0,0,30-K6) -> 30 | M6: =L6+J6+G6 -> 47.8 | N6: =IFERROR(IF(C6="O1",2000,IF(C6="O2",1000,IF(C6="O3",0,2000))),0) -> 2000 | O6: =IF(ISNUMBER(SEARCH("培训",C6)),1,IF(M6>=90,1,IF(M6>=70,1-(90-M6)*0.02,0))) -> 0 | P6: =IF(M6>=90,N6,IF(M6<70,0,IF(AND(90>M6,M6>=70),N6-N6*((90-M6)*0.02)))) -> 0 | Q6: 612000 | R6: 887364.8 | S6: -11549.3 | T6: =R6+S6 -> 875815.5 | U6: 0 | V6: 0 | W6: 0 | X6: =V6+W6 -> 0 | Y6: =T6 -> 875815.5 | Z6: =Y6/Q6 -> 1.4310711 | AA6: =R6/Q6 -> 1.4499425 | AB6: 0.013280635 | AC6: =IF(ISNUMBER(SEARCH("保薪",C6)),IFERROR(IF(Z6<0.7,0%,IF(AND(Z6>=0.7,Z6<1),0.8%,IF(AND(Z6>=1,Z6<1.2),1.2%,IF(Z6>=1.2,2%)))),0),IFERROR(IF(AND(Z6>=1.5,AB6>=0.4),0.05,IF(AND(Z6>=1.5,AB6<0.4),0.04,IF(AND(Z6<1.5,Z6>=1.2),0.04,IF(AND(Z6<1.2,Z6>=1),0.03,IF(AND(Z6<1,Z6>=0.8),0.018,IF(AND(Z6<0.8,Z6>=0.7),0.008,IF(AND(Z6<0.7,AA6>=0.7),0.008,IF(AND(Z6<0.7,AA6<0.7),0)))))))),0)) -> 0.04 | AD6: =Y6*AC6+X6*1% -> 35032.62 | AE6: =IF(F6>=1,0.002,IF(F6<0.7,-0.002,IF(AND(F6>=0.7,F6<1),0))) -> -0.002 | AF6: =E6*(AE6) -> 0 | AG6: =AF6+AD6 -> 35032.62 | AH6: =P6+AG6 -> 35032.62
A7: 202604 | B7: 王志鹏 | C7: 培训期 保薪期 | D7: 0 | E7: 0 | F7: =IFERROR(E7/D7,"") | G7: =IFERROR(IF(F7>=1,30,IF(AND(1>F7,F7>=0.7),F7*30,IF(F7<70,0))),0) -> 30 | H7: 0.2 | I7: 0.1667 | J7: =_xlfn.IFS(I7<H7,(100*40%)-(H7-I7)*100*5,I7>=H7,100*40%) -> 23.35 | K7: 0 | L7: =IF(30-K7<0,0,30-K7) -> 30 | M7: =L7+J7+G7 -> 83.35 | N7: =IFERROR(IF(C7="O1",2000,IF(C7="O2",1000,IF(C7="O3",0,2000))),0) -> 2000 | O7: =IF(ISNUMBER(SEARCH("培训",C7)),1,IF(M7>=90,1,IF(M7>=70,1-(90-M7)*0.02,0))) -> 1 | P7: =N7 -> 2000 | Q7: 156000 | R7: 163850.65 | S7: -5849.1 | T7: =R7+S7 -> 158001.55 | U7: 0 | V7: 3410.4 | W7: 0 | X7: =V7+W7 -> 3410.4 | Y7: =T7 -> 158001.55 | Z7: =Y7/Q7 -> 1.0128304 | AA7: =R7/Q7 -> 1.0503247 | AB7: 3.59808 | AC7: =IF(ISNUMBER(SEARCH("保薪",C7)),IFERROR(IF(Z7<0.7,0%,IF(AND(Z7>=0.7,Z7<1),0.8%,IF(AND(Z7>=1,Z7<1.2),1.2%,IF(Z7>=1.2,2%)))),0),IFERROR(IF(AND(Z7>=1.5,AB7>=0.4),0.05,IF(AND(Z7>=1.5,AB7<0.4),0.04,IF(AND(Z7<1.5,Z7>=1.2),0.04,IF(AND(Z7<1.2,Z7>=1),0.03,IF(AND(Z7<1,Z7>=0.8),0.018,IF(AND(Z7<0.8,Z7>=0.7),0.008,IF(AND(Z7<0.7,AA7>=0.7),0.008,IF(AND(Z7<0.7,AA7<0.7),0)))))))),0)) -> 0.012 | AD7: =Y7*AC7+X7*1% -> 1930.1226 | AE7: =IF(F7>=1,0.002,IF(F7<0.7,-0.002,IF(AND(F7>=0.7,F7<1),0))) -> 0.002 | AF7: 0 | AG7: =AF7+AD7 -> 1930.1226 | AH7: =P7+AG7 -> 3930.1226
A9: 提点方案 | B9: 职级 | C9: 说明
A10: 高提点方案 | B10: O1 | C10: 老顾问选择
B11: O2 | C11: 老顾问选择
B12: O3 | C12: 老顾问选择
B13: 培训期 | C13: 新顾问高提点方案选择，前三月阶段下标期间，选择此标签，全标后，正常选择【O1】
A14: 低提点方案 | B14: 培训期 保薪期 | C14: 新顾问低提点方案选择，前三月阶段下标期间，选择此标签，全标后，正常选择【保薪期】
B15: 保薪期 | C15: 新顾问低提点方案选择，结束保薪后正常选择【O1】

Sheet 签约明细
A1: 日期 | B1: 学员姓名 | E1: 学费 | F1: 学员号 | K1: 顾问
A2: 46173 | B2: 包涵 | C2: 国内考试 | E2: 97800 | F2: XDF072229135753387 | H2: 新签 | I2: 已交接 | J2: 毛坯数据 | K2: 李涛 | L2: 46173.722 | M2: 李涛 | N2: 46173.724 | O2: 46125.851
A3: 46173 | B3: 武子煜 | C3: 国内考试 | E3: 15300 | F3: BJWY6127303623 | G3: 死单激活谭悦 | H3: 新签 | I3: 已交接 | J3: 内部员工推荐(大学内部员工推荐) | K3: 谭悦 | L3: 46173.658 | M3: 谭悦 | N3: 46173.658 | O3: 46172.661
A4: 46173 | B4: 苏梓漪 | C4: 国内考试 | E4: 47800 | F4: BJWY2920053816 | H4: 新签 | I4: 已交接 | J4: 小红书KOS | K4: 李涛 | L4: 46173.803 | M4: 李涛 | N4: 46173.803 | O4: 46173.486
A5: 46172 | B5: 张瑞卿 | C5: 国内考试 | E5: 87000 | F5: BJWY1353388976 | G5: 张会艳 | H5: 新签 | I5: 已交接 | J5: 新东方员工推荐 | K5: 赵星火 | L5: 46172.418 | M5: 赵星火 | N5: 46172.423 | O5: 46171.626
A6: 46172 | B6: 权有杰 | C6: 国内考试 | E6: 29300 | F6: BJWY0090690267 | H6: 新签 | I6: 已交接 | J6: 集团-百度品专 | K6: 李涛 | L6: 46172.771 | M6: 李涛 | N6: 46172.771 | O6: 46171.671
A7: 46172 | B7: 石稷韬 | C7: 国内考试 | E7: 10440 | F7: BJWY8419380371 | H7: 新签 | I7: 已交接 | J7: 小红书 | K7: 李涛 | L7: 46172.718 | M7: 李涛 | N7: 46172.718 | O7: 46171.448
A8: 46171 | B8: 张子悦 | C8: 国内考试 | E8: 4460 | F8: BJWY9230749165 | H8: 新签 | I8: 已交接 | J8: 小红书 | K8: 王志鹏 | L8: 46171.66 | M8: 王志鹏 | N8: 46171.66 | O8: 46159.012
A9: 46171 | B9: 斯特格里 | C9: 国内考试 | E9: 9000 | F9: BJWY6863533496 | G9: 葛铭 | H9: 续班 | I9: 已交接 | J9: 学管续费推荐 | K9: 赵星火 | L9: 46171.651 | M9: 赵星火 | N9: 46171.651 | O9: 46159.889
A10: 46169 | B10: 李灿 | C10: 国内考试 | E10: 17500 | F10: BJWY0934899255 | G10: 李亚坤 | H10: 续班 | I10: 已交接 | J10: 学管续费推荐 | K10: 赵星火 | L10: 46169.471 | M10: 赵星火 | N10: 46169.505 | O10: 46160.65
A11: 46169 | B11: 赵予萱 | C11: 国内考试 | E11: 39500 | F11: BJWY4682292351 | H11: 分单 | I11: 已交接 | J11: 巨量本地推 | K11: 谭悦 | L11: 46169.618 | M11: 李涛 | N11: 46169.619 | O11: 46148.64
A12: 46169 | B12: 赵予萱 | C12: 国内考试 | E12: 39500 | F12: BJWY4682292351 | H12: 新签 | I12: 已交接 | J12: 巨量本地推 | K12: 李涛 | L12: 46169.618 | M12: 李涛 | N12: 46169.619 | O12: 46148.64
A13: 46169 | B13: 赵子睿 | C13: 国内考试 | E13: 22100 | F13: BJWY2657109942 | H13: 续班 | I13: 已交接 | J13: 学管续费推荐 | K13: 谭悦 | L13: 46169.614 | M13: 谭悦 | N13: 46169.617 | O13: 46169.599
A14: 46168 | B14: 张乾龙 | C14: 国内考试 | E14: 18300 | F14: XDF062127195653036 | H14: 新签 | I14: 已交接 | J14: 新东方PC官网 | K14: 谭悦 | L14: 46168.701 | M14: 谭悦 | N14: 46168.704 | O14: 46090.474
A15: 46168 | B15: 贺子岳 | C15: 国内考试 | E15: 1400 | F15: BJWY3956726108 | G15: 刘佳林 | H15: 续班 | I15: 已交接 | J15: 学管续费推荐 | K15: 赵星火 | L15: 46168.443 | M15: 赵星火 | N15: 46168.504 | O15: 46167.425
A16: 46168 | B16: 刘婷 | C16: 国内考试 | E16: 10500 | F16: BJWY9928468300 | H16: 分单 | I16: 已交接 | J16: 毛坯数据 | K16: 王志鹏 | L16: 46168.622 | M16: 王秋雨 | N16: 46168.706 | O16: 46168.622
A17: 46167 | B17: 刘婷 | C17: 国内考试 | E17: 11337.25 | F17: BJWY9928468300 | H17: 分单 | I17: 已交接 | J17: 毛坯数据 | K17: 王志鹏 | L17: 46167.892 | M17: 王秋雨 | N17: 46170.889 | O17: 46167.885
A18: 46167 | B18: 王若宇 | C18: 国内考试 | E18: 6650 | F18: BJWY7758394076 | G18: 葛铭 | H18: 续班 | I18: 已交接 | J18: 学管续费推荐 | K18: 谭悦 | L18: 46167.733 | M18: 谭悦 | N18: 46167.733 | O18: 46167.626
A19: 46167 | B19: 王若宇 | C19: 国内考试 | E19: 6650 | F19: BJWY7758394076 | G19: 葛铭 | H19: 分单 | I19: 已交接 | J19: 学管续费推荐 | K19: 赵星火 | L19: 46167.733 | M19: 谭悦 | N19: 46167.733 | O19: 46167.626
A20: 46166 | B20: 王冉 | C20: 国内考试 | E20: 92300 | F20: BJWY1685349038 | H20: 续班 | I20: 已交接 | J20: 总部-巨量本地推 | K20: 李涛 | L20: 46166.564 | M20: 李涛 | N20: 46170.438 | O20: 46146.732
A21: 46165 | B21: 王大伟 | C21: 国内考试 | E21: 31500 | F21: BJWY7693462328 | G21: 王天义 | H21: 续班 | I21: 已交接 | J21: 学管续费推荐 | K21: 赵星火 | L21: 46165.597 | M21: 赵星火 | N21: 46165.599 | O21: 46160.471
A22: 46165 | B22: 王若熙 | C22: 国内考试 | E22: 7650 | F22: BJWY6574639715 | H22: 新签 | I22: 已交接 | J22: 坦途网 | K22: 谭悦 | L22: 46165.567 | M22: 谭悦 | N22: 46165.576 | O22: 46153.51
A23: 46164 | B23: 仲宇昕 | C23: 国内考试 | E23: 14900.1 | F23: BJWY6854548197 | H23: 续班 | I23: 已交接 | J23: 学管续费推荐 | K23: 谭悦 | L23: 46166.754 | M23: 谭悦 | N23: 46166.755 | O23: 46166.754
A24: 46163 | B24: 高梓欣 | C24: 国内考试 | E24: 91800 | F24: BJWY7812550804 | G24: 谭悦 | H24: 续班 | I24: 已交接 | J24: 老带新系统顾问 | K24: 谭悦 | L24: 46163.974 | M24: 谭悦 | N24: 46163.974 | O24: 46160.879
A25: 46163 | B25: 张乃月 | C25: 国内考试 | E25: 8613 | G25: 张志维+zhangzhiwei19@xdf.cn+ID+培训学校-北京学校-高中一对一部-西南区-海淀东分中心 | H25: 分单 | I25: 无须交接 | J25: 新东方员工推荐 | K25: 谭悦 | L25: 46163.81 | M25: 赵星火 | N25: 46163.81 | O25: 46163.809
A26: 46163 | B26: 张乃月 | C26: 国内考试 | E26: 8613 | G26: 张志维+zhangzhiwei19@xdf.cn+ID+培训学校-北京学校-高中一对一部-西南区-海淀东分中心 | H26: 续班 | I26: 无须交接 | J26: 新东方员工推荐 | K26: 赵星火 | L26: 46163.81 | M26: 赵星火 | N26: 46163.81 | O26: 46163.809
A27: 46163 | B27: 杨家锐 | C27: 国内考试 | E27: 12500 | F27: BJWY7405385362 | G27: 张里+zhangli438@xdf.cn+张里438(新东方教育科技集团有限公司-培训学校-华北经济区-北京学校-高中一对一部-西北区-知春路分中心 | 课程顾问) | H27: 分单 | I27: 已交接 | J27: 新东方员工推荐 | K27: 赵星火 | L27: 46163.833 | M27: 王志鹏 | N27: 46163.881 | O27: 46163.621
A28: 46163 | B28: 杨家锐 | C28: 国内考试 | E28: 12500 | F28: BJWY7405385362 | G28: 张里+zhangli438@xdf.cn+张里438(新东方教育科技集团有限公司-培训学校-华北经济区-北京学校-高中一对一部-西北区-知春路分中心 | 课程顾问) | H28: 新签 | I28: 已交接 | J28: 新东方员工推荐 | K28: 王志鹏 | L28: 46163.833 | M28: 王志鹏 | N28: 46163.881 | O28: 46163.621
A29: 46162 | B29: 高梓宸 | C29: 国内考试 | E29: 20300 | F29: BJWY0757953694 | H29: 新签 | I29: 已交接 | J29: 新东方PC官网 | K29: 赵星火 | L29: 46162.426 | M29: 赵星火 | N29: 46162.427 | O29: 46161.44
A30: 46161 | B30: 冯宏韬 | C30: 国内考试 | E30: 22674.5 | F30: BJWY1229134270 | H30: 新签 | I30: 已交接 | J30: 新东方PC官网 | K30: 李涛 | L30: 46161.767 | M30: 李涛 | N30: 46161.767 | O30: 46155.874
A31: 46161 | B31: 刘蓁蓁 | C31: 国内考试 | E31: 15300 | F31: BJWY1256011738 | H31: 续班 | I31: 已交接 | J31: 总部-腾讯广告 | K31: 谭悦 | L31: 46161.856 | M31: 谭悦 | N31: 46161.856 | O31: 46161.856
A32: 46161 | B32: 肖雨涵 | C32: 国内考试 | E32: 5955.2 | F32: BJWY9566008760 | H32: 新签 | I32: 已交接 | J32: 巨量本地推 | K32: 王志鹏 | L32: 46161.803 | M32: 王志鹏 | N32: 46162.427 | O32: 46156.923
A33: 46160 | B33: 张博岩 | C33: 国内考试 | E33: 11900 | F33: BJWY3896078049 | G33: 徐岩 | H33: 续班 | I33: 已交接 | J33: 学管续费推荐 | K33: 谭悦 | L33: 46160.398 | M33: 谭悦 | N33: 46160.399 | O33: 46153.632
A34: 46159 | B34: 薛宗齐 | C34: 国内考试 | E34: 3000 | F34: BJWY9225883231 | G34: 舒志豪 | H34: 续班 | I34: 已交接 | J34: 学管续费推荐 | K34: 谭悦 | L34: 46159.698 | M34: 谭悦 | N34: 46159.7 | O34: 46159.696
A35: 46159 | B35: 王大伟 | C35: 国内考试 | E35: 33500 | F35: BJWY7693462328 | G35: 王天义 | H35: 续班 | I35: 已交接 | J35: 学管续费推荐 | K35: 赵星火 | L35: 46159.486 | M35: 赵星火 | N35: 46159.556 | O35: 46151.499
A36: 46159 | B36: 周闻汐 | C36: 国内考试 | E36: 33800 | F36: BJWY6883909264 | G36: 寇颖 | H36: 续班 | I36: 已交接 | J36: 学管续费推荐 | K36: 谭悦 | L36: 46159.63 | M36: 谭悦 | N36: 46159.631 | O36: 46159.448
A37: 46158 | B37: 张添翼 | C37: 国内考试 | E37: 50000 | F37: BJWY1245358230 | G37: 谭剑波+tanjianbo@xdf.cn+谭剑波(新东方教育科技集团有限公司-产业机构-大学事业部-大学总部-总裁办公室 | 考研资深演讲师) | H37: 新签 | I37: 已交接 | J37: 内部员工推荐(大学内部员工推荐) | K37: 谭悦 | L37: 46158.774 | M37: 谭悦 | N37: 46158.776 | O37: 46144.793
A38: 46158 | B38: 刘天奕 | C38: 国内考试 | E38: 25150 | F38: BJWY6141363890 | G38: 张议文+344748+zhangyiwen34@xdf.cn+产业机构-前途出国-前途北京公司-美国研究生一部+咨询顾问 | H38: 新签 | I38: 已交接 | J38: 内部员工推荐(大学内部员工推荐) | K38: 谭悦 | L38: 46158.751 | M38: 谭悦 | N38: 46158.756 | O38: 46134.836
A39: 46158 | B39: 罗宇航 | C39: 国内考试 | E39: 53400 | F39: BJWY7777555488 | G39: 黄子琪 | H39: 续班 | I39: 已交接 | J39: 学管续费推荐 | K39: 谭悦 | L39: 46158.553 | M39: 谭悦 | N39: 46158.663 | O39: 46153.81
A40: 46158 | B40: 朱德康 | C40: 国内考试 | E40: 49800 | F40: BJWY9871261326 | G40: 谭悦 | H40: 续班 | I40: 已交接 | J40: 老带新系统顾问 | K40: 谭悦 | L40: 46158.769 | M40: 谭悦 | N40: 46158.769 | O40: 46137.507
...

Sheet 退费明细
B1: 学员姓名 | E1: 退费金额 | H1: 顾问
A2: BJWY2158176753 | B2: 张歆艺 | C2: WYP27214 | D2: 46155.859 | E2: -975 | F2: 陈伟钰1 | G2: BJWY2201F8pC6h | H2: 李涛
A3: BJWY2158176753 | B3: 张歆艺 | C3: WYP27215 | D3: 46155.859 | E3: -1190.7 | F3: 陈伟钰1 | G3: BJWY2201F8pC6h | H3: 李涛
A4: BJWY2158176753 | B4: 张歆艺 | C4: WYP27213 | D4: 46155.859 | E4: -1734.5 | F4: 陈伟钰1 | G4: BJWY2201F8pC6h | H4: 李涛
A5: BJWY0626566907 | B5: 薛雯 | C5: WYE27219 | D5: 46154.758 | E5: -2536.2 | F5: 吴凯龙 | G5: BJWY25030q8UPI | H5: 李涛
A6: BJWY0626566907 | B6: 薛雯 | C6: WYP27207 | D6: 46154.758 | E6: -3312.9 | F6: 吴凯龙 | G6: BJWY25030q8UPI | H6: 李涛
A7: BJWY2511364322 | B7: 严于律 | C7: LP1777702061107 | D7: 46150.69 | E7: -1800 | F7: 陈晶 | G7: chenjing171 | H7: 李涛
A8: BJWY7734838818 | B8: 蔡智韬 | C8: WYE27111 | D8: 46170.584 | E8: -3135.15 | F8: 程远 | G8: BJWY24032w1g8X | H8: 谭悦
A9: BJWY7734838818 | B9: 蔡智韬 | C9: WYE27112 | D9: 46170.584 | E9: -1243 | F9: 程远 | G9: BJWY24032w1g8X | H9: 谭悦
A10: BJWY7734838818 | B10: 蔡智韬 | C10: WYZ27002 | D10: 46170.584 | E10: -8883.1 | F10: 程远 | G10: BJWY24032w1g8X | H10: 谭悦
A11: BJWY7734838818 | B11: 蔡智韬 | C11: WYE27108 | D11: 46170.583 | E11: -1744.75 | F11: 程远 | G11: BJWY24032w1g8X | H11: 谭悦
A12: BJWY6023662088 | B12: 董哲语 | C12: LP17695849251042 | D12: 46171.557 | E12: -12000 | F12: 王天一 | G12: wangtianyi55 | H12: 谭悦
A13: BJWY1528223979 | B13: 程珺晗 | C13: WYP27004 | D13: 46167.698 | E13: -550.95 | F13: 段同飞 | G13: BJWY22035556hl | H13: 谭悦
... A28: BJWY2657109942 | B28: 赵子睿 | C28: LP17737194712125 | D28: 46161.612 | E28: -4800 | F28: 马一鸣 | G28: mayiming16 | H28: 谭悦
A29: 106730890 | B29: 学员egi5n | D29: 46155.891 | E29: -19836 | F29: 谭悦 | H29: 谭悦
A30: BJWY1404722327 | B30: 李昕瑶 | C30: LP17566273494478 | D30: 46154.44 | E30: -5000 | F30: 谢仕为 | G30: xieshiwei1 | H30: 谭悦
A31: BJWY7455894214 | B31: 侯童烨 | C31: LP1774854654394 | D31: 46154.436 | E31: -5000 | F31: 陈晶 | G31: chenjing171 | H31: 谭悦
A32: BJWY7455894214 | B32: 侯童烨 | C32: LP1774854654393 | D32: 46154.436 | E32: -18800 | F32: 陈晶 | G32: chenjing171 | H32: 谭悦
A33: 111857137 | B33: DLS_3133893142 | D33: 46147.838 | E33: -1975.4 | F33: 谭悦 | H33: 谭悦
A34: BJWY4293343554 | B34: 代雨鑫 | C34: LP1769403775379 | D34: 46152.675 | E34: -20500 | F34: 马一鸣 | G34: mayiming16 | H34: 谭悦
A35: BJWY5305138836 | B35: 郭宸宇 | C35: LP17632566543722 | D35: 46151.58 | E35: -1600 | F35: 舒志豪 | G35: shuzhihao1 | H35: 谭悦
A36: BJWY0626566907 | B36: 薛雯 | C36: WYE27219 | D36: 46154.758 | E36: -2536.2 | F36: 吴凯龙 | G36: BJWY25030q8UPI | H36: 王志鹏
A37: BJWY0626566907 | B37: 薛雯 | C37: WYP27207 | D37: 46154.758 | E37: -3312.9 | F37: 吴凯龙 | G37: BJWY25030q8UPI | H37: 王志鹏
A38: BJWY6863533496 | B38: 斯特格里 | C38: WYP27103 | D38: 46171.648 | E38: -5740 | F38: 段同飞 | G38: BJWY22035556hl | H38: 赵星火
A39: BJWY6863533496 | B39: 斯特格里 | C39: WYP27102 | D39: 46171.647 | E39: -4700 | F39: 段同飞 | G39: BJWY22035556hl | H39: 赵星火
A40: BJWY6863533496 | B40: 斯特格里 | C40: WYP27101 | D40: 46171.647 | E40: -3160 | F40: 段同飞 | G40: BJWY22035556hl | H40: 赵星火
A41: 111354677 | B41: DLS_1451056855 | D41: 46158.646 | E41: -12090 | F41: 赵星火 | H41: 赵星火
A42: BJWY0892431043 | B42: 贾玥晗 | C42: KYSJJX2707Z | D42: 46154.456 | E42: -5700 | F42: 赵秋侠 | G42: BJWY2306SVFgG7 | H42: 赵星火
A43: BJWY0892431043 | B43: 贾玥晗 | C43: KYSJJXY2705 | D43: 46154.456 | E43: -9050 | F43: 赵秋侠 | G43: BJWY2306SVFgG7 | H43: 赵星火
A44: BJWY0892431043 | B44: 贾玥晗 | C44: KYSJJXZ2705 | D44: 46154.456 | E44: -6050 | F44: 赵秋侠 | G44: BJWY2306SVFgG7 | H44: 赵星火
A45: BJWY0892431043 | B45: 贾玥晗 | C45: LP17649259052164 | D45: 46154.433 | E45: -17772 | F45: 王天一 | G45: wangtianyi55 | H45: 赵星火
A46: BJWY6379218222 | B46: 孙圣霖 | C46: WYP27210 | D46: 46149.518 | E46: -6625.8 | F46: 吴凯龙 | G46: BJWY25030q8UPI | H46: 赵星火
A47: BJWY6379218222 | B47: 孙圣霖 | C47: WYP27212 | D47: 46149.519 | E47: -4549.3 | F47: 吴凯龙 | G47: BJWY25030q8UPI | H47: 赵星火
A48: BJWY6379218222 | B48: 孙圣霖 | C48: WYP27211 | D48: 46149.519 | E48: -3725 | F48: 吴凯龙 | G48: BJWY25030q8UPI | H48: 赵星火

Sheet 5月绩效明细 
B2: 顾问 | E2: 转介绍 | L2: 签约率 | S2: 日常管理
B3: 工号 | C3: 顾问姓名 | D3: 备注 | E3: 工单目标 | F3: 工单实际 | G3: 完成率 | H3: 签约目标 | I3: 签约实际 | J3: 完成率 | K3: 占比 | L3: 主动目标 | M3: 主动实际 | N3: 完成情况 | O3: 被动目标 | P3: 被动实际 | Q3: 完成情况 | R3: 占比 | S3: 自签占比目标比 | T3: 实际 | U3: 占比 | V3: 回访时效 | W3: 占比 | X3: 得分
B4: 341422 | C4: 谭悦 | D4: O3无考核指标 | E4: 3 | F4: 7 | G4: =F4/E4 -> 2.3333333 | H4: =业绩核算!D4 -> 60000 | I4: =业绩核算!E4 -> 288079.2 | J4: =I4/H4 -> 4.80132 | K4: 0.3 | L4: 0.25 | M4: 0.3267 | N4: 完成 | O4: 0.1 | P4: 0.0784 | Q4: 未完成 | R4: 0.4 | S4: 0.3 | T4: 0.36 | U4: 0.2 | V4: 合格 | W4: 0.1 | X4: 70
B5: 238256 | C5: 赵星火 | E5: 3 | F5: 2 | G5: =F5/E5 -> 0.66666667 | H5: =业绩核算!D5 -> 60000 | I5: =业绩核算!E5 -> 95090.8 | J5: =I5/H5 -> 1.5848467 | K5: 0.3 | L5: 0.25 | M5: 0.2667 | N5: 完成 | O5: 0.1 | P5: 0.069 | Q5: 未完成 | R5: 0.4 | S5: 0.3 | T5: 0.43 | U5: 0.2 | V5: 合格 | W5: 0.1 | X5: 50
B6: 404905 | C6: 李涛 | E6: 3 | F6: 1 | G6: =F6/E6 -> 0.33333333 | H6: =业绩核算!D6 -> 60000 | I6: =业绩核算!E6 -> 0 | J6: =I6/H6 -> 0 | K6: 0.3 | L6: 0.2 | M6: 0.1892 | N6: 未完成 | O6: 0.1 | P6: 0.1 | Q6: 完成 | R6: 0.4 | S6: 0.3 | T6: 0.411 | U6: 0.2 | V6: 合格 | W6: 0.1 | X6: 30
B7: 675069 | C7: 王志鹏 | D7: 保护期 | E7: 0 | F7: 0 | G7: 0 | H7: =业绩核算!D7 -> 0 | I7: =业绩核算!E7 -> 0 | J7: 0 | K7: 0.3 | L7: 0.2 | M7: 0.1212 | N7: 未完成 | O7: 0.1 | P7: 0.1622 | Q7: 完成 | R7: 0.4 | S7: 0.3 | T7: 0.127 | U7: 0.2 | V7: 合格 | W7: 0.1 | X7: 30

Sheet 6月绩效目标 
B2: 序号 | C2: 年月 | D2: 部门 | E2: 工号 | F2: 姓名 | G2: 岗位 | H2: 绩效考核项
H3: 1.签约业绩 | I3: 2.主被动转化率 | J3: 3.老带新工单/人头/金额 | K3: 4.项目自签占比 | L3: 5.回访时效
B4: 1 | C4: 2025.05 | E4: 341422 | F4: 谭悦 | H4: 728000 | I4: 主动25%、被动10% | J4: 工单3/人头2/金额6 | K4: 0.3 | L4: 不低于中心75分位值
B5: 2 | C5: 2025.05 | E5: 238256 | F5: 赵星火 | H5: 157000 | I5: 主动25%、被动10% | J5: 工单3/人头1/金额1.5 | K5: 0.3 | L5: 不低于中心75分位值
B6: 3 | C6: 2025.05 | E6: 404905 | F6: 李涛 | H6: 728000 | I6: 主动20%、被动10% | J6: 工单3/人头2/金额6 | K6: 0.3 | L6: 不低于中心75分位值
B7: 4 | C7: 2025.05 | E7: 675069 | F7: 王志鹏 | H7: 314000 | I7: 主动20%、被动10% | J7: 工单3/人头1/金额3 | K7: 0.3 | L7: 不低于中心75分位值
I8: 占比40% | J8: 占比30% | K8: 占比30%
