Workbook

Sheet 汇总
B2: 业绩奖金表（一人可多条，需写清类别）
B3: 序号 | C3: 机构 | D3: 年月 | E3: 工号 | F3: 姓名 | G3: 部门 | H3: 薪资项目 | I3: 金额 | J3: 备注
B4: 1 | C4: 北京中心 | D4: 45931 | E4: 238256 | F4: 赵星火 | G4: O2级学习顾问 | H4: 月度绩效 | I4: ='10月绩效核算'!AD4 -> 600
B5: 2 | C5: 北京中心 | D5: 45932 | E5: 238256 | F5: 赵星火 | G5: O2级学习顾问 | H5: 顾问签约奖金 | I5: =业绩核算!P5 -> 48633.241
B6: 3 | C6: 北京中心 | D6: 45933 | E6: 238256 | F6: 赵星火 | G6: O2级学习顾问 | H6: 组长绩效 | I6: 2000 | J6: 新人满3月留存带教费
B7: 4 | C7: 北京中心 | D7: 45934 | E7: 341422 | F7: 谭悦 | G7: O3级学习顾问 | H7: 月度绩效 | I7: 0 | J7: O3无绩效
B8: 5 | C8: 北京中心 | D8: 45935 | E8: 341422 | F8: 谭悦 | G8: O3级学习顾问 | H8: 顾问签约奖金 | I8: =业绩核算!P4 -> 56041.305
B9: 6 | C9: 北京中心 | D9: 45936 | E9: 404905 | F9: 李涛 | G9: O1级学习顾问 | H9: 月度绩效 | I9: ='10月绩效核算'!AD5 -> 1200
B10: 7 | C10: 北京中心 | D10: 45937 | E10: 404905 | F10: 李涛 | G10: O1级学习顾问 | H10: 顾问签约奖金 | I10: =业绩核算!P6 -> 28491.419 | J10: 2025.10结束保护期
B11: 8 | C11: 北京中心 | D11: 45933 | E11: 238256 | F11: 赵星火 | G11: O2级学习顾问 | H11: 转介绍负激励 | I11: =-0.2%*(19303.2+50180) -> -138.9664 | J11: 九月老带新业绩50180十月老带新业绩19303.2
B12: 9 | C12: 北京中心 | D12: 45934 | E12: 341422 | F12: 谭悦 | G12: O3级学习顾问 | H12: 转介绍负激励 | I12: =-0.2%*(25040+17586.2) -> -85.2524 | J12: 九月老带新业绩25040十月老带新业绩17586.2

Sheet 业绩核算
B2: 2025.10个性化顾问业绩
B3: 序号 | C3: 顾问姓名 | D3: 地面目标 | E3: 网课目标 | F3: 综合目标 | G3: 四六级签约 | H3: 网课签约 | I3: 无忧签约 | J3: 集训签约 | K3: 个性化 | L3: 业绩合计 | M3: 退费合计 | N3: 综合业绩 | O3: 完成率
B4: 1 | C4: 谭悦 | D4: 650000 | E4: 20000 | F4: =D4+E4 -> 670000 | G4: =GETPIVOTDATA("学费",签约单明细!$C$2,"签约单录入人","谭悦","项目类别","四六级") -> 53661.1 | H4: =GETPIVOTDATA("学费",签约单明细!$C$2,"签约单录入人","谭悦","项目类别","网课") -> 59354.7 | I4: =GETPIVOTDATA("学费",签约单明细!$C$2,"签约单录入人","谭悦","项目类别","无忧") -> 421119.5 | J4: =GETPIVOTDATA("学费",签约单明细!$C$2,"签约单录入人","谭悦","项目类别","集训营") -> 71628.9 | K4: =GETPIVOTDATA("学费",签约单明细!$C$2,"签约单录入人","谭悦","项目类别","个性化") -> 584850 | L4: =SUM(G4:K4) -> 1190614.2 | M4: =退费明细!AO26 -> 69788.1 | N4: =L4-M4 -> 1120826.1 | O4: =N4/D4 -> 1.7243478 | P4: =N4*5% -> 56041.305
B5: 2 | C5: 赵星火 | D5: 650000 | E5: 20000 | F5: =D5+E5 -> 670000 | G5: =GETPIVOTDATA("学费",签约单明细!$C$2,"签约单录入人","赵星火","项目类别","四六级") -> 117950 | H5: =GETPIVOTDATA("学费",签约单明细!$C$2,"签约单录入人","赵星火","项目类别","网课") -> 35003.13 | I5: =GETPIVOTDATA("学费",签约单明细!$C$2,"签约单录入人","赵星火","项目类别","无忧") -> 391300 | J5: =GETPIVOTDATA("学费",签约单明细!$C$2,"签约单录入人","赵星火","项目类别","集训营") -> 103968.15 | K5: =GETPIVOTDATA("学费",签约单明细!$C$2,"签约单录入人","赵星火","项目类别","个性化")+GETPIVOTDATA("学费",签约单明细!$C$2,"签约单录入人","赵星火","项目类别","在职") -> 350544 | L5: =SUM(G5:K5) -> 998765.28 | M5: =退费明细!AO36 -> 26100.45 | N5: =L5-M5 -> 972664.83 | O5: =N5/D5 -> 1.4964074 | P5: =N5*5% -> 48633.241
B6: 3 | C6: 李涛 | D6: 325000 | E6: 20000 | F6: =D6+E6 -> 345000 | G6: =GETPIVOTDATA("学费",签约单明细!$C$2,"签约单录入人","李涛","项目类别","四六级") -> 81939 | H6: =GETPIVOTDATA("学费",签约单明细!$C$2,"签约单录入人","李涛","项目类别","网课") -> 53229.38 | I6: =GETPIVOTDATA("学费",签约单明细!$C$2,"签约单录入人","李涛","项目类别","无忧") -> 124700 | K6: =GETPIVOTDATA("学费",签约单明细!$C$2,"签约单录入人","李涛","项目类别","个性化") -> 328500 | L6: =SUM(G6:K6) -> 588368.38 | M6: =退费明细!AO5 -> 18540 | N6: =L6-M6 -> 569828.38 | O6: =N6/D6 -> 1.7533181 | P6: =N6*5% -> 28491.419
B7: 合计 | D7: =SUM(D4:D6) -> 1625000 | E7: 60000 | F7: =D7+E7 -> 1685000 | G7: =SUM(G4:G6) -> 253550.1 | H7: =SUM(H4:H6) -> 147587.21 | I7: =SUM(I4:I6) -> 937119.5 | J7: =SUM(J4:J6) -> 175597.05 | K7: =SUM(K4:K6) -> 1263894 | L7: =SUM(L4:L6) -> 2777747.9 | M7: 587442.07 | N7: =SUM(N4:N6) -> 2663319.3 | O7: =N7/D7 -> 1.6389657
E8: 签约占比 | F8: 谭悦 | G8: =G4/$L4 -> 0.045070099 | H8: =H4/$L4 -> 0.049852169 | I8: =I4/$L4 -> 0.35369938 | J8: =J4/$L4 -> 0.060161302 | K8: =K4/$L4 -> 0.49121705 | L8: =L4/$L4 -> 1
F9: 赵星火 | G9: =G5/$L5 -> 0.11809582 | H9: =H5/$L5 -> 0.035046402 | I9: =I5/$L5 -> 0.39178374 | J9: =J5/$L5 -> 0.10409668 | K9: =K5/$L5 -> 0.35097736 | L9: =L5/$L5 -> 1
F10: 李涛 | G10: =G6/$L6 -> 0.13926479 | H10: =H6/$L6 -> 0.090469478 | I10: =I6/$L6 -> 0.21194205 | J10: =J6/$L6 -> 0 | K10: =K6/$L6 -> 0.55832368 | L10: =L6/$L6 -> 1

Sheet 签约单明细
C2: 求和项:学费 | D2: 项目类别
C3: 签约单录入人 | D3: 个性化 | E3: 集训营 | F3: 四六级 | G3: 网课 | H3: 无忧 | I3: 在职 | J3: 总计
C4: 李涛 | D4: 328500 | F4: 81939 | G4: 53229.38 | H4: 124700 | J4: 588368.38
C5: 谭悦 | D5: 584850 | E5: 71628.9 | F5: 53661.1 | G5: 59354.7 | H5: 421119.5 | J5: 1190614.2
C6: 赵星火 | D6: 343800 | E6: 103968.15 | F6: 117950 | G6: 35003.13 | H6: 391300 | I6: 6744 | J6: 998765.28
C7: 总计 | D7: 1257150 | E7: 175597.05 | F7: 253550.1 | G7: 147587.21 | H7: 937119.5 | I7: 6744 | J7: 2777747.9
A10: 序号 | B10: 学校 | C10: 部门 | D10: 资源姓名 | E10: 资源ID | F10: 资源录入人 | G10: 资源录入时间 | H10: 资源描述 | I10: 市场活动 | J10: 资源年级 | K10: 分配顾问/TMK | L10: 一级获取渠道 | M10: 二级获取渠道 | N10: 转介绍人 | O10: TMK激活人 | P10: TMK激活处理时间 | Q10: 工单姓名 | R10: 跟进顾问 | S10: 工单ID | T10: 工单类型 | U10: 工单录入时间 | V10: 工单等级 | W10: 咨询课程 | X10: 工单年级 | Y10: 学校 | Z10: 院系 | AA10: 专业 | AB10: 签约学生姓名 | AC10: 签约单ID | AD10: 签约单录入人 | AE10: 签约单录入时间 | AF10: 签约单更新人 | AG10: 签约单更新时间 | AH10: 项目类别 | AI10: 班号 | AJ10: 班级名称 | AK10: 面询表类型 | AL10: 订金 | AM10: 学费 | AN10: 续费类型 | AO10: 推荐人 | AP10: 类型 | AQ10: 是否交接 | AR10: 操作人编号 | AS10: 学员号 | AT10: 听课证号 | AU10: 报班日期 | AV10: 学员状态 | AW10: 回访记录 | AX10: 新老生类型 | AY10: 退费金额 | AZ10: 退费日期 | BA10: 课程类型 | BB10: 客户ID | BC10: 是否新东方在线签约 | BD10: 考季 | BE10: 报名产品 | BF10: 报名科目 | BG10: 意向报考专业 | BH10: 学校班型/类型 | BI10: 是否关联协议 | BJ10: 特殊备注 | BK10: 产品品类 | BL10: 业务类型 | BM10: 签约列表在线学员ID | BN10: 大学生源类型 | BO10: 资源来源
A11: 157 | B11: 北京大学部 | C11: 国内大学部 | D11: 白宗翰 | E11: 131188287 | F11: 王天义 | G11: 2025-10-18 10:23:18 | H11: 续费原因：续费专业课 12h；该学生为保护期内续费，原顾问：国内大学部-谭悦(tanyue9@xdf.cn) | J11: 大四 | K11: 谭悦 | L11: 转介绍 | M11: 学管续费推荐 | N11: 王天义wangtianyi56@xdf.cn | Q11: 白宗翰 | R11: 谭悦 | S11: 30429586 | T11: 续费工单 | U11: 2025-10-18 10:38 | V11: A（六个月内有报课意向工单） | W11: 考研专业课 | X11: 大四 | Y11: 首都师范大学 | Z11: 物理系 | AA11: 物理学 | AB11: 白宗翰 | AC11: 5566241 | AD11: 谭悦 | AE11: 2025-10-18 11:40 | AF11: 谭悦 | AG11: 2025-10-18 11:43 | AH11: 个性化 | AI11: LP1760758837490 | AJ11: 985院校升级费（26考季/12小时） | AK11: 国内考试 | AM11: 1200 | AO11: 王天义 | AP11: 续班 | AQ11: 已交接 | AS11: BJWY9470173972 | AU11: 2025-10-18 | AW11: 回访人：谭悦，回访时间：2025-10-18 10:38，回访内容：1；|回访人：谭悦，回访时间：2025-10-18 10:41，回访内容：系统自动签约；|回访人：谭悦，回访时间：2025-10-18 11:39，回访内容：谭悦进行了退单操作!(本条回访记录由系统自动记录)；|回访人：谭悦，回访时间：2025-10-18 11:40，回访内容：系统自动签约 | BB11: 85872093 | BC11: 否 | BD11: 26考季 | BE11: 考研专业课150 | BF11: 专业课150 | BG11: 其他 | BH11: 国内高校-双一流(非985/211) | BI11: 是 | BN11: 本地人本地大学(常规) | BO11: 学管续费推荐
A12: 158 | B12: 北京大学部 | C12: 国内大学部 | D12: 白宗翰 | E12: 131188287 | F12: 王天义 | G12: 2025-10-18 10:23:18 | H12: 续费原因：续费专业课 12h；该学生为保护期内续费，原顾问：国内大学部-谭悦(tanyue9@xdf.cn) | J12: 大四 | K12: 谭悦 | L12: 转介绍 | M12: 学管续费推荐 | N12: 王天义wangtianyi56@xdf.cn | Q12: 白宗翰 | R12: 谭悦 | S12: 30429586 | T12: 续费工单 | U12: 2025-10-18 10:38 | V12: A（六个月内有报课意向工单） | W12: 考研专业课 | X12: 大四 | Y12: 首都师范大学 | Z12: 物理系 | AA12: 物理学 | AB12: 白宗翰 | AC12: 5566241 | AD12: 谭悦 | AE12: 2025-10-18 11:40 | AF12: 谭悦 | AG12: 2025-10-18 11:43 | AH12: 个性化 | AI12: LP1760755301231 | AJ12: 考研专业课一对一伴学班（12h/26考季） | AK12: 国内考试 | AM12: 7200 | AO12: 王天义 | AP12: 续班 | AQ12: 已交接 | AS12: BJWY9470173972 | AU12: 2025-10-18 | AW12: 回访人：谭悦，回访时间：2025-10-18 10:38，回访内容：1；|回访人：谭悦，回访时间：2025-10-18 10:41，回访内容：系统自动签约；|回访人：谭悦，回访时间：2025-10-18 11:39，回访内容：谭悦进行了退单操作!(本条回访记录由系统自动记录)；|回访人：谭悦，回访时间：2025-10-18 11:40，回访内容：系统自动签约 | BB12: 85872093 | BC12: 否 | BD12: 26考季 | BE12: 考研专业课150 | BF12: 专业课150 | BG12: 其他 | BH12: 国内高校-双一流(非985/211) | BI12: 是 | BN12: 本地人本地大学(常规) | BO12: 学管续费推荐
A13: 211 | B13: 北京大学部 | C13: 国内大学部 | D13: 天生有两个口的白羊 | E13: 130137792 | F13: 崔佳慧 | G13: 2025-10-10 19:12:28 | H13: 渠道录入来源：小红书 事件名称：私信留资 小红书账号id：659bd1020000000022000003 小红书账号名称：北京新东方考研一对一咨询 广告投放账号名称：北京新东方考研一对一咨询 活动所属学校id：108 活动所属学校名称：北京大学事业部 统一活动id：2822543 统一活动名称：北京大学事业部25年10月小红书专业号投放 渠道名称：网络营销-小红书-专业号投放 线索创建人邮箱：cuijiahui2@xdf.cn 资源跟进人邮箱：cuijiahui2@xdf.cn 备注：用户地区是【北京市北京市】，在【2025-10-10 19:10:23】留资，私信通线索标签为【留客资】，来源于【北京新东方考研一对一咨询】投放账户，意向项目是【考研/考博】，留资笔记是【】，备注【-】 | I13: 2026财年第5财月小红书 | J13: 未知 | K13: 谭悦 | L13: 线上运营-小红书 | M13: 小红书 | Q13: 白宗翰 | R13: 谭悦 | S13: 30394190 | T13: 正常工单 | U13: 2025-10-10 19:58 | V13: A（六个月内有报课意向工单） | W13: 考研VIP | X13: 大四 | Y13: 首都师范大学 | Z13: 物理系 | AA13: 物理学 | AB13: 白宗翰 | AC13: 5673871 | AD13: 谭悦 | AE13: 2025-10-11 12:57 | AF13: 谭悦 | AG13: 2025-10-11 13:03 | AH13: 个性化 | AI13: LP1760158666473 | AJ13: 考研一对一伴学班（26考季） | AK13: 国内考试 | AM13: 63200 | AP13: 新签 | AQ13: 已交接 | AS13: BJWY9470173972 | AU13: 2025-10-11 | AW13: 回访人：谭悦，回访时间：2025-10-10 19:58，回访内容：一对一辅导，首师大 今年考 ，想学数学，孩子心气高，想考985；|回访人：谭悦，回访时间：2025-10-11 12:57，回访内容：系统自动签约 | BB13: 85872093 | BC13: 否 | BD13: 26考季 | BE13: VIP - 伴学 | BF13: 英语,政治,数学 | BG13: 其他 | BH13: 国内高校-双一流(非985/211) | BI13: 是 | BN13: 本地人本地大学(常规) | BO13: 小红书
A14: 201 | B14: 北京大学部 | C14: 国内大学部 | D14: jxm | E14: 129186213 | F14: 王朝群 | G14: 2025-09-27 15:07:14 | H14: 【王朝群】咨询考研政治线下课程 | J14: 大四 | K14: 赵星火 | L14: 线上运营-小红书 | M14: 小红书KOS | Q14: 包淳鑫 | R14: 赵星火 | S14: 30259600 | T14: 正常工单 | U14: 2025-09-27 17:58 | V14: A（六个月内有报课意向工单） | W14: 考研无忧计划 | X14: 大四 | Y14: 北京化工大学 | Z14: 信息科学与技术学院 | AA14: 人工智能 | AB14: 包淳鑫 | AC14: 5648748 | AD14: 赵星火 | AE14: 2025-10-12 20:20 | AF14: 赵星火 | AG14: 2025-10-12 20:20 | AH14: 无忧 | AI14: GWYP26001 | AJ14: 考研政治无忧计划考前突破班（26考研/刷题带背） | AK14: 国内考试 | AM14: 9800 | AP14: 新签 | AQ14: 已交接 | AR14: WebReg | AS14: XDF8949218256 | AT14: GWYP260010070 | AU14: 2025-10-12 | AW14: 回访人：赵星火，回访时间：2025-10-04 22:27，回访内容：假期休息上班回访；|回访人：赵星火，回访时间：2025-10-06 16:45，回访内容：表示孩子要等孩子回京之后校区沟通下继续维护中；|回访人：赵星火，回访时间：2025-10-09 17:03，回访内容：跟进学生情况中继续维护中看下沟通中；|回访人：赵星火，回访时间：2025-10-11 18:13，回访内容：表示回京之后联系这边还没确定跟进中；|回访人：赵星火，回访时间：2025-10-12 20:20，回访内容：1 | BB14: 85516485 | BC14: 否 | BD14: 26考季 | BE14: 无忧计划-蜂鸟 | BF14: 政治 | BG14: 其他 | BH14: 国内高校-211 | BI14: 是 | BL14: 报名 | BN14: 本地人本地大学(常规) | BO14: 市场
A15: 21 | B15: 北京大学部 | C15: 国内大学部 | D15: 北京市5538 | E15: 130489672 | F15: 杨俊42(国内) | G15: 2025-10-13 12:51:26 | H15: 渠道录入来源：新东方官网M站-客服 意向城市：北京访客省/城市：北京市 访客静态ID：01000000034659033093629490515538 接待分组ID：70455 搜索引擎： 搜索词： 关键词： 设备类型：phone 访客IP：39.155.141.180 对话详细内容：AI-Lbo0rDBXCyBY 2025-10-13 12:48:59 您好同学,欢迎访问北京新东方考研四六级中心. 考研线下课程26/27考季【考研全年集训营】【考研半年集训营】【考研全科线下走读班】【考研寒/暑假集训营】【考研一对一】【考研专业课】【四/六级课程】，热门课程火热报名中,咨询即可领取专享优惠。 **【考研全年集训营】=ff761f# **【考研半年集训营】=ff6b6b# **【考研全科线下走读班】=ffc158# **【考研寒/暑假集训营】=ffc158# **【考研一对一】=ff761f# **【考研专业课】=ff6caa# **【四/六级课程】=ff6caa# **【考研冲刺班】=60e27e# AI-Lbo0rDBXCyBY 2025-10-13 12:49:02 您是想咨询【线下课程】【线上课程】【考研规划】还是【在职考研】呢？**【线下课程】# **【线上课程】#**【考研规划】#**【在职考研】# 01000000034659033093629490515538 2025-10-13 12:49:04 catti二级 AI-Lbo0rDBXCyBY 2025-10-13 12:49:08 同学，你现在是在校还是在职呢？ 01000000034659033093629490515538 2025-10-13 12:49:08 【线下课程】 01000000034659033093629490515538 2025-10-13 12:49:11 在校 AI-Lbo0rDBXCyBY 2025-10-13 12:49:11 具体是想报考什么学校和专业呢？ AI-Lbo0rDBXCyBY 2025-10-13 12:49:15 好的，我这边安排专业老师给您回电，详细沟通一下，请问您的电话是多少呢？ 01000000034659033093629490515538 2025-10-13 12:49:24 15830975316 AI-Lbo0rDBXCyBY 2025-10-13 12:49:28 好的，确认一下你的号码是否正确呢~ 01000000034659033093629490515538 2025-10-13 12:49:33 正确 AI-Lbo0rDBXCyBY 2025-10-13 12:49:37 同学怎么称呼呢？ 01000000034659033093629490515538 2025-10-13 12:49:44 韩 AI-Lbo0rDBXCyBY 2025-10-13 12:49:47 这边马上安排顾问老师联系您，预计半个小时左右给您回电请注意接听~ 来源页：https://bj.xdf.cn/ 备注： | I15: 2026财年第5财月易聊新东方官网M站 | K15: 徐树萌 | L15: 新东方官网 | M15: 新东方官网M站 | O15: 徐树萌 | P15: 2025-10-13 13:13:39 | Q15: 北京市5538 | R15: 赵星火 | S15: 30379360 | T15: 正常工单 | U15: 2025-10-13 15:34 | V15: A（六个月内有报课意向工单） | W15: 英语学习 | X15: 在职 | Y15: 北京物资学院 | Z15: 法学院 | AA15: 法学 | AB15: 北京市5538 | AC15: 5680022 | AD15: 赵星火 | AE15: 2025-10-20 20:24 | AF15: 赵星火 | AG15: 2025-10-20 20:28 | AH15: 网课 | AI15: 97809271276 | AJ15: 【26年考】CATTI二级笔译全程班 | AK15: 国内考试 | AM15: 2934.13 | AP15: 新签 | AQ15: 无须交接 | AU15: 2025-10-20 | AW15: 回访人：赵星火，回访时间：2025-10-13 15:34，回访内容：看下是考虑线下的，表示没有，然后看下这个线上介绍；|回访人：赵星火，回访时间：2025-10-16 15:02，回访内容：联系不上学生情况这边继续维我和中，看下课程考虑；|回访人：赵星火，回访时间：2025-10-19 17:31，回访内容：表示是不是有黄培辰老师，其次没有纸质版教材在就是具体价格；|回访人：赵星火，回访时间：2025-10-20 20:24，回访内容：系统自动签约 | BA15: 长期班 | BB15: 86005371 | BC15: 是 | BH15: 国内高校-双非 | BI15: 否 | BM15: 109418058 | BO15: 易聊在线咨询
A16: 122 | B16: 北京大学部 | C16: 国内大学部 | D16: 蔡哲 | E16: 131883958 | F16: 陈晶 | G16: 2025-10-22 14:30:22 | H16: 续费原因：续费课时，个性化谭悦；该学生为保护期内续费，原顾问：国内大学部-谭悦(tanyue9@xdf.cn) | J16: 大学已毕业 | K16: 谭悦 | L16: 转介绍 | M16: 学管续费推荐 | N16: 陈晶chenjing171@xdf.cn | Q16: 蔡哲 | R16: 谭悦 | S16: 30538237 | T16: 续费工单 | U16: 2025-10-22 15:16 | V16: A（六个月内有报课意向工单） | W16: 考研VIP | X16: 大学已毕业 | Y16: 北京邮电大学 | Z16: 信息与通信工程学院 | AA16: 电子信息工程 | AB16: 蔡哲 | AC16: 5567368 | AD16: 谭悦 | AE16: 2025-10-22 15:59 | AF16: 谭悦 | AG16: 2025-10-22 16:55 | AH16: 个性化 | AI16: LP17611199461015 | AJ16: 考研一对一伴学班（26考季） | AK16: 国内考试 | AM16: 29900 | AO16: 陈晶 | AP16: 续班 | AQ16: 已交接 | AS16: BJWY0874092650 | AU16: 2025-10-22 | AW16: 回访人：谭悦，回访时间：2025-10-22 15:16，回访内容：跟进一对一 ；|回访人：谭悦，回访时间：2025-10-22 15:59，回访内容：系统自动签约 | BB16: 33569231 | BC16: 否 | BD16: 26考季 | BE16: VIP - 伴学 | BF16: 英语,数学 | BG16: 其他 | BH16: 国内高校-211 | BI16: 是 | BO16: 学管续费推荐
A17: 129 | B17: 北京大学部 | C17: 国内大学部 | E17: 125413803 | G17: 2025-08-29 10:27:41 | H17: 续费原因：学生咨询续费一对一价格，老师建议续费 20h；该学生为保护期内续费，原顾问：国内大学部-赵星火(zhaoxinghuo@xdf.cn) | J17: 大学已毕业 | K17: 赵星火 | L17: 转介绍 | M17: 学管续费推荐 | Q17: 曹泽恒 | R17: 赵星火 | S17: 30470659 | T17: 续费工单 | U17: 2025-10-19 18:09 | V17: A（六个月内有报课意向工单） | W17: 考研VIP | X17: 大学已毕业 | Y17: 北京工业大学 | Z17: 城市建设学部 | AA17: 土木工程 | AB17: 曹泽恒 | AC17: 5679654 | AD17: 赵星火 | AE17: 2025-10-20 09:53 | AF17: 赵星火 | AG17: 2025-10-20 11:12 | AH17: 集训营 | AI17: LP176092519905 | AJ17: 26考研一对一伴学（集训） | AK17: 国内考试 | AM17: 16000 | AP17: 续班 | AQ17: 已交接 | AS17: BJWY4116308585 | AU17: 2025-10-20 | AW17: 回访人：赵星火，回访时间：2025-10-19 18:09，回访内容：1；|回访人：赵星火，回访时间：2025-10-20 09:53，回访内容：系统自动签约 | BB17: 33140368 | BC17: 否 | BD17: 26考季 | BE17: VIP - 伴学 | BF17: 英语 | BH17: 国内高校-211 | BI17: 是
A18: 42 | B18: 北京大学部 | C18: 国内大学部 | D18: 家长 | E18: 129593843 | F18: 吕猛 | G18: 2025-10-02 13:08:01 | H18: 咨询英语一对一，尽快联系 | J18: 大四 | K18: 谭悦 | L18: 线上运营-本地生活平台 | M18: 阿里本地通 | Q18: 曾行健 | R18: 谭悦 | S18: 30336781 | T18: 续费工单 | U18: 2025-10-02 14:36 | V18: A（六个月内有报课意向工单） | W18: 考研VIP | X18: 大四 | Y18: 大连海事大学 | Z18: 法学院 | AA18: 法学（海商法） | AB18: 曾行健 | AC18: 5570137 | AD18: 谭悦 | AE18: 2025-10-30 16:17 | AF18: 谭悦 | AG18: 2025-10-30 16:18 | AH18: 个性化 | AI18: LP175954480098 | AJ18: 考研一对一伴学班（定制/26考季） | AK18: 国内考试 | AM18: 0 | AP18: 新签 | AQ18: 无须交接 | AS18: BJWY3312305782 | AU18: 2025-10-04 | AW18: 回访人：谭悦，回访时间：2025-10-02 14:36，回访内容：加微信，建群，跟进中一对一英语 ；|回访人：谭悦，回访时间：2025-10-19 15:05，回访内容：谭悦进行了退单操作!(本条回访记录由系统自动记录)；|回访人：谭悦，回访时间：2025-10-19 16:39，回访内容：学生退费了， 看看考试成绩吧，跟进二战 ；|回访人：谭悦，回访时间：2025-10-26 13:55，回访内容：跟进集训营，还没回复 ；|回访人：谭悦，回访时间：2025-10-30 16:17，回访内容：1 | BB18: 85687580 | BC18: 否 | BD18: 26考季 | BE18: VIP - 伴学 | BF18: 英语,政治 | BG18: 其他 | BH18: 国内高校-211 | BI18: 否 | BN18: 外地人外地大学(常规) | BO18: 客服
A19: 53 | B19: 北京大学部 | C19: 国内大学部 | E19: 132605684 | G19: 2025-10-28 20:22:28 | H19: 【小红书资源】 咨询考研一对一，IP地址在北京 | J19: 大三 | K19: 李涛 | L19: 线上运营-小红书 | M19: 小红书 | Q19: 陈靓怡 | R19: 李涛 | S19: 30642337 | T19: 续费工单 | U19: 2025-10-31 20:48 | V19: A（六个月内有报课意向工单） | W19: 考研VIP | X19: 大三 | Y19: 北京信息科技大学 | Z19: 计算机学院 | AA19: 计算机科学与技术 | AB19: 陈靓怡 | AC19: 5663041 | AD19: 李涛 | AE19: 2025-10-31 20:51 | AF19: 李涛 | AG19: 2025-10-31 21:44 | AH19: 无忧 | AI19: WYE27047 | AJ19: 考研英语无忧计划（27考研/英一冲刺） | AK19: 国内考试 | AM19: 5137.6 | AP19: 新签 | AQ19: 已交接 | AR19: BJWY22035556hl | AS19: BJWY7173848231 | AT19: WYE270470043 | AU19: 2025-10-31 | AW19: 回访人：李涛，回访时间：2025-10-31 20:48，回访内容：续费；|回访人：李涛，回访时间：2025-10-31 20:51，回访内容：系统自动签约 | BB19: 86751591 | BC19: 否 | BD19: 27考季 | BE19: VIP - 伴学 | BF19: 英语,政治,数学,计算机 | BH19: 国内高校-双非 | BI19: 是 | BL19: 报名 | BN19: 本地人本地大学(常规)
A20: 54 | B20: 北京大学部 | C20: 国内大学部 | E20: 132605684 | G20: 2025-10-28 20:22:28 | H20: 【小红书资源】 咨询考研一对一，IP地址在北京 | J20: 大三 | K20: 李涛 | L20: 线上运营-小红书 | M20: 小红书 | Q20: 陈靓怡 | R20: 李涛 | S20: 30642337 | T20: 续费工单 | U20: 2025-10-31 20:48 | V20: A（六个月内有报课意向工单） | W20: 考研VIP | X20: 大三 | Y20: 北京信息科技大学 | Z20: 计算机学院 | AA20: 计算机科学与技术 | AB20: 陈靓怡 | AC20: 5663041 | AD20: 李涛 | AE20: 2025-10-31 20:51 | AF20: 李涛 | AG20: 2025-10-31 21:44 | AH20: 无忧 | AI20: WYP27034 | AJ20: 考研政治无忧计划（27考研/基础） | AK20: 国内考试 | AM20: 6092.2 | AP20: 新签 | AQ20: 已交接 | AR20: BJWY22035556hl | AS20: BJWY7173848231 | AT20: WYP270340039 | AU20: 2025-10-31 | AW20: 回访人：李涛，回访时间：2025-10-31 20:48，回访内容：续费；|回访人：李涛，回访时间：2025-10-31 20:51，回访内容：系统自动签约 | BB20: 86751591 | BC20: 否 | BD20: 27考季 | BE20: VIP - 伴学 | BF20: 英语,政治,数学,计算机 | BH20: 国内高校-双非 | BI20: 是 | BL20: 报名 | BN20: 本地人本地大学(常规)
A21: 55 | B21: 北京大学部 | C21: 国内大学部 | E21: 132605684 | G21: 2025-10-28 20:22:28 | H21: 【小红书资源】 咨询考研一对一，IP地址在北京 | J21: 大三 | K21: 李涛 | L21: 线上运营-小红书 | M21: 小红书 | Q21: 陈靓怡 | R21: 李涛 | S21: 30642337 | T21: 续费工单 | U21: 2025-10-31 20:48 | V21: A（六个月内有报课意向工单） | W21: 考研VIP | X21: 大三 | Y21: 北京信息科技大学 | Z21: 计算机学院 | AA21: 计算机科学与技术 | AB21: 陈靓怡 | AC21: 5663041 | AD21: 李涛 | AE21: 2025-10-31 20:51 | AF21: 李涛 | AG21: 2025-10-31 21:44 | AH21: 无忧 | AI21: WYP27036 | AJ21: 考研政治无忧计划（27考研/冲刺） | AK21: 国内考试 | AM21: 4183.8 | AP21: 新签 | AQ21: 已交接 | AR21: BJWY22035556hl | AS21: BJWY7173848231 | AT21: WYP270360039 | AU21: 2025-10-31 | AW21: 回访人：李涛，回访时间：2025-10-31 20:48，回访内容：续费；|回访人：李涛，回访时间：2025-10-31 20:51，回访内容：系统自动签约 | BB21: 86751591 | BC21: 否 | BD21: 27考季 | BE21: VIP - 伴学 | BF21: 英语,政治,数学,计算机 | BH21: 国内高校-双非 | BI21: 是 | BL21: 报名 | BN21: 本地人本地大学(常规)
A22: 56 | B22: 北京大学部 | C22: 国内大学部 | E22: 132605684 | G22: 2025-10-28 20:22:28 | H22: 【小红书资源】 咨询考研一对一，IP地址在北京 | J22: 大三 | K22: 李涛 | L22: 线上运营-小红书 | M22: 小红书 | Q22: 陈靓怡 | R22: 李涛 | S22: 30642337 | T22: 续费工单 | U22: 2025-10-31 20:48 | V22: A（六个月内有报课意向工单） | W22: 考研VIP | X22: 大三 | Y22: 北京信息科技大学 | Z22: 计算机学院 | AA22: 计算机科学与技术 | AB22: 陈靓怡 | AC22: 5663041 | AD22: 李涛 | AE22: 2025-10-31 20:51 | AF22: 李涛 | AG22: 2025-10-31 21:44 | AH22: 无忧 | AI22: WYP27035 | AJ22: 考研政治无忧计划（27考研/强化） | AK22: 国内考试 | AM22: 3523.2 | AP22: 新签 | AQ22: 已交接 | AR22: BJWY22035556hl | AS22: BJWY7173848231 | AT22: WYP270350039 | AU22: 2025-10-31 | AW22: 回访人：李涛，回访时间：2025-10-31 20:48，回访内容：续费；|回访人：李涛，回访时间：2025-10-31 20:51，回访内容：系统自动签约 | BB22: 86751591 | BC22: 否 | BD22: 27考季 | BE22: VIP - 伴学 | BF22: 英语,政治,数学,计算机 | BH22: 国内高校-双非 | BI22: 是 | BL22: 报名 | BN22: 本地人本地大学(常规)
A23: 57 | B23: 北京大学部 | C23: 国内大学部 | E23: 132605684 | G23: 2025-10-28 20:22:28 | H23: 【小红书资源】 咨询考研一对一，IP地址在北京 | J23: 大三 | K23: 李涛 | L23: 线上运营-小红书 | M23: 小红书 | Q23: 陈靓怡 | R23: 李涛 | S23: 30642337 | T23: 续费工单 | U23: 2025-10-31 20:48 | V23: A（六个月内有报课意向工单） | W23: 考研VIP | X23: 大三 | Y23: 北京信息科技大学 | Z23: 计算机学院 | AA23: 计算机科学与技术 | AB23: 陈靓怡 | AC23: 5663041 | AD23: 李涛 | AE23: 2025-10-31 20:51 | AF23: 李涛 | AG23: 2025-10-31 21:44 | AH23: 无忧 | AI23: WYE27046 | AJ23: 考研英语无忧计划（27考研/英一强化） | AK23: 国内考试 | AM23: 6165.6 | AP23: 新签 | AQ23: 已交接 | AR23: BJWY22035556hl | AS23: BJWY7173848231 | AT23: WYE270460043 | AU23: 2025-10-31 | AW23: 回访人：李涛，回访时间：2025-10-31 20:48，回访内容：续费；|回访人：李涛，回访时间：2025-10-31 20:51，回访内容：系统自动签约 | BB23: 86751591 | BC23: 否 | BD23: 27考季 | BE23: VIP - 伴学 | BF23: 英语,政治,数学,计算机 | BH23: 国内高校-双非 | BI23: 是 | BL23: 报名 | BN23: 本地人本地大学(常规)
A24: 58 | B24: 北京大学部 | C24: 国内大学部 | E24: 132605684 | G24: 2025-10-28 20:22:28 | H24: 【小红书资源】 咨询考研一对一，IP地址在北京 | J24: 大三 | K24: 李涛 | L24: 线上运营-小红书 | M24: 小红书 | Q24: 陈靓怡 | R24: 李涛 | S24: 30642337 | T24: 续费工单 | U24: 2025-10-31 20:48 | V24: A（六个月内有报课意向工单） | W24: 考研VIP | X24: 大三 | Y24: 北京信息科技大学 | Z24: 计算机学院 | AA24: 计算机科学与技术 | AB24: 陈靓怡 | AC24: 5663041 | AD24: 李涛 | AE24: 2025-10-31 20:51 | AF24: 李涛 | AG24: 2025-10-31 21:44 | AH24: 无忧 | AI24: WYE27048 | AJ24: 考研英语无忧计划（27考研/基础） | AK24: 国内考试 | AM24: 4697.6 | AP24: 新签 | AQ24: 已交接 | AR24: BJWY22035556hl | AS24: BJWY7173848231 | AT24: WYE270480013 | AU24: 2025-10-31 | AW24: 回访人：李涛，回访时间：2025-10-31 20:48，回访内容：续费；|回访人：李涛，回访时间：2025-10-31 20:51，回访内容：系统自动签约 | BB24: 86751591 | BC24: 否 | BD24: 27考季 | BE24: VIP - 伴学 | BF24: 英语,政治,数学,计算机 | BH24: 国内高校-双非 | BI24: 是 | BL24: 报名 | BN24: 本地人本地大学(常规)
A25: 59 | B25: 北京大学部 | C25: 国内大学部 | E25: 132605684 | G25: 2025-10-28 20:22:28 | H25: 【小红书资源】 咨询考研一对一，IP地址在北京 | J25: 大三 | K25: 李涛 | L25: 线上运营-小红书 | M25: 小红书 | Q25: 陈靓怡 | R25: 李涛 | S25: 30642337 | T25: 续费工单 | U25: 2025-10-31 20:48 | V25: A（六个月内有报课意向工单） | W25: 考研VIP | X25: 大三 | Y25: 北京信息科技大学 | Z25: 计算机学院 | AA25: 计算机科学与技术 | AB25: 陈靓怡 | AC25: 5663041 | AD25: 李涛 | AE25: 2025-10-31 20:51 | AF25: 李涛 | AG25: 2025-10-31 21:44 | AH25: 四六级 | AI25: WYF25046 | AJ25: 四级无忧冲刺 | AK25: 国内考试 | AM25: 3180 | AP25: 新签 | AQ25: 已交接 | AR25: BJWY2201F8pC6h | AS25: BJWY7173848231 | AT25: WYF250460015 | AU25: 2025-10-31 | AW25: 回访人：李涛，回访时间：2025-10-31 20:48，回访内容：续费；|回访人：李涛，回访时间：2025-10-31 20:51，回访内容：系统自动签约 | BB25: 86751591 | BC25: 否 | BD25: 27考季 | BE25: VIP - 伴学 | BF25: 英语,政治,数学,计算机 | BH25: 国内高校-双非 | BI25: 是 | BL25: 报名 | BN25: 本地人本地大学(常规)
A26: 60 | B26: 北京大学部 | C26: 国内大学部 | E26: 132605684 | G26: 2025-10-28 20:22:28 | H26: 【小红书资源】 咨询考研一对一，IP地址在北京 | J26: 大三 | K26: 李涛 | L26: 线上运营-小红书 | M26: 小红书 | Q26: 陈靓怡 | R26: 李涛 | S26: 30642337 | T26: 续费工单 | U26: 2025-10-31 20:48 | V26: A（六个月内有报课意向工单） | W26: 考研VIP | X26: 大三 | Y26: 北京信息科技大学 | Z26: 计算机学院 | AA26: 计算机科学与技术 | AB26: 陈靓怡 | AC26: 5663041 | AD26: 李涛 | AE26: 2025-10-31 20:51 | AF26: 李涛 | AG26: 2025-10-31 21:44 | AH26: 无忧 | AI26: LP17619151162350 | AJ26: 27考研一对一伴学(无忧) | AK26: 国内考试 | AM26: 80000 | AP26: 新签 | AQ26: 已交接 | AR26: BJWY22035556hl | AS26: BJWY7173848231 | AU26: 2025-10-31 | AW26: 回访人：李涛，回访时间：2025-10-31 20:48，回访内容：续费；|回访人：李涛，回访时间：2025-10-31 20:51，回访内容：系统自动签约 | BB26: 86751591 | BC26: 否 | BD26: 27考季 | BE26: VIP - 伴学 | BF26: 英语,政治,数学,计算机 | BH26: 国内高校-双非 | BI26: 是 | BN26: 本地人本地大学(常规)
A27: 104 | B27: 北京大学部 | C27: 国内大学部 | D27: 许昌苦瓜 | E27: 129687286 | F27: 张亚男 | G27: 2025-10-04 11:26:07 | H27: 渠道录入来源：集团百度投放-基木鱼 账户名：baidu-大学-总部-A22KA00038 线索ID：251004481825693103 线索时间：2025-10-04 11:25:47 页面名称：新东方考研集训营 姓名：许昌苦瓜 城市：北京 IP：2408:8207:7824:a5d0:718f:6e6c:26a9:cc7b 来源页：https://aisite.wejianzhan.com/site/wjzswa2z/a8dbbce4-c4ec-438e-922c-14344008843f?utm_source=jituan_searchengine_douyin__M_douyin_PP&utm_medium=CPD&utm_campaign=jituanpinzhuanjuheye&utm_term=daxuekaoshi_banwei_1&wid=a842d1130c6e4394afaede8ccb14d579_0_0 | I27: 2026财年第5财月集团百度投放-基木鱼 | K27: 谭悦 | L27: 线上运营-投放 | M27: 集团-抖音品专 | Q27: 陈立峰 | R27: 谭悦 | S27: 30355465 | T27: 正常工单 | U27: 2025-10-19 18:27 | V27: A（六个月内有报课意向工单） | W27: 考研专业课,考研无忧计划 | X27: 大三 | Y27: 北京工业大学 | Z27: 信息学部 | AA27: 通信工程 | AB27: 陈立峰 | AC27: 5681454 | AD27: 谭悦 | AE27: 2025-10-23 10:54 | AF27: 谭悦 | AG27: 2025-10-23 10:55 | AH27: 无忧 | AI27: WYE27101 | AJ27: 考研英语无忧计划啄木鸟（27考研/基础） | AK27: 国内考试 | AM27: 5300 | AP27: 新签 | AQ27: 已交接 | AR27: BJWY2201F8pC6h | AS27: BJWY5487120372 | AT27: WYE271010007 | AU27: 2025-10-23 | AW27: 回访人：谭悦，回访时间：2025-10-17 18:42，回访内容：长期不回我消息 ；|回访人：陈伟钰，回访时间：2025-10-19 18:27，回访内容：陈伟钰恢复工单, 系统自动生成回访记录!；|回访人：谭悦，回访时间：2025-10-19 18:43，回访内容：面谈过了， 跟进中，走读班 ；|回访人：谭悦，回访时间：2025-10-22 18:03，回访内容：已出订单；|回访人：谭悦，回访时间：2025-10-23 10:54，回访内容：1 | BB27: 43431314 | BC27: 否 | BD27: 27考季 | BE27: 考研专业课150,无忧计划-啄木鸟 | BF27: 专业课150,英语,政治,数学 | BG27: 其他 | BH27: 国内高校-211 | BI27: 是 | BL27: 报名 | BN27: 本地人本地大学(常规) | BO27: 集团百度投放-基木鱼
A28: 105 | B28: 北京大学部 | C28: 国内大学部 | D28: 许昌苦瓜 | E28: 129687286 | F28: 张亚男 | G28: 2025-10-04 11:26:07 | H28: 渠道录入来源：集团百度投放-基木鱼 账户名：baidu-大学-总部-A22KA00038 线索ID：251004481825693103 线索时间：2025-10-04 11:25:47 页面名称：新东方考研集训营 姓名：许昌苦瓜 城市：北京 IP：2408:8207:7824:a5d0:718f:6e6c:26a9:cc7b 来源页：https://aisite.wejianzhan.com/site/wjzswa2z/a8dbbce4-c4ec-438e-922c-14344008843f?utm_source=jituan_searchengine_douyin__M_douyin_PP&utm_medium=CPD&utm_campaign=jituanpinzhuanjuheye&utm_term=daxuekaoshi_banwei_1&wid=a842d1130c6e4394afaede8ccb14d579_0_0 | I28: 2026财年第5财月集团百度投放-基木鱼 | K28: 谭悦 | L28: 线上运营-投放 | M28: 集团-抖音品专 | Q28: 陈立峰 | R28: 谭悦 | S28: 30355465 | T28: 正常工单 | U28: 2025-10-19 18:27 | V28: A（六个月内有报课意向工单） | W28: 考研专业课,考研无忧计划 | X28: 大三 | Y28: 北京工业大学 | Z28: 信息学部 | AA28: 通信工程 | AB28: 陈立峰 | AC28: 5681454 | AD28: 谭悦 | AE28: 2025-10-23 10:54 | AF28: 谭悦 | AG28: 2025-10-23 10:55 | AH28: 无忧 | AI28: WYM27101 | AJ28: 考研数学无忧计划啄木鸟（27考研/基础） | AK28: 国内考试 | AM28: 4300 | AP28: 新签 | AQ28: 已交接 | AR28: BJWY2201F8pC6h | AS28: BJWY5487120372 | AT28: WYM271010002 | AU28: 2025-10-23 | AW28: 回访人：谭悦，回访时间：2025-10-17 18:42，回访内容：长期不回我消息 ；|回访人：陈伟钰，回访时间：2025-10-19 18:27，回访内容：陈伟钰恢复工单, 系统自动生成回访记录!；|回访人：谭悦，回访时间：2025-10-19 18:43，回访内容：面谈过了， 跟进中，走读班 ；|回访人：谭悦，回访时间：2025-10-22 18:03，回访内容：已出订单；|回访人：谭悦，回访时间：2025-10-23 10:54，回访内容：1 | BB28: 43431314 | BC28: 否 | BD28: 27考季 | BE28: 考研专业课150,无忧计划-啄木鸟 | BF28: 专业课150,英语,政治,数学 | BG28: 其他 | BH28: 国内高校-211 | BI28: 是 | BL28: 报名 | BN28: 本地人本地大学(常规) | BO28: 集团百度投放-基木鱼
A29: 106 | B29: 北京大学部 | C29: 国内大学部 | D29: 许昌苦瓜 | E29: 129687286 | F29: 张亚男 | G29: 2025-10-04 11:26:07 | H29: 渠道录入来源：集团百度投放-基木鱼 账户名：baidu-大学-总部-A22KA00038 线索ID：251004481825693103 线索时间：2025-10-04 11:25:47 页面名称：新东方考研集训营 姓名：许昌苦瓜 城市：北京 IP：2408:8207:7824:a5d0:718f:6e6c:26a9:cc7b 来源页：https://aisite.wejianzhan.com/site/wjzswa2z/a8dbbce4-c4ec-438e-922c-14344008843f?utm_source=jituan_searchengine_douyin__M_douyin_PP&utm_medium=CPD&utm_campaign=jituanpinzhuanjuheye&utm_term=daxuekaoshi_banwei_1&wid=a842d1130c6e4394afaede8ccb14d579_0_0 | I29: 2026财年第5财月集团百度投放-基木鱼 | K29: 谭悦 | L29: 线上运营-投放 | M29: 集团-抖音品专 | Q29: 陈立峰 | R29: 谭悦 | S29: 30355465 | T29: 正常工单 | U29: 2025-10-19 18:27 | V29: A（六个月内有报课意向工单） | W29: 考研专业课,考研无忧计划 | X29: 大三 | Y29: 北京工业大学 | Z29: 信息学部 | AA29: 通信工程 | AB29: 陈立峰 | AC29: 5681454 | AD29: 谭悦 | AE29: 2025-10-23 10:54 | AF29: 谭悦 | AG29: 2025-10-23 10:55 | AH29: 无忧 | AI29: WYM27103 | AJ29: 考研数学无忧计划啄木鸟（27考研/冲刺） | AK29: 国内考试 | AM29: 3900 | AP29: 新签 | AQ29: 已交接 | AR29: BJWY2201F8pC6h | AS29: BJWY5487120372 | AT29: WYM271030002 | AU29: 2025-10-23 | AW29: 回访人：谭悦，回访时间：2025-10-17 18:42，回访内容：长期不回我消息 ；|回访人：陈伟钰，回访时间：2025-10-19 18:27，回访内容：陈伟钰恢复工单, 系统自动生成回访记录!；|回访人：谭悦，回访时间：2025-10-19 18:43，回访内容：面谈过了， 跟进中，走读班 ；|回访人：谭悦，回访时间：2025-10-22 18:03，回访内容：已出订单；|回访人：谭悦，回访时间：2025-10-23 10:54，回访内容：1 | BB29: 43431314 | BC29: 否 | BD29: 27考季 | BE29: 考研专业课150,无忧计划-啄木鸟 | BF29: 专业课150,英语,政治,数学 | BG29: 其他 | BH29: 国内高校-211 | BI29: 是 | BL29: 报名 | BN29: 本地人本地大学(常规) | BO29: 集团百度投放-基木鱼
A30: 107 | B30: 北京大学部 | C30: 国内大学部 | D30: 许昌苦瓜 | E30: 129687286 | F30: 张亚男 | G30: 2025-10-04 11:26:07 | H30: 渠道录入来源：集团百度投放-基木鱼 账户名：baidu-大学-总部-A22KA00038 线索ID：251004481825693103 线索时间：2025-10-04 11:25:47 页面名称：新东方考研集训营 姓名：许昌苦瓜 城市：北京 IP：2408:8207:7824:a5d0:718f:6e6c:26a9:cc7b 来源页：https://aisite.wejianzhan.com/site/wjzswa2z/a8dbbce4-c4ec-438e-922c-14344008843f?utm_source=jituan_searchengine_douyin__M_douyin_PP&utm_medium=CPD&utm_campaign=jituanpinzhuanjuheye&utm_term=daxuekaoshi_banwei_1&wid=a842d1130c6e4394afaede8ccb14d579_0_0 | I30: 2026财年第5财月集团百度投放-基木鱼 | K30: 谭悦 | L30: 线上运营-投放 | M30: 集团-抖音品专 | Q30: 陈立峰 | R30: 谭悦 | S30: 30355465 | T30: 正常工单 | U30: 2025-10-19 18:27 | V30: A（六个月内有报课意向工单） | W30: 考研专业课,考研无忧计划 | X30: 大三 | Y30: 北京工业大学 | Z30: 信息学部 | AA30: 通信工程 | AB30: 陈立峰 | AC30: 5681454 | AD30: 谭悦 | AE30: 2025-10-23 10:54 | AF30: 谭悦 | AG30: 2025-10-23 10:55 | AH30: 无忧 | AI30: WYE27105 | AJ30: 考研英语无忧计划啄木鸟（27考研/英二强化） | AK30: 国内考试 | AM30: 6600 | AP30: 新签 | AQ30: 已交接 | AR30: BJWY2201F8pC6h | AS30: BJWY5487120372 | AT30: WYE271050003 | AU30: 2025-10-23 | AW30: 回访人：谭悦，回访时间：2025-10-17 18:42，回访内容：长期不回我消息 ；|回访人：陈伟钰，回访时间：2025-10-19 18:27，回访内容：陈伟钰恢复工单, 系统自动生成回访记录!；|回访人：谭悦，回访时间：2025-10-19 18:43，回访内容：面谈过了， 跟进中，走读班 ；|回访人：谭悦，回访时间：2025-10-22 18:03，回访内容：已出订单；|回访人：谭悦，回访时间：2025-10-23 10:54，回访内容：1 | BB30: 43431314 | BC30: 否 | BD30: 27考季 | BE30: 考研专业课150,无忧计划-啄木鸟 | BF30: 专业课150,英语,政治,数学 | BG30: 其他 | BH30: 国内高校-211 | BI30: 是 | BL30: 报名 | BN30: 本地人本地大学(常规) | BO30: 集团百度投放-基木鱼
A31: 108 | B31: 北京大学部 | C31: 国内大学部 | D31: 许昌苦瓜 | E31: 129687286 | F31: 张亚男 | G31: 2025-10-04 11:26:07 | H31: 渠道录入来源：集团百度投放-基木鱼 账户名：baidu-大学-总部-A22KA00038 线索ID：251004481825693103 线索时间：2025-10-04 11:25:47 页面名称：新东方考研集训营 姓名：许昌苦瓜 城市：北京 IP：2408:8207:7824:a5d0:718f:6e6c:26a9:cc7b 来源页：https://aisite.wejianzhan.com/site/wjzswa2z/a8dbbce4-c4ec-438e-922c-14344008843f?utm_source=jituan_searchengine_douyin__M_douyin_PP&utm_medium=CPD&utm_campaign=jituanpinzhuanjuheye&utm_term=daxuekaoshi_banwei_1&wid=a842d1130c6e4394afaede8ccb14d579_0_0 | I31: 2026财年第5财月集团百度投放-基木鱼 | K31: 谭悦 | L31: 线上运营-投放 | M31: 集团-抖音品专 | Q31: 陈立峰 | R31: 谭悦 | S31: 30355465 | T31: 正常工单 | U31: 2025-10-19 18:27 | V31: A（六个月内有报课意向工单） | W31: 考研专业课,考研无忧计划 | X31: 大三 | Y31: 北京工业大学 | Z31: 信息学部 | AA31: 通信工程 | AB31: 陈立峰 | AC31: 5681454 | AD31: 谭悦 | AE31: 2025-10-23 10:54 | AF31: 谭悦 | AG31: 2025-10-23 10:55 | AH31: 无忧 | AI31: WYM27102 | AJ31: 考研数学无忧计划啄木鸟（27考研/强化） | AK31: 国内考试 | AM31: 7100 | AP31: 新签 | AQ31: 已交接 | AR31: BJWY2201F8pC6h | AS31: BJWY5487120372 | AT31: WYM271020002 | AU31: 2025-10-23 | AW31: 回访人：谭悦，回访时间：2025-10-17 18:42，回访内容：长期不回我消息 ；|回访人：陈伟钰，回访时间：2025-10-19 18:27，回访内容：陈伟钰恢复工单, 系统自动生成回访记录!；|回访人：谭悦，回访时间：2025-10-19 18:43，回访内容：面谈过了， 跟进中，走读班 ；|回访人：谭悦，回访时间：2025-10-22 18:03，回访内容：已出订单；|回访人：谭悦，回访时间：2025-10-23 10:54，回访内容：1 | BB31: 43431314 | BC31: 否 | BD31: 27考季 | BE31: 考研专业课150,无忧计划-啄木鸟 | BF31: 专业课150,英语,政治,数学 | BG31: 其他 | BH31: 国内高校-211 | BI31: 是 | BL31: 报名 | BN31: 本地人本地大学(常规) | BO31: 集团百度投放-基木鱼
A32: 109 | B32: 北京大学部 | C32: 国内大学部 | D32: 许昌苦瓜 | E32: 129687286 | F32: 张亚男 | G32: 2025-10-04 11:26:07 | H32: 渠道录入来源：集团百度投放-基木鱼 账户名：baidu-大学-总部-A22KA00038 线索ID：251004481825693103 线索时间：2025-10-04 11:25:47 页面名称：新东方考研集训营 姓名：许昌苦瓜 城市：北京 IP：2408:8207:7824:a5d0:718f:6e6c:26a9:cc7b 来源页：https://aisite.wejianzhan.com/site/wjzswa2z/a8dbbce4-c4ec-438e-922c-14344008843f?utm_source=jituan_searchengine_douyin__M_douyin_PP&utm_medium=CPD&utm_campaign=jituanpinzhuanjuheye&utm_term=daxuekaoshi_banwei_1&wid=a842d1130c6e4394afaede8ccb14d579_0_0 | I32: 2026财年第5财月集团百度投放-基木鱼 | K32: 谭悦 | L32: 线上运营-投放 | M32: 集团-抖音品专 | Q32: 陈立峰 | R32: 谭悦 | S32: 30355465 | T32: 正常工单 | U32: 2025-10-19 18:27 | V32: A（六个月内有报课意向工单） | W32: 考研专业课,考研无忧计划 | X32: 大三 | Y32: 北京工业大学 | Z32: 信息学部 | AA32: 通信工程 | AB32: 陈立峰 | AC32: 5681454 | AD32: 谭悦 | AE32: 2025-10-23 10:54 | AF32: 谭悦 | AG32: 2025-10-23 10:55 | AH32: 无忧 | AI32: WYE27106 | AJ32: 考研英语无忧计划啄木鸟（27考研/英二冲刺） | AK32: 国内考试 | AM32: 2900 | AP32: 新签 | AQ32: 已交接 | AR32: BJWY2201F8pC6h | AS32: BJWY5487120372 | AT32: WYE271060003 | AU32: 2025-10-23 | AW32: 回访人：谭悦，回访时间：2025-10-17 18:42，回访内容：长期不回我消息 ；|回访人：陈伟钰，回访时间：2025-10-19 18:27，回访内容：陈伟钰恢复工单, 系统自动生成回访记录!；|回访人：谭悦，回访时间：2025-10-19 18:43，回访内容：面谈过了， 跟进中，走读班 ；|回访人：谭悦，回访时间：2025-10-22 18:03，回访内容：已出订单；|回访人：谭悦，回访时间：2025-10-23 10:54，回访内容：1 | BB32: 43431314 | BC32: 否 | BD32: 27考季 | BE32: 考研专业课150,无忧计划-啄木鸟 | BF32: 专业课150,英语,政治,数学 | BG32: 其他 | BH32: 国内高校-211 | BI32: 是 | BL32: 报名 | BN32: 本地人本地大学(常规) | BO32: 集团百度投放-基木鱼
A33: 110 | B33: 北京大学部 | C33: 国内大学部 | D33: 许昌苦瓜 | E33: 129687286 | F33: 张亚男 | G33: 2025-10-04 11:26:07 | H33: 渠道录入来源：集团百度投放-基木鱼 账户名：baidu-大学-总部-A22KA00038 线索ID：251004481825693103 线索时间：2025-10-04 11:25:47 页面名称：新东方考研集训营 姓名：许昌苦瓜 城市：北京 IP：2408:8207:7824:a5d0:718f:6e6c:26a9:cc7b 来源页：https://aisite.wejianzhan.com/site/wjzswa2z/a8dbbce4-c4ec-438e-922c-14344008843f?utm_source=jituan_searchengine_douyin__M_douyin_PP&utm_medium=CPD&utm_campaign=jituanpinzhuanjuheye&utm_term=daxuekaoshi_banwei_1&wid=a842d1130c6e4394afaede8ccb14d579_0_0 | I33: 2026财年第5财月集团百度投放-基木鱼 | K33: 谭悦 | L33: 线上运营-投放 | M33: 集团-抖音品专 | Q33: 陈立峰 | R33: 谭悦 | S33: 30355465 | T33: 正常工单 | U33: 2025-10-19 18:27 | V33: A（六个月内有报课意向工单） | W33: 考研专业课,考研无忧计划 | X33: 大三 | Y33: 北京工业大学 | Z33: 信息学部 | AA33: 通信工程 | AB33: 陈立峰 | AC33: 5681454 | AD33: 谭悦 | AE33: 2025-10-23 10:54 | AF33: 谭悦 | AG33: 2025-10-23 10:55 | AH33: 无忧 | AI33: WYP27035 | AJ33: 考研政治无忧计划（27考研/强化） | AK33: 国内考试 | AM33: 4000 | AP33: 新签 | AQ33: 已交接 | AR33: BJWY2201F8pC6h | AS33: BJWY5487120372 | AT33: WYP270350033 | AU33: 2025-10-23 | AW33: 回访人：谭悦，回访时间：2025-10-17 18:42，回访内容：长期不回我消息 ；|回访人：陈伟钰，回访时间：2025-10-19 18:27，回访内容：陈伟钰恢复工单, 系统自动生成回访记录!；|回访人：谭悦，回访时间：2025-10-19 18:43，回访内容：面谈过了， 跟进中，走读班 ；|回访人：谭悦，回访时间：2025-10-22 18:03，回访内容：已出订单；|回访人：谭悦，回访时间：2025-10-23 10:54，回访内容：1 | BB33: 43431314 | BC33: 否 | BD33: 27考季 | BE33: 考研专业课150,无忧计划-啄木鸟 | BF33: 专业课150,英语,政治,数学 | BG33: 其他 | BH33: 国内高校-211 | BI33: 是 | BL33: 报名 | BN33: 本地人本地大学(常规) | BO33: 集团百度投放-基木鱼
A34: 111 | B34: 北京大学部 | C34: 国内大学部 | D34: 许昌苦瓜 | E34: 129687286 | F34: 张亚男 | G34: 2025-10-04 11:26:07 | H34: 渠道录入来源：集团百度投放-基木鱼 账户名：baidu-大学-总部-A22KA00038 线索ID：251004481825693103 线索时间：2025-10-04 11:25:47 页面名称：新东方考研集训营 姓名：许昌苦瓜 城市：北京 IP：2408:8207:7824:a5d0:718f:6e6c:26a9:cc7b 来源页：https://aisite.wejianzhan.com/site/wjzswa2z/a8dbbce4-c4ec-438e-922c-14344008843f?utm_source=jituan_searchengine_douyin__M_douyin_PP&utm_medium=CPD&utm_campaign=jituanpinzhuanjuheye&utm_term=daxuekaoshi_banwei_1&wid=a842d1130c6e4394afaede8ccb14d579_0_0 | I34: 2026财年第5财月集团百度投放-基木鱼 | K34: 谭悦 | L34: 线上运营-投放 | M34: 集团-抖音品专 | Q34: 陈立峰 | R34: 谭悦 | S34: 30355465 | T34: 正常工单 | U34: 2025-10-19 18:27 | V34: A（六个月内有报课意向工单） | W34: 考研专业课,考研无忧计划 | X34: 大三 | Y34: 北京工业大学 | Z34: 信息学部 | AA34: 通信工程 | AB34: 陈立峰 | AC34: 5681454 | AD34: 谭悦 | AE34: 2025-10-23 10:54 | AF34: 谭悦 | AG34: 2025-10-23 10:55 | AH34: 无忧 | AI34: WYP27034 | AJ34: 考研政治无忧计划（27考研/基础） | AK34: 国内考试 | AM34: 6100 | AP34: 新签 | AQ34: 已交接 | AR34: BJWY2201F8pC6h | AS34: BJWY5487120372 | AT34: WYP270340033 | AU34: 2025-10-23 | AW34: 回访人：谭悦，回访时间：2025-10-17 18:42，回访内容：长期不回我消息 ；|回访人：陈伟钰，回访时间：2025-10-19 18:27，回访内容：陈伟钰恢复工单, 系统自动生成回访记录!；|回访人：谭悦，回访时间：2025-10-19 18:43，回访内容：面谈过了， 跟进中，走读班 ；|回访人：谭悦，回访时间：2025-10-22 18:03，回访内容：已出订单；|回访人：谭悦，回访时间：2025-10-23 10:54，回访内容：1 | BB34: 43431314 | BC34: 否 | BD34: 27考季 | BE34: 考研专业课150,无忧计划-啄木鸟 | BF34: 专业课150,英语,政治,数学 | BG34: 其他 | BH34: 国内高校-211 | BI34: 是 | BL34: 报名 | BN34: 本地人本地大学(常规) | BO34: 集团百度投放-基木鱼
A35: 112 | B35: 北京大学部 | C35: 国内大学部 | D35: 许昌苦瓜 | E35: 129687286 | F35: 张亚男 | G35: 2025-10-04 11:26:07 | H35: 渠道录入来源：集团百度投放-基木鱼 账户名：baidu-大学-总部-A22KA00038 线索ID：251004481825693103 线索时间：2025-10-04 11:25:47 页面名称：新东方考研集训营 姓名：许昌苦瓜 城市：北京 IP：2408:8207:7824:a5d0:718f:6e6c:26a9:cc7b 来源页：https://aisite.wejianzhan.com/site/wjzswa2z/a8dbbce4-c4ec-438e-922c-14344008843f?utm_source=jituan_searchengine_douyin__M_douyin_PP&utm_medium=CPD&utm_campaign=jituanpinzhuanjuheye&utm_term=daxuekaoshi_banwei_1&wid=a842d1130c6e4394afaede8ccb14d579_0_0 | I35: 2026财年第5财月集团百度投放-基木鱼 | K35: 谭悦 | L35: 线上运营-投放 | M35: 集团-抖音品专 | Q35: 陈立峰 | R35: 谭悦 | S35: 30355465 | T35: 正常工单 | U35: 2025-10-19 18:27 | V35: A（六个月内有报课意向工单） | W35: 考研专业课,考研无忧计划 | X35: 大三 | Y35: 北京工业大学 | Z35: 信息学部 | AA35: 通信工程 | AB35: 陈立峰 | AC35: 5681454 | AD35: 谭悦 | AE35: 2025-10-23 10:54 | AF35: 谭悦 | AG35: 2025-10-23 10:55 | AH35: 无忧 | AI35: WYP27036 | AJ35: 考研政治无忧计划（27考研/冲刺） | AK35: 国内考试 | AM35: 4100 | AP35: 新签 | AQ35: 已交接 | AR35: BJWY2201F8pC6h | AS35: BJWY5487120372 | AT35: WYP270360033 | AU35: 2025-10-23 | AW35: 回访人：谭悦，回访时间：2025-10-17 18:42，回访内容：长期不回我消息 ；|回访人：陈伟钰，回访时间：2025-10-19 18:27，回访内容：陈伟钰恢复工单, 系统自动生成回访记录!；|回访人：谭悦，回访时间：2025-10-19 18:43，回访内容：面谈过了， 跟进中，走读班 ；|回访人：谭悦，回访时间：2025-10-22 18:03，回访内容：已出订单；|回访人：谭悦，回访时间：2025-10-23 10:54，回访内容：1 | BB35: 43431314 | BC35: 否 | BD35: 27考季 | BE35: 考研专业课150,无忧计划-啄木鸟 | BF35: 专业课150,英语,政治,数学 | BG35: 其他 | BH35: 国内高校-211 | BI35: 是 | BL35: 报名 | BN35: 本地人本地大学(常规) | BO35: 集团百度投放-基木鱼
A36: 113 | B36: 北京大学部 | C36: 国内大学部 | D36: 许昌苦瓜 | E36: 129687286 | F36: 张亚男 | G36: 2025-10-04 11:26:07 | H36: 渠道录入来源：集团百度投放-基木鱼 账户名：baidu-大学-总部-A22KA00038 线索ID：251004481825693103 线索时间：2025-10-04 11:25:47 页面名称：新东方考研集训营 姓名：许昌苦瓜 城市：北京 IP：2408:8207:7824:a5d0:718f:6e6c:26a9:cc7b 来源页：https://aisite.wejianzhan.com/site/wjzswa2z/a8dbbce4-c4ec-438e-922c-14344008843f?utm_source=jituan_searchengine_douyin__M_douyin_PP&utm_medium=CPD&utm_campaign=jituanpinzhuanjuheye&utm_term=daxuekaoshi_banwei_1&wid=a842d1130c6e4394afaede8ccb14d579_0_0 | I36: 2026财年第5财月集团百度投放-基木鱼 | K36: 谭悦 | L36: 线上运营-投放 | M36: 集团-抖音品专 | Q36: 陈立峰 | R36: 谭悦 | S36: 30355465 | T36: 正常工单 | U36: 2025-10-19 18:27 | V36: A（六个月内有报课意向工单） | W36: 考研专业课,考研无忧计划 | X36: 大三 | Y36: 北京工业大学 | Z36: 信息学部 | AA36: 通信工程 | AB36: 陈立峰 | AC36: 5681454 | AD36: 谭悦 | AE36: 2025-10-23 10:54 | AF36: 谭悦 | AG36: 2025-10-23 10:55 | AH36: 无忧 | AI36: LP1761186112116 | AJ36: 考研初试专业课一对一（27考研/无忧30小时） | AK36: 国内考试 | AM36: 10000 | AP36: 新签 | AQ36: 已交接 | AR36: BJWY2201F8pC6h | AS36: BJWY5487120372 | AU36: 2025-10-23 | AW36: 回访人：谭悦，回访时间：2025-10-17 18:42，回访内容：长期不回我消息 ；|回访人：陈伟钰，回访时间：2025-10-19 18:27，回访内容：陈伟钰恢复工单, 系统自动生成回访记录!；|回访人：谭悦，回访时间：2025-10-19 18:43，回访内容：面谈过了， 跟进中，走读班 ；|回访人：谭悦，回访时间：2025-10-22 18:03，回访内容：已出订单；|回访人：谭悦，回访时间：2025-10-23 10:54，回访内容：1 | BB36: 43431314 | BC36: 否 | BD36: 27考季 | BE36: 考研专业课150,无忧计划-啄木鸟 | BF36: 专业课150,英语,政治,数学 | BG36: 其他 | BH36: 国内高校-211 | BI36: 是 | BN36: 本地人本地大学(常规) | BO36: 集团百度投放-基木鱼
A37: 172 | B37: 北京大学部 | C37: 国内大学部 | D37: 北京市7303 | E37: 130801054 | F37: 杨俊42(国内) | G37: 2025-10-15 12:38:47 | H37: AI-37815-492 2025-10-15 12:36:12 您好同学，欢迎访问新东方考研官网，【新东方考研】全新升级，课程灵活多样，【考研全年集训营】【考研半年集训营】【考研冲刺营】【线下走读班】【考研一对一】【在职考研】【四六级】火热报名中 ，现在报名更有高达3000元优惠！ AI-37815-492 2025-10-15 12:36:14 您是想咨询【考研走读班】【考研集训营】【考研规划】还是【在职考研】呢？ 01000000037815050295739111827303 2025-10-15 12:36:29 考研咨询 AI-37815-492 2025-10-15 12:36:32 同学，你现在是在校还是在职呢？ 01000000037815050295739111827303 2025-10-15 12:36:38 刚毕业 AI-37815-492 2025-10-15 12:36:41 具体是想报考什么学校和专业呢？ 01000000037815050295739111827303 2025-10-15 12:36:47 有电话吗 AI-37815-492 2025-10-15 12:36:50 有的，您现在方便接电话吗，说下的电话号码，我跟老师说下您的情况，让这边考研课程老师联系一下您，您看可以么？ 01000000037815050295739111827303 2025-10-15 12:37:12 我打过去咨询一下 AI-37815-492 2025-10-15 12:37:15 好的，了解。我们新东方在全国32个城市都有校区，您倾向在哪个城市上课，或者希望哪里的老师给您介绍下呢？ 01000000037815050295739111827303 2025-10-15 12:37:21 北京 AI-37815-492 2025-10-15 12:37:25 您可以留下您的姓名和电话，我这边可以立刻安排对应校区顾问老师给您回电！ 01000000037815050295739111827303 2025-10-15 12:37:45 18122856609 AI-37815-492 2025-10-15 12:37:49 好的，确认一下你的号码是否正确呢~ 01000000037815050295739111827303 2025-10-15 12:38:02 大概什么时间打过来 AI-37815-492 2025-10-15 12:38:06 这个手机号是您的微信吗？如果不是您可以留一下您的微信号 01000000037815050295739111827303 2025-10-15 12:38:06 对的 AI-37815-492 2025-10-15 12:38:09 同学怎么称呼呢？ 01000000037815050295739111827303 2025-10-15 12:38:14 陈 AI-37815-492 2025-10-15 12:38:18 这边马上安排顾问老师联系您，预计半个小时左右给您回电请注意接听~ | I37: 2026财年第5财月百度投放新东方官网小程序 | K37: 杨欢欢 | L37: 新东方官网 | M37: 新东方官网小程序 | O37: 杨欢欢 | P37: 2025-10-15 12:45:55 | Q37: 陈杞荣 | R37: 李涛 | S37: 30448384 | T37: 正常工单 | U37: 2025-10-15 13:26 | V37: A（六个月内有报课意向工单） | W37: 考研VIP | X37: 大学已毕业 | Y37: 北京师范大学 | Z37: 艺术与传媒学院 | AA37: 舞蹈学 | AB37: 陈杞荣 | AC37: 5650748 | AD37: 李涛 | AE37: 2025-10-16 11:16 | AF37: 李涛 | AG37: 2025-10-16 11:17 | AH37: 个性化 | AI37: LP1760584615310 | AJ37: 考研一对一伴学班（26考季） | AK37: 国内考试 | AM37: 50200 | AP37: 新签 | AQ37: 已交接 | AS37: BJWY8687315134 | AU37: 2025-10-16 | AW37: 回访人：李涛，回访时间：2025-10-15 13:26，回访内容：今年考北师大 舞蹈专业！ 本科是北京体育大学，4-6级没有考！ 有学过雅思 5分左右！ 学习时间每天 专业课是在魏公村！下午到学校面谈！；|回访人：李涛，回访时间：2025-10-16 11:16，回访内容：系统自动签约 | BB37: 86079300 | BC37: 否 | BD37: 26考季 | BE37: VIP - 伴学 | BF37: 英语 | BG37: 其他 | BH37: 国内高校-985 | BI37: 是 | BO37: 百度投放
A38: 214 | B38: 北京大学部 | C38: 国内大学部 | E38: 91185805 | G38: 2024-12-20 19:49:46 | H38: 续费原因：学员咨询接下来的考研课程，辛苦流转；该学生为保护期外续费，原顾问部门：国内大学部 | J38: 大二 | K38: 谭悦 | L38: 转介绍 | M38: 学管续费推荐 | Q38: 陈若瑜 | R38: 谭悦 | S38: 30415504 | T38: 续费工单 | U38: 2025-10-11 10:08 | V38: A（六个月内有报课意向工单） | W38: 考研集训营 | X38: 大三 | Y38: 中北大学 | Z38: 机械工程学院 | AA38: 机械设计制造及其自动化 | AB38: 陈若瑜 | AC38: 5647188 | AD38: 谭悦 | AE38: 2025-10-11 10:13 | AF38: 谭悦 | AG38: 2025-10-11 10:24 | AH38: 个性化 | AI38: LP1760148823102 | AJ38: 考研初试专业课一对一（26考研/30小时） | AK38: 国内考试 | AM38: 18300 | AP38: 续班 | AQ38: 已交接 | AS38: XDF072214235615410 | AU38: 2025-10-11 | AW38: 回访人：谭悦，回访时间：2025-10-11 10:08，回访内容：1；|回访人：谭悦，回访时间：2025-10-11 10:13，回访内容：系统自动签约 | BB38: 33338537 | BC38: 否 | BD38: 26考季 | BE38: 寒暑假集训营（春秋OMO） | BF38: 英语,政治 | BH38: 国内高校-双非 | BI38: 是 | BN38: 外地人外地大学(常规)
A39: 24 | B39: 北京大学部 | C39: 国内大学部 | E39: 92994255 | G39: 2025-01-13 16:06:45 | H39: 赵星火老师死单激活资源；赵星火老师死单激活资源 外呼主题：FY24-国内9月死单回访（第四周） 赵星火老师死单激活资源(资源备注人:吴凯龙;资源备注时间:2025-01-13 16:07) | J39: 大三 | K39: 赵星火 | L39: 线上运营-投放 | M39: 百度投放 | Q39: 陈廷进 | R39: 高龙明 | S39: 30469649 | T39: 续费工单 | U39: 2025-10-19 15:47 | V39: A（六个月内有报课意向工单） | W39: 考研VIP | X39: 大学已毕业 | Y39: 吉林大学 | Z39: 物理学院 | AA39: 物理学 | AB39: 陈廷进 | AC39: 5653215 | AD39: 赵星火 | AE39: 2025-10-19 15:47 | AF39: 高龙明 | AG39: 2025-10-19 15:48 | AH39: 集训营 | AK39: 国内考试 | AM39: 9018.15 | AN39: 同科续费 | AP39: 分单 | AQ39: 无须交接 | AS39: BJWY4776417923 | AW39: 回访人：高龙明，回访时间：2025-10-19 15:47，回访内容：1；|回访人：高龙明，回访时间：2025-10-19 15:47，回访内容：1 | BB39: 62316553 | BC39: 否 | BD39: 26考季 | BE39: VIP - 伴学 | BF39: 数学 | BH39: 国内高校-985 | BI39: 否 | BN39: 外地人外地大学(常规)
A40: 44 | B40: 北京大学部 | C40: 国内大学部 | E40: 101338732 | G40: 2025-05-05 17:07:28 | H40: 渠道录入来源：集团百度投放-基木鱼 账户名：baidu-大学-总部-A22KA00038 线索ID：250505456599343480 线索时间：2025-05-05 17:07:25 页面名称：表单单页 姓名：李女士 城市：北京 IP：106.39.151.230 来源页：https://aisite.wejianzhan.com/site/wjzswa2z/ae4b1107-66a0-456e-a487-5b127e799c11?fid=nHcLnjcsPW6zn1fvnHb4PWRLP7tznWPxn6&ch=4&bd_vid=nHcLnjcsPW6zn1fvnHb4PWRLP7tznWPxn-tknjKxP7tknjnkPWf3nWRdn10&bd_bxst=EiaKZ_Blwva8CKZx00cD05kyisFDg0f000000KQfsopoVeLRv_OxEe1wYnoqYpTSm-z800000aFAPbFDrH6zPbRvPHmvPYFKnD7AwH-arHIKfbDvnjKKrZsscDc1f1uawH6znj6sPbPjPHbvf16drRu7PYfswWb3rjIDt1QcFitgly3a00008btpKw6000KgrKHSef0000D0xsDcEe1wYnoqYpTmEe1wYnoqYpTVYn2vJeXqEe1wYnL3dU39000005OOOOOOOOOOEDq7r6 描述：VIP课程 | I40: 2025财年第12财月集团百度投放-基木鱼 | K40: 谭悦 | L40: 线上运营-投放 | M40: 总部-百度投放 | Q40: 陈翔 | R40: 谭悦 | S40: 30223170 | T40: 续费工单 | U40: 2025-09-30 17:20 | V40: A（六个月内有报课意向工单） | W40: 线上考研产品 | X40: 大学已毕业 | Y40: 北京电子科技学院 | Z40: 电子与通信工程系 | AA40: 电子信息工程 | AB40: 陈翔 | AC40: 5642275 | AD40: 谭悦 | AE40: 2025-09-30 17:20 | AF40: 谭悦 | AG40: 2025-10-01 17:50 | AH40: 网课 | AI40: 94083352139 | AJ40: 2026考研英语大纲冲刺班,2026考研政治大纲冲刺班,2026考研数学直通车 5期 | AK40: 国内考试 | AM40: 5686.8 | AP40: 续班 | AQ40: 无须交接 | AU40: 2025-10-01 | AW40: 回访人：谭悦，回访时间：2025-09-30 17:20，回访内容：1；|回访人：谭悦，回访时间：2025-09-30 17:20，回访内容：1 | BA40: 长期班,长期班,长期班 | BB40: 69951253 | BC40: 是 | BD40: 26考季 | BE40: 线上直通车 | BF40: 数学 | BH40: 国内高校-双非 | BI40: 否 | BM40: 110159583
A41: 15 | B41: 北京大学部 | C41: 国内大学部 | E41: 132519662 | G41: 2025-10-28 11:15:27 | H41: 续费原因：学生27考研，需要一对一，辛苦谭悦老师跟进；该学生为保护期内续费，原顾问：国内大学部-谭悦(tanyue9@xdf.cn) | J41: 大四 | K41: 谭悦 | L41: 转介绍 | M41: 学管续费推荐 | Q41: 陈一凡 | R41: 谭悦 | S41: 30609934 | T41: 续费工单 | U41: 2025-10-30 16:10 | V41: A（六个月内有报课意向工单） | W41: 考研VIP | X41: 大四 | Y41: 北方工业大学 | Z41: 信息学院 | AA41: 数据科学与大数据技术 | AB41: 陈一凡 | AC41: 5687773 | AD41: 谭悦 | AE41: 2025-10-30 16:10 | AF41: 谭悦 | AG41: 2025-10-30 16:12 | AH41: 四六级 | AI41: WYFBK25060 | AJ41: 四级无忧计划（补优惠/ 陈一凡 ） | AK41: 国内考试 | AM41: 1481.1 | AP41: 续班 | AQ41: 已交接 | AR41: BJWY24032w1g8X | AS41: BJWY8503976521 | AT41: WYFBK250600001 | AU41: 2025-10-30 | AW41: 回访人：谭悦，回访时间：2025-10-30 16:10，回访内容：1；|回访人：谭悦，回访时间：2025-10-30 16:10，回访内容：补四六级班级优惠入班 | BB41: 58815635 | BC41: 否 | BD41: 26考季 | BE41: VIP - 伴学 | BF41: 英语,政治 | BH41: 国内高校-211 | BI41: 否 | BL41: 报名 | BN41: 本地人本地大学(常规)
A42: 16 | B42: 北京大学部 | C42: 国内大学部 | E42: 132519662 | G42: 2025-10-28 11:15:27 | H42: 续费原因：学生27考研，需要一对一，辛苦谭悦老师跟进；该学生为保护期内续费，原顾问：国内大学部-谭悦(tanyue9@xdf.cn) | J42: 大四 | K42: 谭悦 | L42: 转介绍 | M42: 学管续费推荐 | Q42: 陈一凡 | R42: 谭悦 | S42: 30609934 | T42: 续费工单 | U42: 2025-10-30 16:10 | V42: A（六个月内有报课意向工单） | W42: 考研VIP | X42: 大四 | Y42: 北方工业大学 | Z42: 信息学院 | AA42: 数据科学与大数据技术 | AB42: 陈一凡 | AC42: 5687773 | AD42: 谭悦 | AE42: 2025-10-30 16:10 | AF42: 谭悦 | AG42: 2025-10-30 16:12 | AH42: 无忧 | AI42: WYM26009 | AJ42: 考研数学无忧计划（26考研/冲刺） | AK42: 国内考试 | AM42: 4200 | AP42: 续班 | AQ42: 已交接 | AR42: BJWY22035556hl | AS42: BJWY8503976521 | AT42: WYM260090062 | AU42: 2025-10-26 | AW42: 回访人：谭悦，回访时间：2025-10-30 16:10，回访内容：1；|回访人：谭悦，回访时间：2025-10-30 16:10，回访内容：补四六级班级优惠入班 | BB42: 58815635 | BC42: 否 | BD42: 26考季 | BE42: VIP - 伴学 | BF42: 英语,政治 | BH42: 国内高校-211 | BI42: 否 | BL42: 转出 | BN42: 本地人本地大学(常规)
A43: 17 | B43: 北京大学部 | C43: 国内大学部 | E43: 132519662 | G43: 2025-10-28 11:15:27 | H43: 续费原因：学生27考研，需要一对一，辛苦谭悦老师跟进；该学生为保护期内续费，原顾问：国内大学部-谭悦(tanyue9@xdf.cn) | J43: 大四 | K43: 谭悦 | L43: 转介绍 | M43: 学管续费推荐 | Q43: 陈一凡 | R43: 谭悦 | S43: 30609934 | T43: 续费工单 | U43: 2025-10-30 16:10 | V43: A（六个月内有报课意向工单） | W43: 考研VIP | X43: 大四 | Y43: 北方工业大学 | Z43: 信息学院 | AA43: 数据科学与大数据技术 | AB43: 陈一凡 | AC43: 5687773 | AD43: 谭悦 | AE43: 2025-10-30 16:10 | AF43: 谭悦 | AG43: 2025-10-30 16:12 | AH43: 无忧 | AI43: WYP26021 | AJ43: 考研政治无忧计划（26考研/冲刺） | AK43: 国内考试 | AM43: 5700 | AP43: 续班 | AQ43: 已交接 | AR43: BJWY22035556hl | AS43: BJWY8503976521 | AT43: WYP260210063 | AU43: 2025-10-26 | AW43: 回访人：谭悦，回访时间：2025-10-30 16:10，回访内容：1；|回访人：谭悦，回访时间：2025-10-30 16:10，回访内容：补四六级班级优惠入班 | BB43: 58815635 | BC43: 否 | BD43: 26考季 | BE43: VIP - 伴学 | BF43: 英语,政治 | BH43: 国内高校-211 | BI43: 否 | BL43: 转出 | BN43: 本地人本地大学(常规)
...

Sheet 退费明细
A1: 提交日期 | B1: OA流水号 | C1: 学管姓名 | D1: 学管是否代办 | E1: 顾问姓名 | F1: 顾问是否代办 | G1: 91系统-最新报名二级渠道 | H1: 原班所属项目 | I1: 新报入班级所属项目 | J1: 退费阶段 | K1: 退费一级原因（开课前） | L1: 退费一级原因 (开课后) | M1: 退费二级原因（专业课师资匹配原因） | N1: 退费二级原因（学员意愿转变_开课前） | O1: 退费二级原因（计划冲突_开课前） | P1: 退费二级原因（中心原因_开课前） | Q1: 退费二级原因（签约话术） | R1: 退费二级原因（教师） | S1: 退费二级原因（教学） | T1: 退费二级原因（课程安排） | U1: 退费二级原因（配套服务） | V1: 退费二级原因（配套学习设施） | W1: 退费二级原因（中心原因_开课后） | X1: 退费二级原因（计划冲突_开课后） | Y1: 退费二级原因（学员意愿转变_开课后） | Z1: 退费三级原因（完全匹配不上）-院校、学院、专业、专业课代码及名称 | AA1: 退费详细原因说明（与OA退费详细说明保持一致） | AB1: 预计报名新班学费金额 | AC1: 转班金额（请学管填写所在班级实际金额） | AD1: 转班详细原因说明 | AE1: 提交时间 | AF1: 学校 | AG1: 学院 | AH1: 年级 | AI1: 专业 | AJ1: 您所办理的业务类型 | AK1: 提交人 | AL1: 退费类型 | AM1: 学员姓名 | AN1: 学员编码 | AO1: 退费金额 | AP1: 办理日期-客服 | AQ1: 退费方式-客服 | AR1: 需要跟进的顾问/学管 | AS1: 退费/转班特殊情况备注（若需要学管提供银行卡信息，可将需求填写在此处）-客服 | AT1: 是否完成退费/转班-客服 | AU1: 父记录 | AV1: 备注
A2: 2025/10/11 | C2: 罗志勇1 | E2: 李涛48 | G2: 京内毛坯数据 | H2: 四六级项目-班课 | AC2: ¥6180.00 | AD2: 上下午班 | AE2: 2025-10-11 | AJ2: 转班 | AK2: 罗志勇1 | AM2: 冯文玥 | AN2: BJWY3141371973 | AO2: 6180 | AP2: 2025/10/11 | AQ2: 已转班 | AT2: TRUE
A3: 2025/10/11 | C3: 罗志勇1 | E3: 李涛48 | G3: 公众号 | H3: 四六级项目-班课 | AC3: ¥6180.00 | AD3: 转魏公村 花园桥太远 | AE3: 2025-10-11 | AJ3: 转班 | AK3: 罗志勇1 | AM3: 张腾 | AN3: BJWY4523927820 | AO3: 6180 | AP3: 2025/10/11 | AQ3: 已转班 | AT3: TRUE
A4: 2025/10/11 | C4: 罗志勇1 | E4: 李涛48 | G4: 公众号 | H4: 四六级项目-班课 | AC4: ¥6180.00 | AD4: 花园桥远 转入魏公村 | AE4: 2025-10-11 | AJ4: 转班 | AK4: 罗志勇1 | AM4: 高原 | AN4: BJWY2095765425 | AO4: 6180 | AP4: 2025/10/11 | AQ4: 已转班 | AT4: TRUE
AN5: 李涛合计 | AO5: =SUM(AO2:AO4) -> 18540
A6: 2025/09/26 | B6: NO.18929128 | C6: 寇颖 | E6: 谭悦9 | G6: 顾问转介绍-老带新 | H6: 无忧项目-班课 | J6: 开课后退费 | L6: 学员意愿转变_开课后 | Y6: 保研 | AA6: 退费原因：学生基本确定保研，后面课程不需要了，申请退出。【此退费为投诉退费，已走特殊申请】 | AE6: 2025-09-26 | AF6: 中央民族大学 | AG6: 音乐学院 | AH6: 大四 | AI6: 音乐表演（声乐） | AJ6: 退费 | AK6: 寇颖 | AL6: 真实产生的退费 | AM6: 官智贤 | AN6: BJWY6283856593 | AO6: 2709.6 | AP6: 2025/10/02 | AQ6: 原路径微信退回 | AT6: TRUE
A7: 2025/09/26 | B7: NO.18929111 | C7: 寇颖 | E7: 谭悦9 | G7: 顾问转介绍-老带新 | H7: 无忧项目-班课 | J7: 开课后退费 | L7: 学员意愿转变_开课后 | Y7: 保研 | AA7: 学生基本确定保研，后面课程不需要了，申请退出。【此退费为投诉退费，已走特殊申请】 | AE7: 2025-09-26 | AF7: 中央民族大学 | AG7: 音乐学院 | AH7: 大四 | AI7: 音乐表演（声乐） | AJ7: 退费 | AK7: 寇颖 | AL7: 真实产生的退费 | AM7: 官智贤 | AN7: BJWY6283856593 | AO7: 3652.8 | AP7: 2025/10/02 | AQ7: 原路径微信退回 | AT7: TRUE
A8: 2025/10/06 | C8: 寇颖 | E8: 谭悦9 | G8: 学管续费推荐 | H8: 无忧项目-班课 | AC8: ¥3038.30 | AD8: 转班信息如下： WYZ26001转WYZ26002 转班原因：学生时间冲突，需转班 | AE8: 2025-10-06 | AJ8: 转班 | AK8: 寇颖 | AM8: 孙雨涵 | AN8: BJWY6398433958 | AO8: 2531.9 | AP8: 2025/10/06 | AQ8: 10.6已转班 | AT8: TRUE | AV8: 系统实际绑单2531.9
A9: 2025/10/08 | B9: 18940587 | C9: 黄小妹7 | E9: 谭悦9 | G9: 集团-百度品专 | H9: 无忧项目-班课 | J9: 开课后退费 | L9: 学员意愿转变_开课后 | Y9: 个人身体原因无法承受高强度学习 | AA9: 【已开课退费】上课环境太远，无力兼顾来回跑 | AE9: 2025-10-08 | AF9: 中国石油大学昌平校区 | AG9: 工学院 | AH9: 大四 | AI9: 环境工程 | AJ9: 退费 | AK9: 黄小妹7 | AL9: 真实产生的退费 | AM9: 赵一泽 | AN9: BJWY5334447793 | AO9: 5725 | AP9: 2025/10/11 | AQ9: 微信退13958.3（账户6800为专业课补优惠金额）——————[图片] 20758.3暂退至学员账户，专业课确定退出后才能全部提现退回，若专业课不退需补优惠6800@刘佳林25 (刘佳林) [图片][图片] 未办理：OA未到前台（10.10） 未办理：OA未到前台（10.9） 未办理：OA未到前台（10.8） | AT9: TRUE
A10: 2025/10/08 | B10: 18940539 | C10: 黄小妹7 | E10: 谭悦9 | G10: 集团-百度品专 | H10: 无忧项目-班课 | J10: 开课后退费 | L10: 学员意愿转变_开课后 | Y10: 个人身体原因无法承受高强度学习 | AA10: 【已开课退费】上课环境太远，无力兼顾来回跑 | AE10: 2025-10-08 | AF10: 中国石油大学 | AG10: 工学院 | AH10: 大四 | AI10: 环境工程 | AJ10: 退费 | AK10: 黄小妹7 | AL10: 真实产生的退费 | AM10: 赵一泽 | AN10: BJWY5334447793 | AO10: 15033.3 | AP10: 2025/10/11 | AQ10: 微信退13958.3（账户6800为专业课补优惠金额）@黄小妹7 (黄小妹)——————[图片] 20758.3暂退至学员账户，专业课确定退出后才能全部提现退回，若专业课不退需补优惠6800@刘佳林25 (刘佳林) [图片][图片] 未办理：OA未到前台（10.10） 未办理：OA未到前台（10.9） 未办理：OA未到前台（10.8） | AT10: TRUE
A11: 2025/10/09 | B11: NO.8358680908401152856 | C11: 谭悦9 | E11: 谭悦9 | F11: TRUE | G11: 直访 | H11: VIP项目-VIP | J11: 开课前退费 | K11: 学员意愿转变_开课前 | N11: 家人不支持考研/不支持跟班学习/意见不一致 | AA11: 家长直访，汪宇萌老师帮忙接待，给学生报名的10小时一对一，学生坚持不学，意见不一致，确定要退费。 | AE11: 2025-10-09 | AF11: 吉林大学 | AG11: 能源动力 | AH11: 在职 | AI11: 能源动力 | AJ11: 退费 | AK11: 谭悦9 | AL11: 真实产生的退费 | AM11: 于潇 | AN11: BJWY3517193451 | AO11: 0 | AP11: 2025/10/13 | AQ11: 10.16原路径退费失败，改手工账号:6212264200017221013开户行:中国工商银行长春二区支行开户姓名:于宏伟，顾问汪宇萌提供信息 银联扫码退回：微信133636826509978376 未办理：OA未到前台（10.12） 未办理：OA未到前台（10.11） 未办理：OA未到前台（10.10） | AT11: TRUE | AV11: 当月退费签约退费都不算
A12: 2025/10/12 | C12: 唐源曼 | E12: 谭悦9 | G12: 总部-百度投放 | H12: 集训营项目-班课 | AC12: ¥15281.60 | AD12: 学员因换院校转成英二 | AE12: 2025-10-12 | AJ12: 转班 | AK12: 唐源曼 | AM12: 张梓桐 | AN12: BJWY2669115733 | AO12: 8404.9 | AP12: 2025/10/12 | AQ12: 已转班 | AT12: TRUE | AV12: 系统实际绑单8404.9
A13: 2025/10/14 | B13: 18947384 | C13: 郝琨 | E13: 谭悦9 | G13: 学管续费推荐 | H13: 无忧项目-班课 | I13: VIP项目 | J13: 开课后退费 | L13: 中心原因_开课后 | W13: 退出重报（取消班/合班/延转/选班/扩科等） | AA13: 学生姓名：陈一凡学员编号：BJWY8503976521退费方式：报名英政数专退英政数专退费原因：学生心理状态问题，今年不打算考研，想把公共课和专业课剩余金额转成一对一后续学习班课退费班级：、WYE26007、WYE26008、WYP26005、WYP26006、WYM26005、WYM26006应退金额：12250.7，其中1481.1元保留给六级班，总计退出给学生10769.6元最后出勤日期：6.28 | AB13: ¥2948.90 | AE13: 2025-10-14 | AF13: 北方工业大学 | AG13: 信息学院 | AH13: 大四 | AI13: 数据科学与大数据技术 | AJ13: 退费 | AK13: 郝琨 | AL13: 转项目/转班/退出重报等未产生实际退费 | AM13: 陈一凡 | AN13: BJWY8503976521 | AO13: 0 | AP13: 2025/10/26 | AQ13: 10.27 已退回账户余额 10.26 这个已经退回账户余额啦 10.24 未办理，退回后的oa未到前台 10.23学管要求退回oa，已回退@郝琨 未办理：补给四六级的1481.1从哪个办理退出（10.23）@郝琨 未办理：补给四六级的1481.1从哪个办理退出（10.22）@郝琨 未办理：补给四六级的1481.1从哪个办理退出（10.20）@郝琨[图片] 未办理，OA未到前台（10.19）@郝琨 未办理，OA未到前台（10.18） 未办理，OA未到前台（10.17） 未办理，OA未到前台（10.16） 未办理，OA未到前台（10.15） | AT13: TRUE | AV13: 代离职顾问办理，栗晓环 | AX13: 2948.9
A14: 2025/10/14 | B14: 18947393 | C14: 郝琨 | E14: 谭悦9 | G14: 学管续费推荐 | H14: 无忧项目-班课 | I14: VIP项目 | J14: 开课后退费 | L14: 中心原因_开课后 | W14: 退出重报（取消班/合班/延转/选班/扩科等） | AA14: 学生姓名：陈一凡学员编号：BJWY8503976521退费方式：报名英政数专退英政数专退费原因：学生心理状态问题，今年不打算考研，想把公共课和专业课剩余金额转成一对一后续学习班课退费班级：、WYE26007、WYE26008、WYP26005、WYP26006、WYM26005、WYM26006应退金额：12250.7，其中1481.1元保留给六级班，总计退出给学生10769.6元最后出勤日期：6.28 | AB14: ¥20000.00 | AE14: 2025-10-14 | AF14: 北方工业大学 | AG14: 信息学院 | AH14: 大四 | AI14: 数据科学与大数据技术 | AJ14: 退费 | AK14: 郝琨 | AL14: 转项目/转班/退出重报等未产生实际退费 | AM14: 陈一凡 | AN14: BJWY8503976521 | AO14: 0 | AP14: 2025/10/26 | AQ14: 10.27已退回账户余额 10.26，救命啊😱，WYP26006 退费的时候发现课次变化了，先转班一下老师，转班之后再退：@郝琨 [图片] 10.24 未办理，退回后的oa未到前台 10.23学管要求退回oa，已回退@郝琨 未办理：补给四六级的1481.1从哪个办理退出（10.23）@郝琨 未办理：补给四六级的1481.1从哪个办理退出（10.22）@郝琨 未办理：补给四六级的1481.1从哪个办理退出（10.20）@郝琨[图片] 未办理，OA未到前台（10.19）@郝琨 未办理，OA未到前台（10.18） 未办理，OA未到前台（10.17） 未办理，OA未到前台（10.16） 未办理，OA未到前台（10.15） | AT14: TRUE | AV14: 代离职顾问办理，栗晓环 | AX14: 4774.6
A15: 2025/10/14 | B15: 18947405 | C15: 郝琨 | E15: 谭悦9 | G15: 学管续费推荐 | H15: 无忧项目-班课 | I15: VIP项目 | J15: 开课后退费 | L15: 中心原因_开课后 | W15: 退出重报（取消班/合班/延转/选班/扩科等） | AA15: 学生姓名：陈一凡学员编号：BJWY8503976521退费方式：报名英政数专退英政数专退费原因：学生心理状态问题，今年不打算考研，想把公共课和专业课剩余金额转成一对一后续学习班课退费班级：、WYE26007、WYE26008、WYP26005、WYP26006、WYM26005、WYM26006应退金额：12250.7，其中1481.1元保留给六级班，总计退出给学生10769.6元最后出勤日期：6.28 | AB15: ¥20000.00 | AE15: 2025-10-14 | AF15: 北方工业大学 | AG15: 信息学院 | AH15: 大四 | AI15: 数据科学与大数据技术 | AJ15: 退费 | AK15: 郝琨 | AL15: 转项目/转班/退出重报等未产生实际退费 | AM15: 陈一凡 | AN15: BJWY8503976521 | AO15: 0 | AP15: 2025/10/26 | AQ15: 10.27已退回账户余额 10.26，救命啊，这个WYM26006也要转班：@郝琨 [图片] 10.24 未办理，退回后的oa未到前台 10.23学管要求退回oa，已回退@郝琨 未办理：补给四六级的1481.1从哪个办理退出（10.23）@郝琨 未办理：补给四六级的1481.1从哪个办理退出（10.22）@郝琨 未办理：补给四六级的1481.1从哪个办理退出（10.20）@郝琨[图片] 未办理，OA未到前台（10.19）@郝琨 未办理，OA未到前台（10.18） 未办理，OA未到前台（10.17） 未办理，OA未到前台（10.16） 未办理，OA未到前台（10.15） | AT15: TRUE | AV15: 代离职顾问办理，栗晓环 | AX15: 3370.3
A16: 2025/10/24 | B16: 18959033 | C16: 郝琨 | E16: 谭悦9 | G16: 学管续费推荐 | H16: 无忧项目-班课 | I16: VIP项目 | J16: 开课后退费 | L16: 中心原因_开课后 | W16: 退出重报（取消班/合班/延转/选班/扩科等） | AA16: 学生姓名：陈一凡学员编号：BJWY8503976521退费方式：报名英政数专退英政数专退费原因：学生心理状态问题，今年不打算考研，想把公共课和专业课剩余金额转成一对一后续学习班课退费班级：、WYE26007、WYE26008、WYP26005、WYP26006、WYM26005、WYM26006应退金额：12250.7，其中1481.1元保留给六级班，总计退出给学生10769.6元最后出勤日期：6.28 应退金额：12250.7，其中1481.1元保留给六级班，英语冲刺班退出2948.9元，政治冲刺班退出4774.6元 数学冲刺班退出3370.3，政治强化班退出1156.9元，金额保留在学员账户，公共课部分10769.6元，后续入一对一 | AB16: ¥20000.00 | AE16: 2025-10-24 | AF16: 北方工业大学 | AG16: 计算机学院 | AH16: 大四 | AI16: 大数据技术 | AJ16: 退费 | AK16: 郝琨 | AL16: 转项目/转班/退出重报等未产生实际退费 | AM16: 陈一凡 | AN16: BJWY8503976521 | AO16: 0 | AP16: 2025/10/26 | AQ16: 10.27已退回账户余额 10.26，这个OA已经退回账户余额啦，等等上面那俩转班的@郝琨 | AT16: TRUE | AV16: 代离职顾问办理，栗晓环 | AX16: 1156.9
A17: 2025/10/18 | B17: NO.864691128456653152 | C17: 刘佳林25 | E17: 谭悦9 | G17: 学管续费推荐 | H17: 集训营项目-专业课 | J17: 开课前退费 | K17: 学员意愿转变_开课前 | N17: 家人不支持考研/不支持跟班学习/意见不一致 | AA17: 学生是中石油的，来花园桥距离太远来回奔波，家长要求退费，专业课也要一同退费；经过挽单，原本是等学生专业课测试成绩出来后，再决定专业课这边是否退费，但是目前学生对考本校专业课比较有信心，孩子坚持不需要，需要办理退费 | AE17: 2025-10-18 | AF17: 中国石油大学 | AG17: 环境工程 | AH17: 大四 | AI17: 环境工程 | AJ17: 退费 | AK17: 刘佳林25 | AL17: 真实产生的退费 | AM17: 赵一泽 | AN17: BJWY5334447793 | AO17: 5500 | AP17: 2025/10/18 | AQ17: 原路径微信退回 | AT17: TRUE
A18: 2025/10/18 | C18: 黄小妹7 | E18: 谭悦9 | G18: 巨量广告 | H18: 无忧项目-班课 | AC18: ¥3891.10 | AD18: 学生需要往后转班3月上课，目前花园桥没有新班，需要先转到知春路避免学生看回放形成客诉 | AE18: 2025-10-18 | AJ18: 转班 | AK18: 黄小妹7 | AM18: 郑雅洁 | AN18: BJWY5564317069 | AO18: 3891.1 | AP18: 2025/10/18 | AQ18: 已转班 | AT18: TRUE
A19: 2025/10/14 | B19: 2025101402418 | C19: 陈晶171 | E19: 谭悦9 | G19: 阿里本地通 | H19: 无忧项目-VIP | J19: 开课前退费 | K19: 学员意愿转变_开课前 | N19: 找到工作 | AA19: 得知孩子退费的消息第一时间联系了孩子，主要是从尝试和老师接触开始第一次的课程学习，工作后就再也没时间考研了，以及以后的工作学历要求高几个方面说起，孩子态度比较坚决，说是和家长商量好了决定工作，详细的不愿意多说。 但是问到孩子我还要发后续的学习资料吗，孩子还是要发，今年可能还要考，但要把课程费用退出，我后续会继续跟进服务，最好是能再让孩子报一些课时考前冲刺用 | AE19: 2025-10-18 | AF19: 大连海事大学 | AG19: 法学院 | AH19: 大三 | AI19: 法律 | AJ19: 退费 | AK19: 陈晶171 | AL19: 真实产生的退费 | AM19: 曾行健 | AN19: BJWY3312305782 | AO19: 0 | AP19: 2025/10/19 | AQ19: 10.19原渠道微信已退回@陈晶171 (陈晶) | AT19: TRUE | AV19: 当月退费签约退费都不算
A20: 2025/10/26 | C20: 郝琨 | E20: 谭悦9 | G20: 学管续费推荐 | H20: 无忧项目-班课 | AC20: ¥8144.90 | AD20: 姓名：陈一凡 电话：18322094303 学员编号： BJWY8503976521 转班原因：退费转班 转班信息： WYM26006转WYM26009，WYP26006转WYP26021 已登记表格，辛苦老师办理 | AE20: 2025-10-26 | AJ20: 转班 | AK20: 郝琨 | AM20: 陈一凡 | AN20: BJWY8503976521 | AO20: 8144.9 | AP20: 2025/10/26 | AQ20: 已转班，新班已退 | AT20: TRUE
A21: 2025/10/27 | C21: 葛铭 | E21: 谭悦9 | G21: 线下校代 | H21: 无忧项目-班课 | AC21: ¥9000.00 | AD21: 学员更换专业，申请转班 | AE21: 2025-10-27 | AJ21: 转班 | AK21: 葛铭 | AM21: 汤世瑞 | AN21: BJWY7703355611 | AO21: 9000 | AP21: 2025/10/27 | AQ21: 已转班 | AT21: TRUE
A22: 2025/10/30 | B22: 18967999 | C22: 余韵7 | E22: 谭悦9 | G22: 大众点评 | H22: 无忧项目-班课 | J22: 开课后退费 | L22: 学员意愿转变_开课后 | Y22: 认为课程用处不大/不适合自己 | AA22: 学生姓名：许凯贤 学员编号：BJWY0058842315 报名班级：无忧英语政治 报名手机号：18611288017 考勤截至日期：10月19号 实际课消：英语2次课共4课时 退费明细：资料费用68.2元 其中已开课班次WYE27019退4184-（2/108）*21800-68.2元=3712.1元 其他未开课班次WYP27016，WYP27017，WYP27018，WYE27022，WYE27023退23116元 总退费金额：3712.1+23116=26828.1元 | AE22: 2025-10-30 | AF22: 首都体育学院 | AG22: 体育教育训练学院 | AH22: 在职 | AI22: 体育教育 | AJ22: 退费 | AK22: 余韵7 | AL22: 真实产生的退费 | AM22: 许凯贤 | AN22: BJWY0058842315 | AO22: 0 | AP22: 2025/10/31 | AQ22: 11.1已提交退款，目前显示退款失败商户头寸不足，原因如下图，辛苦老师确认@余韵7 (余韵)[图片] 10.31暂退学生账户，学生另一个班级课消有误@余韵7 (余韵) 10.30未办理，oa未到前台@余韵7 (余韵) | AV22: 魏公村班取消，不扣除业绩
E23: 谭悦9 | AL23: 网课退费 | AM23: 学员9ljko | AN23: 110139778 | AO23: 100 | AP23: 45961
E24: 谭悦9 | AL24: 网课退费 | AM24: DLS_5125394710 | AN24: 110976963 | AO24: 399 | AP24: 45943
E25: 谭悦9 | AL25: 网课退费 | AM25: DLS_4437884727 | AN25: 110159583 | AO25: 4695.6 | AP25: 45931
AN26: 谭悦合计 | AO26: =SUM(AO6:AO25) -> 69788.1
A27: 2025/10/17 | B27: 18950454 | C27: 罗志勇1 | E27: 赵星火 | G27: 直访 | H27: 四六级项目-班课 | J27: 开课前退费 | K27: 学员意愿转变_开课前 | N27: 个人身体原因无法承受高强度学习 | AA27: 【开课前退费】学生因为身体原因，无法参与学习，多次沟通不愿意转班或者是线上，申请退费。 | AE27: 2025-10-17 | AF27: 北京联合大学 | AG27: 历史 | AH27: 大二 | AI27: 历史学 | AJ27: 退费 | AK27: 罗志勇1 | AL27: 真实产生的退费 | AM27: 薛绍钧 | AN27: BJWY0461942484 | AO27: =6180/2 -> 3090 | AP27: 2025/10/30 | AQ27: 10.30已办理，原渠道是微信支付，已到账@罗志勇1 (罗志勇) [图片] 10.29未办理，oa未到前台@罗志勇1 (罗志勇) 未办理，OA未到前台（10.28）已经在群内同步提醒@罗志勇1 (罗志勇) 未办理，OA未到前台（10.27）@罗志勇1 (罗志勇) 未办理，OA未到前台（10.26）@罗志勇1 (罗志勇) 未办理，OA未到前台（10.24）@罗志勇1 (罗志勇) 未办理，OA未到前台（10.23）@罗志勇1 (罗志勇) 未办理，OA未到前台（10.22）@罗志勇1 (罗志勇) 未办理，OA未到前台（10.21） 未办理，OA未到前台（10.20） 未办理，OA未到前台（10.19） 未办理，OA未到前台（10.18） 未办理，OA未到前台（10.17） | AT27: TRUE | AV27: 和高龙明分单6180
A28: 2025/10/22 | B28: NO.2025102100844 | C28: 谢仕为1 | E28: 赵星火 | G28: 学管续费推荐 | H28: 集训营项目-专业课 | J28: 开课后退费 | L28: 计划冲突_开课后 | X28: 专业课学习时间和新东方时间冲突 | AA28: 学生觉得专业课内容太多 学不完 要调整一部分到公共课一对一上 | AE28: 2025-10-22 | AF28: 保定理工学院 | AG28: 资源与工程技术学院 | AH28: 大四 | AI28: 土地资源管理 | AJ28: 退费 | AK28: 谢仕为1 | AL28: 真实产生的退费 | AM28: 霍盈杉 | AN28: BJWY9038592627 | AO28: 6476 | AP28: 2025/10/22 | AQ28: 退至学员账户 | AT28: TRUE
A29: 2025/10/23 | B29: 18956851 | C29: 葛铭 | E29: 赵星火 | G29: 百度投放 | H29: 无忧项目-班课 | I29: 无忧项目 | J29: 开课后退费 | L29: 计划冲突_开课后 | X29: 个人生活/工作事务和新东方时间冲突 | AA29: 学员开学大三，明年正式考研，在报名蜂鸟英数班，报名时已确定后续冲刺班退出 | AB29: ¥18300.00 | AE29: 2025-10-23 | AF29: 北京电子科技大学 | AG29: 电子信息 | AH29: 大三 | AI29: 电子信息 | AJ29: 退费 | AK29: 葛铭 | AL29: 转项目/转班/退出重报等未产生实际退费 | AM29: 杨欣 | AN29: XDF3140342751 | AO29: 4121.2 | AP29: 2025/10/23 | AQ29: 已退回账户余额（10.23）@葛铭@赵星火 | AT29: TRUE
A30: 2025/10/23 | B30: 18956753 | C30: 葛铭 | E30: 赵星火 | G30: 百度投放 | H30: 无忧项目-班课 | I30: 无忧项目 | J30: 开课后退费 | L30: 计划冲突_开课后 | X30: 个人生活/工作事务和新东方时间冲突 | AA30: 学员开学大三，明年正式考研，在报名蜂鸟英数班，报名时已确定后续冲刺班退出。 | AB30: ¥18300.00 | AE30: 2025-10-23 | AF30: 北京电子科技大学 | AG30: 电子信息 | AH30: 大三 | AI30: 电子信息 | AJ30: 退费 | AK30: 葛铭 | AL30: 转项目/转班/退出重报等未产生实际退费 | AM30: 杨欣 | AN30: XDF3140342751 | AO30: 3978.9 | AP30: 2025/10/23 | AQ30: 已退回账户余额（10.23）@葛铭@赵星火 | AT30: TRUE
A31: 2025/10/23 | B31: 18956887 | C31: 葛铭 | E31: 赵星火 | G31: 百度投放 | H31: 无忧项目-班课 | J31: 开课后退费 | L31: 计划冲突_开课后 | X31: 个人生活/工作事务和新东方时间冲突 | AA31: 学员开学大三，明年正式考研，在报名蜂鸟英数班，报名时已确定后续冲刺班退出。 | AE31: 2025-10-23 | AF31: 北京信息科技大学 | AG31: 电子信息 | AH31: 大三 | AI31: 电子信息 | AJ31: 退费 | AK31: 葛铭 | AL31: 真实产生的退费 | AM31: 杨欣 | AN31: XDF3140342751 | AO31: 92.55 | AP31: 2025/10/26 | AQ31: 10.28顾问已确认，留在账户余额，已办理完成@赵星火@葛铭 10.28账户余额192.6元，需要怎么处理么？@葛铭@赵星火 10.26 退回账户余额92.5@葛铭@赵星火，这点零钱是要退回给家长吗？ 10.24未办理，退回后的oa未到前台@葛铭@赵星火 未办理：（10.23）OA金额有误，92.5不是92.55，OA已回退@葛铭 | AT31: TRUE
A32: 2025/10/27 | B32: 2025101702316 | C32: 徐岩91 | E32: 赵星火 | G32: 百度地图 | H32: 四六级项目-VIP | J32: 开课后退费 | L32: 学员意愿转变_开课后 | Y32: 认为课程用处不大/不适合自己 | AA32: 目前孩子比较抗拒上课，家长也没有办法，之前上六级没过，不想在上课了，已经说了可以上其他的科目，但家长还是坚持退费 | AE32: 2025-10-27 | AF32: 北京大学 | AG32: 物理学院 | AH32: 大二 | AI32: 物理学 | AJ32: 退费 | AK32: 徐岩91 | AL32: 真实产生的退费 | AM32: 田浩天 | AN32: BJWY9272845607 | AO32: 775 | AP32: 2025/10/29 | AQ32: 11.1显示已退款@徐岩91 (徐岩)[图片] 10.31用户已确认，退款中@徐岩91 (徐岩) 10.30用户已确认，退款中@徐岩91 (徐岩) [图片] 10.29微信支付的775元已经原路返回已经到账，700元渠道是支付宝，已失效，已提交手工退款，已发送确认短信到139****0325，需要用户短信确认@徐岩91 (徐岩)[图片] [图片] [图片] 10.28未办理，缺少顾问和学管老师的挽单截图@徐岩91 (徐岩) 未办理：缺少顾问和学管老师的挽单截图（10.27）@徐岩91 (徐岩) | AT32: TRUE | AV32: 两笔退费，第一笔700代离职顾问杨阳办理
AM33: 学员0wg6u | AN33: 100806138 | AO33: 100 | AQ33: 45960
AM34: DLS_0044058589 | AN34: 111045497 | AO34: 100 | AQ34: 45951
AM35: 学员7x9u_ | AN35: 104236314 | AO35: 7366.8 | AQ35: 45940
AN36: 赵星火合计 | AO36: =SUM(AO27:AO35) -> 26100.45

Sheet 10月绩效核算
B2: 顾问 | E2: 转介绍 | M2: 签约率 | U2: 日常管理 | AA2: 总计
B3: 工号 | C3: 顾问姓名 | D3: 备注 | E3: 工单目标 | F3: 工单实际 | G3: 完成率 | H3: 签约目标 | I3: 签约实际 | J3: 完成率 | K3: 占比 | L3: 得分 | M3: 主动目标 | N3: 主动实际 | O3: 完成情况 | P3: 被动目标 | Q3: 被动实际 | R3: 完成情况 | S3: 占比 | T3: 得分 | U3: 自签占比目标比 | V3: 实际 | W3: 占比 | X3: 回访时效 | Y3: 占比 | Z3: 得分 | AA3: 得分合计 | AB3: 绩效标准 | AC3: 发放比例 | AD3: 实发绩效
B4: 238256 | C4: 赵星火 | E4: 6 | F4: 0 | G4: =F4/E4 -> 0 | H4: 6 | I4: 1.9 | J4: =I4/H4 -> 0.31666667 | K4: 0.3 | L4: 0 | M4: 0.25 | N4: 0.42 | O4: 完成 | P4: 0.1 | Q4: 0.15 | R4: 完成 | S4: 0.4 | T4: 40 | U4: 0.3 | V4: 0.38 | W4: 0.2 | X4: 合格 | Y4: 0.1 | Z4: 30 | AA4: =L4+T4+Z4 -> 70 | AB4: 1000 | AC4: =(100-(90-AA4)*2)% -> 0.6 | AD4: =AB4*AC4 -> 600
B5: 404905 | C5: 李涛 | D5: 结束保护期 | E5: 2 | F5: 1 | G5: =F5/E5 -> 0.5 | H5: 2 | I5: 0 | J5: =I5/H5 -> 0 | K5: 0.3 | L5: 0 | M5: 0.1 | N5: 0.23 | O5: 完成 | P5: 0.1 | Q5: 0.26 | R5: 完成 | S5: 0.4 | T5: 40 | U5: 0.3 | V5: 0.69 | W5: 0.2 | X5: 合格 | Y5: 0.1 | Z5: =W5*100+10 -> 30 | AA5: =L5+T5+Z5 -> 70 | AB5: 2000 | AC5: =(100-(90-AA5)*2)% -> 0.6 | AD5: =AB5*AC5 -> 1200
B6: 341422 | C6: 谭悦 | D6: O3无考核指标 | E6: 6 | F6: 0 | G6: =F6/E6 -> 0 | H6: 6 | I6: 1.7587 | J6: =I6/H6 -> 0.29311667 | K6: 0.3 | L6: 0 | M6: 0.25 | N6: 0.45 | O6: 完成 | P6: 0.1 | Q6: 0.26 | R6: 完成 | S6: 0.4 | T6: 40 | U6: 0.3 | V6: 0.5 | W6: 0.2 | X6: 合格 | Y6: 0.1 | Z6: =W6*100+10 -> 30 | AA6: =L6+T6+Z6 -> 70 | AB6: 0 | AD6: =AB6*AA6% -> 0

Sheet 11月绩效目标
B2: 序号 | C2: 年月 | D2: 部门 | E2: 工号 | F2: 姓名 | G2: 岗位 | H2: 绩效考核项
H3: 1.签约业绩 | I3: 2.主被动转化率 | J3: 3.老带新工单/人头/金额 | K3: 4.项目自签占比 | L3: 5.回访时效
B4: 1 | C4: 202511 | D4: 个性化项目部 | E4: 238256 | F4: 赵星火 | G4: 学习顾问 | H4: 51.5w（含在线代售5000） | I4: 主动25%、被动10% | J4: 工单6/人头2/金额5 | K4: 0.35 | L4: 不低于中心75分位值
B5: 2 | C5: 202511 | E5: 341422 | F5: 谭悦 | H5: 51.5w（含在线代售5000） | I5: 主动25%、被动10% | J5: 工单6/人头2/金额5 | K5: 0.35 | L5: 不低于中心75分位值
B6: 3 | C6: 202511 | E6: 404905 | F6: 李涛 | H6: 51.4w（含在线代售4000） | I6: 主动20%、被动10% | J6: 工单4/人头2/金额4 | K6: 0.35 | L6: 不低于中心75分位值
I7: 占比40% | J7: 占比30% | K7: 占比30%

Sheet Sheet1
