Workbook

Sheet 汇总
B2: 业绩奖金表（一人可多条，需写清类别）
B3: 序号 | C3: 机构 | D3: 年月 | E3: 工号 | F3: 姓名 | G3: 部门 | H3: 薪资项目 | I3: 金额
B4: 1 | C4: 北京中心 | D4: 2025.06 | E4: 238256 | F4: 赵星火 | G4: A级学习顾问 | H4: 月度绩效 | I4: =顾问绩效!R4 -> 800
B5: 2 | C5: 北京中心 | D5: 2025.06 | E5: 238256 | F5: 赵星火 | G5: A级学习顾问 | H5: 顾问签约奖金 | I5: =业绩汇总表!M8 -> 6519.6664
B6: 3 | C6: 北京中心 | D6: 2025.06 | E6: 238256 | F6: 赵星火 | G6: A级学习顾问 | H6: 组长绩效 | I6: 0
B7: 4 | C7: 北京中心 | D7: 2025.06 | E7: 341422 | F7: 谭悦 | G7: B级学习顾问 | H7: 月度绩效 | I7: =顾问绩效!R5 -> 2000
B8: 5 | C8: 北京中心 | D8: 2025.06 | E8: 341422 | F8: 谭悦 | G8: B级学习顾问 | H8: 顾问签约奖金 | I8: =业绩汇总表!M7 -> 38700.501
B9: 6 | C9: 北京中心 | D9: 2025.06 | E9: 341422 | F9: 谭悦 | G9: B级学习顾问 | H9: 组长绩效 | I9: 0

Sheet 业绩汇总表
B5: 2025.06个性化顾问业绩
B6: 序号 | C6: 顾问姓名 | D6: 月度目标 | E6: 地面业绩 | F6: 网课代售业绩 | G6: 业绩合计 | H6: 线下退费 | I6: 网课退费 | J6: 退费合计 | K6: 综合业绩 | L6: 完成率
B7: 1 | C7: 谭悦 | D7: 1100000 | E7: =GETPIVOTDATA("学费",'91签约明细'!$B$2,"代售标签",,"签约单录入人","谭悦") -> 1468317.2 | F7: =GETPIVOTDATA("学费",'91签约明细'!$B$2,"代售标签","在线网课","签约单录入人","谭悦") -> 41749.7 | G7: =E7+F7 -> 1510066.9 | H7: ='退费（取自钉钉客服退费表单）'!X19 -> 220050.2 | I7: 0 | J7: =H7+I7 -> 220050.2 | K7: =G7-J7 -> 1290016.7 | L7: =K7/D7 -> 1.1727425 | M7: =K7*3% -> 38700.501
B8: 2 | C8: 星火 | D8: 1150000 | E8: =GETPIVOTDATA("学费",'91签约明细'!$B$2,"代售标签",,"签约单录入人","赵星火") -> 922880.8 | F8: =GETPIVOTDATA("学费",'91签约明细'!$B$2,"代售标签","在线网课","签约单录入人","赵星火") -> 67148.9 | G8: =E8+F8 -> 990029.7 | H8: =SUM('退费（取自钉钉客服退费表单）'!X21:X34) -> 166607.4 | I8: ='退费（取自钉钉客服退费表单）'!X35 -> 8464 | J8: =H8+I8 -> 175071.4 | K8: =G8-J8 -> 814958.3 | L8: =K8/D8 -> 0.70865939 | M8: =K8*0.008 -> 6519.6664
B9: 合计 | D9: =SUM(D7:D8) -> 2250000 | E9: =SUM(E7:E8) -> 2391198 | F9: =SUM(F7:F8) -> 108898.6 | G9: =E9+F9 -> 2500096.6 | H9: =SUM(H7:H8) -> 386657.6 | I9: =SUM(I7:I8) -> 8464 | J9: =H9+I9 -> 395121.6 | K9: =G9-J9 -> 2104975 | L9: =K9/D9 -> 0.93554444

Sheet 数据表1
A1: 提交日期 | B1: 您所办理的业务类型 | C1: OA流水号 | D1: 学管姓名 | E1: 学管是否代办 | F1: 顾问姓名 | G1: 顾问是否代办 | H1: 91系统-最新报名二级渠道 | I1: 原班所属项目 | J1: 新报入班级所属项目 | K1: 退费阶段 | L1: 退费一级原因（开课前） | M1: 退费一级原因 (开课后) | N1: 退费二级原因（专业课师资匹配原因） | O1: 退费二级原因（学员意愿转变_开课前） | P1: 退费二级原因（计划冲突_开课前） | Q1: 退费二级原因（中心原因_开课前） | R1: 退费二级原因（签约话术） | S1: 退费二级原因（教师） | T1: 退费二级原因（教学） | U1: 退费二级原因（课程安排） | V1: 退费二级原因（配套服务） | W1: 退费二级原因（配套学习设施） | X1: 退费二级原因（中心原因_开课后） | Y1: 退费二级原因（计划冲突_开课后） | Z1: 退费二级原因（学员意愿转变_开课后） | AA1: 退费三级原因（完全匹配不上）-院校、学院、专业、专业课代码及名称 | AB1: 退费详细原因说明（与OA退费详细说明保持一致） | AC1: 预计报名新班学费金额 | AD1: 转班金额（请学管填写所在班级实际金额） | AE1: 转班详细原因说明 | AF1: 提交时间 | AG1: 提交人 | AH1: 退费类型 | AI1: 学员姓名 | AJ1: 学员编码 | AK1: 退费金额 | AL1: 办理日期-客服 | AM1: 退费方式-客服 | AN1: 需要跟进的顾问/学管 | AO1: 退费/转班特殊情况备注（若需要学管提供银行卡信息，可将需求填写在此处）-客服 | AP1: 是否完成退费/转班-客服 | AQ1: 父记录 | AR1: 父记录
A2: 2025/05/28 | B2: 退费 | C2: 18649504 | D2: 郑雪新 | F2: 钱雪冰 | H2: 巨量广告 | I2: 集训营项目 | K2: 开课后退费 | M2: 学员意愿转变_开课后 | Z2: 个人身体原因无法承受高强度学习 | AB2: 刘浩宇BJWY3212612620自报到后提出了3次退费，先后跟妈妈共同沟通挽单无效；主要是自报到后睡眠效果不好，经济上感觉家里有压力，最终执意回家先备考（7-8月份还有一个专业课面授班）挽单失败，强冲阶段的费用明细： 1】KYJS25006A0079 KYJS25006A 26考研数学全年集训营（强冲）课前全额退15860 2】KYJY25006A0061 KYJY25006A 26考研英语全年集训营（强冲/英语一）课前全额退17870 3】KYJZ25006A0070 KYJZ25006A 26考研政治全年集训营（强冲）课前全额退12500 | AF2: 2025-06-30 | AG2: 郑雪新 | AH2: 真实产生的退费 | AI2: 刘浩宇 | AJ2: BJWY3212612620 | AK2: 46230 | AL2: 2025/06/18 | AM2: 微信共退90521 [图片] [图片] | AP2: TRUE
A3: 2025/05/28 | B3: 退费 | C3: 18649547 | D3: 郑雪新 | F3: 钱雪冰 | H3: 巨量广告 | I3: 集训营项目 | K3: 开课后退费 | M3: 学员意愿转变_开课后 | Z3: 个人身体原因无法承受高强度学习 | AB3: 刘浩宇BJWY3212612620自报到后提出了3次退费，先后跟妈妈共同沟通挽单无效；主要是自报到后睡眠效果不好，经济上感觉家里有压力，最终执意回家先备考（7-8月份还有一个专业课面授班）挽单失败 KYJY250070042 KYJY25007 26考研英语全年集训营（基础/四月）实缴13070--总课时58；课耗22；恋练有词88元--扣费：（13870/58*22）+88=5349.0--退还：13070-5349=7721.0 | AF3: 2025-06-30 | AG3: 郑雪新 | AH3: 真实产生的退费 | AI3: 刘浩宇 | AJ3: BJWY3212612620 | AK3: 7721 | AL3: 2025/06/18 | AM3: 微信共退90521 [图片] [图片] | AP3: TRUE
A4: 2025/05/28 | B4: 退费 | C4: 18649542 | D4: 郑雪新 | F4: 钱雪冰 | H4: 巨量广告 | I4: 集训营项目 | K4: 开课后退费 | M4: 学员意愿转变_开课后 | Z4: 个人身体原因无法承受高强度学习 | AB4: 刘浩宇BJWY3212612620自报到后提出了3次退费，先后跟妈妈共同沟通挽单无效；主要是自报到后睡眠效果不好，经济上感觉家里有压力，最终执意回家先备考（7-8月份还有一个专业课面授班）挽单失败 KYJS250070026 KYJS25007 26考研数学全年集训营（基础/四月）实缴7670--总课时52；课耗16；资料费43.8元--扣费：（8340/52*16）+43.8=2610.0--退还：7670-2610=5060.0 | AF4: 2025-06-30 | AG4: 郑雪新 | AH4: 真实产生的退费 | AI4: 刘浩宇 | AJ4: BJWY3212612620 | AK4: 5060 | AL4: 2025/06/18 | AM4: 微信共退90521 [图片] [图片] | AP4: TRUE
A5: 2025/05/28 | B5: 退费 | C5: 18649549 | D5: 郑雪新 | F5: 钱雪冰 | H5: 巨量广告 | I5: 集训营项目 | K5: 开课后退费 | M5: 学员意愿转变_开课后 | Z5: 个人身体原因无法承受高强度学习 | AB5: 刘浩宇BJWY3212612620自报到后提出了3次退费，先后跟妈妈共同沟通挽单无效；主要是自报到后睡眠效果不好，经济上感觉家里有压力，最终执意回家先备考（7-8月份还有一个专业课面授班）挽单失败 KYJZ250070042 KYJZ25007 26考研政治全年集训营（基础/四月）实缴7630--总课时40；课耗16；不涉及书本费--扣费：8300/40*16=3320--退还：7630-3320=4310.0 | AF5: 2025-06-30 | AG5: 郑雪新 | AH5: 真实产生的退费 | AI5: 刘浩宇 | AJ5: BJWY3212612620 | AK5: 4310 | AL5: 2025/06/18 | AM5: 微信共退90521 [图片] [图片] | AP5: TRUE
A6: 2025/05/30 | B6: 退费 | C6: 2025052100094 | D6: 张子晗67-张子晗 | F6: 刘晓娟 | H6: 虚拟人 | I6: 四六级项目 | K6: 开课后退费 | M6: 学员意愿转变_开课后 | Z6: 认为课程用处不大/不适合自己 | AB6: 学生认为课程不适合自己 | AF6: 2025-06-30 | AG6: 张子晗67-张子晗 | AH6: 真实产生的退费 | AI6: 金立威 | AJ6: BJWY0665091701 | AK6: 8388 | AL6: 2025/06/01 | AM6: 微信退回[图片] | AP6: TRUE
A7: 2025/06/01 | B7: 退费 | C7: 18658679 | D7: 王立颖17-王立颖 | F7: 杨明43-杨明（北京在职mba考研） | H7: 公众号 | I7: 在职研项目 | K7: 开课后退费 | M7: 学员意愿转变_开课后 | Z7: 选择出国留学 | AB7: 姓名：张元正 电话：13520118637 学员编号：BJWY3510399937 产品名称：ZZYG26002 考研在职管理类综合全程班（26） 退费原因：计划有变，准备出国留学。 实际退费金额=总课时费-课时消耗金额-教材费用 课耗金额=21800/70*6=1868.6元 教材费用=100元 实际退费金额=21300-1868.6-100=19331.4元 | AF7: 2025-06-30 | AG7: 王立颖17-王立颖 | AH7: 真实产生的退费 | AI7: 张元正 | AJ7: BJWY3510399937 | AK7: 19331.4 | AL7: 2025/06/03 | AM7: 微信退回 | AO7: [图片] | AP7: TRUE
A8: 2025/06/02 | B8: 退费 | C8: 2025052903139 | D8: 张泽7-张泽 | F8: 赵星火 | H8: 学管续费推荐 | I8: VIP项目 | J8: 无忧项目 | K8: 开课后退费 | M8: 学员意愿转变_开课后 | Z8: 认为课程用处不大/不适合自己 | AB8: 投诉学员乔怡娜，处理方案：一对一剩余课时费4000元，特殊申请转入无忧走读班级（原价25600），无需补充差价；6.28开课：英语二强化+冲刺WYFE26007,WYFE26008 政治：WYFP26003,WYFP26004 姓名：乔怡娜 学员号：BJWY3184144484 课时包编码：LP1715735991942，考研一对一伴学班（25考季） 退费原因：公共课未考到目标学校分数线剩余5小时需要退费，报如无忧班课 退费金额=报名金额-课消金额=32000-800*35=4000元 | AC8: ¥4000.00 | AF8: 2025-06-30 | AG8: 张泽7-张泽 | AH8: 转项目/转班/退出重报等未产生实际退费 | AI8: 乔怡娜 | AJ8: BJWY3184144484 | AK8: 4000 | AL8: 2025/06/02 | AM8: 退至学员账户 | AP8: TRUE
A9: 2025/05/21 | B9: 退费 | C9: NO.7205759403793977957 | D9: 马一鸣16-马一鸣 | F9: 钱雪冰 | H9: 学管续费推荐 | I9: 无忧项目 | K9: 开课后退费 | M9: 学员意愿转变_开课后 | Z9: 认为课程用处不大/不适合自己 | AB9: 学生初级会计师考试结束，不需要课程了。询问是否学习其他内容，学生不需要，坚持退费。 | AF9: 2025-06-30 | AG9: 马一鸣16-马一鸣 | AH9: 真实产生的退费 | AI9: 毕嫣然 | AJ9: BJWY2440766155 | AK9: 32600 | AL9: 2025/06/03 | AM9: 6.10财务反馈退款失败，已重新提交新的银行卡：毕嫣然6214686200322381北京海淀北京银行新华支行 | AP9: TRUE
A10: 2025/06/03 | B10: 退费 | C10: NO.18656618 | D10: 高龙明 | F10: 高龙明 | H10: 顾问转介绍-老带新 | I10: 集训营项目 | K10: 开课前退费 | L10: 学员意愿转变_开课前 | O10: 找到工作 | AB10: 学生找到工作不考研了 | AF10: 2025-06-30 | AG10: 高龙明 | AH10: 真实产生的退费 | AI10: 王鹏 | AJ10: BJWY7229276582 | AK10: 95000 | AL10: 2025/06/03 | AM10: 支付宝退回 | AP10: TRUE
A11: 2025/06/03 | B11: 退费 | C11: 18656571 | D11: 高龙明 | F11: 高龙明 | H11: 内部工单推荐 | I11: 集训营项目 | K11: 开课前退费 | L11: 学员意愿转变_开课前 | O11: 去其他机构 | AB11: 孩子不来学习，家长沟通过了，尊重孩子想法 | AF11: 2025-06-30 | AG11: 高龙明 | AH11: 真实产生的退费 | AI11: 关子仁 | AJ11: XDF6597266200 | AK11: 75920 | AL11: 2025/06/05 | AM11: 已手工退款 | AP11: TRUE
A12: 2025/06/03 | B12: 退费 | C12: 8646911284552491678 | D12: 高龙明 | F12: 高龙明 | H12: 内部工单推荐 | I12: 集训营项目 | K12: 开课前退费 | L12: 学员意愿转变_开课前 | O12: 去其他机构 | AB12: 孩子不来学习，家长沟通过了，尊重孩子想法 | AF12: 2025-06-30 | AG12: 高龙明 | AH12: 真实产生的退费 | AI12: 关子仁 | AJ12: XDF6597266200 | AK12: 11000 | AL12: 2025/06/10 | AM12: 已手工退款 | AP12: TRUE
A13: 2025/06/03 | B13: 退费 | C13: 2025060301379 | D13: 李润基 | F13: 徐健坤1-徐健坤 | H13: 地推 | I13: VIP项目 | K13: 开课后退费 | M13: 学员意愿转变_开课后 | Z13: 认为课程用处不大/不适合自己 | AB13: 学生对两节课不满意，故退4H，（37000/50×4h=2960元） | AF13: 2025-06-30 | AG13: 李润基 | AH13: 真实产生的退费 | AI13: 张艺璇 | AJ13: BJWY0321441887 | AK13: 2960 | AL13: 2025/06/06 | AM13: 支付宝退回 | AP13: TRUE
A14: 2025/06/03 | B14: 退费 | C14: 2025052600102 | D14: 韦艺鑫 | F14: 高龙明 | H14: 公众号 | I14: VIP项目 | J14: 无忧项目 | K14: 开课前退费 | L14: 中心原因_开课前 | Q14: 退出重报（报错班级） | AB14: 课时包无法直接转产品到无忧，退出重报 退费金额=缴费金额=25500元 | AC14: ¥25500.00 | AF14: 2025-06-30 | AG14: 韦艺鑫 | AH14: 转项目/转班/退出重报等未产生实际退费 | AI14: 刘怡然 | AJ14: BJWY2674858025 | AK14: 25500 | AL14: 2025/06/03 | AM14: 退回账户余额 | AP14: TRUE
A15: 2025/06/03 | B15: 退费 | C15: 18664265 | D15: 郝琨 | F15: 刘创9-刘创（北京考研/四六级） | G15: TRUE | H15: 大众点评 | I15: 无忧项目 | K15: 开课后退费 | M15: 学员意愿转变_开课后 | Z15: 选择出国留学 | AB15: 学生姓名：邱浩嘉学员编号：BJWY9031976688退费方式：报英政数专退全科退费原因：学生考研留学两手准备，4.6号沟通转5月班级学习，最后出勤截止到4.6号，未到转班时间学生现在已经申请好英国的学校，提出退费退费班级：WYE26033、WYE26031、WYE26032、WYM26013、WYM26014、WYM26015、WYP26026、WYP26027、WYP26025退费明细：实缴金额：44800；课消费用：5301.8；教材费：198应退金额：实缴金额-课消-教材费=44800-5301.8-198=39300.2元 学生现金支付退回银行卡：6214 6800 8868 3543 北京银行田村支行 | AF15: 2025-06-30 | AG15: 郝琨 | AH15: 真实产生的退费 | AI15: 邱浩嘉 | AJ15: BJWY9031976688 | AK15: 2942.4 | AL15: 2025/06/04 | AM15: 6.11退款完成49300.2—————— ​原支付渠道为现金，6.10已转手工退至学员本人银行卡：邱浩嘉6214680088683543北京银行田村支行 | AP15: TRUE
A16: 2025/06/03 | B16: 退费 | C16: 18664327 | D16: 郝琨 | F16: 刘创9-刘创（北京考研/四六级） | G16: TRUE | H16: 大众点评 | I16: 无忧项目 | K16: 开课后退费 | M16: 学员意愿转变_开课后 | Z16: 选择出国留学 | AB16: 学生姓名：邱浩嘉学员编号：BJWY9031976688退费方式：报英政数专退全科退费原因：学生考研留学两手准备，4.6号沟通转5月班级学习，最后出勤截止到4.6号，未到转班时间学生现在已经申请好英国的学校，提出退费退费班级：WYE26033、WYE26031、WYE26032、WYM26013、WYM26014、WYM26015、WYP26026、WYP26027、WYP26025退费明细：实缴金额：44800；课消费用：5301.8；教材费：198应退金额：实缴金额-课消-教材费=44800-5301.8-198=39300.2元 学生现金支付退回银行卡：6214 6800 8868 3543 北京银行田村支行 | AF16: 2025-06-30 | AG16: 郝琨 | AH16: 真实产生的退费 | AI16: 邱浩嘉 | AJ16: BJWY9031976688 | AK16: 3445.6 | AL16: 2025/06/04 | AM16: 6.11退款完成49300.2—————— ​原支付渠道为现金，6.10已转手工退至学员本人银行卡：邱浩嘉6214680088683543北京银行田村支行 | AP16: TRUE
A17: 2025/06/03 | B17: 退费 | C17: 18664353 | D17: 郝琨 | F17: 刘创9-刘创（北京考研/四六级） | G17: TRUE | H17: 大众点评 | I17: 无忧项目 | K17: 开课后退费 | M17: 学员意愿转变_开课后 | Z17: 选择出国留学 | AB17: 学生姓名：邱浩嘉学员编号：BJWY9031976688退费方式：报英政数专退全科退费原因：学生考研留学两手准备，4.6号沟通转5月班级学习，最后出勤截止到4.6号，未到转班时间学生现在已经申请好英国的学校，提出退费退费班级：WYE26033、WYE26031、WYE26032、WYM26013、WYM26014、WYM26015、WYP26026、WYP26027、WYP26025退费明细：实缴金额：44800；课消费用：5301.8；教材费：198应退金额：实缴金额-课消-教材费=44800-5301.8-198=39300.2元 学生现金支付退回银行卡：6214 6800 8868 3543 北京银行田村支行 | AF17: 2025-06-30 | AG17: 郝琨 | AH17: 真实产生的退费 | AI17: 邱浩嘉 | AJ17: BJWY9031976688 | AK17: 4577.6 | AL17: 2025/06/04 | AM17: 6.11退款完成49300.2—————— ​原支付渠道为现金，6.10已转手工退至学员本人银行卡：邱浩嘉6214680088683543北京银行田村支行 | AP17: TRUE
A18: 2025/06/03 | B18: 退费 | C18: 18664390 | D18: 郝琨 | F18: 刘创9-刘创（北京考研/四六级） | G18: TRUE | H18: 大众点评 | I18: 无忧项目 | K18: 开课后退费 | M18: 学员意愿转变_开课后 | Z18: 选择出国留学 | AB18: 学生姓名：邱浩嘉学员编号：BJWY9031976688退费方式：报英政数专退全科退费原因：学生考研留学两手准备，4.6号沟通转5月班级学习，最后出勤截止到4.6号，未到转班时间学生现在已经申请好英国的学校，提出退费退费班级：WYE26033、WYE26031、WYE26032、WYM26013、WYM26014、WYM26015、WYP26026、WYP26027、WYP26025退费明细：实缴金额：44800；课消费用：5301.8；教材费：198应退金额：实缴金额-课消-教材费=44800-5301.8-198=39300.2元 学生现金支付退回银行卡：6214 6800 8868 3543 北京银行田村支行 | AF18: 2025-06-30 | AG18: 郝琨 | AH18: 真实产生的退费 | AI18: 邱浩嘉 | AJ18: BJWY9031976688 | AK18: 28334.6 | AL18: 2025/06/04 | AM18: 6.11退款完成49300.2—————— ​原支付渠道为现金，6.10已转手工退至学员本人银行卡：邱浩嘉6214680088683543北京银行田村支行 | AP18: TRUE
A19: 2025/06/03 | B19: 退费 | C19: 18664899 | D19: 葛铭 | F19: 刘海玲 | H19: 小红书 | I19: 无忧项目 | K19: 开课后退费 | M19: 学员意愿转变_开课后 | Z19: 选择出国留学 | AB19: 学员出国，放弃考研 | AF19: 2025-06-30 | AG19: 葛铭 | AH19: 真实产生的退费 | AI19: 李芊雨 | AJ19: BJWY2714713335 | AK19: 10528 | AL19: 2025/06/06 | AM19: 微信退13245.3 | AO19: [图片] | AP19: TRUE
A20: 2025/06/03 | B20: 退费 | C20: 18664846 | D20: 葛铭 | F20: 刘海玲 | H20: 小红书 | I20: 无忧项目 | K20: 开课后退费 | M20: 学员意愿转变_开课后 | Z20: 选择出国留学 | AB20: 学员出国，放弃考研 | AF20: 2025-06-30 | AG20: 葛铭 | AH20: 真实产生的退费 | AI20: 李芊雨 | AJ20: BJWY2714713335 | AK20: 2717.3 | AL20: 2025/06/06 | AM20: 微信退13245.3 | AO20: [图片] | AP20: TRUE
A21: 2025/06/03 | B21: 退费 | C21: NO.3746994889973389362 | D21: 陈猛飞 | F21: 李崇宇1-李崇宇（北京考研/四六级） | H21: 其他网络投放 | I21: 无忧项目 | K21: 开课后退费 | M21: 学员意愿转变_开课后 | Z21: 认为课程用处不大/不适合自己 | AB21: 学生上了一段时间专业课，由于家庭原因和学生觉得这部分内容自己可以自学解决，坚持退掉专业课 | AF21: 2025-06-30 | AG21: 陈猛飞 | AH21: 真实产生的退费 | AI21: 孟凡宇 | AJ21: BJWY5191841449 | AK21: 13588 | AL21: 2025/06/10 | AM21: 支付宝退回 | AP21: TRUE
A22: 2025/06/03 | B22: 退费 | C22: 18664589 | D22: 汤之然 | F22: 刘贵宁 | H22: 直访 | I22: 英语学习部 | K22: 开课后退费 | M22: 学员意愿转变_开课后 | Z22: 英学专用——不再需要此类课程 | AB22: 青少学员报名一对一课程进行考前冲刺，上完后未消耗课程已办理退费，现在考试结果出来了学员考试没过要投诉，咨询法务老师建议全额退款降低风险，申请已消耗的费用3600元全额退款。已走邮件申请 | AF22: 2025-06-30 | AG22: 汤之然 | AH22: 真实产生的退费 | AI22: 傅方静 | AJ22: BJWY5845279213 | AK22: 3600 | AL22: 2025/06/03 | AM22: 支付宝退3600 | AO22: [图片] | AP22: TRUE
A23: 2025/06/04 | B23: 退费 | C23: 18664187 | D23: 韦艺鑫 | F23: 刘创9-刘创（北京考研/四六级） | H23: 新东方在线员工推荐 | I23: 无忧项目 | K23: 开课后退费 | M23: 计划冲突_开课后 | Y23: 学校事务和新东方时间冲突 | AB23: 因为学校绩点原因再次延毕，需要重修20门课，无法参加26考研，也不考虑转到27考研，需要先处理学校毕业的事情 | AF23: 2025-06-30 | AG23: 韦艺鑫 | AH23: 真实产生的退费 | AI23: 史一博 | AJ23: BJWY4662945918 | AK23: 2055.6 | AL23: 2025/06/04 | AM23: 6.5已转手工退至学员本人银行卡：史一博6212260200196036251中国工商银行石景山玉泉路支行 | AP23: TRUE
A24: 2025/06/04 | B24: 退费 | C24: 18664211 | D24: 韦艺鑫 | F24: 刘创9-刘创（北京考研/四六级） | H24: 新东方在线员工推荐 | I24: 无忧项目 | K24: 开课前退费 | L24: 计划冲突_开课前 | P24: 学校事务和新东方时间冲突 | AB24: 因为学校绩点原因再次延毕，需要重修20门课，无法参加26考研，也不考虑转到27考研，需要先处理学校毕业的事情 | AF24: 2025-06-30 | AG24: 韦艺鑫 | AH24: 真实产生的退费 | AI24: 史一博 | AJ24: BJWY4662945918 | AK24: 10500 | AL24: 2025/06/04 | AM24: 6.5已转手工退至学员本人银行卡：史一博6212260200196036251中国工商银行石景山玉泉路支行 | AP24: TRUE
A25: 2025/06/03 | B25: 退费 | C25: NO.1166353 | D25: 马一鸣16-马一鸣 | F25: 周佳欣17-周佳欣-武汉考研四六级 | H25: 大众点评 | I25: 无忧项目 | K25: 开课前退费 | L25: 学员意愿转变_开课前 | O25: 选择出国留学 | AB25: 学生考研留学两手准备，3.30号学生沟通先暂停考研。学生现在已经申请好英国的学校，提出退费。 | AF25: 2025-06-30 | AG25: 马一鸣16-马一鸣 | AH25: 真实产生的退费 | AI25: 邱浩嘉 | AJ25: BJWY9031976688 | AK25: 10000 | AL25: 2025/06/10 | AM25: 6.11退款完成49300.2—————— ​原支付渠道为现金，6.10已转手工退至学员本人银行卡：邱浩嘉6214680088683543北京银行田村支行 | AP25: TRUE
A26: 2025/05/18 | B26: 退费 | C26: 18632485 | D26: 陈号东5-陈号东 | F26: 李崇宇1-李崇宇（北京考研/四六级） | H26: 小红书 | I26: 无忧项目 | K26: 开课后退费 | M26: 学员意愿转变_开课后 | Z26: 考研信心不足（因跟不上、基础薄弱、目标过高） | AB26: 学生和家长表示跨专业考试难度大，不计划考研 | AF26: 2025-06-30 | AG26: 陈号东5-陈号东 | AH26: 真实产生的退费 | AI26: 彭迦奥 | AJ26: XDF2736875298 | AK26: 4451.1 | AL26: 2025/06/04 | AM26: 支付宝退回 | AP26: TRUE
A27: 2025/05/18 | B27: 退费 | C27: 18632563 | D27: 陈号东5-陈号东 | F27: 李崇宇1-李崇宇（北京考研/四六级） | H27: 小红书 | I27: 无忧项目 | K27: 开课前退费 | L27: 学员意愿转变_开课前 | O27: 考研信心不足（因跟不上、基础薄弱、目标过高） | AB27: 学生和家长表示跨专业考试难度大，不计划考研 | AF27: 2025-06-30 | AG27: 陈号东5-陈号东 | AH27: 真实产生的退费 | AI27: 彭迦奥 | AJ27: XDF2736875298 | AK27: 17357.7 | AL27: 2025/06/04 | AM27: 支付宝退回 | AP27: TRUE
A28: 2025/06/18 | B28: 转班 | D28: 陈号东5-陈号东 | F28: 高龙明 | H28: 小红书 | I28: 无忧项目 | AD28: 11900 | AE28: 学生由英语一改考英语二 | AF28: 2025-06-30 | AG28: 陈号东5-陈号东 | AI28: 王朗芮 | AJ28: BJWY3327364490 | AL28: 2025/06/04 | AM28: 支付宝退回 | AP28: TRUE
A29: 2025/06/04 | B29: 退费 | C29: NO.5476377146883719625 | D29: 王士源13-王士源 | F29: 钱雪冰 | H29: 顾问转介绍-老带新 | I29: 集训营项目 | K29: 开课前退费 | L29: 学员意愿转变_开课前 | O29: 家人不支持考研/不支持跟班学习/意见不一致 | AB29: 学员报入后提供了择校服务，搜集了大量的相关资料,但学员近期说自己找到了研究生老师上课，询问后学员决定不在新东方学习专业课。 | AF29: 2025-06-30 | AG29: 王士源13-王士源 | AH29: 真实产生的退费 | AI29: 傅鑫昕 | AJ29: BJWY8658310322 | AK29: 23500 | AL29: 2025/06/10 | AM29: 支付宝退回 | AP29: TRUE
A30: 2025/06/04 | B30: 转班 | D30: 葛铭 | F30: 赵星火 | H30: 百度投放 | I30: 无忧项目 | AD30: 44800 | AE30: 学员时间冲突，申请转班 | AF30: 2025-06-30 | AG30: 葛铭 | AI30: 李尚烨 | AJ30: BJWY8264939203 | AL30: 2025/06/04 | AM30: 已转班 | AP30: TRUE
A31: 2025/06/04 | B31: 退费 | C31: NO.8358680908400807930 | D31: 郭又华 | F31: 谭悦9-谭悦 | H31: 代理商合作 | I31: 无忧项目 | K31: 开课后退费 | M31: 学员意愿转变_开课后 | Z31: 选择出国留学 | AB31: 学生今年计划出国，不打算考研了，目前也没有其他课程需求，后边有需要再联系。 | AF31: 2025-06-30 | AG31: 郭又华 | AH31: 真实产生的退费 | AI31: 何禹轩 | AJ31: BJWY2841652509 | AK31: 1979.6 | AL31: 2025/06/10 | AM31: 6.18退款完成22397.3—————— 6.17已经提交报账单 6.16转手工22397.3，待客户短信确认（@史文涵1 (史文涵)@郭又华）———————— 22397.3退回账户余额，原支付渠道微信超时失效，请提供学员本人银行卡手工退款：@谭悦9 (谭悦)@史文涵1 (史文涵)@郭又华 [图片] 暂退至学员账户，等无忧退费后一起提现 | AP31: TRUE
A32: 2025/06/04 | B32: 退费 | C32: 18668674 | D32: 葛铭 | F32: 赵星火 | H32: 新东方PC官网 | I32: 无忧项目 | K32: 开课后退费 | M32: 学员意愿转变_开课后 | Z32: 家人不支持考研/不支持跟班学习/意见不一致 | AB32: 学员家长生病，无法考研，申请退费 | AF32: 2025-06-30 | AG32: 葛铭 | AH32: 真实产生的退费 | AI32: 董菡 | AJ32: BJWY1429919607 | AK32: 25758.3 | AM32: 【作废】学管已重新提交OA | AP32: TRUE
A33: 2025/06/04 | B33: 退费 | C33: 18669053 | D33: 葛铭 | F33: 刘创9-刘创（北京考研/四六级） | H33: 新东方官网M站 | I33: 无忧项目 | K33: 开课后退费 | M33: 计划冲突_开课后 | Y33: 个人生活/工作事务和新东方时间冲突 | AB33: 学员怀孕，不能线下上课 | AF33: 2025-06-30 | AG33: 葛铭 | AH33: 真实产生的退费 | AI33: 李静 | AJ33: BJWY0432862919 | AK33: 11702 | AL33: 2025/06/16 | AM33: 6.22原路径支付宝退回 6.18强化班未申请新OA，等中—————— 6.16冲刺班已退，暂退账户4000，等强化班一起提现。 强化班需扣除198教材费，需单独申请OA，申请金额7900-198@葛铭[图片] | AP33: TRUE
A34: 2025/06/04 | B34: 退费 | C34: NO.3746994889973391167 | D34: 王嘉庆5-王嘉庆 | F34: 刘欢67-刘欢 | H34: 集团-百度品专 | I34: VIP项目 | K34: 开课后退费 | M34: 学员意愿转变_开课后 | Z34: 经济困难 | AB34: 学生家中出现变故，不打算继续考研，且不考虑转其他课程 | AF34: 2025-06-30 | AG34: 王嘉庆5-王嘉庆 | AH34: 真实产生的退费 | AI34: 孙畅 | AJ34: BJWY9068474562 | AK34: 4640 | AL34: 2025/06/10 | AM34: 微信退回 | AP34: TRUE
A35: 2025/06/04 | B35: 退费 | C35: 2025060402257 | D35: 黄小妹7-黄小妹 | F35: 谭悦9-谭悦 | H35: 学管续费推荐 | I35: VIP项目 | J35: 无忧项目 | K35: 开课前退费 | L35: 中心原因_开课前 | Q35: 退出重报（取消班/合班/延转/选班/扩科等） | AB35: 无课程消耗，需要退出报入 考研一对一VIP伴学(60小时/26考季)一对一-无忧 | AC35: ¥46800.00 | AF35: 2025-06-30 | AG35: 黄小妹7-黄小妹 | AH35: 转项目/转班/退出重报等未产生实际退费 | AI35: 孙洢妮 | AJ35: BJWY3739115067 | AK35: 46800 | AL35: 2025/06/10 | AM35: 退回账户余额 | AP35: TRUE
A36: 2025/06/04 | B36: 退费 | C36: 18668851 | D36: 李梦娇4-李梦娇 | F36: 刘贵宁 | H36: 学管续费推荐 | I36: 英语学习部 | K36: 开课后退费 | M36: 学员意愿转变_开课后 | Z36: 去其他机构 | AB36: 家长说家门口开了一个补习班，还是想要线下上课，申请退费 | AF36: 2025-06-30 | AG36: 李梦娇4-李梦娇 | AH36: 真实产生的退费 | AI36: 马荟坪 | AJ36: BJWY3479839951 | AK36: 38640 | AL36: 2025/06/04 | AM36: 支付宝退回 | AP36: TRUE
A37: 2025/06/04 | B37: 转班 | D37: 汤之然 | F37: 刘贵宁 | H37: 小红书 | I37: 英语学习部 | AD37: 6800 | AE37: 时间原因转班，原班未出勤 | AF37: 2025-06-30 | AG37: 汤之然 | AI37: 王玉雯 | AJ37: BJWY5216506845 | AL37: 2025/06/04 | AM37: 已转班 | AP37: TRUE
A38: 2025/06/04 | B38: 退费 | C38: 2025060403432 | D38: 刘畅778-刘畅 | F38: 刘文君6-刘文君(北京四六级/专四专八/大学预科) | H38: 学管续费推荐 | I38: 四六级项目 | J38: 四六级项目 | K38: 开课后退费 | M38: 教师 | S38: 教学能力 | AB38: 家长对老师授课不满意，要求换老师 | AC38: ¥2600.00 | AF38: 2025-06-30 | AG38: 刘畅778-刘畅 | AH38: 转项目/转班/退出重报等未产生实际退费 | AI38: 李奇霖 | AJ38: BJWY9604668618 | AK38: 1800 | AL38: 2025/06/05 | AM38: 退回学员账户余额 | AP38: TRUE
A39: 2025/06/05 | B39: 退费 | C39: 18666373 | D39: 刘爱馨-爱馨 | F39: 刘爱馨-爱馨 | H39: 小红书 | I39: 英语学习部 | K39: 开课后退费 | M39: 学员意愿转变_开课后 | Z39: 英学专用——不再需要此类课程 | AB39: 学生个人规划原因，无法安排后续学习。 | AF39: 2025-06-30 | AG39: 王宇乾16-王宇乾 | AH39: 真实产生的退费 | AI39: 周晓夏 | AJ39: BJWY3567803585 | AK39: 4500 | AL39: 2025/06/05 | AM39: 支付宝退回 | AP39: TRUE
A40: 2025/06/05 | B40: 退费 | C40: 18666347 | D40: 刘爱馨-爱馨 | F40: 刘爱馨-爱馨 | H40: 小红书 | I40: 英语学习部 | K40: 开课后退费 | M40: 学员意愿转变_开课后 | Z40: 英学专用——不再需要此类课程 | AB40: 学生个人规划原因，无法安排后续学习。 | AF40: 2025-06-30 | AG40: 王宇乾16-王宇乾 | AH40: 真实产生的退费 | AI40: 周晓夏 | AJ40: BJWY3567803585 | AK40: 5850 | AL40: 2025/06/05 | AM40: 支付宝退回 | AP40: TRUE
...

Sheet 退费（取自钉钉客服退费表单）
A1: 提交日期 | B1: 您所办理的业务类型 | C1: OA流水号 | D1: 学管姓名 | E1: 学管是否代办 | F1: 顾问姓名 | G1: 顾问是否代办 | H1: 91系统-最新报名二级渠道 | I1: 原班所属项目 | J1: 新报入班级所属项目 | K1: 退费阶段 | L1: 退费一级原因（开课前） | M1: 退费二级原因（学员意愿转变_开课后） | N1: 退费三级原因（完全匹配不上）-院校、学院、专业、专业课代码及名称 | O1: 退费详细原因说明（与OA退费详细说明保持一致） | P1: 预计报名新班学费金额 | Q1: 转班金额（请学管填写所在班级实际金额） | R1: 转班详细原因说明 | S1: 提交时间 | T1: 提交人 | U1: 退费类型 | V1: 学员姓名 | W1: 学员编码 | X1: 退费金额 | Y1: 办理日期-客服 | Z1: 退费方式-客服 | AA1: 需要跟进的顾问/学管 | AB1: 退费/转班特殊情况备注（若需要学管提供银行卡信息，可将需求填写在此处）-客服 | AC1: 是否完成退费/转班-客服 | AD1: 父记录 | AE1: 父记录
A2: 2025/06/04 | B2: 退费 | C2: NO.8358680908400807930 | D2: 郭又华 | F2: 谭悦9-谭悦 | H2: 代理商合作 | I2: 无忧项目 | K2: 开课后退费 | M2: 选择出国留学 | O2: 学生今年计划出国，不打算考研了，目前也没有其他课程需求，后边有需要再联系。 | S2: 2025-06-30 | T2: 郭又华 | U2: 真实产生的退费 | V2: 何禹轩 | W2: BJWY2841652509 | X2: 1979.6 | Y2: 2025/06/10 | Z2: 6.18退款完成22397.3—————— 6.17已经提交报账单 6.16转手工22397.3，待客户短信确认（@史文涵1 (史文涵)@郭又华）———————— 22397.3退回账户余额，原支付渠道微信超时失效，请提供学员本人银行卡手工退款：@谭悦9 (谭悦)@史文涵1 (史文涵)@郭又华 [图片] 暂退至学员账户，等无忧退费后一起提现 | AC2: TRUE
A3: 2025/06/04 | B3: 退费 | C3: 2025060402257 | D3: 黄小妹7-黄小妹 | F3: 谭悦9-谭悦 | H3: 学管续费推荐 | I3: VIP项目 | J3: 无忧项目 | K3: 开课前退费 | L3: 中心原因_开课前 | O3: 无课程消耗，需要退出报入 考研一对一VIP伴学(60小时/26考季)一对一-无忧 | P3: ¥46800.00 | S3: 2025-06-30 | T3: 黄小妹7-黄小妹 | U3: 转项目/转班/退出重报等未产生实际退费 | V3: 孙洢妮 | W3: BJWY3739115067 | X3: 46800 | Y3: 2025/06/10 | Z3: 退回账户余额 | AC3: TRUE
A4: 2025/06/12 | B4: 退费 | C4: 18686243 | D4: 史文涵1-史文涵 | F4: 谭悦9-谭悦 | H4: 代理商合作 | I4: 无忧项目 | K4: 开课后退费 | M4: 选择出国留学 | O4: 学生今年计划出国，不打算考研了 | S4: 2025-06-30 | T4: 史文涵1-史文涵 | U4: 真实产生的退费 | V4: 何禹轩 | W4: BJWY2841652509 | X4: 0 | Y4: 2025/06/13 | Z4: 6.18退款完成22397.3———————— 6.17已提交报账单 6.16转手工22397.3，待客户短信确认（@史文涵1 (史文涵)@郭又华）———————— 22397.3退回账户余额，原支付渠道微信超时失效，请提供学员本人银行卡手工退款：@谭悦9 (谭悦)@史文涵1 (史文涵)@郭又华 [图片] 暂退至学员账户，等无忧退费后一起提现 | AC4: TRUE
A5: 2025/06/12 | B5: 退费 | C5: 18686291 | D5: 史文涵1-史文涵 | F5: 谭悦9-谭悦 | H5: 代理商合作 | I5: 无忧项目 | K5: 开课后退费 | M5: 选择出国留学 | O5: 学生今年计划出国，不打算考研了 | S5: 2025-06-30 | T5: 史文涵1-史文涵 | U5: 真实产生的退费 | V5: 何禹轩 | W5: BJWY2841652509 | X5: 3140.1 | Y5: 2025/06/13 | Z5: 6.18退款完成22397.3———————— 6.17已提交报账单 6.16转手工22397.3，待客户短信确认（@史文涵1 (史文涵)@郭又华）———————— 22397.3退回账户余额，原支付渠道微信超时失效，请提供学员本人银行卡手工退款：@谭悦9 (谭悦)@史文涵1 (史文涵)@郭又华 [图片] 暂退至学员账户，等无忧退费后一起提现 | AC5: TRUE
A6: 2025/06/12 | B6: 退费 | C6: 18686324 | D6: 史文涵1-史文涵 | F6: 谭悦9-谭悦 | H6: 代理商合作 | I6: 无忧项目 | K6: 开课后退费 | M6: 选择出国留学 | O6: 学生今年计划出国，不打算考研了 | S6: 2025-06-30 | T6: 史文涵1-史文涵 | U6: 真实产生的退费 | V6: 何禹轩 | W6: BJWY2841652509 | X6: 0 | Y6: 2025/06/13 | Z6: 6.18退款完成22397.3———————— 6.17已提交报账单 6.16转手工22397.3，待客户短信确认（@史文涵1 (史文涵)@郭又华）———————— 22397.3退回账户余额，原支付渠道微信超时失效，请提供学员本人银行卡手工退款：@谭悦9 (谭悦)@史文涵1 (史文涵)@郭又华 [图片] 暂退至学员账户，等无忧退费后一起提现 | AC6: TRUE
A7: 2025/06/12 | B7: 退费 | C7: 18686362 | D7: 史文涵1-史文涵 | F7: 谭悦9-谭悦 | H7: 代理商合作 | I7: 无忧项目 | K7: 开课后退费 | M7: 选择出国留学 | O7: 学生今年计划出国，不打算考研了 | S7: 2025-06-30 | T7: 史文涵1-史文涵 | U7: 真实产生的退费 | V7: 何禹轩 | W7: BJWY2841652509 | X7: 3595 | Y7: 2025/06/13 | Z7: 6.18退款完成22397.3———————— 6.17已提交报账单 6.16转手工22397.3，待客户短信确认（@史文涵1 (史文涵)@郭又华）———————— 22397.3退回账户余额，原支付渠道微信超时失效，请提供学员本人银行卡手工退款：@谭悦9 (谭悦)@史文涵1 (史文涵)@郭又华 [图片] 暂退至学员账户，等无忧退费后一起提现 | AC7: TRUE
A8: 2025/06/12 | B8: 退费 | C8: 18686450 | D8: 史文涵1-史文涵 | F8: 谭悦9-谭悦 | H8: 代理商合作 | I8: 无忧项目 | K8: 开课后退费 | M8: 选择出国留学 | O8: 学生今年计划出国，不打算考研了 | S8: 2025-06-30 | T8: 史文涵1-史文涵 | U8: 真实产生的退费 | V8: 何禹轩 | W8: BJWY2841652509 | X8: 0 | Y8: 2025/06/13 | Z8: 6.18退款完成22397.3———————— 6.17已提交报账单 6.16转手工22397.3，待客户短信确认（@史文涵1 (史文涵)@郭又华）———————— 22397.3退回账户余额，原支付渠道微信超时失效，请提供学员本人银行卡手工退款：@谭悦9 (谭悦)@史文涵1 (史文涵)@郭又华 [图片] 暂退至学员账户，等无忧退费后一起提现 | AC8: TRUE
A9: 2025/06/12 | B9: 退费 | C9: 18686483 | D9: 史文涵1-史文涵 | F9: 谭悦9-谭悦 | H9: 代理商合作 | I9: 无忧项目 | K9: 开课后退费 | M9: 选择出国留学 | O9: 学生今年计划出国，不打算考研了 | S9: 2025-06-30 | T9: 史文涵1-史文涵 | U9: 真实产生的退费 | V9: 何禹轩 | W9: BJWY2841652509 | X9: 2530.3 | Y9: 2025/06/13 | Z9: 6.18退款完成22397.3———————— 6.17已提交报账单 6.16转手工22397.3，待客户短信确认（@史文涵1 (史文涵)@郭又华）———————— 22397.3退回账户余额，原支付渠道微信超时失效，请提供学员本人银行卡手工退款：@谭悦9 (谭悦)@史文涵1 (史文涵)@郭又华 [图片] 暂退至学员账户，等无忧退费后一起提现 | AC9: TRUE
A10: 2025/06/12 | B10: 退费 | C10: 18686559 | D10: 史文涵1-史文涵 | F10: 谭悦9-谭悦 | H10: 代理商合作 | I10: 无忧项目 | K10: 开课后退费 | M10: 选择出国留学 | O10: 学生今年计划出国，不打算考研了 | S10: 2025-06-30 | T10: 史文涵1-史文涵 | U10: 真实产生的退费 | V10: 何禹轩 | W10: BJWY2841652509 | X10: 11152.3 | Y10: 2025/06/13 | Z10: 6.18退款完成22397.3———————— 6.17已提交报账单 6.16转手工22397.3，待客户短信确认（@史文涵1 (史文涵)@郭又华）———————— 22397.3退回账户余额，原支付渠道微信超时失效，请提供学员本人银行卡手工退款：@谭悦9 (谭悦)@史文涵1 (史文涵)@郭又华 [图片] 暂退至学员账户，等无忧退费后一起提现 | AC10: TRUE
A11: 2025/06/15 | B11: 转班 | D11: 史文涵1-史文涵 | F11: 谭悦9-谭悦 | H11: 代理商合作 | I11: 无忧项目 | R11: 退费需转班 | S11: 2025-06-30 | T11: 史文涵1-史文涵 | V11: 何禹轩 | W11: BJWY2841652509 | X11: 7890.6 | Y11: 2025/06/15 | Z11: 已转班 | AC11: TRUE
A12: 2025/06/18 | B12: 转班 | D12: 唐源曼 | F12: 谭悦9-谭悦 | G12: TRUE | H12: 知了好学 | I12: 集训营项目 | R12: 学生从英政经综班转到英政数班。价格一样，开课前转班。 | S12: 2025-06-30 | T12: 谭悦9-谭悦 | V12: 王英帆 | W12: BJWY4965756550 | X12: 94500 | Y12: 2025/06/19 | Z12: 已转班 | AC12: TRUE
A13: 2025/06/23 | B13: 转班 | D13: 郝琨 | F13: 谭悦9-谭悦 | H13: 阿里本地通 | I13: 无忧项目 | R13: 姓名：朱建金 电话：15910521973 学员编号：BJWY1520278143 转班原因：学生目前没定好院校，先按照英一准备 转班信息： WYE26028、WYE26029转WYE26026、WYE26027 已登记表格，辛苦老师办理 | S13: 2025-06-30 | T13: 郝琨 | V13: 朱建金 | W13: BJWY1520278143 | X13: 9959.6 | Y13: 2025/06/24 | Z13: 已转班 | AC13: TRUE
A14: 2025/06/24 | B14: 退费 | C14: 2882303761518362655 | D14: 王天义56-王天义 | E14: TRUE | F14: 谭悦9-谭悦 | H14: 学管续费推荐 | I14: VIP项目 | K14: 开课后退费 | M14: 认为课程用处不大/不适合自己 | O14: 25 考季复试学员，已上岸，交接时与学员电话沟通，剩余 2课时，学员要求退费，劝说保留四六级，学生 ok；5月 26 日与学员沟通上六级冲刺课程，学员不回复；目前要求退费，再次劝说课程报名时候应该用了一些优惠，退费的话课时可惜，推荐六级或雅思课，学员坚持退费。 退费核算：补专业课优惠：4800-4554=246 元；退费金额=总课时费-消耗课时费-补专业课优惠=9746-10*900-246 =500 元 | S14: 2025-06-30 | T14: 王天义56-王天义 | U14: 真实产生的退费 | V14: 张梓靖 | W14: BJWY8290701880 | X14: 500 | Y14: 2025/06/30 | Z14: 微信退回500元，账户246元补专业课优惠 | AC14: TRUE
A15: 2025/06/25 | B15: 转班 | D15: 葛铭 | F15: 谭悦9-谭悦 | H15: 大众点评 | I15: 无忧项目 | R15: 学员专业变化，需要转班 | S15: 2025-06-30 | T15: 葛铭 | V15: 付豪 | W15: BJWY0827309575 | X15: 9849.7 | Y15: 2025/06/25 | Z15: 已转班 | AC15: TRUE
A16: 2025/06/25 | B16: 退费 | C16: NO.1152921504608122823 | D16: 王嘉庆5-王嘉庆 | F16: 谭悦9-谭悦 | H16: 内部工单推荐 | I16: 无忧项目 | J16: 无忧项目 | K16: 开课后退费 | O16: 学生目标专业改考408，打算将专业课一对一课程改为408班课 | P16: ¥18800.00 | S16: 2025-06-30 | T16: 王嘉庆5-王嘉庆 | U16: 转项目/转班/退出重报等未产生实际退费 | V16: 林子策 | W16: BJWY0442645574 | X16: 8873 | Y16: 2025/06/28 | Z16: 退回学员账户余额 | AC16: TRUE
A17: 2025/06/27 | B17: 转班 | D17: 李小龙25-李小龙 | F17: 谭悦9-谭悦 | H17: 学管转介绍 | I17: 四六级项目 | R17: 学员暑期有事情，转到二期上课 | S17: 2025-06-30 | T17: 李小龙25-李小龙 | V17: 程悦 | W17: BJWY8477545262 | X17: 6480 | Y17: 2025/06/27 | Z17: 已转班 | AC17: TRUE
A18: 2025/06/30 | B18: 转班 | D18: 许庆典 | F18: 谭悦9-谭悦 | H18: 社群、虚拟人 | I18: 无忧项目 | R18: 学生英语一改考英语二。 | S18: 2025-06-30 | T18: 许庆典 | V18: 张霄翮 | W18: BJWY1043586545 | X18: 12800 | Y18: 2025/06/30 | Z18: 已转班 | AC18: TRUE
W19: 谭悦退费 | X19: =SUM(X2:X18) -> 220050.2
A20: 2025/06/02 | B20: 退费 | C20: 2025052903139 | D20: 张泽7-张泽 | F20: 赵星火 | H20: 学管续费推荐 | I20: VIP项目 | J20: 无忧项目 | K20: 开课后退费 | M20: 认为课程用处不大/不适合自己 | O20: 投诉学员乔怡娜，处理方案：一对一剩余课时费4000元，特殊申请转入无忧走读班级（原价25600），无需补充差价；6.28开课：英语二强化+冲刺WYFE26007,WYFE26008 政治：WYFP26003,WYFP26004 姓名：乔怡娜 学员号：BJWY3184144484 课时包编码：LP1715735991942，考研一对一伴学班（25考季） 退费原因：公共课未考到目标学校分数线剩余5小时需要退费，报如无忧班课 退费金额=报名金额-课消金额=32000-800*35=4000元 | P20: ¥4000.00 | S20: 2025-06-30 | T20: 张泽7-张泽 | U20: 转项目/转班/退出重报等未产生实际退费 | V20: 乔怡娜 | W20: BJWY3184144484 | Y20: 2025/06/02 | Z20: 退至学员账户 | AC20: TRUE | AD20: 特殊投诉学员，退转特批入班，换顾问跟进，新班级未绑定业绩， | AE20: 4000
A21: 2025/06/04 | B21: 转班 | D21: 葛铭 | F21: 赵星火 | H21: 百度投放 | I21: 无忧项目 | R21: 学员时间冲突，申请转班 | S21: 2025-06-30 | T21: 葛铭 | V21: 李尚烨 | W21: BJWY8264939203 | X21: 44800 | Y21: 2025/06/04 | Z21: 已转班 | AC21: TRUE
A22: 2025/06/04 | B22: 退费 | C22: 18668674 | D22: 葛铭 | F22: 赵星火 | H22: 新东方PC官网 | I22: 无忧项目 | K22: 开课后退费 | M22: 家人不支持考研/不支持跟班学习/意见不一致 | O22: 学员家长生病，无法考研，申请退费 | S22: 2025-06-30 | T22: 葛铭 | U22: 真实产生的退费 | V22: 董菡 | W22: BJWY1429919607 | X22: 25758.3 | Z22: 【作废】学管已重新提交OA | AC22: TRUE
A23: 2025/06/06 | B23: 退费 | C23: 18668674 | D23: 葛铭 | F23: 赵星火 | H23: 新东方官网M站 | I23: 无忧项目 | K23: 开课后退费 | O23: 学员 家长生病，放弃考研 | S23: 2025-06-30 | T23: 葛铭 | U23: 真实产生的退费 | V23: 董菡 | W23: BJWY1429919607 | X23: 21026.2 | Y23: 2025/06/10 | Z23: 支付宝退回 | AC23: TRUE
A24: 2025/06/06 | B24: 退费 | C24: 18674781 | D24: 葛铭 | F24: 赵星火 | H24: 新东方官网M站 | I24: 无忧项目 | K24: 开课后退费 | O24: 学员 家长生病，放弃考研 | S24: 2025-06-30 | T24: 葛铭 | U24: 真实产生的退费 | V24: 董菡 | W24: BJWY1429919607 | X24: 4732.1 | Y24: 2025/06/10 | Z24: 支付宝退回 | AC24: TRUE
A25: 2025/06/08 | B25: 退费 | C25: NO.2882303761518315242 | D25: 王嘉庆5-王嘉庆 | F25: 赵星火 | H25: 新东方PC官网 | I25: 无忧项目 | K25: 开课后退费 | M25: 家人不支持考研/不支持跟班学习/意见不一致 | O25: 学生家中有特殊情况，目前时间不支持继续考研，且不考虑转其他课程 | S25: 2025-06-30 | T25: 王嘉庆5-王嘉庆 | U25: 真实产生的退费 | V25: 董菡 | W25: BJWY1429919607 | X25: 727 | Y25: 2025/06/14 | Z25: 支付宝原路退回 | AC25: TRUE
A26: 2025/06/13 | B26: 退费 | C26: 2025060301380 | D26: 李玉迪1-李玉迪 | F26: 赵星火 | G26: TRUE | H26: 学管续费推荐 | I26: 四六级项目 | K26: 开课后退费 | M26: 自己找到老师复习 | O26: 学员觉得之后没有什么课程需要了。申请退费，学生有考研想法，确定在别的机构学习。这个学生只想上女老师的课，但是学数学专业，专业课数学部分只有曹超老师可以讲解，上过一次曹老师的课觉得不太喜欢，目前跟成小伟老师上课，成老师讲不了考研专业课部分。 | S26: 2025-06-30 | T26: 李玉迪1-李玉迪 | U26: 真实产生的退费 | V26: 潘雨时 | W26: BJWY2595990334 | X26: 20400 | Y26: 2025/06/14 | Z26: 6.17付款完成 6.14已转手工，等待用户短信自助确认 | AC26: TRUE
A27: 2025/06/10 | B27: 退费 | C27: NO.18688753 | D27: 王立颖17-王立颖 | F27: 赵星火 | H27: 内部工单推荐 | I27: 在职研项目 | K27: 开课后退费 | M27: 考研信心不足（因跟不上、基础薄弱、目标过高） | O27: 退费原因：学生目标是北大EMBA，不学习MBA 辅导课程，尝试学习过管综，觉得完全跟不上。 | S27: 2025-06-30 | T27: 王立颖17-王立颖 | U27: 真实产生的退费 | V27: 黄琳 | W27: BJWY4447076368 | X27: 11146.5 | Y27: 2025/06/14 | Z27: 微信退回28980.4（6.15） | AC27: TRUE
A28: 2025/06/10 | B28: 退费 | C28: NO.18688836 | D28: 王立颖17-王立颖 | F28: 赵星火 | H28: 内部工单推荐 | I28: 在职研项目 | K28: 开课后退费 | M28: 考研信心不足（因跟不上、基础薄弱、目标过高） | O28: 退费原因：学生目标是北大EMBA，不学习MBA 辅导课程，尝试学习过管综，觉得完全跟不上。 | S28: 2025-06-30 | T28: 王立颖17-王立颖 | U28: 真实产生的退费 | V28: 黄琳 | W28: BJWY4447076368 | X28: 10907 | Y28: 2025/06/15 | Z28: 微信退回28980.4（6.15） | AC28: TRUE
A29: 2025/06/10 | B29: 退费 | C29: NO.18688904 | D29: 王立颖17-王立颖 | F29: 赵星火 | H29: 内部工单推荐 | I29: 在职研项目 | K29: 开课后退费 | M29: 考研信心不足（因跟不上、基础薄弱、目标过高） | O29: 退费原因：学生目标是北大EMBA，不学习MBA 辅导课程，尝试学习过管综，觉得完全跟不上。 | S29: 2025-06-30 | T29: 王立颖17-王立颖 | U29: 真实产生的退费 | V29: 黄琳 | W29: BJWY4447076368 | X29: 4760.7 | Y29: 2025/06/14 | Z29: 微信退回28980.4（6.15） | AC29: TRUE
A30: 2025/06/10 | B30: 退费 | C30: NO.18688920 | D30: 王立颖17-王立颖 | F30: 赵星火 | H30: 内部工单推荐 | I30: 在职研项目 | K30: 开课后退费 | M30: 考研信心不足（因跟不上、基础薄弱、目标过高） | O30: 退费原因：学生目标是北大EMBA，不学习MBA 辅导课程，尝试学习过管综，觉得完全跟不上。 | S30: 2025-06-30 | T30: 王立颖17-王立颖 | U30: 真实产生的退费 | V30: 黄琳 | W30: BJWY4447076368 | X30: 2166.2 | Y30: 2025/06/14 | Z30: 微信退回28980.4（6.15） | AC30: TRUE
A31: 2025/06/22 | B31: 退费 | C31: 18724459 | D31: 黄小妹7-黄小妹 | F31: 赵星火 | H31: 学管续费推荐 | I31: 无忧项目 | K31: 开课后退费 | O31: 【开课后退费】学生毕业后北京无住宿条件，已经入营，退费班课。 | S31: 2025-06-30 | T31: 黄小妹7-黄小妹 | U31: 真实产生的退费 | V31: 赵祥辰 | W31: BJWY8097075006 | X31: 11623.1 | Y31: 2025/06/23 | Z31: 微信退回 | AC31: TRUE
A32: 2025/06/22 | B32: 退费 | C32: 18724348 | D32: 黄小妹7-黄小妹 | F32: 赵星火 | H32: 学管续费推荐 | I32: 无忧项目 | K32: 开课后退费 | O32: 【开课后退费】学生毕业后北京无住宿条件，已经入营，退费班课。 | S32: 2025-06-30 | T32: 黄小妹7-黄小妹 | U32: 真实产生的退费 | V32: 赵祥辰 | W32: BJWY8097075006 | X32: 443.6 | Y32: 2025/06/23 | Z32: 微信退回 | AC32: TRUE
A33: 2025/06/06 | B33: 退费 | C33: NO.7782220156097415399 | D33: 刘佳林25-刘佳林 | F33: 高龙明,赵星火 | H33: 直访 | I33: 集训营项目 | K33: 开课后退费 | M33: 认为课程用处不大/不适合自己 | O33: 学生目前三战，目前觉得专业课不符合预期，不适合自己，也不考虑其他课程，经挽单也坚持退费 | S33: 2025-06-30 | T33: 刘佳林25-刘佳林 | U33: 真实产生的退费 | V33: 王嘉祥 | W33: BJWY4539181865 | X33: =AE33/2 -> 3116.7 | Y33: 2025/06/15 | Z33: 6.25付款成功。退款待到账（6.25）,6.17转手工退 [图片] | AC33: TRUE | AD33: 高龙明分单 | AE33: 6233.4
C34: 18733849 | D34: 郝琨 | E34: FALSE | F34: 陈伟钰1-陈伟钰,苏乾楠-苏乾楠（北京考研四六级） | G34: FALSE | H34: 直访 | I34: 无忧项目 | J34: 无忧项目 | K34: 开课前退费 | L34: 中心原因_开课前 | Q34: 退出重报（取消班/合班/延转/选班/扩科等） | T34: 郝琨 | U34: 转项目/转班/退出重报等未产生实际退费 | V34: 张文 | W34: BJWY3211945534 | X34: =AE34/2 -> 5000 | Y34: 45836 | Z34: 账户余额 | AC34: TRUE | AD34: 高龙明分单 | AE34: 10000 | AM34: 退回学员账户余额
F35: 赵星火 | I35: 在线网课 | O35: 生姓名： 张文学员编号：BJWY3211945534退费方式：退出重报退费原因：学生要考自主命题院校，从408班课转专业课一对一退费班级：WYC26001退费明细：实缴价格=10000元，退出金额10000元 | V35: 学员1pg3r | W35: 108722739 | X35: 8464 | Y35: 2025/06/28
W36: 星火退费 | X36: =SUM(X20:X34:X35) -> 175071.4

Sheet 顾问绩效
B2: FY26-6月个性化顾问绩效核算
B3: 工号 | C3: 顾问 | D3: 转介绍工单目标 | E3: 转介绍工单完成 | F3: 顾问转介绍得分（50） | G3: 转介绍签约目标 | H3: 转介绍签约完成 | I3: 转介绍签约的份（30） | J3: 主动转化率目标 | K3: 主动转化率 | L3: 被动转化率目标 | M3: 被动转化率 | N3: 转化率得分（20） | O3: 合计得分 | P3: 发放比例 | Q3: 月度绩效标准 | R3: 月绩效应发
B4: 238256 | C4: 赵星火 | D4: 3 | E4: 3 | F4: 50 | G4: 1 | H4: 2 | I4: 30 | J4: 0.3 | K4: =39/135 -> 0.28888889 | L4: 0.1 | M4: =3/60 -> 0.05 | N4: 0 | O4: =F4+I4+N4 -> 80 | P4: =IF(AND(O4<70),0,IF(AND(O4>=70,O4<90),O4/100,1)) -> 0.8 | Q4: 1000 | R4: =Q4*P4 -> 800
B5: 341422 | C5: 谭悦 | D5: 3 | E5: 7 | F5: 50 | G5: 1 | H5: 2 | I5: 30 | J5: 0.3 | K5: =52/132 -> 0.39393939 | L5: 0.1 | M5: =8/51 -> 0.15686275 | N5: 20 | O5: =F5+I5+N5 -> 100 | P5: =IF(AND(O5<70),0,IF(AND(O5>=70,O5<90),O5/100,1)) -> 1 | Q5: 2000 | R5: =Q5*P5 -> 2000

Sheet 91签约明细
B2: 签约单录入人 | C2: 代售标签 | D2: 求和项:学费
B3: 谭悦 | C3: 在线网课 | D3: 41749.7
C4: (空白) | D4: 1468317.2
B5: 谭悦 汇总 | D5: 1510066.9
B6: 赵星火 | C6: 在线网课 | D6: 67148.9
C7: (空白) | D7: 922880.8
B8: 赵星火 汇总 | D8: 990029.7
B9: 总计 | D9: 2500096.6
A11: 代售标签 | B11: 序号 | C11: 学校 | D11: 部门 | E11: 资源姓名 | F11: 资源ID | G11: 资源录入人 | H11: 资源录入时间 | I11: 资源描述 | J11: 市场活动 | K11: 资源年级 | L11: 分配顾问/TMK | M11: 一级获取渠道 | N11: 二级获取渠道 | O11: 转介绍人 | P11: TMK激活人 | Q11: TMK激活处理时间 | R11: 工单姓名 | S11: 跟进顾问 | T11: 工单ID | U11: 工单类型 | V11: 工单录入时间 | W11: 工单等级 | X11: 咨询课程 | Y11: 工单年级 | Z11: 学校 | AA11: 院系 | AB11: 专业 | AC11: 签约学生姓名 | AD11: 签约单ID | AE11: 签约单录入人 | AF11: 签约单录入时间 | AG11: 签约单更新人 | AH11: 签约单更新时间 | AI11: 班号 | AJ11: 班级名称 | AK11: 面询表类型 | AL11: 订金 | AM11: 学费 | AN11: 续费类型 | AO11: 推荐人 | AP11: 类型 | AQ11: 是否交接 | AR11: 操作人编号 | AS11: 学员号 | AT11: 听课证号 | AU11: 报班日期 | AV11: 学员状态 | AW11: 回访记录 | AX11: 新老生类型 | AY11: 退费金额 | AZ11: 退费日期 | BA11: 课程类型 | BB11: 客户ID | BC11: 是否新东方在线签约 | BD11: 考季 | BE11: 报名产品 | BF11: 报名科目 | BG11: 意向报考专业 | BH11: 学校班型/类型 | BI11: 是否关联协议 | BJ11: 特殊备注 | BK11: 产品品类 | BL11: 业务类型 | BM11: 签约列表在线学员ID | BN11: 大学生源类型 | BO11: 资源来源
B12: 1 | C12: 北京大学部 | D12: 国内大学部 | E12: 同学 | F12: 116722017 | G12: 吴凯龙 | H12: 2025-06-30 13:56:56 | I12: 谭悦9的顾问转介绍工单 | K12: 大二 | L12: 谭悦 | M12: 转介绍 | N12: 顾问转介绍-老带新 | O12: 谭悦tanyue9@xdf.cn | R12: 姜源 | S12: 谭悦 | T12: 28724631 | U12: 正常工单 | V12: 2025-06-30 14:07 | W12: A（六个月内有报课意向工单） | X12: 六级 | Y12: 大二 | Z12: 西华大学 | AA12: 金融 | AB12: 金融 | AC12: 姜源 | AD12: 5461899 | AE12: 谭悦 | AF12: 2025-06-30 19:54 | AG12: 谭悦 | AH12: 2025-06-30 19:54 | AI12: ZVVB26001 | AJ12: 六级暑假集训营（24H冲刺直播） | AK12: 国内考试 | AM12: 15000 | AO12: 谭悦 | AP12: 新签 | AQ12: 已交接 | AR12: BJWY2011wXCx1W | AS12: BJWY7326008490 | AT12: ZVVB260010032 | AU12: 2025-06-30 | AW12: 回访人：谭悦，回访时间：2025-06-30 14:07，回访内容：准备报名六级集训营 ；|回访人：谭悦，回访时间：2025-06-30 19:54，回访内容：1 | BB12: 80739196 | BC12: 否 | BD12: 26上考季 | BE12: 六级无忧计划 | BH12: 国内高校-C9 | BI12: 是 | BL12: 报名 | BN12: 本地人外地大学(归巢) | BO12: 客服
A13: 在线网课 | B13: 2 | C13: 北京大学部 | D13: 国内大学部 | E13: 魏小姐 | F13: 115503604 | G13: 张亚男 | H13: 2025-06-20 19:56:01 | I13: 渠道录入来源：集团百度投放-基木鱼 账户名：baidu-大学-总部-A22KA00038 线索ID：250620465438808391 线索时间：2025-06-20 19:55:56 页面名称：新东方考研品专 姓名：魏小姐 城市：北京 IP：2409:8a00:8433:4f0:d0aa:bf9:75d3:a380 来源页：https://aisite.wejianzhan.com/site/wjzswa2z/73c5def5-883c-47c6-9bd9-9ce1d92bf9bf?wd=%E6%96%B0%E4%B8%9C%E6%96%B9%E8%80%83%E7%A0%94&utm_source=0_02_searchengine_Baidu_m_market&utm_medium=CPD&utm_campaign=DXSYB_XX_BD_DXPP-WY_M_240924&utm_1st_id=7&utm_2nd_id=63&xdf_source_channel_code=9ddc99f35fa8479d92b29f6c0ee04c33&wid=65437bc36a42436d8a6ec1e177ccb52f_0_0 | J13: 2026财年第1财月集团百度投放-基木鱼 | L13: 赵星火 | M13: 线上运营-投放 | N13: 集团-百度品专 | R13: 魏小姐 | S13: 赵星火 | T13: 28488427 | U13: 正常工单 | V13: 2025-06-20 20:27 | W13: A（六个月内有报课意向工单） | X13: MBA | Y13: 在职 | Z13: 北京工业大学 | AA13: 信息学部 | AB13: 信息安全（实验班） | AC13: 魏小姐 | AD13: 5433227 | AE13: 赵星火 | AF13: 2025-06-30 20:38 | AG13: 赵星火 | AH13: 2025-06-30 20:41 | AI13: 45374323934 | AJ13: 2026考研管综全科在职优学班（4期） | AK13: 国内考试 | AM13: 11385 | AP13: 新签 | AQ13: 无须交接 | AU13: 2025-06-30 | AW13: 回访人：赵星火，回访时间：2025-06-21 11:06，回访内容：回访学生现在了解情况跟进中，发送充足介绍内容；|回访人：赵星火，回访时间：2025-06-27 16:52，回访内容：感觉价格贵，在就是重读的话，没有择校服务这些要跟家里在沟通下。；|回访人：赵星火，回访时间：2025-06-30 17:10，回访内容：关注学生这边重读条件，跟进中，要过线不过线的问题。 | BA13: 长期班 | BB13: 80201508 | BC13: 是 | BD13: 26考季 | BE13: 考研在职管理类冲刺精讲班 | BF13: 英语 | BH13: 国内高校-211 | BI13: 否 | BM13: 110462239 | BO13: 集团百度投放-基木鱼
B14: 3 | C14: 北京大学部 | D14: 国内大学部 | E14: 郭宸宇 | F14: 116756538 | G14: 李润基 | H14: 2025-06-30 15:42:33 | I14: 续费原因：家长对数学没需求了，想了解六级班课，家长已主动联系谭悦老师（原来的顾问），很信任原顾问谭悦老师；该学生为保护期内续费，原顾问：国内大学部-谭悦(tanyue9@xdf.cn) | K14: 大一 | L14: 谭悦 | M14: 转介绍 | N14: 学管续费推荐 | O14: 李润基lirunji@xdf.cn | R14: 郭宸宇 | S14: 谭悦 | T14: 28737200 | U14: 续费工单 | V14: 2025-06-30 15:55 | W14: A（六个月内有报课意向工单） | X14: 六级 | Y14: 大一 | Z14: 北京工业大学 | AA14: 经济与管理学院 | AB14: 金融学 | AC14: 郭宸宇 | AD14: 5406309 | AE14: 谭悦 | AF14: 2025-06-30 19:42 | AG14: 谭悦 | AH14: 2025-06-30 19:42 | AI14: WYSJ25033 | AJ14: 六级无忧计划 | AK14: 国内考试 | AM14: 5180 | AN14: 同科续费 | AO14: 李润基 | AP14: 续班 | AQ14: 已交接 | AR14: WebReg | AS14: BJWY5305138836 | AT14: WYSJ250330038 | AU14: 2025-06-30 | AW14: 回访人：谭悦，回访时间：2025-06-30 15:55，回访内容：微信跟进中， 六级暑假班 ；|回访人：谭悦，回访时间：2025-06-30 19:42，回访内容：签约 | BB14: 59798822 | BC14: 否 | BD14: 25下考季 | BE14: 六级无忧计划 | BH14: 国内高校-211 | BI14: 是 | BL14: 报名 | BN14: 本地人本地大学(常规) | BO14: 学管续费推荐
A15: 在线网课 | B15: 4 | C15: 北京大学部 | D15: 国内大学部 | E15: 上海市4988 | F15: 116596886 | G15: 杨俊42(国内) | H15: 2025-06-28 18:59:51 | I15: 渠道录入来源：新东方PC官网-客服 意向城市：北京访客省/城市：上海市 访客静态ID：01000000034659110818227981814988 接待分组ID：70447 搜索引擎： 搜索词： 关键词： 设备类型：pc 访客IP：124.76.128.169 对话详细内容：AI-Lbo0rDBXCyBY 2025-06-28 18:56:22_x000D_ 您好同学,欢迎访问北京新东方考研四六级中心. 考研线下课程26/27考季【考研全年集训营】【考研半年集训营】【考研全科线下走读班】【考研寒/暑假集训营】【考研一对一】【考研专业课】【四/六级课程】，热门课程火热报名中,咨询即可领取专享优惠。 **【考研全年集训营】=ff761f# **【考研半年集训营】=ff6b6b# **【考研全科线下走读班】=ffc158# **【考研寒/暑假集训营】=ffc158# **【考研一对一】=ff761f# **【考研专业课】=ff6caa# **【四/六级课程】=ff6caa# **【考研冲刺班】=60e27e#_x000D_ _x000D_ AI-Lbo0rDBXCyBY 2025-06-28 18:56:25_x000D_ 您是想咨询【线下课程】【线上课程】【考研规划】还是【在职考研】呢？**【线下课程】# **【线上课程】#**【考研规划】#**【在职考研】#_x000D_ _x000D_ 01000000034659110818227981814988 2025-06-28 18:56:37_x000D_ 【线上课程】_x000D_ _x000D_ AI-Lbo0rDBXCyBY 2025-06-28 18:56:40_x000D_ 同学，你现在是在校还是在职呢？_x000D_ _x000D_ 01000000034659110818227981814988 2025-06-28 18:56:48_x000D_ 在校_x000D_ _x000D_ AI-Lbo0rDBXCyBY 2025-06-28 18:56:52_x000D_ 具体是想报考什么学校和专业呢？_x000D_ _x000D_ 01000000034659110818227981814988 2025-06-28 18:57:09_x000D_ 想报考上海财经大学的管理科学与工程专业_x000D_ _x000D_ AI-Lbo0rDBXCyBY 2025-06-28 18:57:12_x000D_ 好的，我这边安排专业老师给您回电，详细沟通一下，请问您的电话是多少呢？_x000D_ _x000D_ 01000000034659110818227981814988 2025-06-28 18:57:28_x000D_ 能不能微信，不方便电话_x000D_ _x000D_ AI-Lbo0rDBXCyBY 2025-06-28 18:57:32_x000D_ 那方便接收短信吗？您可以先留个电话，我安排顾问先给您发条短信介绍下，或者微信也可以。_x000D_ _x000D_ 01000000034659110818227981814988 2025-06-28 18:57:50_x000D_ 微信号是m17358738071_x000D_ _x000D_ AI-Lbo0rDBXCyBY 2025-06-28 18:57:54_x000D_ 好的，确认一下您的号码是否正确呢？_x000D_ _x000D_ 01000000034659110818227981814988 2025-06-28 18:58:16_x000D_ 正确_x000D_ _x000D_ AI-Lbo0rDBXCyBY 2025-06-28 18:58:20_x000D_ 同学怎么称呼呢？_x000D_ _x000D_ 01000000034659110818227981814988 2025-06-28 18:59:28_x000D_ 先加我微信再说别的_x000D_ _x000D_ AI-Lbo0rDBXCyBY 2025-06-28 18:59:31_x000D_ 这边马上安排顾问老师联系您，预计半个小时左右给您回电请注意接听~_x000D_ _x000D_ 来源页：https://www.xdf.cn/beijing/ 备注： | J15: 2026财年第1财月易聊新东方PC官网 | L15: 王静静 | M15: 新东方官网 | N15: 新东方PC官网 | P15: 王静静 | Q15: 2025-06-28 19:58:25 | R15: 上海市4988 | S15: 赵星火 | T15: 28693701 | U15: 正常工单 | V15: 2025-06-29 11:05 | W15: A（六个月内有报课意向工单） | X15: 考研专业课 | Y15: 大三 | Z15: 上海财经大学 | AA15: 信息管理与工程学院 | AB15: 管理科学与工程 | AC15: 上海市4988 | AD15: 5459675 | AE15: 赵星火 | AF15: 2025-06-29 20:10 | AG15: 赵星火 | AH15: 2025-06-29 20:14 | AI15: 10684230642 | AJ15: 2026考研管综全科在校直通车（3期） | AK15: 国内考试 | AM15: 10778 | AP15: 新签 | AQ15: 无须交接 | AU15: 2025-06-29 | AW15: 回访人：赵星火，回访时间：2025-06-29 11:05，回访内容：学生咨询专业课的考研辅导，开学大四考本校管理科技工程也想了解网课的英证数，已经推荐跟家里沟通 | BA15: 长期班 | BB15: 80705989 | BC15: 是 | BD15: 26考季 | BE15: 考研专业课150 | BF15: 专业课150 | BG15: 其他 | BH15: 国内高校-211 | BI15: 否 | BM15: 110457362 | BN15: 外地人外地大学(常规) | BO15: 新东方官网-易聊
B16: 5 | C16: 北京大学部 | D16: 国内大学部 | F16: 95537575 | H16: 2025-02-25 13:45:01 | I16: 知春路 赵星火(资源备注人:李雪68;资源备注时间:2025-02-25 13:46) | K16: 未知 | L16: 赵星火 | M16: 直访 | N16: 直访 | R16: 张文 | S16: 陈伟钰 | T16: 28714784 | U16: 续费工单 | V16: 2025-06-29 14:15 | W16: A（六个月内有报课意向工单） | X16: 考研专业课,考研无忧计划 | Y16: 大三 | Z16: 北京邮电大学世纪学院 | AA16: 计算机科学与技术系 | AB16: 计算机科学与技术（移动互联网应用方向） | AC16: 张文 | AD16: 5458743 | AE16: 赵星火 | AF16: 2025-06-29 14:17 | AG16: 陈伟钰 | AH16: 2025-06-29 15:39 | AK16: 国内考试 | AM16: 5000 | AP16: 分单 | AQ16: 已交接 | AS16: BJWY3211945534 | AW16: 回访人：陈伟钰，回访时间：2025-06-29 14:15，回访内容：1；|回访人：陈伟钰，回访时间：2025-06-29 14:17，回访内容：1 | BB16: 67265543 | BC16: 否 | BD16: 26考季 | BE16: 无忧计划-啄木鸟,考研专业课150 | BF16: 英语,政治,数学,专业课150 | BH16: 国内高校-双非 | BI16: 否 | BN16: 本地人本地大学(常规)
B17: 6 | C17: 北京大学部 | D17: 国内大学部 | E17: 罗宇航 | F17: 116618352 | G17: 马一鸣 | H17: 2025-06-29 13:03:33 | I17: 续费原因：交3000的升级费，辛苦老师收取一下，学生知道；该学生为保护期内续费，原顾问：国内大学部-谭悦(tanyue9@xdf.cn) | K17: 大三 | L17: 谭悦 | M17: 转介绍 | N17: 学管续费推荐 | O17: 马一鸣mayiming16@xdf.cn | R17: 罗宇航 | S17: 谭悦 | T17: 28714516 | U17: 续费工单 | V17: 2025-06-29 13:52 | W17: A（六个月内有报课意向工单） | X17: 考研专业课 | Y17: 大三 | Z17: 天津大学 | AA17: 化工学院 | AB17: 化学工程与工艺 | AC17: 罗宇航 | AD17: 5458704 | AE17: 谭悦 | AF17: 2025-06-29 14:03 | AG17: 谭悦 | AH17: 2025-07-01 10:11 | AI17: LP17511769792272 | AJ17: 985院校升级费-无忧 | AK17: 国内考试 | AM17: 3000 | AO17: 马一鸣 | AP17: 续班 | AQ17: 已交接 | AS17: BJWY7777555488 | AU17: 2025-06-29 | AW17: 回访人：谭悦，回访时间：2025-06-29 13:52，回访内容：1 | BB17: 65389384 | BC17: 否 | BD17: 26考季 | BE17: 考研专业课150 | BF17: 专业课150 | BG17: 其他 | BH17: 国内高校-985 | BI17: 否 | BN17: 本地人本地大学(常规) | BO17: 学管续费推荐
A18: 在线网课 | B18: 7 | C18: 北京大学部 | D18: 国内大学部 | E18: 刘菊 | F18: 102646871 | G18: 李雪68 | H18: 2025-05-15 15:14:16 | K18: 大三 | L18: 谭悦 | M18: 转介绍 | N18: 顾问转介绍-老带新 | O18: 吴嘉豪 | R18: 赵翔宇 | S18: 谭悦 | T18: 27898670 | U18: 正常工单 | V18: 2025-05-15 15:28 | W18: A（六个月内有报课意向工单） | X18: 线上考研产品 | Y18: 大三 | Z18: 北京理工大学 | AA18: 宇航学院 | AB18: 飞行器设计与工程 | AC18: 赵翔宇 | AD18: 5404397 | AE18: 谭悦 | AF18: 2025-06-28 12:46 | AG18: 谭悦 | AH18: 2025-06-28 12:46 | AI18: 31181722777 | AJ18: 2026考研政治直通车 6期 | AK18: 国内考试 | AM18: 3901.5 | AO18: 吴嘉豪 | AP18: 新签 | AQ18: 无须交接 | AU18: 2025-06-28 | AW18: 回访人：谭悦，回访时间：2025-06-23 15:56，回访内容：邀约来校区沟通 考研规划 ；|回访人：谭悦，回访时间：2025-06-28 12:46，回访内容：签约 | BA18: 长期班 | BB18: 30895369 | BC18: 是 | BD18: 26考季 | BE18: 线上直通车 | BF18: 政治 | BH18: 国内高校-985 | BI18: 否 | BM18: 104592631 | BN18: 本地人本地大学(常规) | BO18: 客服
A19: 在线网课 | B19: 8 | C19: 北京大学部 | D19: 国内大学部 | F19: 115078495 | H19: 2025-06-18 15:03:49 | I19: 【小红书资源】 一会儿到知春路面询 | K19: 未知 | L19: 赵星火 | M19: 线上运营-小红书 | N19: 小红书 | R19: 韩宜航 | S19: 赵星火 | T19: 28704683 | U19: 续费工单 | V19: 2025-06-28 14:12 | W19: A（六个月内有报课意向工单） | X19: 线上考研产品 | Y19: 大四 | Z19: 北京工业大学 | AA19: 环境与生命学部 | AB19: 化学生物学 | AC19: 韩宜航 | AD19: 5397207 | AE19: 赵星火 | AF19: 2025-06-28 14:13 | AG19: 赵星火 | AH19: 2025-06-28 14:13 | AI19: 27469816685 | AJ19: 2026考研英语直通车 6期,2026考研政治直通车 6期,2026考研数学无忧计划·7期 | AK19: 国内考试 | AM19: 18814.4 | AP19: 续班 | AQ19: 无须交接 | AU19: 2025-06-28 | AW19: 回访人：赵星火，回访时间：2025-06-28 14:12，回访内容：1；|回访人：赵星火，回访时间：2025-06-28 14:13，回访内容：1 | BA19: 长期班,长期班,长期班 | BB19: 80013959 | BC19: 是 | BD19: 26考季 | BE19: 线上直通车 | BF19: 英语,政治 | BH19: 国内高校-211 | BI19: 否 | BM19: 108722739 | BN19: 外地人本地大学(常规)
B20: 9 | C20: 北京大学部 | D20: 国内大学部 | F20: 100583092 | H20: 2025-04-24 09:32:59 | I20: 18705439787 毕业 想考北大医学或者首都医科大学 临床 咨询北京校区。辛苦老师建单 | K20: 未知 | L20: 谭悦 | M20: 线上运营-投放 | N20: 总部-百度投放 | R20: 刘紫乔 | S20: 谭悦 | T20: 28720818 | U20: 续费工单 | V20: 2025-06-29 22:22 | W20: A（六个月内有报课意向工单） | X20: 考研专业课,考研集训营 | Y20: 大学已毕业 | Z20: 山东大学 | AA20: 化学与化工学院 | AB20: 应用化学 | AC20: 刘紫乔 | AD20: 5459865 | AE20: 谭悦 | AF20: 2025-06-29 22:22 | AG20: 谭悦 | AH20: 2025-06-29 22:22 | AI20: KYJZ25007A | AJ20: 26考研政治全年集训营（强冲） | AK20: 国内考试 | AM20: 12577.6 | AN20: 同科续费 | AP20: 续班 | AQ20: 已交接 | AR20: BJWY24032w1g8X | AS20: BJWY4374635320 | AT20: KYJZ25007A0046 | AU20: 2025-06-27 | AW20: 回访人：谭悦，回访时间：2025-06-29 22:22，回访内容：1；|回访人：谭悦，回访时间：2025-06-29 22:22，回访内容：1 | BB20: 69612259 | BC20: 否 | BD20: 26考季 | BE20: 全年集训营,考研专业课300 | BF20: 英语,政治,专业课300 | BH20: 国内高校-985 | BI20: 否 | BL20: 转出
B21: 10 | C21: 北京大学部 | D21: 国内大学部 | F21: 98805854 | H21: 2025-04-04 10:21:21 | I21: 咨询考研线下课程（TMK主管分配TMK） 外呼主题：FY25-国内1月死单回访（2.3-2.9） | K21: 大学已毕业 | L21: 赵星火 | M21: 线上运营-本地生活平台 | N21: 地图标点 | R21: 刘云舒 | S21: 谭悦 | T21: 28701617 | U21: 续费工单 | V21: 2025-06-29 22:20 | W21: A（六个月内有报课意向工单） | X21: 考研专业课,考研集训营 | Y21: 在职 | Z21: 青岛科技大学 | AA21: 自动化与电子工程学院 | AB21: 电气工程及其自动化 | AC21: 刘云舒 | AD21: 5459863 | AE21: 谭悦 | AF21: 2025-06-29 22:21 | AG21: 谭悦 | AH21: 2025-06-29 22:21 | AI21: KYJZ25007A | AJ21: 26考研政治全年集训营（强冲） | AK21: 国内考试 | AM21: 5888.9 | AN21: 同科续费 | AP21: 续班 | AQ21: 已交接 | AR21: BJWY24032w1g8X | AS21: BJWY9006140904 | AT21: KYJZ25007A0045 | AU21: 2025-06-27 | AW21: 回访人：谭悦，回访时间：2025-06-29 22:20，回访内容：1；|回访人：谭悦，回访时间：2025-06-29 22:21，回访内容：1 | BB21: 65530077 | BC21: 否 | BD21: 26考季 | BE21: 全年集训营,考研专业课300 | BF21: 英语,政治,专业课300 | BH21: 国内高校-双非 | BI21: 否 | BL21: 转出
B22: 11 | C22: 北京大学部 | D22: 国内大学部 | F22: 95475458 | H22: 2025-02-24 16:56:33 | I22: 续费原因：调剂B 区学校 动物学专业 咨询调剂班 只要能上岸就行；该学生为保护期内续费，原顾问：国内大学部-赵星火(zhaoxinghuo@xdf.cn) | K22: 在职 | L22: 赵星火 | M22: 转介绍 | N22: 学管续费推荐 | R22: 都宣辰 | S22: 赵星火 | T22: 28720769 | U22: 续费工单 | V22: 2025-06-29 21:56 | W22: A（六个月内有报课意向工单） | X22: 考研集训营 | Y22: 在职 | Z22: 牡丹江大学 | AA22: 生物学 | AB22: 生物 | AC22: 都宣辰 | AD22: 5459836 | AE22: 赵星火 | AF22: 2025-06-29 21:57 | AG22: 赵星火 | AH22: 2025-06-29 21:57 | AI22: KYJZ25007A | AJ22: 26考研政治全年集训营（强冲） | AK22: 国内考试 | AM22: 12332.2 | AN22: 同科续费 | AP22: 续班 | AQ22: 无须交接 | AR22: BJWY24032w1g8X | AS22: BJWY0159234810 | AT22: KYJZ25007A0037 | AU22: 2025-06-27 | AW22: 回访人：赵星火，回访时间：2025-06-29 21:56，回访内容：1；|回访人：赵星火，回访时间：2025-06-29 21:57，回访内容：1 | BB22: 38708961 | BC22: 否 | BD22: 26考季 | BE22: 全年集训营 | BF22: 英语,政治 | BH22: 国内高校-双非 | BI22: 否 | BL22: 转出
B23: 12 | C23: 北京大学部 | D23: 国内大学部 | F23: 98805854 | H23: 2025-04-04 10:21:21 | I23: 咨询考研线下课程（TMK主管分配TMK） 外呼主题：FY25-国内1月死单回访（2.3-2.9） | K23: 大学已毕业 | L23: 赵星火 | M23: 线上运营-本地生活平台 | N23: 地图标点 | R23: 刘云舒 | S23: 谭悦 | T23: 28701617 | U23: 续费工单 | V23: 2025-06-29 22:20 | W23: A（六个月内有报课意向工单） | X23: 考研专业课,考研集训营 | Y23: 在职 | Z23: 青岛科技大学 | AA23: 自动化与电子工程学院 | AB23: 电气工程及其自动化 | AC23: 刘云舒 | AD23: 5405561 | AE23: 赵星火 | AF23: 2025-06-29 22:21 | AG23: 谭悦 | AH23: 2025-06-29 22:21 | AK23: 国内考试 | AM23: 5888.9 | AN23: 同科续费 | AP23: 分单 | AQ23: 已交接 | AS23: BJWY9006140904 | AW23: 回访人：谭悦，回访时间：2025-06-29 22:20，回访内容：1；|回访人：谭悦，回访时间：2025-06-29 22:21，回访内容：1 | BB23: 65530077 | BC23: 否 | BD23: 26考季 | BE23: 全年集训营,考研专业课300 | BF23: 英语,政治,专业课300 | BH23: 国内高校-双非 | BI23: 否
B24: 13 | C24: 北京大学部 | D24: 国内大学部 | F24: 95173408 | H24: 2025-02-20 16:07:50 | I24: 续费原因：如果今年成绩不理想，学员考虑再回来，细节已和顾问刘欢老师对接；该学生为保护期外续费，原顾问部门：国内大学部 | K24: 大学已毕业 | L24: 赵星火 | M24: 转介绍 | N24: 学管续费推荐 | R24: 张显 | S24: 赵星火 | T24: 28720746 | U24: 续费工单 | V24: 2025-06-29 21:50 | W24: A（六个月内有报课意向工单） | X24: 考研集训营 | Y24: 大学已毕业 | Z24: 天津财经大学 | AA24: 会计学院 | AB24: 财务管理 | AC24: 张显 | AD24: 5405545 | AE24: 赵星火 | AF24: 2025-06-29 21:51 | AG24: 赵星火 | AH24: 2025-06-29 21:51 | AI24: KYJZ25007A | AJ24: 26考研政治全年集训营（强冲） | AK24: 国内考试 | AM24: 10332.2 | AN24: 同科续费 | AP24: 续班 | AQ24: 无须交接 | AR24: BJWY24032w1g8X | AS24: BJWY3269678401 | AT24: KYJZ25007A0058 | AU24: 2025-06-27 | AW24: 回访人：赵星火，回访时间：2025-06-29 21:50，回访内容：1；|回访人：赵星火，回访时间：2025-06-29 21:51，回访内容：1 | BB24: 52965947 | BC24: 否 | BD24: 26考季 | BE24: 全年集训营 | BF24: 英语,政治 | BH24: 国内高校-C9 | BI24: 否 | BL24: 转出
A25: 在线网课 | B25: 14 | C25: 北京大学部 | D25: 国内大学部 | E25: grnv | F25: 115757231 | G25: 王静静 | H25: 2025-06-23 14:26:30 | I25: 渠道录入来源：集团百度投放-易聊 意向城市：北京市 访客省/城市：北京市 qq: 访客静态ID：01000000034718973185476658716548 接待分组ID：51266 搜索引擎： 搜索词： 关键词： 设备类型：pc 访客IP：111.192.103.219 对话详细内容：AI-KvNH7xJ0CD 2025-06-12 20:37:45_x000D_ 您好同学，欢迎访问新东方考研官网，【新东方考研】全新升级，课程灵活多样，【考研全年集训营】【考研半年集训营】【考研冲刺营】【线下走读班】【考研一对一】【在职考研】【四六级】火热报名中 ，现在报名更有高达3000元优惠！_x000D_ _x000D_ AI-KvNH7xJ0CD 2025-06-12 20:37:47_x000D_ 您是想咨询【考研走读班】【考研集训营】【考研规划】还是【在职考研】呢？_x000D_ _x000D_ 01000000034718973185476658716548 2025-06-12 20:38:28_x000D_ 在职考研_x000D_ _x000D_ AI-KvNH7xJ0CD 2025-06-12 20:38:32_x000D_ 您准备[在职读研] 还是[离职读研] ?**在职读研# **离职读研#_x000D_ _x000D_ 01000000034718973185476658716548 2025-06-12 20:38:38_x000D_ 在职读研_x000D_ _x000D_ AI-KvNH7xJ0CD 2025-06-12 20:38:42_x000D_ 具体是想报考什么学校和专业呢？_x000D_ _x000D_ 01000000034718973185476658716548 2025-06-12 20:38:54_x000D_ 想报考计算机相关专业_x000D_ _x000D_ AI-KvNH7xJ0CD 2025-06-12 20:38:57_x000D_ 同学，您可以留下您的联系方式，稍后顾问老师会给您进行专业的择校及专业选择的指导。_x000D_ _x000D_ 01000000034718973185476658716548 2025-06-12 20:39:08_x000D_ 15650706248_x000D_ _x000D_ 来源页：https://click.xdf.cn/ 备注：（TMK主管分配TMK） | J25: 2026财年第1财月百度投放总部-百度投放 | K25: 在职 | L25: 杨沫 | M25: 线上运营-投放 | N25: 总部-百度投放 | P25: 杨沫 | Q25: 2025-06-27 16:00:22 | R25: grnv | S25: 赵星火 | T25: 28677697 | U25: 正常工单 | V25: 2025-06-27 16:01 | W25: A（六个月内有报课意向工单） | X25: 线上考研产品 | Y25: 在职 | Z25: 北京物资学院 | AA25: 法学院 | AB25: 法学 | AC25: grnv | AD25: 5367500 | AE25: 赵星火 | AF25: 2025-06-27 16:01 | AG25: 赵星火 | AH25: 2025-06-27 16:01 | AI25: 80073851582 | AJ25: 2026考研政治全程班 6班,2026考研英语全程班 6班,2026考研数学全程班 6班,2026考研计算机全程班 | AK25: 国内考试 | AM25: 4547.5 | AP25: 新签 | AQ25: 无须交接 | AU25: 2025-06-27 | AW25: 回访人：赵星火，回访时间：2025-06-27 16:01，回访内容：1 | BA25: 长期班,长期班,长期班,长期班 | BB25: 79611103 | BC25: 是 | BD25: 26考季 | BE25: 线上全程班 | BF25: 英语 | BG25: 计算机 | BH25: 国内高校-双非 | BI25: 否 | BM25: 110448110
B26: 15 | C26: 北京大学部 | D26: 国内大学部 | F26: 86141900 | H26: 2024-10-11 10:31:47 | I26: 明天下午想到知春路校区面询，两位同学一起，尽快联系 渠道录入来源：大众点评 事件名称：在线咨询 大众点评门店名称：新东方考研四六级(知春路校区) 店铺绑定的校区：知春路校区 店铺管理员邮箱：lvmeng2@xdf.cn 备注：2024-10-11 10:31:45,用户在大众点评新东方考研四六级(知春路校区)在线咨询 | J26: 2025财年第5财月大众点评在线咨询 | K26: 大三 | L26: 邓谭(转岗) | M26: 线上运营-本地生活平台 | N26: 大众点评 | R26: 付豪 | S26: 谭悦 | T26: 28701601 | U26: 续费工单 | V26: 2025-06-29 22:13 | W26: B（需长时间跟单或只需要规划） | X26: 考研专业课,考研无忧计划 | Y26: 大三 | Z26: 北京工商学院 | AA26: 化学学院 | AB26: 化妆品工程 | AC26: 付豪 | AD26: 5459853 | AE26: 谭悦 | AF26: 2025-06-29 22:14 | AG26: 谭悦 | AH26: 2025-06-29 22:14 | AI26: WYE26034 | AJ26: 考研英语无忧计划（26考研/英二强化） | AK26: 国内考试 | AM26: 6672.4 | AN26: 同科续费 | AP26: 续班 | AQ26: 已交接 | AR26: BJWY25030q8UPI | AS26: BJWY0827309575 | AT26: WYE260340045 | AU26: 2025-06-25 | AW26: 回访人：谭悦，回访时间：2025-06-29 22:13，回访内容：1；|回访人：谭悦，回访时间：2025-06-29 22:14，回访内容：1 | BB26: 65076597 | BC26: 否 | BD26: 26考季 | BE26: 无忧计划-啄木鸟,考研专业课150 | BF26: 英语,政治,数学,专业课150 | BH26: 国内高校-双非 | BI26: 否 | BL26: 转出 | BN26: 本地人本地大学(常规)
B27: 16 | C27: 北京大学部 | D27: 国内大学部 | F27: 86141900 | H27: 2024-10-11 10:31:47 | I27: 明天下午想到知春路校区面询，两位同学一起，尽快联系 渠道录入来源：大众点评 事件名称：在线咨询 大众点评门店名称：新东方考研四六级(知春路校区) 店铺绑定的校区：知春路校区 店铺管理员邮箱：lvmeng2@xdf.cn 备注：2024-10-11 10:31:45,用户在大众点评新东方考研四六级(知春路校区)在线咨询 | J27: 2025财年第5财月大众点评在线咨询 | K27: 大三 | L27: 邓谭(转岗) | M27: 线上运营-本地生活平台 | N27: 大众点评 | R27: 付豪 | S27: 谭悦 | T27: 28701601 | U27: 续费工单 | V27: 2025-06-29 22:13 | W27: B（需长时间跟单或只需要规划） | X27: 考研专业课,考研无忧计划 | Y27: 大三 | Z27: 北京工商学院 | AA27: 化学学院 | AB27: 化妆品工程 | AC27: 付豪 | AD27: 5459853 | AE27: 谭悦 | AF27: 2025-06-29 22:14 | AG27: 谭悦 | AH27: 2025-06-29 22:14 | AI27: WYE26035 | AJ27: 考研英语无忧计划（26考研/英二冲刺） | AK27: 国内考试 | AM27: 3177.3 | AN27: 同科续费 | AP27: 续班 | AQ27: 已交接 | AR27: BJWY25030q8UPI | AS27: BJWY0827309575 | AT27: WYE260350045 | AU27: 2025-06-25 | AW27: 回访人：谭悦，回访时间：2025-06-29 22:13，回访内容：1；|回访人：谭悦，回访时间：2025-06-29 22:14，回访内容：1 | BB27: 65076597 | BC27: 否 | BD27: 26考季 | BE27: 无忧计划-啄木鸟,考研专业课150 | BF27: 英语,政治,数学,专业课150 | BH27: 国内高校-双非 | BI27: 否 | BL27: 转出 | BN27: 本地人本地大学(常规)
B28: 17 | C28: 北京大学部 | D28: 国内大学部 | F28: 94705727 | H28: 2025-02-15 15:43:36 | I28: 准备到知春路校区面询，尽快联系 | K28: 未知 | L28: 刘创 | M28: 线上运营-本地生活平台 | N28: 阿里本地通 | R28: 朱建金 | S28: 谭悦 | T28: 28575704 | U28: 续费工单 | V28: 2025-06-24 20:45 | W28: B（需长时间跟单或只需要规划） | X28: 考研专业课,考研无忧计划 | Y28: 在职 | Z28: 太原理工大学 | AA28: 土木工程学院 | AB28: 土木工程 | AC28: 朱建金 | AD28: 5402814 | AE28: 谭悦 | AF28: 2025-06-24 20:45 | AG28: 谭悦 | AH28: 2025-06-24 20:46 | AI28: WYE26026 | AJ28: 考研英语无忧计划（26考研/英一强化） | AK28: 国内考试 | AM28: 6746.8 | AN28: 同科续费 | AP28: 续班 | AQ28: 已交接 | AR28: BJWY2101498uW2 | AS28: BJWY1520278143 | AT28: WYE260260064 | AU28: 2025-06-24 | AW28: 回访人：谭悦，回访时间：2025-06-24 20:45，回访内容：1；|回访人：谭悦，回访时间：2025-06-24 20:45，回访内容：1 | BB28: 66984003 | BC28: 否 | BD28: 26考季 | BE28: 无忧计划-啄木鸟,考研专业课150 | BF28: 英语,政治,数学,专业课150 | BH28: 国内高校-211 | BI28: 否 | BL28: 转出
B29: 18 | C29: 北京大学部 | D29: 国内大学部 | F29: 94705727 | H29: 2025-02-15 15:43:36 | I29: 准备到知春路校区面询，尽快联系 | K29: 未知 | L29: 刘创 | M29: 线上运营-本地生活平台 | N29: 阿里本地通 | R29: 朱建金 | S29: 谭悦 | T29: 28575704 | U29: 续费工单 | V29: 2025-06-24 20:45 | W29: B（需长时间跟单或只需要规划） | X29: 考研专业课,考研无忧计划 | Y29: 在职 | Z29: 太原理工大学 | AA29: 土木工程学院 | AB29: 土木工程 | AC29: 朱建金 | AD29: 5402814 | AE29: 谭悦 | AF29: 2025-06-24 20:45 | AG29: 谭悦 | AH29: 2025-06-24 20:46 | AI29: WYE26027 | AJ29: 考研英语无忧计划（26考研/英一冲刺） | AK29: 国内考试 | AM29: 3212.8 | AN29: 同科续费 | AP29: 续班 | AQ29: 已交接 | AR29: BJWY2101498uW2 | AS29: BJWY1520278143 | AT29: WYE260270062 | AU29: 2025-06-24 | AW29: 回访人：谭悦，回访时间：2025-06-24 20:45，回访内容：1；|回访人：谭悦，回访时间：2025-06-24 20:45，回访内容：1 | BB29: 66984003 | BC29: 否 | BD29: 26考季 | BE29: 无忧计划-啄木鸟,考研专业课150 | BF29: 英语,政治,数学,专业课150 | BH29: 国内高校-211 | BI29: 否 | BL29: 转出
A30: 在线网课 | B30: 19 | C30: 北京大学部 | D30: 国内大学部 | E30: 胡家睿 | F30: 92377994 | G30: 张琦文 | H30: 2025-01-06 15:45:51 | I30: 续费原因：心脏不舒服去急诊没有考数学，要是成绩还好可能就报一个一对一在家复习了。老师可以跟进问一下；该学生为保护期内续费，原顾问：国内大学部-赵星火(zhaoxinghuo@xdf.cn) | K30: 大四 | L30: 赵星火 | M30: 转介绍 | N30: 学管续费推荐 | O30: 张琦文zhangqiwen6@xdf.cn | R30: 胡家睿 | S30: 赵星火 | T30: 26221646 | U30: 续费工单 | V30: 2025-01-06 16:21 | W30: A（六个月内有报课意向工单） | X30: 考研集训营 | Y30: 大四 | Z30: 北京信息科技大学 | AA30: 信息与通信工程学院 | AB30: 电子信息工程 | AC30: 胡家睿 | AD30: 5391072 | AE30: 赵星火 | AF30: 2025-06-22 17:15 | AG30: 赵星火 | AH30: 2025-06-22 17:15 | AI30: 52288160146 | AJ30: 2026考研英语直通车 6期,2026考研数学直通车 6期,2026考研政治直通车 6期 | AK30: 国内考试 | AM30: 11336 | AO30: 张琦文 | AP30: 续班 | AQ30: 无须交接 | AU30: 2025-06-22 | AW30: 回访人：赵星火，回访时间：2025-06-14 17:10，回访内容：电话呼出联系联系不上，微信没有回复；|回访人：赵星火，回访时间：2025-06-18 21:21，回访内容：跟进学生情况跟进学生考虑继续维护中。；|回访人：赵星火，回访时间：2025-06-21 20:31，回访内容：电话呼出联系不上学生微信跟进中继续维护。；|回访人：赵星火，回访时间：2025-06-22 17:15，回访内容：1 | BA30: 长期班,长期班,长期班 | BB30: 44083854 | BC30: 是 | BD30: 26考季 | BE30: 半年集训营 | BF30: 英语 | BG30: 计算机 | BH30: 国内高校-双非 | BI30: 否 | BM30: 105716491 | BN30: 本地人本地大学(常规) | BO30: 学管续费推荐
A31: 在线网课 | B31: 20 | C31: 北京大学部 | D31: 国内大学部 | E31: 白兰小字 | F31: 115078495 | G31: 康荧 | H31: 2025-06-18 15:03:49 | I31: 【小红书资源】 一会儿到知春路面询 | K31: 未知 | L31: 赵星火 | M31: 线上运营-小红书 | N31: 小红书 | R31: 韩宜航 | S31: 赵星火 | T31: 28434788 | U31: 正常工单 | V31: 2025-06-18 16:52 | W31: A（六个月内有报课意向工单） | X31: 线上考研产品 | Y31: 大四 | Z31: 北京工业大学 | AA31: 环境与生命学部 | AB31: 化学生物学 | AC31: 韩宜航 | AD31: 5400255 | AE31: 赵星火 | AF31: 2025-06-18 16:53 | AG31: 赵星火 | AH31: 2025-06-18 16:53 | AI31: 53494503643 | AJ31: 2026考研英语直通车 6期,2026考研政治直通车 6期 | AK31: 国内考试 | AM31: 8464 | AP31: 新签 | AQ31: 无须交接 | AU31: 2025-06-18 | AW31: 回访人：赵星火，回访时间：2025-06-18 16:53，回访内容：1 | AY31: 8464.0 | AZ31: 2025-06-28 | BA31: 长期班,长期班 | BB31: 80013959 | BC31: 是 | BD31: 26考季 | BE31: 线上直通车 | BF31: 英语,政治 | BG31: 其他 | BH31: 国内高校-211 | BI31: 否 | BM31: 108722739 | BN31: 外地人本地大学(常规) | BO31: 客服
A32: 在线网课 | B32: 21 | C32: 北京大学部 | D32: 国内大学部 | F32: 85549363 | H32: 2024-09-29 17:21:48 | I32: 续费原因：了解25考研对应课程，需要先看一下院校，学生家长先问的专业课，但是专业课每个学校考的不一样需要先看一下院校，说了公共课急救班还有一对一模式，孩子在老家可以上线上；该学生为保护期外续费，原顾问部门：国内大学部 | K32: 大学已毕业 | L32: 谭悦 | M32: 转介绍 | N32: 学管续费推荐 | R32: 张鸣政 | S32: 谭悦 | T32: 28387513 | U32: 续费工单 | V32: 2025-06-16 20:18 | W32: A（六个月内有报课意向工单） | X32: 教师资格证 | Y32: 大学已毕业 | Z32: 中国人民大学 | AA32: 马克思主义学院 | AB32: 中国共产党历史 | AC32: 张鸣政 | AD32: 5357256 | AE32: 谭悦 | AF32: 2025-06-16 20:21 | AG32: 谭悦 | AH32: 2025-06-16 20:21 | AI32: 15719805143 | AJ32: 【2025下】中学教资笔面直通车 | AK32: 国内考试 | AM32: 3930 | AP32: 续班 | AQ32: 无须交接 | AU32: 2025-06-16 | AW32: 回访人：谭悦，回访时间：2025-06-16 20:18，回访内容：教资网课 ；|回访人：谭悦，回访时间：2025-06-16 20:21，回访内容：1 | BA32: 长期班 | BB32: 39017583 | BC32: 是 | BD32: 25下考季 | BE32: 教师资格证笔试 | BH32: 国内高校-985 | BI32: 否 | BM32: 104315719
A33: 在线网课 | B33: 22 | C33: 北京大学部 | D33: 国内大学部 | F33: 112561935 | H33: 2025-06-06 12:20:44 | I33: 知春路直访，谭悦接待；销售主管分配TMK主管 外呼主题：寇源-等待工单库2025-05-23 | K33: 大三 | L33: 谭悦 | M33: 线上运营-投放 | N33: 百度投放 | R33: 曹玥 | S33: 谭悦 | T33: 28130808 | U33: 续费工单 | V33: 2025-06-10 15:07 | W33: A（六个月内有报课意向工单） | X33: 线上考研产品 | Y33: 大三 | Z33: 北京农学院 | AA33: 植物科学技术学院 | AB33: 农学 | AC33: 曹玥 | AD33: 5351875 | AE33: 谭悦 | AF33: 2025-06-10 15:07 | AG33: 谭悦 | AH33: 2025-06-10 15:07 | AI33: 06888906157 | AJ33: 2026考研专业课定制一对一（50h）-A班 | AK33: 国内考试 | AM33: 18615 | AP33: 续班 | AQ33: 无须交接 | AU33: 2025-06-10 | AW33: 回访人：谭悦，回访时间：2025-06-10 15:07，回访内容：1；|回访人：谭悦，回访时间：2025-06-10 15:07，回访内容：1 | BA33: 长期班 | BB33: 67470457 | BC33: 是 | BD33: 26考季 | BE33: 线上无忧计划 | BF33: 英语,政治,专业课300 | BH33: 国内高校-双非 | BI33: 否 | BM33: 107462026 | BN33: 本地人本地大学(常规)
A34: 在线网课 | B34: 23 | C34: 北京大学部 | D34: 国内大学部 | E34: 曹玥 | F34: 103546571 | G34: 杨俊 | H34: 2025-05-23 14:29:17 | I34: 销售主管分配TMK主管 | K34: 大三 | L34: 杨钰杰 | M34: 线上运营-投放 | N34: 百度投放 | P34: 杨钰杰 | Q34: 2025-06-06 12:20:44 | R34: 曹玥 | S34: 谭悦 | T34: 28176051 | U34: 正常工单 | V34: 2025-06-06 13:37 | W34: A（六个月内有报课意向工单） | X34: 线上考研产品 | Y34: 大三 | Z34: 北京农学院 | AA34: 植物科学技术学院 | AB34: 农学 | AC34: 曹玥 | AD34: 5277327 | AE34: 谭悦 | AF34: 2025-06-10 15:04 | AG34: 谭悦 | AH34: 2025-06-10 15:05 | AI34: 77410743517 | AJ34: 2026考研政治无忧计划·11期,2026考研英语一无忧计划·14期 | AK34: 国内考试 | AM34: 15303.2 | AP34: 新签 | AQ34: 无须交接 | AU34: 2025-06-10 | AW34: 回访人：谭悦，回访时间：2025-06-06 13:37，回访内容：26考研，植物保护，跟进中 ；|回访人：谭悦，回访时间：2025-06-07 16:44，回访内容：微信跟进中，菁英B计划 ；|回访人：谭悦，回访时间：2025-06-10 15:04，回访内容：签约 | BA34: 长期班,长期班 | BB34: 67470457 | BC34: 是 | BD34: 26考季 | BE34: 线上无忧计划 | BF34: 英语,政治,专业课300 | BG34: 其他 | BH34: 国内高校-双非 | BI34: 否 | BM34: 107462026 | BN34: 本地人本地大学(常规) | BO34: 市场
A35: 在线网课 | B35: 24 | C35: 北京大学部 | D35: 国内大学部 | F35: 87708587 | H35: 2024-11-05 14:17:45 | I35: 【考博】学生主动微信找的，毕业专业和院校是 大连医科大学 临床医学。咨询考博的英语辅导，线上大班网课，在上班，不方便电话，辛苦老师加微信，手机号是微信；【考博】毕业专业和院校是 大连医科大学 临床医学。咨询考博的英语辅导，线上大班网课，在上班，不方便电话，辛苦老师加微信 | K35: 在职 | L35: 赵星火 | M35: 直访 | N35: 直访 | R35: 1度 | S35: 赵星火 | T35: 28182825 | U35: 续费工单 | V35: 2025-06-07 13:05 | W35: A（六个月内有报课意向工单） | X35: 考博 | Y35: 在职 | Z35: 大连医科大学 | AA35: 临床学院 | AB35: 临床医学 | AC35: 1度 | AD35: 5377871 | AE35: 赵星火 | AF35: 2025-06-07 13:05 | AG35: 赵星火 | AH35: 2025-06-07 13:06 | AI35: 08181547771 | AJ35: 2026医学考博英语全程班【直播 + 录播】 | AK35: 国内考试 | AM35: 1824 | AP35: 续班 | AQ35: 无须交接 | AU35: 2025-06-07 | AW35: 回访人：赵星火，回访时间：2025-06-07 13:05，回访内容：1；|回访人：赵星火，回访时间：2025-06-07 13:05，回访内容：1 | BA35: 长期班 | BB35: 64038881 | BC35: 是 | BH35: 国内高校-双非 | BI35: 否 | BM35: 108979436
B36: 25 | C36: 北京大学部 | D36: 国内大学部 | F36: 95923932 | H36: 2025-03-01 15:57:49 | I36: 续费原因：咨询考研，辛苦流转赵星火；该学生为保护期内续费，原顾问：国内大学部-赵星火(zhaoxinghuo@xdf.cn) | K36: 大三 | L36: 赵星火 | M36: 转介绍 | N36: 学管续费推荐 | R36: 李尚烨 | S36: 赵星火 | T36: 28161284 | U36: 续费工单 | V36: 2025-06-05 14:42 | W36: A（六个月内有报课意向工单） | X36: 考研无忧计划 | Y36: 大三 | Z36: 北京航空航天大学 | AA36: 机械工程及自动化学院 | AB36: 材料成型及控制工程 | AC36: 李尚烨 | AD36: 5347627 | AE36: 赵星火 | AF36: 2025-06-05 14:42 | AG36: 赵星火 | AH36: 2025-06-05 15:14 | AI36: WYP26043 | AJ36: 考研政治无忧计划（26考研/基础） | AK36: 国内考试 | AM36: 6041.5 | AN36: 同科续费 | AP36: 续班 | AQ36: 无须交接 | AR36: BJWY25030q8UPI | AS36: BJWY8264939203 | AT36: WYP260430050 | AU36: 2025-06-04 | AW36: 回访人：赵星火，回访时间：2025-06-05 14:42，回访内容：1；|回访人：赵星火，回访时间：2025-06-05 14:42，回访内容：1 | BB36: 67086969 | BC36: 否 | BD36: 26考季 | BE36: 无忧计划-啄木鸟 | BF36: 英语,政治,数学 | BH36: 国内高校-985 | BI36: 否 | BL36: 转出 | BN36: 外地人本地大学(常规)
B37: 26 | C37: 北京大学部 | D37: 国内大学部 | F37: 95923932 | H37: 2025-03-01 15:57:49 | I37: 续费原因：咨询考研，辛苦流转赵星火；该学生为保护期内续费，原顾问：国内大学部-赵星火(zhaoxinghuo@xdf.cn) | K37: 大三 | L37: 赵星火 | M37: 转介绍 | N37: 学管续费推荐 | R37: 李尚烨 | S37: 赵星火 | T37: 28161284 | U37: 续费工单 | V37: 2025-06-05 14:42 | W37: A（六个月内有报课意向工单） | X37: 考研无忧计划 | Y37: 大三 | Z37: 北京航空航天大学 | AA37: 机械工程及自动化学院 | AB37: 材料成型及控制工程 | AC37: 李尚烨 | AD37: 5347627 | AE37: 赵星火 | AF37: 2025-06-05 14:42 | AG37: 赵星火 | AH37: 2025-06-05 15:14 | AI37: WYP26044 | AJ37: 考研政治无忧计划（26考研/强化） | AK37: 国内考试 | AM37: 3855.3 | AN37: 同科续费 | AP37: 续班 | AQ37: 无须交接 | AR37: BJWY25030q8UPI | AS37: BJWY8264939203 | AT37: WYP260440050 | AU37: 2025-06-04 | AW37: 回访人：赵星火，回访时间：2025-06-05 14:42，回访内容：1；|回访人：赵星火，回访时间：2025-06-05 14:42，回访内容：1 | BB37: 67086969 | BC37: 否 | BD37: 26考季 | BE37: 无忧计划-啄木鸟 | BF37: 英语,政治,数学 | BH37: 国内高校-985 | BI37: 否 | BL37: 转出 | BN37: 外地人本地大学(常规)
B38: 27 | C38: 北京大学部 | D38: 国内大学部 | F38: 95923932 | H38: 2025-03-01 15:57:49 | I38: 续费原因：咨询考研，辛苦流转赵星火；该学生为保护期内续费，原顾问：国内大学部-赵星火(zhaoxinghuo@xdf.cn) | K38: 大三 | L38: 赵星火 | M38: 转介绍 | N38: 学管续费推荐 | R38: 李尚烨 | S38: 赵星火 | T38: 28161284 | U38: 续费工单 | V38: 2025-06-05 14:42 | W38: A（六个月内有报课意向工单） | X38: 考研无忧计划 | Y38: 大三 | Z38: 北京航空航天大学 | AA38: 机械工程及自动化学院 | AB38: 材料成型及控制工程 | AC38: 李尚烨 | AD38: 5347627 | AE38: 赵星火 | AF38: 2025-06-05 14:42 | AG38: 赵星火 | AH38: 2025-06-05 15:14 | AI38: WYP26045 | AJ38: 考研政治无忧计划（26考研/冲刺） | AK38: 国内考试 | AM38: 4578.2 | AN38: 同科续费 | AP38: 续班 | AQ38: 无须交接 | AR38: BJWY25030q8UPI | AS38: BJWY8264939203 | AT38: WYP260450050 | AU38: 2025-06-04 | AW38: 回访人：赵星火，回访时间：2025-06-05 14:42，回访内容：1；|回访人：赵星火，回访时间：2025-06-05 14:42，回访内容：1 | BB38: 67086969 | BC38: 否 | BD38: 26考季 | BE38: 无忧计划-啄木鸟 | BF38: 英语,政治,数学 | BH38: 国内高校-985 | BI38: 否 | BL38: 转出 | BN38: 外地人本地大学(常规)
