Workbook

Sheet 绩效汇总
B2: 业绩奖金表（一人可多条，需写清类别）
B3: 序号 | C3: 机构 | D3: 年月 | E3: 工号 | F3: 姓名 | G3: 部门 | H3: 薪资项目 | I3: 金额
B4: 1 | C4: 北京中心 | D4: 2025.07 | E4: 238256 | F4: 赵星火 | G4: O2级学习顾问 | H4: 月度绩效 | I4: ='7月绩效核算'!T4 -> 920
B5: 2 | C5: 北京中心 | D5: 2026.07 | E5: 238256 | F5: 赵星火 | G5: O2级学习顾问 | H5: 顾问签约奖金 | I5: ='业绩汇总'!N5 -> 53861.437
B6: 3 | C6: 北京中心 | D6: 2028.07 | E6: 341422 | F6: 谭悦 | G6: O3级学习顾问 | H6: 月度绩效 | I6: 0 | J6: 新财年按照O3发放顾问底薪
B7: 4 | C7: 北京中心 | D7: 2029.07 | E7: 341422 | F7: 谭悦 | G7: O3级学习顾问 | H7: 顾问签约奖金 | I7: ='业绩汇总'!N4 -> 94270.822
B8: 5 | C8: 北京中心 | D8: 2030.07 | E8: 341422 | F8: 谭悦 | G8: O3级学习顾问 | H8: PK赛奖金 | I8: 4000 | J8: 前两周第一名
B9: 6 | C9: 北京中心 | D9: 2030.07 | E9: 341422 | F9: 李涛 | G9: O1级学习顾问 | H9: 月度绩效 | I9: =2000*(24/31) -> 1548.3871 | J9: 2025/7/8入职

Sheet 业绩汇总
B2: 2025.07个性化顾问业绩
B3: 序号 | C3: 顾问姓名 | D3: 月度目标 | E3: 地面业绩 | F3: 网课代售业绩 | G3: 业绩合计 | H3: 线下退费 | I3: 网课退费 | J3: 退费合计 | K3: 综合业绩 | L3: 完成率
B4: 1 | C4: 谭悦 | D4: 1100000 | E4: =GETPIVOTDATA("学费",'7月签约班级明细导出'!$C$1,"标签","地面业绩","签约单录入人","谭悦") -> 2167026.9 | F4: =GETPIVOTDATA("学费",'7月签约班级明细导出'!$C$1,"标签","代售网课","签约单录入人","谭悦") -> 104102.6 | G4: =E4+F4 -> 2271129.5 | H4: ='7月钉钉退费共享表明细'!AP39-'7月钉钉退费共享表明细'!AP38-'7月钉钉退费共享表明细'!AP37-'7月钉钉退费共享表明细'!AP36 -> 385463.05 | I4: ='7月钉钉退费共享表明细'!AP36+'7月钉钉退费共享表明细'!AP37+'7月钉钉退费共享表明细'!AP38 -> 250 | J4: =H4+I4 -> 385713.05 | K4: =G4-J4 -> 1885416.4 | L4: =K4/D4 -> 1.714015 | N4: =K4*0.05 -> 94270.822
B5: 2 | C5: 星火 | D5: 1100000 | E5: =GETPIVOTDATA("学费",'7月签约班级明细导出'!$C$1,"标签","地面业绩","签约单录入人","赵星火") -> 1478651.6 | F5: =GETPIVOTDATA("学费",'7月签约班级明细导出'!$C$1,"标签","代售网课","签约单录入人","赵星火") -> 71792.8 | G5: =E5+F5 -> 1550444.4 | H5: ='7月钉钉退费共享表明细'!AP64-'7月钉钉退费共享表明细'!AP63-'7月钉钉退费共享表明细'!AP62 -> 196501.85 | I5: ='7月钉钉退费共享表明细'!AP62+'7月钉钉退费共享表明细'!AP63 -> 7406.63 | J5: =H5+I5 -> 203908.48 | K5: =G5-J5 -> 1346535.9 | L5: =K5/D5 -> 1.2241236 | N5: =K5*0.04 -> 53861.437
B6: 合计 | D6: =SUM(D4:D5) -> 2200000 | E6: =SUM(E4:E5) -> 3645678.5 | F6: 108898.6 | G6: =E6+F6 -> 3754577.1 | H6: ¥386,657.60 | I6: 8464 | J6: =SUM(J4:J5) -> 589621.53 | K6: =SUM(K4:K5) -> 3231952.4 | L6: =K6/D6 -> 1.4690693

Sheet 7月签约班级明细导出
D1: 标签 | E1: 求和项:学费
C2: 谭悦 | E2: 2271129.5
D3: 代售网课 | E3: 104102.6
D4: 地面业绩 | E4: 2167026.9
C5: 赵星火 | E5: 1550444.4
D6: 代售网课 | E6: 71792.8
D7: 地面业绩 | E7: 1478651.6
C8: Grand Total | E8: 3821573.9
A10: 标签 | B10: 序号 | C10: 学校 | D10: 部门 | E10: 资源姓名 | F10: 资源ID | G10: 资源录入人 | H10: 资源录入时间 | I10: 资源描述 | J10: 市场活动 | K10: 资源年级 | L10: 分配顾问/TMK | M10: 一级获取渠道 | N10: 二级获取渠道 | O10: 转介绍人 | P10: TMK激活人 | Q10: TMK激活处理时间 | R10: 工单姓名 | S10: 跟进顾问 | T10: 工单ID | U10: 工单类型 | V10: 工单录入时间 | W10: 工单等级 | X10: 咨询课程 | Y10: 工单年级 | Z10: 学校 | AA10: 院系 | AB10: 专业 | AC10: 签约学生姓名 | AD10: 签约单ID | AE10: 签约单录入人 | AF10: 签约单录入时间 | AG10: 签约单更新人 | AH10: 签约单更新时间 | AI10: 班号 | AJ10: 班级名称 | AK10: 面询表类型 | AL10: 订金 | AM10: 学费 | AN10: 续费类型 | AO10: 推荐人 | AP10: 类型 | AQ10: 是否交接 | AR10: 操作人编号 | AS10: 学员号 | AT10: 听课证号 | AU10: 报班日期 | AV10: 学员状态 | AW10: 回访记录 | AX10: 新老生类型 | AY10: 退费金额 | AZ10: 退费日期 | BA10: 课程类型 | BB10: 客户ID | BC10: 是否新东方在线签约 | BD10: 考季 | BE10: 报名产品 | BF10: 报名科目 | BG10: 意向报考专业 | BH10: 学校班型/类型 | BI10: 是否关联协议 | BJ10: 特殊备注 | BK10: 产品品类 | BL10: 业务类型 | BM10: 签约列表在线学员ID | BN10: 大学生源类型 | BO10: 资源来源
A11: 地面业绩 | B11: 1 | C11: 北京大学部 | D11: 国内大学部 | E11: 杨显婷 | F11: 121602812 | G11: 许庆典 | H11: 2025-07-31 19:54:31 | I11: 续费原因：续费27考研；该学生为保护期内续费，原顾问：国内大学部-谭悦(tanyue9@xdf.cn) | K11: 大二 | L11: 谭悦 | M11: 转介绍 | N11: 学管续费推荐 | O11: 许庆典xuqingdian@xdf.cn | R11: 杨显婷 | S11: 谭悦 | T11: 29440654 | U11: 续费工单 | V11: 2025-07-31 20:06 | W11: A（六个月内有报课意向工单） | X11: 考研专业课,考研无忧计划 | Y11: 大二 | Z11: 北京物资学院 | AA11: 信息学院 | AB11: 应用统计学 | AC11: 杨显婷 | AD11: 5528120 | AE11: 谭悦 | AF11: 2025-07-31 20:06 | AG11: 谭悦 | AH11: 2025-07-31 20:06 | AI11: WYM27002 | AJ11: 考研数学无忧计划（27考研/强化） | AK11: 国内考试 | AM11: 6100 | AN11: 同科续费 | AO11: 许庆典 | AP11: 续班 | AQ11: 已交接 | AR11: BJWY2101498uW2 | AS11: BJWY5113272165 | AT11: WYM270020036 | AU11: 2025-07-31 | AW11: 回访人：谭悦，回访时间：2025-07-31 20:06，回访内容：27考研 | BB11: 44495810 | BC11: 否 | BD11: 27考季 | BE11: 无忧计划-啄木鸟,考研专业课150 | BF11: 英语,政治,数学,专业课150 | BG11: 其他 | BH11: 国内高校-双非 | BI11: 是 | BL11: 报名 | BN11: 本地人本地大学(常规) | BO11: 学管续费推荐
A12: 地面业绩 | B12: 2 | C12: 北京大学部 | D12: 国内大学部 | E12: 杨显婷 | F12: 121602812 | G12: 许庆典 | H12: 2025-07-31 19:54:31 | I12: 续费原因：续费27考研；该学生为保护期内续费，原顾问：国内大学部-谭悦(tanyue9@xdf.cn) | K12: 大二 | L12: 谭悦 | M12: 转介绍 | N12: 学管续费推荐 | O12: 许庆典xuqingdian@xdf.cn | R12: 杨显婷 | S12: 谭悦 | T12: 29440654 | U12: 续费工单 | V12: 2025-07-31 20:06 | W12: A（六个月内有报课意向工单） | X12: 考研专业课,考研无忧计划 | Y12: 大二 | Z12: 北京物资学院 | AA12: 信息学院 | AB12: 应用统计学 | AC12: 杨显婷 | AD12: 5528120 | AE12: 谭悦 | AF12: 2025-07-31 20:06 | AG12: 谭悦 | AH12: 2025-07-31 20:06 | AI12: WYP27005 | AJ12: 考研政治无忧计划（27考研/强化） | AK12: 国内考试 | AM12: 3600 | AN12: 同科续费 | AO12: 许庆典 | AP12: 续班 | AQ12: 已交接 | AR12: BJWY2101498uW2 | AS12: BJWY5113272165 | AT12: WYP270050012 | AU12: 2025-07-31 | AW12: 回访人：谭悦，回访时间：2025-07-31 20:06，回访内容：27考研 | BB12: 44495810 | BC12: 否 | BD12: 27考季 | BE12: 无忧计划-啄木鸟,考研专业课150 | BF12: 英语,政治,数学,专业课150 | BG12: 其他 | BH12: 国内高校-双非 | BI12: 是 | BL12: 报名 | BN12: 本地人本地大学(常规) | BO12: 学管续费推荐
A13: 地面业绩 | B13: 3 | C13: 北京大学部 | D13: 国内大学部 | E13: 杨显婷 | F13: 121602812 | G13: 许庆典 | H13: 2025-07-31 19:54:31 | I13: 续费原因：续费27考研；该学生为保护期内续费，原顾问：国内大学部-谭悦(tanyue9@xdf.cn) | K13: 大二 | L13: 谭悦 | M13: 转介绍 | N13: 学管续费推荐 | O13: 许庆典xuqingdian@xdf.cn | R13: 杨显婷 | S13: 谭悦 | T13: 29440654 | U13: 续费工单 | V13: 2025-07-31 20:06 | W13: A（六个月内有报课意向工单） | X13: 考研专业课,考研无忧计划 | Y13: 大二 | Z13: 北京物资学院 | AA13: 信息学院 | AB13: 应用统计学 | AC13: 杨显婷 | AD13: 5528120 | AE13: 谭悦 | AF13: 2025-07-31 20:06 | AG13: 谭悦 | AH13: 2025-07-31 20:06 | AI13: WYP27006 | AJ13: 考研政治无忧计划（27考研/冲刺） | AK13: 国内考试 | AM13: 4275 | AN13: 同科续费 | AO13: 许庆典 | AP13: 续班 | AQ13: 已交接 | AR13: BJWY2101498uW2 | AS13: BJWY5113272165 | AT13: WYP270060012 | AU13: 2025-07-31 | AW13: 回访人：谭悦，回访时间：2025-07-31 20:06，回访内容：27考研 | BB13: 44495810 | BC13: 否 | BD13: 27考季 | BE13: 无忧计划-啄木鸟,考研专业课150 | BF13: 英语,政治,数学,专业课150 | BG13: 其他 | BH13: 国内高校-双非 | BI13: 是 | BL13: 报名 | BN13: 本地人本地大学(常规) | BO13: 学管续费推荐
A14: 地面业绩 | B14: 4 | C14: 北京大学部 | D14: 国内大学部 | E14: 杨显婷 | F14: 121602812 | G14: 许庆典 | H14: 2025-07-31 19:54:31 | I14: 续费原因：续费27考研；该学生为保护期内续费，原顾问：国内大学部-谭悦(tanyue9@xdf.cn) | K14: 大二 | L14: 谭悦 | M14: 转介绍 | N14: 学管续费推荐 | O14: 许庆典xuqingdian@xdf.cn | R14: 杨显婷 | S14: 谭悦 | T14: 29440654 | U14: 续费工单 | V14: 2025-07-31 20:06 | W14: A（六个月内有报课意向工单） | X14: 考研专业课,考研无忧计划 | Y14: 大二 | Z14: 北京物资学院 | AA14: 信息学院 | AB14: 应用统计学 | AC14: 杨显婷 | AD14: 5528120 | AE14: 谭悦 | AF14: 2025-07-31 20:06 | AG14: 谭悦 | AH14: 2025-07-31 20:06 | AI14: WYE27026 | AJ14: 考研英语无忧计划（27考研/英二冲刺） | AK14: 国内考试 | AM14: 5250 | AN14: 同科续费 | AO14: 许庆典 | AP14: 续班 | AQ14: 已交接 | AR14: BJWY2101498uW2 | AS14: BJWY5113272165 | AT14: WYE270260019 | AU14: 2025-07-31 | AW14: 回访人：谭悦，回访时间：2025-07-31 20:06，回访内容：27考研 | BB14: 44495810 | BC14: 否 | BD14: 27考季 | BE14: 无忧计划-啄木鸟,考研专业课150 | BF14: 英语,政治,数学,专业课150 | BG14: 其他 | BH14: 国内高校-双非 | BI14: 是 | BL14: 报名 | BN14: 本地人本地大学(常规) | BO14: 学管续费推荐
A15: 地面业绩 | B15: 5 | C15: 北京大学部 | D15: 国内大学部 | E15: 杨显婷 | F15: 121602812 | G15: 许庆典 | H15: 2025-07-31 19:54:31 | I15: 续费原因：续费27考研；该学生为保护期内续费，原顾问：国内大学部-谭悦(tanyue9@xdf.cn) | K15: 大二 | L15: 谭悦 | M15: 转介绍 | N15: 学管续费推荐 | O15: 许庆典xuqingdian@xdf.cn | R15: 杨显婷 | S15: 谭悦 | T15: 29440654 | U15: 续费工单 | V15: 2025-07-31 20:06 | W15: A（六个月内有报课意向工单） | X15: 考研专业课,考研无忧计划 | Y15: 大二 | Z15: 北京物资学院 | AA15: 信息学院 | AB15: 应用统计学 | AC15: 杨显婷 | AD15: 5528120 | AE15: 谭悦 | AF15: 2025-07-31 20:06 | AG15: 谭悦 | AH15: 2025-07-31 20:06 | AI15: WYE27004 | AJ15: 考研英语无忧计划（27考研/英二强化） | AK15: 国内考试 | AM15: 6300 | AN15: 同科续费 | AO15: 许庆典 | AP15: 续班 | AQ15: 已交接 | AR15: BJWY2101498uW2 | AS15: BJWY5113272165 | AT15: WYE270040026 | AU15: 2025-07-31 | AW15: 回访人：谭悦，回访时间：2025-07-31 20:06，回访内容：27考研 | BB15: 44495810 | BC15: 否 | BD15: 27考季 | BE15: 无忧计划-啄木鸟,考研专业课150 | BF15: 英语,政治,数学,专业课150 | BG15: 其他 | BH15: 国内高校-双非 | BI15: 是 | BL15: 报名 | BN15: 本地人本地大学(常规) | BO15: 学管续费推荐
A16: 地面业绩 | B16: 6 | C16: 北京大学部 | D16: 国内大学部 | E16: 杨显婷 | F16: 121602812 | G16: 许庆典 | H16: 2025-07-31 19:54:31 | I16: 续费原因：续费27考研；该学生为保护期内续费，原顾问：国内大学部-谭悦(tanyue9@xdf.cn) | K16: 大二 | L16: 谭悦 | M16: 转介绍 | N16: 学管续费推荐 | O16: 许庆典xuqingdian@xdf.cn | R16: 杨显婷 | S16: 谭悦 | T16: 29440654 | U16: 续费工单 | V16: 2025-07-31 20:06 | W16: A（六个月内有报课意向工单） | X16: 考研专业课,考研无忧计划 | Y16: 大二 | Z16: 北京物资学院 | AA16: 信息学院 | AB16: 应用统计学 | AC16: 杨显婷 | AD16: 5528120 | AE16: 谭悦 | AF16: 2025-07-31 20:06 | AG16: 谭悦 | AH16: 2025-07-31 20:06 | AI16: WYM27010 | AJ16: 考研数学无忧计划（27考研/冲刺） | AK16: 国内考试 | AM16: 5400 | AN16: 同科续费 | AO16: 许庆典 | AP16: 续班 | AQ16: 已交接 | AR16: BJWY2101498uW2 | AS16: BJWY5113272165 | AT16: WYM270100025 | AU16: 2025-07-31 | AW16: 回访人：谭悦，回访时间：2025-07-31 20:06，回访内容：27考研 | BB16: 44495810 | BC16: 否 | BD16: 27考季 | BE16: 无忧计划-啄木鸟,考研专业课150 | BF16: 英语,政治,数学,专业课150 | BG16: 其他 | BH16: 国内高校-双非 | BI16: 是 | BL16: 报名 | BN16: 本地人本地大学(常规) | BO16: 学管续费推荐
A17: 地面业绩 | B17: 7 | C17: 北京大学部 | D17: 国内大学部 | E17: 杨显婷 | F17: 121602812 | G17: 许庆典 | H17: 2025-07-31 19:54:31 | I17: 续费原因：续费27考研；该学生为保护期内续费，原顾问：国内大学部-谭悦(tanyue9@xdf.cn) | K17: 大二 | L17: 谭悦 | M17: 转介绍 | N17: 学管续费推荐 | O17: 许庆典xuqingdian@xdf.cn | R17: 杨显婷 | S17: 谭悦 | T17: 29440654 | U17: 续费工单 | V17: 2025-07-31 20:06 | W17: A（六个月内有报课意向工单） | X17: 考研专业课,考研无忧计划 | Y17: 大二 | Z17: 北京物资学院 | AA17: 信息学院 | AB17: 应用统计学 | AC17: 杨显婷 | AD17: 5528120 | AE17: 谭悦 | AF17: 2025-07-31 20:06 | AG17: 谭悦 | AH17: 2025-07-31 20:06 | AI17: WYE27006 | AJ17: 考研英语无忧计划（27考研/基础） | AK17: 国内考试 | AM17: 4800 | AN17: 同科续费 | AO17: 许庆典 | AP17: 续班 | AQ17: 已交接 | AR17: BJWY2101498uW2 | AS17: BJWY5113272165 | AT17: WYE270060023 | AU17: 2025-07-31 | AW17: 回访人：谭悦，回访时间：2025-07-31 20:06，回访内容：27考研 | BB17: 44495810 | BC17: 否 | BD17: 27考季 | BE17: 无忧计划-啄木鸟,考研专业课150 | BF17: 英语,政治,数学,专业课150 | BG17: 其他 | BH17: 国内高校-双非 | BI17: 是 | BL17: 报名 | BN17: 本地人本地大学(常规) | BO17: 学管续费推荐
A18: 地面业绩 | B18: 8 | C18: 北京大学部 | D18: 国内大学部 | E18: 杨显婷 | F18: 121602812 | G18: 许庆典 | H18: 2025-07-31 19:54:31 | I18: 续费原因：续费27考研；该学生为保护期内续费，原顾问：国内大学部-谭悦(tanyue9@xdf.cn) | K18: 大二 | L18: 谭悦 | M18: 转介绍 | N18: 学管续费推荐 | O18: 许庆典xuqingdian@xdf.cn | R18: 杨显婷 | S18: 谭悦 | T18: 29440654 | U18: 续费工单 | V18: 2025-07-31 20:06 | W18: A（六个月内有报课意向工单） | X18: 考研专业课,考研无忧计划 | Y18: 大二 | Z18: 北京物资学院 | AA18: 信息学院 | AB18: 应用统计学 | AC18: 杨显婷 | AD18: 5528120 | AE18: 谭悦 | AF18: 2025-07-31 20:06 | AG18: 谭悦 | AH18: 2025-07-31 20:06 | AI18: WYP27004 | AJ18: 考研政治无忧计划（27考研/基础） | AK18: 国内考试 | AM18: 6225 | AN18: 同科续费 | AO18: 许庆典 | AP18: 续班 | AQ18: 已交接 | AR18: BJWY2101498uW2 | AS18: BJWY5113272165 | AT18: WYP270040012 | AU18: 2025-07-31 | AW18: 回访人：谭悦，回访时间：2025-07-31 20:06，回访内容：27考研 | BB18: 44495810 | BC18: 否 | BD18: 27考季 | BE18: 无忧计划-啄木鸟,考研专业课150 | BF18: 英语,政治,数学,专业课150 | BG18: 其他 | BH18: 国内高校-双非 | BI18: 是 | BL18: 报名 | BN18: 本地人本地大学(常规) | BO18: 学管续费推荐
A19: 地面业绩 | B19: 9 | C19: 北京大学部 | D19: 国内大学部 | E19: 杨显婷 | F19: 121602812 | G19: 许庆典 | H19: 2025-07-31 19:54:31 | I19: 续费原因：续费27考研；该学生为保护期内续费，原顾问：国内大学部-谭悦(tanyue9@xdf.cn) | K19: 大二 | L19: 谭悦 | M19: 转介绍 | N19: 学管续费推荐 | O19: 许庆典xuqingdian@xdf.cn | R19: 杨显婷 | S19: 谭悦 | T19: 29440654 | U19: 续费工单 | V19: 2025-07-31 20:06 | W19: A（六个月内有报课意向工单） | X19: 考研专业课,考研无忧计划 | Y19: 大二 | Z19: 北京物资学院 | AA19: 信息学院 | AB19: 应用统计学 | AC19: 杨显婷 | AD19: 5528120 | AE19: 谭悦 | AF19: 2025-07-31 20:06 | AG19: 谭悦 | AH19: 2025-07-31 20:06 | AI19: WYM27001 | AJ19: 考研数学无忧计划（27考研/基础） | AK19: 国内考试 | AM19: 4350 | AN19: 同科续费 | AO19: 许庆典 | AP19: 续班 | AQ19: 已交接 | AR19: BJWY2101498uW2 | AS19: BJWY5113272165 | AT19: WYM270010036 | AU19: 2025-07-31 | AW19: 回访人：谭悦，回访时间：2025-07-31 20:06，回访内容：27考研 | BB19: 44495810 | BC19: 否 | BD19: 27考季 | BE19: 无忧计划-啄木鸟,考研专业课150 | BF19: 英语,政治,数学,专业课150 | BG19: 其他 | BH19: 国内高校-双非 | BI19: 是 | BL19: 报名 | BN19: 本地人本地大学(常规) | BO19: 学管续费推荐
A20: 地面业绩 | B20: 10 | C20: 北京大学部 | D20: 国内大学部 | E20: 杨显婷 | F20: 121602812 | G20: 许庆典 | H20: 2025-07-31 19:54:31 | I20: 续费原因：续费27考研；该学生为保护期内续费，原顾问：国内大学部-谭悦(tanyue9@xdf.cn) | K20: 大二 | L20: 谭悦 | M20: 转介绍 | N20: 学管续费推荐 | O20: 许庆典xuqingdian@xdf.cn | R20: 杨显婷 | S20: 谭悦 | T20: 29440654 | U20: 续费工单 | V20: 2025-07-31 20:06 | W20: A（六个月内有报课意向工单） | X20: 考研专业课,考研无忧计划 | Y20: 大二 | Z20: 北京物资学院 | AA20: 信息学院 | AB20: 应用统计学 | AC20: 杨显婷 | AD20: 5528120 | AE20: 谭悦 | AF20: 2025-07-31 20:06 | AG20: 谭悦 | AH20: 2025-07-31 20:06 | AI20: LP17539617712673 | AJ20: 考研初试专业课一对一（27考研/无忧30小时） | AK20: 国内考试 | AM20: 9000 | AN20: 同科续费 | AO20: 许庆典 | AP20: 续班 | AQ20: 已交接 | AR20: BJWY2101498uW2 | AS20: BJWY5113272165 | AU20: 2025-07-31 | AW20: 回访人：谭悦，回访时间：2025-07-31 20:06，回访内容：27考研 | BB20: 44495810 | BC20: 否 | BD20: 27考季 | BE20: 无忧计划-啄木鸟,考研专业课150 | BF20: 英语,政治,数学,专业课150 | BG20: 其他 | BH20: 国内高校-双非 | BI20: 是 | BN20: 本地人本地大学(常规) | BO20: 学管续费推荐
A21: 地面业绩 | B21: 11 | C21: 北京大学部 | D21: 国内大学部 | E21: 杨希恒 | F21: 121517724 | G21: 段同飞 | H21: 2025-07-30 22:05:58 | I21: 同学介绍的，转谭悦 | K21: 大四 | L21: 谭悦 | M21: 转介绍 | N21: 顾问转介绍-老带新 | O21: 谭悦tanyue9@xdf.cn | R21: 杨希恒 | S21: 谭悦 | T21: 29435689 | U21: 正常工单 | V21: 2025-07-31 12:15 | W21: A（六个月内有报课意向工单） | X21: 考研无忧计划 | Y21: 大四 | Z21: 北京化工大学 | AA21: 材料科学与工程学院 | AB21: 高分子材料与工程精英班 | AC21: 杨希恒 | AD21: 5528086 | AE21: 谭悦 | AF21: 2025-07-31 19:51 | AG21: 谭悦 | AH21: 2025-07-31 19:51 | AI21: GWYM26001 | AJ21: 考研数学无忧计划考前突破班（26考研/专项突破） | AK21: 国内考试 | AM21: 7600 | AO21: 谭悦 | AP21: 新签 | AQ21: 已交接 | AR21: BJWY2101498uW2 | AS21: BJWY2409130365 | AT21: GWYM260010002 | AU21: 2025-07-31 | AW21: 回访人：谭悦，回访时间：2025-07-31 12:15，回访内容：26考研，英语政治刚开始备考，考虑上课学习 ；|回访人：谭悦，回访时间：2025-07-31 19:51，回访内容：签约 | BB21: 30795044 | BC21: 否 | BD21: 26考季 | BE21: 无忧计划-蜂鸟 | BF21: 英语,政治,数学 | BG21: 其他 | BH21: 国内高校-211 | BI21: 是 | BL21: 报名 | BN21: 外地人本地大学(常规) | BO21: 客服
A22: 地面业绩 | B22: 12 | C22: 北京大学部 | D22: 国内大学部 | E22: 杨希恒 | F22: 121517724 | G22: 段同飞 | H22: 2025-07-30 22:05:58 | I22: 同学介绍的，转谭悦 | K22: 大四 | L22: 谭悦 | M22: 转介绍 | N22: 顾问转介绍-老带新 | O22: 谭悦tanyue9@xdf.cn | R22: 杨希恒 | S22: 谭悦 | T22: 29435689 | U22: 正常工单 | V22: 2025-07-31 12:15 | W22: A（六个月内有报课意向工单） | X22: 考研无忧计划 | Y22: 大四 | Z22: 北京化工大学 | AA22: 材料科学与工程学院 | AB22: 高分子材料与工程精英班 | AC22: 杨希恒 | AD22: 5528086 | AE22: 谭悦 | AF22: 2025-07-31 19:51 | AG22: 谭悦 | AH22: 2025-07-31 19:51 | AI22: GWYP26001 | AJ22: 考研政治无忧计划考前突破班（26考研/刷题带背） | AK22: 国内考试 | AM22: 7100 | AO22: 谭悦 | AP22: 新签 | AQ22: 已交接 | AR22: BJWY2101498uW2 | AS22: BJWY2409130365 | AT22: GWYP260010005 | AU22: 2025-07-31 | AW22: 回访人：谭悦，回访时间：2025-07-31 12:15，回访内容：26考研，英语政治刚开始备考，考虑上课学习 ；|回访人：谭悦，回访时间：2025-07-31 19:51，回访内容：签约 | BB22: 30795044 | BC22: 否 | BD22: 26考季 | BE22: 无忧计划-蜂鸟 | BF22: 英语,政治,数学 | BG22: 其他 | BH22: 国内高校-211 | BI22: 是 | BL22: 报名 | BN22: 外地人本地大学(常规) | BO22: 客服
A23: 地面业绩 | B23: 13 | C23: 北京大学部 | D23: 国内大学部 | E23: 杨希恒 | F23: 121517724 | G23: 段同飞 | H23: 2025-07-30 22:05:58 | I23: 同学介绍的，转谭悦 | K23: 大四 | L23: 谭悦 | M23: 转介绍 | N23: 顾问转介绍-老带新 | O23: 谭悦tanyue9@xdf.cn | R23: 杨希恒 | S23: 谭悦 | T23: 29435689 | U23: 正常工单 | V23: 2025-07-31 12:15 | W23: A（六个月内有报课意向工单） | X23: 考研无忧计划 | Y23: 大四 | Z23: 北京化工大学 | AA23: 材料科学与工程学院 | AB23: 高分子材料与工程精英班 | AC23: 杨希恒 | AD23: 5528086 | AE23: 谭悦 | AF23: 2025-07-31 19:51 | AG23: 谭悦 | AH23: 2025-07-31 19:51 | AI23: GWYE26001 | AJ23: 考研英语无忧计划考前突破班（26考研/英语一） | AK23: 国内考试 | AM23: 7100 | AO23: 谭悦 | AP23: 新签 | AQ23: 已交接 | AR23: BJWY2101498uW2 | AS23: BJWY2409130365 | AT23: GWYE260010003 | AU23: 2025-07-31 | AW23: 回访人：谭悦，回访时间：2025-07-31 12:15，回访内容：26考研，英语政治刚开始备考，考虑上课学习 ；|回访人：谭悦，回访时间：2025-07-31 19:51，回访内容：签约 | BB23: 30795044 | BC23: 否 | BD23: 26考季 | BE23: 无忧计划-蜂鸟 | BF23: 英语,政治,数学 | BG23: 其他 | BH23: 国内高校-211 | BI23: 是 | BL23: 报名 | BN23: 外地人本地大学(常规) | BO23: 客服
A24: 地面业绩 | B24: 14 | C24: 北京大学部 | D24: 国内大学部 | F24: 92994255 | H24: 2025-01-13 16:06:45 | I24: 赵星火老师死单激活资源；赵星火老师死单激活资源 外呼主题：FY24-国内9月死单回访（第四周） 赵星火老师死单激活资源(资源备注人:吴凯龙;资源备注时间:2025-01-13 16:07) | K24: 大三 | L24: 赵星火 | M24: 线上运营-投放 | N24: 百度投放 | R24: 陈廷进 | S24: 高龙明 | T24: 29460345 | U24: 续费工单 | V24: 2025-07-31 18:11 | W24: A（六个月内有报课意向工单） | X24: 考研集训营 | Y24: 大学已毕业 | Z24: 吉林大学 | AA24: 物理学院 | AB24: 物理学 | AC24: 陈廷进 | AD24: 5527877 | AE24: 赵星火 | AF24: 2025-07-31 18:24 | AG24: 高龙明 | AH24: 2025-07-31 18:25 | AK24: 国内考试 | AM24: 1417.5 | AP24: 分单 | AQ24: 无须交接 | AS24: BJWY4776417923 | AW24: 回访人：高龙明，回访时间：2025-07-31 18:11，回访内容：转；|回访人：高龙明，回访时间：2025-07-31 18:11，回访内容：报；|回访人：高龙明，回访时间：2025-07-31 18:19，回访内容：高龙明进行了退单操作!(本条回访记录由系统自动记录) | BB24: 62316553 | BC24: 否 | BD24: 26考季 | BE24: 半年集训营 | BF24: 英语 | BH24: 国内高校-985 | BI24: 否 | BN24: 外地人外地大学(常规)
A25: 代售网课 | B25: 15 | C25: 北京大学部 | D25: 国内大学部 | E25: 北京市5435 | F25: 120078696 | G25: 张亚男 | H25: 2025-07-21 16:45:27 | I25: 渠道录入来源：集团百度投放-易聊 意向城市：北京市 访客省/城市：北京市 qq: 访客静态ID：01000000034718308740867391835435 接待分组ID：51266 搜索引擎： 搜索词： 关键词： 设备类型：pc 访客IP：117.133.62.42 对话详细内容：AI-KvNH7xJ0CD 2025-07-21 16:44:01 您好同学，欢迎访问新东方考研官网，【新东方考研】全新升级，课程灵活多样，【考研全年集训营】【考研半年集训营】【考研冲刺营】【线下走读班】【考研一对一】【在职考研】【四六级】火热报名中 ，现在报名更有高达3000元优惠！ AI-KvNH7xJ0CD 2025-07-21 16:44:03 您是想咨询【考研走读班】【考研集训营】【考研规划】还是【在职考研】呢？ 01000000034718308740867391835435 2025-07-21 16:44:27 【在职考研】 AI-KvNH7xJ0CD 2025-07-21 16:44:31 您准备[在职读研] 还是[离职读研] ?**在职读研# **离职读研# 01000000034718308740867391835435 2025-07-21 16:44:36 在职读研 AI-KvNH7xJ0CD 2025-07-21 16:44:40 具体是想报考什么学校和专业呢？ 01000000034718308740867391835435 2025-07-21 16:44:53 人民大学 应用心理学 AI-KvNH7xJ0CD 2025-07-21 16:44:57 好的，了解。我们新东方在全国32个城市都有校区，您倾向在哪个城市上课，或者希望哪里的老师给您介绍下呢？ 01000000034718308740867391835435 2025-07-21 16:45:07 北京 AI-KvNH7xJ0CD 2025-07-21 16:45:11 您可以留下您的姓名和电话，我这边可以立刻安排对应校区顾问老师给您回电！ 01000000034718308740867391835435 2025-07-21 16:45:26 张惠晴 13716251966 来源页：https://click.xdf.cn/ 备注： | J25: 2026财年第2财月百度投放总部-百度投放 | L25: 谭悦 | M25: 线上运营-投放 | N25: 总部-百度投放 | R25: grace | S25: 谭悦 | T25: 29254778 | U25: 正常工单 | V25: 2025-07-31 13:30 | W25: A（六个月内有报课意向工单） | X25: 线上考研产品 | Y25: 在职 | Z25: 中国人民大学 | AA25: 社会与人口学院 | AB25: 社会工作 | AC25: grace | AD25: 5527161 | AE25: 谭悦 | AF25: 2025-07-31 14:11 | AG25: 谭悦 | AH25: 2025-07-31 14:12 | AI25: 33782039713 | AJ25: 2026考研英语直通车 6期 | AK25: 国内考试 | AM25: 6791.5 | AP25: 新签 | AQ25: 无须交接 | AU25: 2025-07-31 | AW25: 回访人：谭悦，回访时间：2025-07-24 21:34，回访内容：微信跟进中 考研学习 ；|回访人：谭悦，回访时间：2025-07-30 16:42，回访内容：不回复消息 ；|回访人：吴凯龙，回访时间：2025-07-31 13:30，回访内容：吴凯龙恢复工单, 系统自动生成回访记录!；|回访人：谭悦，回访时间：2025-07-31 14:11，回访内容：1 | BA25: 长期班 | BB25: 82103592 | BC25: 是 | BD25: 26考季 | BE25: 线上直通车 | BF25: 英语 | BG25: 其他 | BH25: 国内高校-985 | BI25: 否 | BM25: 110624761 | BO25: 百度投放
A26: 代售网课 | B26: 16 | C26: 北京大学部 | D26: 国内大学部 | E26: 未知 | F26: 121602784 | G26: 李雪68 | H26: 2025-07-31 19:33:50 | I26: 激活 | K26: 大四 | L26: 赵星火 | M26: 毛坯数据 | N26: 毛坯数据 | R26: 韩月鹏 | S26: 赵星火 | T26: 29460986 | U26: 正常工单 | V26: 2025-07-31 20:01 | W26: A（六个月内有报课意向工单） | X26: 线上考研产品 | Y26: 大四 | Z26: 北京工业大学 | AA26: 北京-都柏林国际学院 | AB26: 电子信息工程1 | AC26: 韩月鹏 | AD26: 5500336 | AE26: 赵星火 | AF26: 2025-07-31 20:01 | AG26: 赵星火 | AH26: 2025-07-31 20:02 | AI26: 01384944814 | AJ26: 2026考研直通车VIP【计算机】,2026考研英语直通车 6期,2026考研数学直通车 6期,2026考研政治直通车 6期 | AK26: 国内考试 | AM26: 17136 | AP26: 新签 | AQ26: 无须交接 | AU26: 2025-07-31 | AW26: 回访人：赵星火，回访时间：2025-07-31 20:01，回访内容：签约 | BA26: 长期班,长期班,长期班,长期班 | BB26: 30923959 | BC26: 是 | BD26: 26考季 | BE26: 线上直通车 | BF26: 计算机 | BG26: 计算机 | BH26: 国内高校-211 | BI26: 否 | BM26: 109947422 | BN26: 本地人本地大学(常规) | BO26: 客服
A27: 地面业绩 | B27: 17 | C27: 北京大学部 | D27: 国内大学部 | F27: 121258774 | H27: 2025-07-30 12:45:19 | I27: 续费原因：学生决定考浙江大学，辛苦联系黄禹淇的妈妈收取一下升级费3000；该学生为保护期内续费，原顾问：国内大学部-谭悦(tanyue9@xdf.cn) | K27: 大四 | L27: 谭悦 | M27: 转介绍 | N27: 学管续费推荐 | R27: 黄禹淇 | S27: 谭悦 | T27: 29422728 | U27: 续费工单 | V27: 2025-07-30 18:55 | W27: A（六个月内有报课意向工单） | X27: 考研无忧计划 | Y27: 大四 | Z27: 北京交通大学 | AA27: 机械与电子控制工程学院 | AB27: 机械工程 | AC27: 黄禹淇 | AD27: 5526455 | AE27: 谭悦 | AF27: 2025-07-30 18:55 | AG27: 谭悦 | AH27: 2025-07-30 18:56 | AI27: WYE26003 | AJ27: 考研英语无忧计划（26考研/英一冲刺） | AK27: 国内考试 | AM27: 2965.2 | AN27: 同科续费 | AP27: 续班 | AQ27: 无须交接 | AR27: BJWY24032w1g8X | AS27: BJWY4049653605 | AT27: WYE260030072 | AU27: 2025-07-30 | AW27: 回访人：谭悦，回访时间：2025-07-30 18:55，回访内容：转班；|回访人：谭悦，回访时间：2025-07-30 18:55，回访内容：1 | BB27: 60647114 | BC27: 否 | BD27: 26考季 | BE27: 无忧计划-啄木鸟 | BF27: 英语 | BH27: 国内高校-211 | BI27: 否 | BL27: 转出 | BN27: 本地人本地大学(常规)
A28: 地面业绩 | B28: 18 | C28: 北京大学部 | D28: 国内大学部 | F28: 121258774 | H28: 2025-07-30 12:45:19 | I28: 续费原因：学生决定考浙江大学，辛苦联系黄禹淇的妈妈收取一下升级费3000；该学生为保护期内续费，原顾问：国内大学部-谭悦(tanyue9@xdf.cn) | K28: 大四 | L28: 谭悦 | M28: 转介绍 | N28: 学管续费推荐 | R28: 黄禹淇 | S28: 谭悦 | T28: 29422728 | U28: 续费工单 | V28: 2025-07-30 18:55 | W28: A（六个月内有报课意向工单） | X28: 考研无忧计划 | Y28: 大四 | Z28: 北京交通大学 | AA28: 机械与电子控制工程学院 | AB28: 机械工程 | AC28: 黄禹淇 | AD28: 5526455 | AE28: 谭悦 | AF28: 2025-07-30 18:55 | AG28: 谭悦 | AH28: 2025-07-30 18:56 | AI28: WYE26002 | AJ28: 考研英语无忧计划（26考研/英一强化） | AK28: 国内考试 | AM28: 2732.2 | AN28: 同科续费 | AP28: 续班 | AQ28: 无须交接 | AR28: BJWY24032w1g8X | AS28: BJWY4049653605 | AT28: WYE260020071 | AU28: 2025-07-30 | AW28: 回访人：谭悦，回访时间：2025-07-30 18:55，回访内容：转班；|回访人：谭悦，回访时间：2025-07-30 18:55，回访内容：1 | BB28: 60647114 | BC28: 否 | BD28: 26考季 | BE28: 无忧计划-啄木鸟 | BF28: 英语 | BH28: 国内高校-211 | BI28: 否 | BL28: 转出 | BN28: 本地人本地大学(常规)
A29: 地面业绩 | B29: 19 | C29: 北京大学部 | D29: 国内大学部 | F29: 90288454 | H29: 2024-12-09 20:46:29 | I29: 在校，考中国科学院大学 遥感方面的都行 IP：北京 | K29: 未知 | L29: 赵星火 | M29: 线上运营-投放 | N29: 其他网络投放 | R29: 朱博政 | S29: 赵星火 | T29: 29421355 | U29: 续费工单 | V29: 2025-07-30 17:05 | W29: A（六个月内有报课意向工单） | X29: 考研专业课,考研无忧计划 | Y29: 大四 | Z29: 中国传媒大学 | AA29: 信息与通信工程学院 | AB29: 通信工程 | AC29: 朱博政 | AD29: 5526266 | AE29: 赵星火 | AF29: 2025-07-30 17:06 | AG29: 赵星火 | AH29: 2025-07-30 17:07 | AI29: WYE26026 | AJ29: 考研英语无忧计划（26考研/英一强化） | AK29: 国内考试 | AM29: 3812.8 | AN29: 同科续费 | AP29: 续班 | AQ29: 无须交接 | AR29: BJWY2101498uW2 | AS29: BJWY5552920417 | AT29: WYE260260066 | AU29: 2025-07-30 | AW29: 回访人：赵星火，回访时间：2025-07-30 17:05，回访内容：1；|回访人：赵星火，回访时间：2025-07-30 17:06，回访内容：1 | BB29: 65132392 | BC29: 否 | BD29: 26考季 | BE29: 无忧计划-啄木鸟,考研专业课150 | BF29: 英语,政治,数学,专业课150 | BH29: 国内高校-211 | BI29: 否 | BL29: 转出 | BN29: 本地人本地大学(常规)
A30: 地面业绩 | B30: 20 | C30: 北京大学部 | D30: 国内大学部 | F30: 90288454 | H30: 2024-12-09 20:46:29 | I30: 在校，考中国科学院大学 遥感方面的都行 IP：北京 | K30: 未知 | L30: 赵星火 | M30: 线上运营-投放 | N30: 其他网络投放 | R30: 朱博政 | S30: 赵星火 | T30: 29421355 | U30: 续费工单 | V30: 2025-07-30 17:05 | W30: A（六个月内有报课意向工单） | X30: 考研专业课,考研无忧计划 | Y30: 大四 | Z30: 中国传媒大学 | AA30: 信息与通信工程学院 | AB30: 通信工程 | AC30: 朱博政 | AD30: 5526266 | AE30: 赵星火 | AF30: 2025-07-30 17:06 | AG30: 赵星火 | AH30: 2025-07-30 17:07 | AI30: WYE26027 | AJ30: 考研英语无忧计划（26考研/英一冲刺） | AK30: 国内考试 | AM30: 3177.3 | AN30: 同科续费 | AP30: 续班 | AQ30: 无须交接 | AR30: BJWY2101498uW2 | AS30: BJWY5552920417 | AT30: WYE260270064 | AU30: 2025-07-30 | AW30: 回访人：赵星火，回访时间：2025-07-30 17:05，回访内容：1；|回访人：赵星火，回访时间：2025-07-30 17:06，回访内容：1 | BB30: 65132392 | BC30: 否 | BD30: 26考季 | BE30: 无忧计划-啄木鸟,考研专业课150 | BF30: 英语,政治,数学,专业课150 | BH30: 国内高校-211 | BI30: 否 | BL30: 转出 | BN30: 本地人本地大学(常规)
A31: 地面业绩 | B31: 21 | C31: 北京大学部 | D31: 国内大学部 | E31: 黄禹淇 | F31: 121258774 | G31: 马一鸣 | H31: 2025-07-30 12:45:19 | I31: 续费原因：学生决定考浙江大学，辛苦联系黄禹淇的妈妈收取一下升级费3000；该学生为保护期内续费，原顾问：国内大学部-谭悦(tanyue9@xdf.cn) | K31: 大四 | L31: 谭悦 | M31: 转介绍 | N31: 学管续费推荐 | O31: 马一鸣mayiming16@xdf.cn | R31: 黄禹淇 | S31: 谭悦 | T31: 29428581 | U31: 续费工单 | V31: 2025-07-30 13:38 | W31: A（六个月内有报课意向工单） | X31: 考研专业课 | Y31: 大四 | Z31: 北京交通大学 | AA31: 机械与电子控制工程学院 | AB31: 机械工程 | AC31: 黄禹淇 | AD31: 5420608 | AE31: 谭悦 | AF31: 2025-07-30 13:40 | AG31: 谭悦 | AH31: 2025-07-30 14:11 | AI31: LP1753854023771 | AJ31: 985院校升级费-无忧 | AK31: 国内考试 | AM31: 3000 | AO31: 马一鸣 | AP31: 续班 | AQ31: 无须交接 | AS31: BJWY4049653605 | AU31: 2025-07-30 | AW31: 回访人：谭悦，回访时间：2025-07-30 13:38，回访内容：1 | BB31: 60647114 | BC31: 否 | BD31: 26考季 | BE31: 考研专业课150 | BF31: 专业课150 | BG31: 其他 | BH31: 国内高校-211 | BI31: 否 | BN31: 本地人本地大学(常规) | BO31: 学管续费推荐
A32: 代售网课 | B32: 22 | C32: 北京大学部 | D32: 国内大学部 | E32: 同学 | F32: 120882682 | G32: 方勃文 | H32: 2025-07-26 13:43:34 | I32: 咨询英语一一对一【已在群内反馈】 | K32: 大四 | L32: 赵星火 | M32: 线上运营-私域中台 | N32: 社群、虚拟人 | R32: Merih | S32: 赵星火 | T32: 29342786 | U32: 正常工单 | V32: 2025-07-27 14:45 | W32: A（六个月内有报课意向工单） | X32: 线上考研产品 | Y32: 大四 | Z32: 河北大学 | AA32: 管理学院 | AB32: 图书馆学 | AC32: Merih | AD32: 5420588 | AE32: 赵星火 | AF32: 2025-07-30 12:47 | AG32: 赵星火 | AH32: 2025-07-30 12:47 | AI32: 96565840801 | AJ32: 2026考研英语全程班 6班 | AK32: 国内考试 | AM32: 1096.5 | AP32: 新签 | AQ32: 无须交接 | AU32: 2025-07-30 | AW32: 回访人：赵星火，回访时间：2025-07-27 14:45，回访内容：联系不上学生微信上问下给到课程介绍跟进中；|回访人：赵星火，回访时间：2025-07-28 14:49，回访内容：跟进学生情况这边继续维护学生跟进中。；|回访人：赵星火，回访时间：2025-07-30 12:47，回访内容：1 | BA32: 长期班 | BB32: 82421047 | BC32: 是 | BD32: 26考季 | BE32: 线上全程班 | BH32: 国内高校-双非 | BI32: 否 | BM32: 110614822 | BN32: 本地人本地大学(常规) | BO32: 市场
A33: 代售网课 | B33: 23 | C33: 北京大学部 | D33: 国内大学部 | E33: 北京市6271 | F33: 120932120 | G33: 杨俊42(国内) | H33: 2025-07-28 08:56:20 | I33: 渠道录入来源：新东方官网M站-客服 意向城市：北京访客省/城市：北京市 访客静态ID：01000000034659366398395471906271 接待分组ID：70455 搜索引擎： 搜索词： 关键词： 设备类型：phone 访客IP：221.217.26.141 对话详细内容：AI-Lbo0rDBXCyBY 2025-07-28 08:53:08 您好同学,欢迎访问北京新东方考研四六级中心. 考研线下课程26/27考季【考研全年集训营】【考研半年集训营】【考研全科线下走读班】【考研寒/暑假集训营】【考研一对一】【考研专业课】【四/六级课程】，热门课程火热报名中,咨询即可领取专享优惠。 **【考研全年集训营】=ff761f# **【考研半年集训营】=ff6b6b# **【考研全科线下走读班】=ffc158# **【考研寒/暑假集训营】=ffc158# **【考研一对一】=ff761f# **【考研专业课】=ff6caa# **【四/六级课程】=ff6caa# **【考研冲刺班】=60e27e# AI-Lbo0rDBXCyBY 2025-07-28 08:53:11 您是想咨询【线下课程】【线上课程】【考研规划】还是【在职考研】呢？**【线下课程】# **【线上课程】#**【考研规划】#**【在职考研】# 01000000034659366398395471906271 2025-07-28 08:53:19 【在职考研】 AI-Lbo0rDBXCyBY 2025-07-28 08:53:23 您准备【边工作边读研]】还是【脱产读研】 ?**边工作边读研# **脱产读研# 01000000034659366398395471906271 2025-07-28 08:53:27 脱产读研 AI-Lbo0rDBXCyBY 2025-07-28 08:53:31 具体是想报考什么学校和专业呢？ 01000000034659366398395471906271 2025-07-28 08:53:46 北京理工大学软件工程硕士 AI-Lbo0rDBXCyBY 2025-07-28 08:53:50 好的，我这边安排专业老师给您回电，详细沟通一下，请问您的电话是多少呢？ 01000000034659366398395471906271 2025-07-28 08:54:18 18500224563 AI-Lbo0rDBXCyBY 2025-07-28 08:54:21 好的，确认一下你的号码是否正确呢~ 来源页：https://bj.xdf.cn/ 备注： | J33: 2026财年第2财月易聊新东方官网M站 | L33: 徐树萌 | M33: 新东方官网 | N33: 新东方官网M站 | P33: 徐树萌 | Q33: 2025-07-28 09:32:37 | R33: 北京市6271 | S33: 赵星火 | T33: 29345437 | U33: 正常工单 | V33: 2025-07-28 14:14 | W33: A（六个月内有报课意向工单） | X33: 线上考研产品 | Y33: 在职 | Z33: 北京工业大学耿丹学院 | AA33: 工学院 | AB33: 计算机科学与技术 | AC33: 北京市6271 | AD33: 5524661 | AE33: 赵星火 | AF33: 2025-07-29 10:09 | AG33: 赵星火 | AH33: 2025-07-29 10:11 | AI33: 58407124528 | AJ33: 2026考研英语一无忧计划·16期,2026考研政治无忧计划·13期,2026考研数学无忧计划·7期 | AK33: 国内考试 | AM33: 24471 | AP33: 新签 | AQ33: 无须交接 | AU33: 2025-07-29 | AW33: 回访人：赵星火，回访时间：2025-07-28 14:14，回访内容：基础薄弱这边想要考研，刚才开始准备，集训价格高，推荐线上小班课程继续维护中。 | BA33: 长期班,长期班,长期班 | BB33: 82475627 | BC33: 是 | BD33: 26考季 | BE33: 线上无忧计划 | BF33: 英语 | BG33: 计算机 | BH33: 国内高校-双非 | BI33: 否 | BM33: 110610561 | BO33: 易聊在线咨询
A34: 地面业绩 | B34: 24 | C34: 北京大学部 | D34: 国内大学部 | F34: 92994255 | H34: 2025-01-13 16:06:45 | I34: 赵星火老师死单激活资源；赵星火老师死单激活资源 外呼主题：FY24-国内9月死单回访（第四周） 赵星火老师死单激活资源(资源备注人:吴凯龙;资源备注时间:2025-01-13 16:07) | K34: 大三 | L34: 赵星火 | M34: 线上运营-投放 | N34: 百度投放 | R34: 陈廷进 | S34: 高龙明 | T34: 29432626 | U34: 续费工单 | V34: 2025-07-30 18:41 | W34: A（六个月内有报课意向工单） | X34: 考研集训营 | Y34: 大学已毕业 | Z34: 吉林大学 | AA34: 物理学院 | AB34: 物理学 | AC34: 陈廷进 | AD34: 5498616 | AE34: 赵星火 | AF34: 2025-07-30 18:41 | AG34: 高龙明 | AH34: 2025-07-30 18:43 | AK34: 国内考试 | AM34: 10855.2 | AN34: 同科续费 | AP34: 分单 | AQ34: 无须交接 | AS34: BJWY4776417923 | AW34: 回访人：高龙明，回访时间：2025-07-30 18:41，回访内容：转；|回访人：高龙明，回访时间：2025-07-30 18:41，回访内容：报 | BB34: 62316553 | BC34: 否 | BD34: 26考季 | BE34: 半年集训营 | BF34: 英语 | BH34: 国内高校-985 | BI34: 否 | BN34: 外地人外地大学(常规)
A35: 代售网课 | B35: 25 | C35: 北京大学部 | D35: 国内大学部 | E35: 叶宸羽 | F35: 119043886 | G35: 北京国内管理员 | H35: 2025-07-14 17:09:37 | I35: 渠道录入来源：SCRM-客服推送 商机ID：5009267870 商机编码：XSJ20250714027807 针对人群：大学 学生学校：不详 咨询课程：英语一 创建人邮箱：wangguibing@xdf.cn 创建时间：2025-07-14 17:09:33 资源类型：单个资源 跟进记录：商机备注：学员妈妈咨询考研课程，天津理工大学，咨询线上课程，27年考研，辛苦老师沟通;接触点：呼入； | K35: 大三 | L35: 赵星火 | M35: 新东方官网 | N35: 新东方PC官网 | R35: 叶宸羽 | S35: 赵星火 | T35: 29084490 | U35: 正常工单 | V35: 2025-07-14 18:32 | W35: A（六个月内有报课意向工单） | X35: 线上考研产品 | Y35: 大三 | Z35: 天津理工大学 | AA35: 管理学院 | AB35: 工商管理 | AC35: 叶宸羽 | AD35: 5494164 | AE35: 赵星火 | AF35: 2025-07-26 13:57 | AG35: 赵星火 | AH35: 2025-07-26 13:57 | AI35: 53555637604 | AJ35: 2027考研政治直通车 长线2期,2027考研数学直通车 长线2期,2027考研英语直通车 长线2期 | AK35: 国内考试 | AM35: 11902.8 | AP35: 新签 | AQ35: 无须交接 | AU35: 2025-07-26 | AW35: 回访人：赵星火，回访时间：2025-07-17 19:43，回访内容：电话呼出联系不上，微信继续问一下情况；|回访人：赵星火，回访时间：2025-07-20 16:04，回访内容：表示还没确定确定了这边再说跟进中。；|回访人：赵星火，回访时间：2025-07-23 16:16，回访内容：对比海文和新东方跟进学生情况中继续维护学生；|回访人：赵星火，回访时间：2025-07-25 19:43，回访内容：表示明后天这边确定一下跟进中继续维护中。；|回访人：赵星火，回访时间：2025-07-26 13:57，回访内容：1 | BA35: 长期班,长期班,长期班 | BB35: 81577565 | BC35: 是 | BD35: 27考季 | BE35: 线上直通车 | BF35: 英语 | BG35: 其他 | BH35: 国内高校-双非 | BI35: 否 | BM35: 110601979 | BN35: 外地人外地大学(常规) | BO35: SCRM-客服推送
A36: 地面业绩 | B36: 26 | C36: 北京大学部 | D36: 国内大学部 | E36: 蔡哲 | F36: 118843591 | G36: 陈晶 | H36: 2025-07-13 12:08:52 | I36: 续费原因：续费一对一；该学生为保护期内续费，原顾问：国内大学部-谭悦(tanyue9@xdf.cn) | K36: 大学已毕业 | L36: 谭悦 | M36: 转介绍 | N36: 学管续费推荐 | O36: 陈晶chenjing171@xdf.cn | R36: 蔡哲 | S36: 谭悦 | T36: 29060027 | U36: 续费工单 | V36: 2025-07-13 19:11 | W36: A（六个月内有报课意向工单） | X36: 考研VIP | Y36: 大学已毕业 | Z36: 北京邮电大学 | AA36: 信息与通信工程学院 | AB36: 电子信息工程 | AC36: 蔡哲 | AD36: 5418288 | AE36: 谭悦 | AF36: 2025-07-24 18:36 | AG36: 谭悦 | AH36: 2025-07-24 19:10 | AI36: LP17533534131898 | AJ36: 考研一对一伴学班（26考季） | AK36: 国内考试 | AM36: 15600 | AO36: 陈晶 | AP36: 续班 | AQ36: 已交接 | AS36: BJWY0874092650 | AU36: 2025-07-24 | AW36: 回访人：谭悦，回访时间：2025-07-20 18:25，回访内容：跟进续费中 | BB36: 33569231 | BC36: 否 | BD36: 26考季 | BE36: VIP - 伴学 | BF36: 英语,政治 | BG36: 其他 | BH36: 国内高校-211 | BI36: 是 | BO36: 学管续费推荐
A37: 地面业绩 | B37: 27 | C37: 北京大学部 | D37: 国内大学部 | F37: 115849673 | H37: 2025-06-23 15:33:28 | I37: 【考研】学生本人，北京农学院，大三，食品专业，想考中国农业大学，食品加工与安全专业，问士兵计划的分数，也要了解课程，线上还是线下课程没说，想先确定了解好学校分数，或者查北林，北农的分数加微信介绍；渠道录入来源：抖音新东方考研直播间 koouserID：110429453 城市：北京 产品分组：考研 线索来源：直播间小风车收资-大学生-线下面授 市场人员： 是否兼职： 备注信息：请选择当前所属阶段：:大三;请选择倾向的备考方式：:线下面授;请选择备考城市：:北京 外呼主题：2026财年第1财月抖音新东方考研直播间 | J37: 2026财年第1财月抖音新东方考研直播间 | K37: 大三 | L37: 谭悦 | M37: 线上运营-抖音 | N37: 抖音新东方考研直播间 | R37: 周靖程 | S37: 谭悦 | T37: 29252280 | U37: 续费工单 | V37: 2025-07-21 16:03 | W37: A（六个月内有报课意向工单） | X37: 考研专业课,考研集训营 | Y37: 大四 | Z37: 北京农学院 | AA37: 食品科学与工程学院 | AB37: 食品科学与工程 | AC37: 周靖程 | AD37: 5487404 | AE37: 谭悦 | AF37: 2025-07-21 16:14 | AG37: 谭悦 | AH37: 2025-07-21 16:16 | AI37: LP17530856811511 | AJ37: 985院校升级费-集训 | AK37: 国内考试 | AM37: 1500 | AP37: 续班 | AQ37: 已交接 | AS37: BJWY0787829408 | AU37: 2025-07-21 | AW37: 回访人：谭悦，回访时间：2025-07-21 16:03，回访内容：1 | BB37: 82087801 | BC37: 否 | BD37: 26考季 | BE37: 半年集训营,考研专业课300 | BF37: 英语,政治,专业课300 | BH37: 国内高校-双非 | BI37: 是 | BN37: 本地人本地大学(常规)
A38: 代售网课 | B38: 28 | C38: 北京大学部 | D38: 国内大学部 | E38: 杨 | F38: 119920344 | G38: 北京客服部 | H38: 2025-07-20 09:16:56 | I38: 政治和英语 | J38: 2026财年第2财月代理商 | L38: 乔文娇 | M38: 线上运营-商务合作 | N38: 米化 | P38: 乔文娇 | Q38: 2025-07-20 10:55:29 | R38: 王喆 | S38: 谭悦 | T38: 29212534 | U38: 正常工单 | V38: 2025-07-20 15:00 | W38: A（六个月内有报课意向工单） | X38: 线上考研产品 | Y38: 大四 | Z38: 北京物资学院 | AA38: 商学院 | AB38: 财务管理 | AC38: 王喆 | AD38: 5416998 | AE38: 谭悦 | AF38: 2025-07-21 16:02 | AG38: 谭悦 | AH38: 2025-07-21 16:02 | AI38: 69208835259 | AJ38: 2026考研英语一无忧计划·16期,2026考研政治无忧计划·12期 | AK38: 国内考试 | AM38: 15651 | AP38: 新签 | AQ38: 无须交接 | AU38: 2025-07-21 | AW38: 回访人：谭悦，回访时间：2025-07-20 15:00，回访内容：打电话非常强势，问英语政治，加微信叫温柔 ；|回访人：谭悦，回访时间：2025-07-21 16:02，回访内容：1 | BA38: 长期班,长期班 | BB38: 82071259 | BC38: 是 | BD38: 26考季 | BE38: 线上无忧计划 | BF38: 英语,政治 | BG38: 其他 | BH38: 国内高校-双非 | BI38: 否 | BM38: 107965657 | BN38: 本地人本地大学(常规) | BO38: 线下代理商
A39: 代售网课 | B39: 29 | C39: 北京大学部 | D39: 国内大学部 | E39: 赵家长 | F39: 119930462 | G39: 北京客服部 | H39: 2025-07-20 15:11:56 | I39: 赵家长 13601221052 首都经贸大学 马上大三 考研辅导 会计专硕 无意向机构 | J39: 2026财年第2财月代理商 | L39: 乔文娇 | M39: 线上运营-商务合作 | N39: 坦途网 | P39: 乔文娇 | Q39: 2025-07-20 15:26:41 | R39: 赵嘉华 | S39: 谭悦 | T39: 29212948 | U39: 正常工单 | V39: 2025-07-20 15:31 | W39: A（六个月内有报课意向工单） | X39: 线上考研产品 | Y39: 大三 | Z39: 首都经济贸易大学 | AA39: 会计学院 | AB39: 会计学1 | AC39: 赵嘉华 | AD39: 5486586 | AE39: 谭悦 | AF39: 2025-07-20 18:20 | AG39: 谭悦 | AH39: 2025-07-20 18:21 | AI39: 45051853639 | AJ39: 2026考研管综全科在校全程班（3期） | AK39: 国内考试 | AM39: 4139.5 | AP39: 新签 | AQ39: 无须交接 | AU39: 2025-07-20 | AW39: 回访人：谭悦，回访时间：2025-07-20 15:31，回访内容：马上过来面谈 ；|回访人：谭悦，回访时间：2025-07-20 18:20，回访内容：签约 | BA39: 长期班 | BB39: 82058266 | BC39: 是 | BD39: 26考季 | BE39: 线上全程班 | BF39: 英语,管综 | BG39: 其他 | BH39: 国内高校-双非 | BI39: 否 | BM39: 110572419 | BN39: 本地人本地大学(常规) | BO39: 线下代理商
A40: 代售网课 | B40: 30 | C40: 北京大学部 | D40: 国内大学部 | E40: 赵泽阳 | F40: 119012024 | G40: 北京国内管理员 | H40: 2025-07-14 17:08:22 | I40: 渠道录入来源：SCRM-客服推送 商机ID：5009282307 商机编码：XSJ20250714027730 针对人群：大学 学员号：BJ1221164274 学生学校：不详 咨询课程：不区分 创建人邮箱：liuxinyi91@xdf.cn 创建时间：2025-07-14 17:08:16 资源类型：单个资源 跟进记录：商机备注：孩子妈妈来电，孩子开学大三，想了解线上的考研公共课和专业课，四级过了，六级还没出分，辛苦顾问老师联系手机号2介绍，手机号2是学员自己的电话;接触点：呼入； | K40: 大三 | L40: 谭悦 | M40: 新东方官网 | N40: 新东方PC官网 | R40: 赵泽阳 | S40: 赵星火 | T40: 29084286 | U40: 续费工单 | V40: 2025-07-18 13:55 | W40: A（六个月内有报课意向工单） | X40: 线上考研产品 | Y40: 大三 | Z40: 北京物资学院 | AA40: 信息学院 | AB40: 信息工程 | AC40: 赵泽阳 | AD40: 5483935 | AE40: 赵星火 | AF40: 2025-07-18 13:57 | AG40: 赵星火 | AH40: 2025-07-18 13:57 | AI40: 17320768233 | AJ40: 2027考研政治直通车 长线2期,2027考研英语直通车 长线2期 | AK40: 国内考试 | AM40: 4443.6 | AP40: 续班 | AQ40: 无须交接 | AU40: 2025-07-18 | AW40: 回访人：谭悦，回访时间：2025-07-14 18:14，回访内容：人工智能，电子信息，27考研，学生想上网课 ；|回访人：谭悦，回访时间：2025-07-15 16:50，回访内容：考虑网课学习 ；|回访人：赵星火，回访时间：2025-07-18 13:57，回访内容：1 | BA40: 长期班,长期班 | BB40: 50793454 | BC40: 是 | BD40: 26考季 | BE40: 线上直通车 | BF40: 英语,政治 | BG40: 其他 | BH40: 国内高校-双非 | BI40: 否 | BM40: 107425955 | BN40: 本地人本地大学(常规) | BO40: SCRM-客服推送
A41: 地面业绩 | B41: 31 | C41: 北京大学部 | D41: 国内大学部 | E41: 赵泽阳 | F41: 119012024 | G41: 北京国内管理员 | H41: 2025-07-14 17:08:22 | I41: 渠道录入来源：SCRM-客服推送 商机ID：5009282307 商机编码：XSJ20250714027730 针对人群：大学 学员号：BJ1221164274 学生学校：不详 咨询课程：不区分 创建人邮箱：liuxinyi91@xdf.cn 创建时间：2025-07-14 17:08:16 资源类型：单个资源 跟进记录：商机备注：孩子妈妈来电，孩子开学大三，想了解线上的考研公共课和专业课，四级过了，六级还没出分，辛苦顾问老师联系手机号2介绍，手机号2是学员自己的电话;接触点：呼入； | K41: 大三 | L41: 谭悦 | M41: 新东方官网 | N41: 新东方PC官网 | R41: 赵泽阳 | S41: 赵星火 | T41: 29084286 | U41: 续费工单 | V41: 2025-07-18 13:55 | W41: A（六个月内有报课意向工单） | X41: 线上考研产品 | Y41: 大三 | Z41: 北京物资学院 | AA41: 信息学院 | AB41: 信息工程 | AC41: 赵泽阳 | AD41: 5455920 | AE41: 谭悦 | AF41: 2025-07-18 13:57 | AG41: 赵星火 | AH41: 2025-07-18 13:57 | AK41: 国内考试 | AM41: 4443.6 | AP41: 分单 | AQ41: 无须交接 | AW41: 回访人：谭悦，回访时间：2025-07-14 18:14，回访内容：人工智能，电子信息，27考研，学生想上网课 ；|回访人：谭悦，回访时间：2025-07-15 16:50，回访内容：考虑网课学习 ；|回访人：赵星火，回访时间：2025-07-18 13:57，回访内容：1 | BB41: 50793454 | BC41: 是 | BD41: 26考季 | BE41: 线上直通车 | BF41: 英语,政治 | BG41: 其他 | BH41: 国内高校-双非 | BI41: 否 | BN41: 本地人本地大学(常规) | BO41: SCRM-客服推送
...

Sheet 7月钉钉退费共享表明细
A1: 提交日期 | B1: 您所办理的业务类型 | C1: OA流水号 | D1: 学管姓名 | E1: 学管是否代办 | F1: 顾问姓名 | G1: 顾问是否代办 | H1: 91系统-最新报名二级渠道 | I1: 原班所属项目 | J1: 新报入班级所属项目 | K1: 退费阶段 | L1: 退费一级原因（开课前） | M1: 退费一级原因 (开课后) | N1: 退费二级原因（专业课师资匹配原因） | O1: 退费二级原因（学员意愿转变_开课前） | P1: 退费二级原因（计划冲突_开课前） | Q1: 退费二级原因（中心原因_开课前） | R1: 退费二级原因（签约话术） | S1: 退费二级原因（教师） | T1: 退费二级原因（教学） | U1: 退费二级原因（课程安排） | V1: 退费二级原因（配套服务） | W1: 退费二级原因（配套学习设施） | X1: 退费二级原因（中心原因_开课后） | Y1: 退费二级原因（计划冲突_开课后） | Z1: 退费二级原因（学员意愿转变_开课后） | AA1: 退费三级原因（完全匹配不上）-院校、学院、专业、专业课代码及名称 | AB1: 退费详细原因说明（与OA退费详细说明保持一致） | AC1: 预计报名新班学费金额 | AD1: 转班金额（请学管填写所在班级实际金额） | AE1: 转班详细原因说明 | AF1: 提交时间 | AG1: 学校 | AH1: 学院 | AI1: 年级 | AJ1: 专业 | AK1: 提交人 | AL1: 退费类型 | AM1: 学员姓名 | AN1: 学员编码 | AO1: 退费金额 | AP1: 退转金额 | AQ1: 办理日期-客服 | AR1: 退费方式-客服 | AS1: 需要跟进的顾问/学管 | AT1: 退费/转班特殊情况备注（若需要学管提供银行卡信息，可将需求填写在此处）-客服 | AU1: 是否完成退费/转班-客服 | AV1: 父记录 | AW1: 父记录
A2: 2025/07/02 | B2: 转班 | D2: 韦艺鑫 | F2: 谭悦 | H2: 大众点评 | I2: 无忧项目（弃用） | AD2: 9940.4 | AE2: 更换目标院校，改考英语二 | AF2: 2025-07-02 | AK2: 韦艺鑫 | AM2: 黄禹淇 | AN2: BJWY4049653605 | AP2: 9940.4 | AQ2: 2025/07/02 | AR2: 已转班 | AU2: TRUE
A3: 2025/07/30 | B3: 转班 | D3: 许庆典 | F3: 谭悦 | H3: 大众点评 | I3: 无忧项目-班课 | AD3: 6911.7 | AE3: 更换目标院校，改考英语一 | AF3: 2025-07-30 | AK3: 许庆典 | AM3: 黄禹淇 | AN3: BJWY4049653605 | AP3: 6911.7 | AQ3: 2025/07/30 | AR3: 已转班 | AU3: TRUE
A4: 2025/07/02 | B4: 退费 | C4: NO.4323455642276930888 | D4: 马一鸣16-马一鸣 | F4: 谭悦 | H4: 学管续费推荐 | I4: 无忧项目（弃用） | K4: 开课后退费 | M4: 学员意愿转变_开课后 | Z4: 考研信心不足（因跟不上、基础薄弱、目标过高） | AB4: 学生原先报考浙江大学，因测试后觉得自己考不上，打算报考本校北京交通大学，换一个更加稳妥的学校。 | AF4: 2025-07-04 | AK4: 马一鸣16-马一鸣 | AL4: 真实产生的退费 | AM4: 黄禹淇 | AN4: BJWY4049653605 | AO4: 2550 | AP4: 2550 | AQ4: 2025/07/05 | AR4: 7.9财务付款成功 7.7已转手工退至学员本人银行卡，用户短信已确认（6.8）@马一鸣16 (马一鸣) | AU4: TRUE
A5: 2025/07/02 | B5: 退费 | C5: 18750907 | D5: 郑雪新 | F5: 谭悦 | H5: 总部-百度投放 | I5: 集训营项目（弃用） | K5: 开课前退费 | L5: 计划冲突_开课前 | P5: 学校事务和新东方时间冲突 | AB5: 1】KYJS250180006 KYJS25018 26考研数学OMO全程集训营（政英数联报） 187602】KYJZ250180006 KYJZ25018 26考研政治OMO全程集训营（政英数联报）12043.23】KYJY250180006 KYJY25018 26考研英语OMO全程集训营（英政数联报）13816.84】KYZ250180006 KYZ25018 26考研OMO全程集训营（住宿费/政英数/经综）7680【扣7300补给专业课优惠】5】专业课系统费用11000，保留专业课需要扣除18800-500=18300，即补专业课7300元（此部分费用从住宿费班号扣除） | AF5: 2025-07-02 | AK5: 郑雪新 | AL5: 真实产生的退费 | AM5: 吴嘉豪 | AN5: BJWY8214160628 | AO5: 44620 | AP5: 44620 | AQ5: 2025/07/03 | AR5: 7.10财务付款成功 7.4已转手工退，用户短信已确认 | AU5: TRUE
A6: 2025/07/02 | B6: 退费 | C6: 18750919 | D6: 郑雪新 | F6: 谭悦 | H6: 总部-百度投放 | I6: 集训营项目（弃用） | K6: 开课前退费 | L6: 计划冲突_开课前 | P6: 学校事务和新东方时间冲突 | AB6: 1】KYJS250180006 KYJS25018 26考研数学OMO全程集训营（政英数联报） 187602】KYJZ250180006 KYJZ25018 26考研政治OMO全程集训营（政英数联报）12043.23】KYJY250180006 KYJY25018 26考研英语OMO全程集训营（英政数联报）13816.84】KYZ250180006 KYZ25018 26考研OMO全程集训营（住宿费/政英数/经综）7680【扣7300补给专业课优惠】5】专业课系统费用11000，保留专业课需要扣除18800-500=18300，即补专业课7300元（此部分费用从住宿费班号扣除） | AF6: 2025-07-02 | AK6: 郑雪新 | AL6: 真实产生的退费 | AM6: 吴嘉豪 | AN6: BJWY8214160628 | AO6: 380 | AP6: 380 | AQ6: 2025/07/03 | AR6: 7.10财务付款成功 7.4已转手工退，用户短信已确认 | AU6: TRUE
A7: 2025/07/06 | B7: 转班 | D7: 黄小妹7-黄小妹 | F7: 谭悦 | H7: 百度投放 | I7: 无忧项目-班课 | AD7: 9959.6 | AE7: 学生报考院校公告考试科目变更 英二转英一 | AF7: 2025-07-06 | AK7: 黄小妹7-黄小妹 | AM7: 刘明喆 | AN7: XDF032220080227974 | AP7: 9959.6 | AQ7: 2025/07/06 | AR7: 已转班 | AU7: TRUE
A8: 2025/07/06 | B8: 退费 | C8: 18770083 | D8: 张琦文6-张琦文 | F8: 谭悦 | H8: 小红书 | I8: 集训营项目（弃用） | J8: 集训营项目 | K8: 开课后退费 | M8: 中心原因_开课后 | X8: 退出重报（取消班/合班/延转/选班/扩科等） | AB8: 学员转班七月半年集训营，退出现有班级金额到学员账户，重新入班 | AC8: ¥67200.00 | AF8: 2025-07-06 | AK8: 张琦文6-张琦文 | AL8: 转项目/转班/退出重报等未产生实际退费 | AM8: 王仪阳 | AN8: BJWY6088825240 | AO8: 4960 | AP8: 4960 | AQ8: 2025/07/07 | AR8: 退至学员账户 | AU8: TRUE
A9: 2025/07/06 | B9: 退费 | C9: 18770068 | D9: 张琦文6-张琦文 | F9: 谭悦 | H9: 小红书 | I9: 集训营项目（弃用） | J9: 集训营项目 | K9: 开课后退费 | M9: 中心原因_开课后 | X9: 退出重报（取消班/合班/延转/选班/扩科等） | AB9: 学员转班七月半年集训营，退出现有班级金额到学员账户，重新入班 | AC9: ¥67200.00 | AF9: 2025-07-06 | AK9: 张琦文6-张琦文 | AL9: 转项目/转班/退出重报等未产生实际退费 | AM9: 王仪阳 | AN9: BJWY6088825240 | AO9: 11879 | AP9: 11879 | AQ9: 2025/07/07 | AR9: 退至学员账户 | AU9: TRUE
A10: 2025/07/06 | B10: 退费 | C10: 18770042 | D10: 张琦文6-张琦文 | F10: 谭悦 | H10: 小红书 | I10: 集训营项目（弃用） | J10: 集训营项目 | K10: 开课后退费 | M10: 中心原因_开课后 | X10: 退出重报（取消班/合班/延转/选班/扩科等） | AB10: 学员转班七月半年集训营，退出现有班级金额到学员账户，重新入班 | AC10: ¥67200.00 | AF10: 2025-07-06 | AK10: 张琦文6-张琦文 | AL10: 转项目/转班/退出重报等未产生实际退费 | AM10: 王仪阳 | AN10: BJWY6088825240 | AO10: 5863 | AP10: 5863 | AQ10: 2025/07/07 | AR10: 退至学员账户 | AU10: TRUE
A11: 2025/07/06 | B11: 退费 | C11: NO.1152921504608137010 | D11: 郭又华 | F11: 谭悦 | H11: 学管续费推荐 | I11: 无忧项目（弃用） | J11: VIP项目 | K11: 开课前退费 | L11: 中心原因_开课前 | Q11: 退出重报（取消班/合班/延转/选班/扩科等） | AB11: 学生心理状态不太好，今年先不打算考研了，想把公共课和专业课剩余课时全部退到学员账户，再转成一对一课程，重新报入 | AC11: ¥10000.00 | AF11: 2025-07-06 | AK11: 郭又华 | AL11: 转项目/转班/退出重报等未产生实际退费 | AM11: 陈一凡 | AN11: BJWY8503976521 | AO11: 10000 | AP11: 5863 | AQ11: 2025/07/14 | AR11: 要求退学生账户 | AU11: TRUE | AX11: 离职顾问代办理 | AY11: 10000
A12: 2025/07/11 | B12: 退费 | C12: 18783288 | D12: 唐源曼 | F12: 谭悦 | H12: 知了好学 | I12: 集训营项目-班课 | K12: 开课后退费 | M12: 学员意愿转变_开课后 | Z12: 考研信心不足（因跟不上、基础薄弱、目标过高） | AB12: 学员换了学校不需要考数三，转到七月政英经综班 | AF12: 2025-07-15 | AG12: 北京邮电大学 | AH12: 电子工程学院 | AI12: 已毕业 | AJ12: 电子信息科学与技术 | AK12: 唐源曼 | AL12: 真实产生的退费 | AM12: 王英帆 | AN12: BJWY4965756550 | AO12: 16900 | AP12: =AY12/2 -> 8450 | AQ12: 2025/07/16 | AR12: 7.23退款完成 7.22用户短信已确认，退款中@唐源曼 7.19转手工，待用户短信确认—————— 合计退费金额为81902.1 ，暂退至学员账户，原渠道为汇款，需提供原汇款账户6226622106991108的详细信息@唐源曼 [图片] | AU12: TRUE | AX12: 谭悦，星火分单 | AY12: 16900
A13: 2025/07/11 | B13: 退费 | C13: 18783290 | D13: 唐源曼 | F13: 谭悦 | H13: 知了好学 | I13: 集训营项目-班课 | K13: 开课后退费 | M13: 学员意愿转变_开课后 | Z13: 考研信心不足（因跟不上、基础薄弱、目标过高） | AB13: 学员换了学校不需要考数三，转到七月政英经综班 | AF13: 2025-07-15 | AG13: 北京邮电大学 | AH13: 电子工程学院 | AI13: 已毕业 | AJ13: 电子信息科学与技术 | AK13: 唐源曼 | AL13: 真实产生的退费 | AM13: 王英帆 | AN13: BJWY4965756550 | AO13: 4816.2 | AP13: =AY13/2 -> 2408.1 | AQ13: 2025/07/16 | AR13: 7.23退款完成 7.22用户短信已确认，退款中@唐源曼 7.19转手工，待用户短信确认—————— 合计退费金额为81902.1 ，暂退至学员账户，原渠道为汇款，需提供原汇款账户6226622106991108的详细信息@唐源曼 [图片] | AU13: TRUE | AX13: 谭悦，星火分单 | AY13: 4816.2
A14: 2025/07/11 | B14: 退费 | C14: 18783292 | D14: 唐源曼 | F14: 谭悦 | H14: 知了好学 | I14: 集训营项目-班课 | K14: 开课后退费 | M14: 学员意愿转变_开课后 | Z14: 考研信心不足（因跟不上、基础薄弱、目标过高） | AB14: 学员换了学校不需要考数三，转到七月政英经综班 | AF14: 2025-07-15 | AG14: 北京邮电大学 | AH14: 电子工程学院 | AI14: 已毕业 | AJ14: 电子信息科学与技术 | AK14: 唐源曼 | AL14: 真实产生的退费 | AM14: 王英帆 | AN14: BJWY4965756550 | AO14: 14855.3 | AP14: =AY14/2 -> 7427.65 | AQ14: 2025/07/16 | AR14: 7.23退款完成 7.22用户短信已确认，退款中@唐源曼 7.19转手工，待用户短信确认—————— 合计退费金额为81902.1 ，暂退至学员账户，原渠道为汇款，需提供原汇款账户6226622106991108的详细信息@唐源曼 [图片] | AU14: TRUE | AX14: 谭悦，星火分单 | AY14: 14855.3
A15: 2025/07/11 | B15: 退费 | C15: 18783293 | D15: 唐源曼 | F15: 谭悦 | H15: 知了好学 | I15: 集训营项目-班课 | K15: 开课后退费 | M15: 学员意愿转变_开课后 | Z15: 考研信心不足（因跟不上、基础薄弱、目标过高） | AB15: 学员换了学校不需要考数三，转到七月政英经综班 | AF15: 2025-07-15 | AG15: 北京邮电大学 | AH15: 电子工程学院 | AI15: 已毕业 | AJ15: 电子信息科学与技术 | AK15: 唐源曼 | AL15: 真实产生的退费 | AM15: 王英帆 | AN15: BJWY4965756550 | AO15: 5561.8 | AP15: =AY15/2 -> 2780.9 | AQ15: 2025/07/16 | AR15: 7.23退款完成 7.22用户短信已确认，退款中@唐源曼 7.19转手工，待用户短信确认—————— 合计退费金额为81902.1 ，暂退至学员账户，原渠道为汇款，需提供原汇款账户6226622106991108的详细信息@唐源曼 [图片] | AU15: TRUE | AX15: 谭悦，星火分单 | AY15: 5561.8
A16: 2025/07/11 | B16: 退费 | C16: 18783296 | D16: 唐源曼 | F16: 谭悦 | H16: 知了好学 | I16: 集训营项目-班课 | K16: 开课后退费 | M16: 学员意愿转变_开课后 | Z16: 考研信心不足（因跟不上、基础薄弱、目标过高） | AB16: 学员换了学校不需要考数三，转到七月政英经综班 | AF16: 2025-07-15 | AG16: 北京邮电大学 | AH16: 电子工程学院 | AI16: 已毕业 | AJ16: 电子信息科学与技术 | AK16: 唐源曼 | AL16: 真实产生的退费 | AM16: 王英帆 | AN16: BJWY4965756550 | AO16: 9703.8 | AP16: =AY16/2 -> 4851.9 | AQ16: 2025/07/16 | AR16: 7.23退款完成 7.22用户短信已确认，退款中@唐源曼 7.19转手工，待用户短信确认—————— 合计退费金额为81902.1 ，暂退至学员账户，原渠道为汇款，需提供原汇款账户6226622106991108的详细信息@唐源曼 [图片] | AU16: TRUE | AX16: 谭悦，星火分单 | AY16: 9703.8
A17: 2025/07/11 | B17: 退费 | C17: 18783285 | D17: 唐源曼 | F17: 谭悦 | H17: 知了好学 | I17: 集训营项目-班课 | K17: 开课前退费 | L17: 学员意愿转变_开课前 | O17: 考研信心不足（因跟不上、基础薄弱、目标过高） | AB17: 学员换了学校不需要考数三，转到七月政英经综班 | AF17: 2025-07-15 | AG17: 北京邮电大学 | AH17: 电子工程学院 | AI17: 已毕业 | AJ17: 电子信息科学与技术 | AK17: 唐源曼 | AL17: 真实产生的退费 | AM17: 王英帆 | AN17: BJWY4965756550 | AO17: 5265 | AP17: =AY17/2 -> 2632.5 | AQ17: 2025/07/17 | AR17: 7.23退款完成 7.22用户短信已确认，退款中@唐源曼 7.19转手工，待用户短信确认—————— 合计退费金额为81902.1 ，暂退至学员账户，原渠道为汇款，需提供原汇款账户6226622106991108的详细信息@唐源曼 [图片] | AU17: TRUE | AX17: 谭悦，星火分单 | AY17: 5265
A18: 2025/07/11 | B18: 退费 | C18: 18783281 | D18: 唐源曼 | F18: 谭悦 | H18: 知了好学 | I18: 集训营项目-班课 | K18: 开课后退费 | M18: 学员意愿转变_开课后 | Z18: 考研信心不足（因跟不上、基础薄弱、目标过高） | AB18: 学员换了学校不需要考数三，转到七月政英经综班 | AF18: 2025-07-15 | AG18: 北京邮电大学 | AH18: 电子工程学院 | AI18: 已毕业 | AJ18: 电子信息科学与技术 | AK18: 唐源曼 | AL18: 真实产生的退费 | AM18: 王英帆 | AN18: BJWY4965756550 | AO18: 24800 | AP18: =AY18/2 -> 12400 | AQ18: 2025/07/16 | AR18: 7.23退款完成 7.22用户短信已确认，退款中@唐源曼 7.19转手工，待用户短信确认—————— 合计退费金额为81902.1 ，暂退至学员账户，原渠道为汇款，需提供原汇款账户6226622106991108的详细信息@唐源曼 [图片] | AU18: TRUE | AX18: 谭悦，星火分单 | AY18: 24800
A19: 2025/07/10 | B19: 退费 | C19: 2025071100308 | D19: 陈晶171-陈晶 | F19: 谭悦 | H19: 集团-百度品专 | I19: VIP项目-VIP | K19: 开课后退费 | M19: 学员意愿转变_开课后 | Z19: 认为课程用处不大/不适合自己 | AB19: 初复试课时都没用完，现在收到录取通知书了，不辅导其他内容 | AF19: 2025-07-14 | AG19: 北京电影学院 | AH19: 表演系 | AI19: 大四 | AJ19: 表演 | AK19: 陈晶171-陈晶 | AL19: 真实产生的退费 | AM19: 祝雪妍 | AN19: BJWY1605479028 | AO19: 19200 | AP19: 19200 | AQ19: 2025/07/17 | AR19: 支付宝退回 | AU19: TRUE
A20: 2025/07/18 | B20: 退费 | C20: 18800865 | D20: 郝琨 | F20: 谭悦 | H20: 学管续费推荐 | I20: 无忧项目-班课 | J20: VIP项目 | K20: 开课前退费 | L20: 中心原因_开课前 | Q20: 退出重报（取消班/合班/延转/选班/扩科等） | AB20: 学生2000老生二战优惠保留给数学，英语退班需退出15800 实际分摊金额不够，需要从数学班中返款2000 | AC20: ¥20000.00 | AF20: 2025-07-18 | AG20: 北京邮电大学 | AH20: 计算机学院 | AI20: 毕业 | AJ20: 通信工程 | AK20: 郝琨 | AL20: 转项目/转班/退出重报等未产生实际退费 | AM20: 蔡哲 | AN20: BJWY0874092650 | AO20: 2000 | AP20: 2000 | AQ20: 2025/07/19 | AR20: 暂退账户2000 | AU20: TRUE
A21: 2025/07/18 | B21: 退费 | C21: 18800521 | D21: 郝琨 | F21: 谭悦 | H21: 学管续费推荐 | I21: 无忧项目-班课 | J21: VIP项目 | K21: 开课前退费 | L21: 中心原因_开课前 | Q21: 退出重报（取消班/合班/延转/选班/扩科等） | AB21: 学生姓名：蔡哲学员编号：BJWY0874092650退费方式：报英语数学退英语退费原因：学生退掉暑假候鸟班英语，保留数学班，保留二战优惠，退费到储值参加一对一辅导退费班级：WYHE26007、WYHE26005退费明细：英语班退出13800，从数学班返款2000，总计退出15800 | AC21: ¥20000.00 | AF21: 2025-07-18 | AG21: 北京邮电大学 | AH21: 计算机学院 | AI21: 毕业 | AJ21: 通信工程 | AK21: 郝琨 | AL21: 转项目/转班/退出重报等未产生实际退费 | AM21: 蔡哲 | AN21: BJWY0874092650 | AO21: 13800 | AP21: 13800 | AQ21: 2025/07/20 | AR21: 退回账户余额入班 | AU21: TRUE
A22: 2025/07/19 | B22: 转班 | D22: 黄小妹7-黄小妹 | F22: 谭悦 | H22: 学管转介绍 | I22: 无忧项目-班课 | AD22: 3915 | AE22: 学生时间冲突，向后转班 | AF22: 2025-07-19 | AK22: 黄小妹7-黄小妹 | AM22: 程悦 | AN22: BJWY8477545262 | AP22: 3915 | AQ22: 2025/07/19 | AR22: 已转班 | AU22: TRUE
A23: 2025/07/21 | B23: 退费 | C23: 18797336 | D23: 陈号东5-陈号东 | F23: 谭悦 | H23: 总部-巨量广告 | I23: 无忧项目-班课 | K23: 开课后退费 | M23: 学员意愿转变_开课后 | Z23: 认为课程用处不大/不适合自己 | AB23: 学生觉得课程简单，不想学中途离场 ，决定报名报网课 | AF23: 2025-07-21 | AG23: 北京交通大学 | AH23: 自动化与智能学院 | AI23: 2022级 | AJ23: 人工智能 | AK23: 陈号东5-陈号东 | AL23: 真实产生的退费 | AM23: 刘泽宇 | AN23: BJWY6304152842 | AO23: 18247.1 | AP23: 18247.1 | AQ23: 2025/07/22 | AR23: 7.24退款到账 银联商务POS退回：浦发银行621792*********5901 | AU23: TRUE
A24: 2025/07/24 | B24: 转班 | D24: 黄子琪3-黄子琪 | F24: 谭悦 | H24: 巨量广告 | I24: 无忧项目-班课 | AD24: 3891.1 | AE24: 姓名：郑雅洁 学员号：BJWY5564317069 转班信息如下：WYE27013转WYE27018 转班原因：时间有问题，想转到9月班上课 | AF24: 2025-07-24 | AK24: 黄子琪3-黄子琪 | AM24: 郑雅洁 | AN24: BJWY5564317069 | AP24: 3891.1 | AQ24: 2025/07/24 | AR24: 已转班 | AU24: TRUE
A25: 2025/07/25 | B25: 转班 | D25: 徐岩91-徐岩 | F25: 谭悦 | H25: 京内毛坯数据 | I25: 四六级项目-班课 | AD25: 6180 | AE25: 原班取消 | AF25: 2025-07-25 | AK25: 徐岩91-徐岩 | AM25: 杨达京 | AN25: BJWY8544603962 | AP25: 6180 | AQ25: 2025/07/27 | AR25: 已转班 | AU25: TRUE
A26: 2025/07/26 | B26: 转班 | D26: 徐岩91-徐岩 | F26: 谭悦 | G26: TRUE | H26: 京内毛坯数据 | I26: 四六级项目-班课 | AD26: 5180 | AE26: 从知春路班级，转到花园桥班级，已经办理，补流程。 | AF26: 2025-07-26 | AK26: 谭悦9-谭悦 | AM26: 杨达京 | AN26: BJWY8544603962 | AP26: 5180 | AQ26: 2025/07/27 | AR26: 已转班 | AU26: TRUE
A27: 2025/07/24 | B27: 退费 | C27: 18813759 | D27: 罗志勇1-罗志勇 | F27: 谭悦 | H27: 地图标点 | I27: 四六级项目-班课 | K27: 开课前退费 | L27: 学员意愿转变_开课前 | O27: 个人身体原因无法承受高强度学习 | AB27: 【开课前退费】张佳卉，ZVVA26001，学生和家长来现场报名四级集训营，由于身体不适去医院了，要调养三周，不能参加四级集训了，先做退费，后期再看需要什么样的课程。 | AF27: 2025-07-24 | AG27: 吉林建筑大学 | AH27: 建筑与规划学院 | AI27: 大四 | AJ27: 城乡规划 | AK27: 罗志勇1-罗志勇 | AL27: 真实产生的退费 | AM27: 张佳卉 | AN27: BJWY1792811322 | AO27: 15800 | AP27: 15800 | AQ27: 2025/07/31 | AR27: 微信退还 | AU27: TRUE
A28: 2025/07/28 | B28: 退费 | C28: 3458764513821909095 | D28: 史文涵1-史文涵 | F28: 谭悦 | H28: 学管续费推荐 | I28: 无忧项目-VIP | K28: 开课后退费 | M28: 学员意愿转变_开课后 | Z28: 考研信心不足（因跟不上、基础薄弱、目标过高） | AB28: 学员放弃考研 | AF28: 2025-07-28 | AG28: 北京联合大学 | AH28: 管理学院 | AI28: 大三 | AJ28: 工商管理 | AK28: 史文涵1-史文涵 | AL28: 真实产生的退费 | AM28: 孙宇航 | AN28: BJWY6390615397 | AO28: 33500 | AP28: 33500 | AQ28: 2025/07/31 | AR28: 微信退还 | AU28: TRUE
A29: 2025/07/10 | B29: 转班 | D29: 葛铭 | F29: 谭悦 | H29: 职递 | I29: 无忧项目-班课 | AD29: 4800 | AE29: 学员时间冲突，申请转班 | AF29: 2025-07-10 | AK29: 葛铭 | AM29: 毕琦昕 | AN29: BJWY1550131227 | AP29: 4800 | AQ29: 2025/07/10 | AR29: 已转班 | AU29: TRUE
A30: 2025/07/06 | B30: 退费 | C30: NO.2882303761518374667 | D30: 王嘉庆5-王嘉庆 | F30: 谭悦 | H30: 地图标点 | I30: 无忧项目（弃用） | K30: 开课前退费 | L30: 学员意愿转变_开课前 | O30: 去其他机构 | AB30: 学生自己通过朋友联系到了专业课老师，且不考虑转成其他课程 | AF30: 2025-07-06 | AK30: 王嘉庆5-王嘉庆 | AL30: 真实产生的退费 | AM30: 安麒 | AN30: BJWY3081505061 | AO30: 21000 | AP30: =AY30/2 -> 10500 | AQ30: 2025/07/11 | AR30: 支付宝退回 | AU30: TRUE | AX30: 谭悦,张俊旺分单 | AY30: 21000
A31: 2025/07/01 | B31: 转班 | D31: 郑雪新 | F31: 谭悦 | H31: 内部员工推荐 | I31: 集训营项目（弃用） | AD31: 0 | AE31: 姓名：章俊骐 学员号：BJWY4692076178 手机号：15313850822 转班信息如下：KYJY25004转到KYJY25003；KYJZ25004转到KYJZ25003 转班原因：学生英语二变更英语一，申请转班(学员原本是定的英二，今天突然更改确为英一） | AF31: 2025-07-01 | AK31: 郑雪新 | AL31: 集训批量转班 | AM31: 章俊骐 | AN31: BJWY4692076178 | AO31: 18999.4 | AP31: 38498.8 | AQ31: 2025/07/01 | AR31: 已转班 | AU31: TRUE
F32: 谭悦 | AK32: 郑雪新 | AL32: 集训批量转班 | AM32: 白恩宁 | AP32: 18969.1
F33: 谭悦 | AK33: 郑雪新 | AL33: 集训批量转班 | AM33: 谌蕙荃 | AP33: 18628.7
F34: 谭悦 | AK34: 郑雪新 | AL34: 集训批量转班 | AM34: 李兆同 | AP34: 14237.7
F35: 谭悦 | AK35: 郑雪新 | AL35: 集训批量转班 | AM35: 张思远 | AP35: 14237.8
F36: 谭悦 | AL36: 网课退费 | AM36: 学员h0d2p | AP36: 80 | AQ36: 45854.687
F37: 谭悦 | AL37: 网课退费 | AM37: DLS_7932216421 | AP37: 70 | AQ37: 45850.769
F38: 谭悦 | AL38: 网课退费 | AM38: 学员uh9jj | AP38: 100 | AQ38: 45841.552
AN39: 谭悦合计 | AP39: =SUM(AP2:AP38) -> 385713.05
A40: 2025/07/11 | B40: 退费 | C40: 18783288 | D40: 唐源曼 | F40: 赵星火 | H40: 知了好学 | I40: 集训营项目-班课 | K40: 开课后退费 | M40: 学员意愿转变_开课后 | Z40: 考研信心不足（因跟不上、基础薄弱、目标过高） | AB40: 学员换了学校不需要考数三，转到七月政英经综班 | AF40: 2025-07-15 | AG40: 北京邮电大学 | AH40: 电子工程学院 | AI40: 已毕业 | AJ40: 电子信息科学与技术 | AK40: 唐源曼 | AL40: 真实产生的退费 | AM40: 王英帆 | AN40: BJWY4965756550 | AO40: 16900 | AP40: =AY40/2 -> 8450 | AQ40: 2025/07/16 | AR40: 7.23退款完成 7.22用户短信已确认，退款中@唐源曼 7.19转手工，待用户短信确认—————— 合计退费金额为81902.1 ，暂退至学员账户，原渠道为汇款，需提供原汇款账户6226622106991108的详细信息@唐源曼 [图片] | AU40: TRUE | AX40: 谭悦，星火分单 | AY40: 16900
...

Sheet 7月绩效核算
C2: FY25-7月个性化顾问绩效核算
C3: 工号 | D3: 顾问 | E3: 备注 | F3: 转介绍工单目标 | G3: 转介绍工单完成 | H3: 顾问转介绍得分（50） | I3: 转介绍签约目标 | J3: 转介绍签约完成 | K3: 转介绍签约的份（30） | L3: 主动转化率目标 | M3: 主动转化率 | N3: 被动转化率目标 | O3: 被动转化率 | P3: 转化率得分（20） | Q3: 合计得分 | R3: 发放比例 | S3: 月度绩效标准 | T3: 月绩效应发
C4: 238256 | D4: 赵星火 | F4: 3 | G4: 5 | H4: 50 | I4: 1 | J4: 2 | K4: 30 | L4: 0.3 | M4: 0.27 | N4: 0.1 | O4: =3/60 -> 0.05 | P4: 12 | Q4: =H4+K4+P4 -> 92 | R4: 1 | S4: 1000 | T4: 920
C5: 341422 | D5: 谭悦 | F5: 3 | G5: 14 | H5: 50 | I5: 1 | J5: 5 | K5: 30 | L5: 0.3 | M5: 0.42 | N5: 0.1 | O5: =8/51 -> 0.15686275 | P5: 20 | Q5: 100 | R5: 0.7 | S5: 0 | T5: 0 | U5: O3无绩效

Sheet 8月绩效目标
B3: 序号 | C3: 年月 | D3: 部门 | E3: 工号 | F3: 姓名 | G3: 岗位 | H3: 绩效考核项
H4: 1.签约业绩 | I4: 2.主被动转化率 | J4: 3.老带新工单/人头/金额 | K4: 4.规划课签约人头 | L4: 5.回访时效
B5: 1 | C5: 202508 | D5: 个性化项目部 | E5: 238256 | F5: 赵星火 | G5: 学习顾问 | H5: 地面75w+代售在线3w | I5: 主动25%、被动10% | J5: 工单6/人头3/金额6 | K5: 2 | L5: 不低于中心50分位值
B6: 2 | C6: 202508 | E6: 341422 | F6: 谭悦 | H6: 地面75w+代售在线3w | I6: 主动25%、被动10% | J6: 工单6/人头3/金额6 | K6: 2 | L6: 不低于中心50分位值
B7: 3 | C7: 202508 | E7: 404905 | F7: 李涛 | H7: 整体10w | I7: 整体10% | L7: 不低于中心50分位值
