Workbook

Sheet 汇总
A1: 序号 | B1: 工号 | C1: 姓名 | D1: 部门 | E1: 岗位 | F1: 薪资项目 | G1: 金额 | H1: 备注 | K1: 说明
A2: 1 | B2: 238256 | C2: 赵星火 | D2: 考研个性化 | E2: 学习顾问 | F2: 月度绩效 | G2: =核算模版!P4 -> 600 | K2: 兵种 | L2: 薪资名称 | M2: 标化薪资项目请选择
A3: 2 | B3: 341422 | C3: 谭悦 | D3: 考研个性化 | E3: 学习顾问 | F3: 其他业绩奖金 | G3: 1000 | H3: 菁英计划签约奖金1000，学员陈政元 | K3: 顾问 | L3: 月绩效 | M3: 月度绩效
A4: 3 | B4: 404905 | C4: 李涛 | D4: 考研个性化 | E4: 学习顾问 | F4: 月度绩效 | G4: =核算模版!P6 -> 1200 | L4: 业绩提点 | M4: 提成奖金
A5: 4 | B5: 238256 | C5: 赵星火 | D5: 考研个性化 | E5: 学习顾问 | F5: 提成奖金 | G5: =核算模版!AG4 -> 1390.4312 | L5: 转介绍额外激励 | M5: 提成奖金
A6: 5 | B6: 341422 | C6: 谭悦 | D6: 考研个性化 | E6: 学习顾问 | F6: 提成奖金 | G6: =核算模版!AH5 -> 27810.468 | L6: PK赛激励 | M6: 其他业绩奖金
A7: 6 | B7: 404905 | C7: 李涛 | D7: 考研个性化 | E7: 学习顾问 | F7: 提成奖金 | G7: =核算模版!AD6 -> 0 | K7: 特殊项 | L7: 业绩回算正数 | M7: 往月薪资补发
A8: 7 | L8: 业绩回算负值 | M8: 业绩扣款
A9: 8
A10: 9
A11: 10
A12: 11
A13: 12
A14: 13
A15: 14
A16: 15
A17: 16
A18: 17
A19: 18
A20: 19
... A30: 29

Sheet 核算模版
A1: 手动填写灰色、蓝色单元格，其他含公式，勿动
A2: 个性化顾问 | D2: 转介绍业绩-30% | H2: 签约率-40% | K2: 日常管理-30% | M2: 月度绩效 | Q2: 基本提成 | AE2: 转介绍提成 | AG2: 提成奖金合计 | AH2: 合计
A3: 月份 | B3: 姓名 | C3: 职级（下滑选择） | D3: 转介绍目标 | E3: 转介绍业绩（净） | F3: 完成率 | G3: 得分 | H3: 目标 | I3: 签约率 | J3: 得分 | K3: 日常管理扣分次数 | L3: 得分 | M3: 总得分 | N3: 绩效基数 | O3: 发放比例 | P3: 发放金额 | Q3: 地面现金目标 | R3: 地面现金签约 | S3: 地面退费 | T3: 地面净现金 | U3: 在线现金目标 | V3: 在线现金签约 | W3: 在线退费 | X3: 在线净现金 | Y3: 总现金完成-退费后 | Z3: 现金完成率-退费后 | AA3: 现金完成率-退费前 | AB3: 上月退费后业绩完成率 | AC3: 奖金提点系数 | AD3: 基本提成 | AE3: 转介绍业绩提成比率 | AF3: 转介绍提成
A4: 202511 | B4: 赵星火 | C4: O2 | D4: 50000 | E4: 0 | F4: =E4/D4 -> 0 | G4: =IFERROR(IF(F4>=1,30,IF(AND(1>F4,F4>=0.7),F4*30,IF(F4<70,0))),0) -> 0 | H4: 0.25 | I4: =33/99 -> 0.33333333 | J4: =IFERROR(IF(I4>=H4,40,IF(AND(0.08>=H4-I4,H4-I4>=0.01),20-(H4-I4)*100*5,IF(H4-I4>0.08,0))),0) -> 40 | K4: 0 | L4: =IF(30-K4<0,0,30-K4) -> 30 | M4: =L4+J4+G4 -> 70 | N4: =IFERROR(IF(C4="O1",2000,IF(C4="O2",1000,IF(C4="O3",0,2000))),0) -> 1000 | O4: =IF(ISNUMBER(SEARCH("培训",C4)),1,IF(M4>=90,1,IF(M4>=70,1-(90-M4)*0.02,0))) -> 0.6 | P4: =IF(M4>=90,N4,IF(M4<70,0,IF(AND(90>M4,M4>=70),N4-N4*((90-M4)*0.02)))) -> 600 | Q4: 510000 | R4: 456580 | S4: =退费明细!AD49 -> 335830.5 | T4: =R4-S4 -> 120749.5 | U4: 5000 | V4: 53154.4 | W4: 100 | X4: =V4-W4 -> 53054.4 | Y4: =X4+T4 -> 173803.9 | Z4: =Y4/(Q4+U4) -> 0.3374833 | AA4: =(R4+V4)/Q4 -> 0.99947922 | AB4: 0.4 | AC4: =IF(ISNUMBER(SEARCH("保薪",C4)),IFERROR(IF(Z4<0.7,0%,IF(AND(Z4>=0.7,Z4<1),0.8%,IF(AND(Z4>=1,Z4<1.2),1.2%,IF(Z4>=1.2,2%)))),0),IFERROR(IF(AND(Z4>=1.5,AB4>=0.4),0.05,IF(AND(Z4>=1.5,AB4<0.4),0.04,IF(AND(Z4<1.5,Z4>=1.2),0.04,IF(AND(Z4<1.2,Z4>=1),0.03,IF(AND(Z4<1,Z4>=0.8),0.018,IF(AND(Z4<0.8,Z4>=0.7),0.008,IF(AND(Z4<0.7,AA4>=0.7),0.008,IF(AND(Z4<0.7,AA4<0.7),0)))))))),0)) -> 0.008 | AD4: =Y4*AC4 -> 1390.4312 | AE4: =IF(F4>=1,0.002,IF(F4<0.7,-0.002,IF(AND(F4>=0.7,F4<1),0))) -> -0.002 | AF4: =E4*(AE4) -> 0 | AG4: =AF4+AD4 -> 1390.4312 | AH4: =AF4+AD4+P4 -> 1990.4312
A5: 202511 | B5: 谭悦 | C5: O3 | D5: 50000 | E5: 33650 | F5: =E5/D5 -> 0.673 | G5: =IFERROR(IF(F5>=1,30,IF(AND(1>F5,F5>=0.7),F5*30,IF(F5<70,0))),0) -> 0 | H5: 0.25 | I5: =49/126 -> 0.38888889 | J5: =IFERROR(IF(I5>=H5,40,IF(AND(0.08>=H5-I5,H5-I5>=0.01),20-(H5-I5)*100*5,IF(H5-I5>0.08,0))),0) -> 40 | K5: 0 | L5: =IF(30-K5<0,0,30-K5) -> 30 | M5: =L5+J5+G5 -> 70 | N5: =IFERROR(IF(C5="O1",2000,IF(C5="O2",1000,IF(C5="O3",0,2000))),0) -> 0 | O5: =IF(ISNUMBER(SEARCH("培训",C5)),1,IF(M5>=90,1,IF(M5>=70,1-(90-M5)*0.02,0))) -> 0.6 | P5: =IF(M5>=90,N5,IF(M5<70,0,IF(AND(90>M5,M5>=70),N5-N5*((90-M5)*0.02)))) -> 0 | Q5: 510000 | R5: 746086.1 | S5: =退费明细!AD16 -> 105192.9 | T5: =R5-S5 -> 640893.2 | U5: 5000 | V5: 56251 | W5: 200 | X5: =V5-W5 -> 56051 | Y5: =X5+T5 -> 696944.2 | Z5: =Y5/(Q5+U5) -> 1.3532897 | AA5: =(R5+V5)/Q5 -> 1.57321 | AB5: 0.4 | AC5: =IF(ISNUMBER(SEARCH("保薪",C5)),IFERROR(IF(Z5<0.7,0%,IF(AND(Z5>=0.7,Z5<1),0.8%,IF(AND(Z5>=1,Z5<1.2),1.2%,IF(Z5>=1.2,2%)))),0),IFERROR(IF(AND(Z5>=1.5,AB5>=0.4),0.05,IF(AND(Z5>=1.5,AB5<0.4),0.04,IF(AND(Z5<1.5,Z5>=1.2),0.04,IF(AND(Z5<1.2,Z5>=1),0.03,IF(AND(Z5<1,Z5>=0.8),0.018,IF(AND(Z5<0.8,Z5>=0.7),0.008,IF(AND(Z5<0.7,AA5>=0.7),0.008,IF(AND(Z5<0.7,AA5<0.7),0)))))))),0)) -> 0.04 | AD5: =Y5*AC5 -> 27877.768 | AE5: =IF(F5>=1,0.002,IF(F5<0.7,-0.002,IF(AND(F5>=0.7,F5<1),0))) -> -0.002 | AF5: =E5*(AE5) -> -67.3 | AG5: =AF5+AD5 -> 27810.468 | AH5: =AF5+AD5+P5 -> 27810.468
A6: 202511 | B6: 李涛 | C6: O1 | D6: 40000 | E6: 0 | F6: =E6/D6 -> 0 | G6: =IFERROR(IF(F6>=1,30,IF(AND(1>F6,F6>=0.7),F6*30,IF(F6<70,0))),0) -> 0 | H6: 0.1 | I6: =8/43 -> 0.18604651 | J6: =IFERROR(IF(I6>=H6,40,IF(AND(0.08>=H6-I6,H6-I6>=0.01),20-(H6-I6)*100*5,IF(H6-I6>0.08,0))),0) -> 40 | K6: 0 | L6: =IF(30-K6<0,0,30-K6) -> 30 | M6: =L6+J6+G6 -> 70 | N6: =IFERROR(IF(C6="O1",2000,IF(C6="O2",1000,IF(C6="O3",0,2000))),0) -> 2000 | O6: =IF(ISNUMBER(SEARCH("培训",C6)),1,IF(M6>=90,1,IF(M6>=70,1-(90-M6)*0.02,0))) -> 0.6 | P6: =IF(M6>=90,N6,IF(M6<70,0,IF(AND(90>M6,M6>=70),N6-N6*((90-M6)*0.02)))) -> 1200 | Q6: 510000 | R6: 174610 | S6: =退费明细!AD4 -> 96900 | T6: =R6-S6 -> 77710 | U6: 4000 | V6: 18900 | W6: =退费明细!AD53 -> 27266.45 | X6: =V6-W6 -> -8366.45 | Y6: =X6+T6 -> 69343.55 | Z6: =Y6/(Q6+U6) -> 0.13490963 | AA6: =(R6+V6)/Q6 -> 0.37943137 | AB6: 0.4 | AC6: =IF(ISNUMBER(SEARCH("保薪",C6)),IFERROR(IF(Z6<0.7,0%,IF(AND(Z6>=0.7,Z6<1),0.8%,IF(AND(Z6>=1,Z6<1.2),1.2%,IF(Z6>=1.2,2%)))),0),IFERROR(IF(AND(Z6>=1.5,AB6>=0.4),0.05,IF(AND(Z6>=1.5,AB6<0.4),0.04,IF(AND(Z6<1.5,Z6>=1.2),0.04,IF(AND(Z6<1.2,Z6>=1),0.03,IF(AND(Z6<1,Z6>=0.8),0.018,IF(AND(Z6<0.8,Z6>=0.7),0.008,IF(AND(Z6<0.7,AA6>=0.7),0.008,IF(AND(Z6<0.7,AA6<0.7),0)))))))),0)) -> 0 | AD6: =Y6*AC6 -> 0 | AE6: =IF(F6>=1,0.002,IF(F6<0.7,-0.002,IF(AND(F6>=0.7,F6<1),0))) -> -0.002 | AF6: =E6*(AE6) -> 0 | AG6: =AF6+AD6 -> 0 | AH6: =AF6+AD6+P6 -> 1200
C7: 培训期 | F7: =E7/D7 -> #DIV/0! | G7: =IFERROR(IF(F7>=1,30,IF(AND(1>F7,F7>=0.7),F7*30,IF(F7<70,0))),0) -> 0 | J7: =IFERROR(IF(I7>=H7,40,IF(AND(0.08>=H7-I7,H7-I7>=0.01),20-(H7-I7)*100*5,IF(H7-I7>0.08,0))),0) -> 40 | L7: =IF(30-K7<0,0,30-K7) -> 30 | M7: =L7+J7+G7 -> 70 | N7: =IFERROR(IF(C7="O1",2000,IF(C7="O2",1000,IF(C7="O3",0,2000))),0) -> 2000 | O7: =IF(ISNUMBER(SEARCH("培训",C7)),1,IF(M7>=90,1,IF(M7>=70,1-(90-M7)*0.02,0))) -> 1 | P7: =IF(M7>=90,N7,IF(M7<70,0,IF(AND(90>M7,M7>=70),N7-N7*((90-M7)*0.02)))) -> 1200 | T7: =R7-S7 -> 0 | X7: =V7-W7 -> 0 | Y7: =X7+T7 -> 0 | Z7: =Y7/(Q7+U7) -> #DIV/0! | AA7: =(R7+V7)/Q7 -> #DIV/0! | AB7: 0.4 | AC7: =IF(ISNUMBER(SEARCH("保薪",C7)),IFERROR(IF(Z7<0.7,0%,IF(AND(Z7>=0.7,Z7<1),0.8%,IF(AND(Z7>=1,Z7<1.2),1.2%,IF(Z7>=1.2,2%)))),0),IFERROR(IF(AND(Z7>=1.5,AB7>=0.4),0.05,IF(AND(Z7>=1.5,AB7<0.4),0.04,IF(AND(Z7<1.5,Z7>=1.2),0.04,IF(AND(Z7<1.2,Z7>=1),0.03,IF(AND(Z7<1,Z7>=0.8),0.018,IF(AND(Z7<0.8,Z7>=0.7),0.008,IF(AND(Z7<0.7,AA7>=0.7),0.008,IF(AND(Z7<0.7,AA7<0.7),0)))))))),0)) -> 0 | AD7: =Y7*AC7 -> 0 | AE7: =IF(F7>=1,0.002,IF(F7<0.7,-0.002,IF(AND(F7>=0.7,F7<1),0))) -> #DIV/0! | AF7: =E7*(1+AE7) -> #DIV/0! | AG7: =AF7+AD7 -> #DIV/0! | AH7: =AF7+AD7+P7 -> #DIV/0!
C8: 培训期+保薪期 | F8: =E8/D8 -> #DIV/0! | G8: =IFERROR(IF(F8>=1,30,IF(AND(1>F8,F8>=0.7),F8*30,IF(F8<70,0))),0) -> 0 | J8: =IFERROR(IF(I8>=H8,40,IF(AND(0.08>=H8-I8,H8-I8>=0.01),20-(H8-I8)*100*5,IF(H8-I8>0.08,0))),0) -> 40 | L8: =IF(30-K8<0,0,30-K8) -> 30 | M8: =L8+J8+G8 -> 70 | N8: =IFERROR(IF(C8="O1",2000,IF(C8="O2",1000,IF(C8="O3",0,2000))),0) -> 2000 | O8: =IF(ISNUMBER(SEARCH("培训",C8)),1,IF(M8>=90,1,IF(M8>=70,1-(90-M8)*0.02,0))) -> 1 | P8: =IF(M8>=90,N8,IF(M8<70,0,IF(AND(90>M8,M8>=70),N8-N8*((90-M8)*0.02)))) -> 1200 | T8: =R8-S8 -> 0 | X8: =V8-W8 -> 0 | Y8: =X8+T8 -> 0 | Z8: =Y8/(Q8+U8) -> #DIV/0! | AA8: =(R8+V8)/Q8 -> #DIV/0! | AB8: 0.4 | AC8: =IF(ISNUMBER(SEARCH("保薪",C8)),IFERROR(IF(Z8<0.7,0%,IF(AND(Z8>=0.7,Z8<1),0.8%,IF(AND(Z8>=1,Z8<1.2),1.2%,IF(Z8>=1.2,2%)))),0),IFERROR(IF(AND(Z8>=1.5,AB8>=0.4),0.05,IF(AND(Z8>=1.5,AB8<0.4),0.04,IF(AND(Z8<1.5,Z8>=1.2),0.04,IF(AND(Z8<1.2,Z8>=1),0.03,IF(AND(Z8<1,Z8>=0.8),0.018,IF(AND(Z8<0.8,Z8>=0.7),0.008,IF(AND(Z8<0.7,AA8>=0.7),0.008,IF(AND(Z8<0.7,AA8<0.7),0)))))))),0)) -> 0 | AD8: =Y8*AC8 -> 0 | AE8: =IF(F8>=1,0.002,IF(F8<0.7,-0.002,IF(AND(F8>=0.7,F8<1),0))) -> #DIV/0! | AF8: =E8*(1+AE8) -> #DIV/0! | AG8: =AF8+AD8 -> #DIV/0! | AH8: =AF8+AD8+P8 -> #DIV/0!
B11: 职级 | C11: 说明
A12: 高提点方案 | B12: O1 | C12: 老顾问选择
B13: O2 | C13: 老顾问选择
B14: O3 | C14: 老顾问选择
B15: 培训期 | C15: 新顾问高提点方案选择，前三月阶段下标期间，选择此标签，全标后，正常选择【O1】
A16: 低提点方案 | B16: 培训期+保薪期 | C16: 新顾问低提点方案选择，前三月阶段下标期间，选择此标签，全标后，正常选择【保薪期】
B17: 保薪期 | C17: 新顾问低提点方案选择，结束保薪后正常选择【O1】

Sheet 签约明细
C1: 求和项:学费 | D1: 项目类别
C2: 签约单录入人 | D2: 个性化 | E2: 集训 | F2: 无忧 | G2: 在职 | H2: 四六级 | I2: 网课 | J2: 总计
C3: 李涛 | D3: 158460 | F3: 16150 | I3: 18900 | J3: 193510
C4: 谭悦 | D4: 431550 | E4: 4800 | F4: 149341.1 | G4: 65300 | H4: 95095 | I4: 56251 | J4: 802337.1
C5: 赵星火 | D5: 224130 | E5: 23500 | F5: 170550 | H5: 38400 | I5: 53154.4 | J5: 509734.4
C6: 总计 | D6: 814140 | E6: 28300 | F6: 336041.1 | G6: 65300 | H6: 133495 | I6: 128305.4 | J6: 1505581.5
A9: 序号 | B9: 学校 | C9: 部门 | D9: 资源姓名 | E9: 资源ID | F9: 资源录入人 | G9: 资源录入时间 | H9: 资源描述 | I9: 市场活动 | J9: 资源年级 | K9: 分配顾问/TMK | L9: 一级获取渠道 | M9: 二级获取渠道 | N9: 转介绍人 | O9: TMK激活人 | P9: TMK激活处理时间 | Q9: 工单姓名 | R9: 跟进顾问 | S9: 工单ID | T9: 工单类型 | U9: 工单录入时间 | V9: 工单等级 | W9: 咨询课程 | X9: 工单年级 | Y9: 学校 | Z9: 院系 | AA9: 专业 | AB9: 签约学生姓名 | AC9: 签约单ID | AD9: 签约单录入人 | AE9: 签约单录入时间 | AF9: 签约单更新人 | AG9: 签约单更新时间 | AH9: 项目类别 | AI9: 班号 | AJ9: 班级名称 | AK9: 面询表类型 | AL9: 订金 | AM9: 学费 | AN9: 续费类型 | AO9: 推荐人 | AP9: 类型 | AQ9: 是否交接 | AR9: 操作人编号 | AS9: 学员号 | AT9: 听课证号 | AU9: 报班日期 | AV9: 学员状态 | AW9: 回访记录 | AX9: 新老生类型 | AY9: 退费金额 | AZ9: 退费日期 | BA9: 课程类型 | BB9: 客户ID | BC9: 是否新东方在线签约 | BD9: 考季 | BE9: 报名产品 | BF9: 报名科目 | BG9: 意向报考专业 | BH9: 学校班型/类型 | BI9: 是否关联协议 | BJ9: 特殊备注 | BK9: 产品品类 | BL9: 业务类型 | BM9: 签约列表在线学员ID | BN9: 大学生源类型 | BO9: 资源来源
A10: 15 | B10: 北京大学部 | C10: 国内大学部 | E10: 127127668 | G10: 2025-09-11 16:33:44 | H10: 知春路直访，咨询考研 | J10: 大三 | K10: 谭悦 | L10: 直访 | M10: 直访 | Q10: 安思羽 | R10: 谭悦 | S10: 30745364 | T10: 续费工单 | U10: 2025-11-10 19:46 | V10: A（六个月内有报课意向工单） | W10: 考研专业课,考研无忧计划 | X10: 大三 | Y10: 北京科技大学 | Z10: 计算机与通信工程学院 | AA10: 计算机科学与技术 | AB10: 安思羽 | AC10: 5694808 | AD10: 谭悦 | AE10: 2025-11-10 19:46 | AF10: 谭悦 | AG10: 2025-11-10 19:46 | AH10: 无忧 | AI10: WYC27103 | AJ10: 考研专业课无忧Pro优才走读班（27考研/408计算机） | AK10: 国内考试 | AM10: 9000 | AN10: 同科续费 | AP10: 续班 | AQ10: 无须交接 | AR10: BJWY2101498uW2 | AS10: BJWY5747046882 | AT10: WYC271030004 | AU10: 2025-11-07 | AW10: 回访人：谭悦，回访时间：2025-11-10 19:46，回访内容：1；|回访人：谭悦，回访时间：2025-11-10 19:46，回访内容：1 | BB10: 84810126 | BC10: 否 | BD10: 27考季 | BE10: 无忧计划-啄木鸟,考研专业课150 | BF10: 英语,政治,数学,计算机 | BH10: 国内高校-211 | BI10: 否 | BL10: 转出 | BN10: 本地人本地大学(常规)
A11: 16 | B11: 北京大学部 | C11: 国内大学部 | E11: 115852926 | G11: 2025-06-23 16:42:01 | H11: 北京新东方考研18714556226 | J11: 幼儿 | K11: 杨晓超 | L11: 市场-代理商合作 | M11: 职递 | Q11: 毕琦昕 | R11: 杨晓超 | S11: 30715344 | T11: 续费工单 | U11: 2025-11-10 10:51 | V11: A（六个月内有报课意向工单） | W11: 考研专业课,考研无忧计划 | X11: 大三 | Y11: 北京邮电大学 | Z11: 国际学院 | AA11: 物联网工程 | AB11: 毕琦昕 | AC11: 5694390 | AD11: 谭悦 | AE11: 2025-11-10 10:51 | AF11: 杨晓超 | AG11: 2025-11-10 10:52 | AH11: 无忧 | AK11: 国内考试 | AM11: 4500 | AN11: 同科续费 | AP11: 分单 | AQ11: 无须交接 | AS11: BJWY1550131227 | AW11: 回访人：杨晓超，回访时间：2025-11-10 10:51，回访内容：1；|回访人：杨晓超，回访时间：2025-11-10 10:51，回访内容：签约 | BB11: 80376945 | BC11: 否 | BD11: 27考季 | BE11: 无忧计划-啄木鸟 | BF11: 英语,政治,数学,计算机 | BH11: 国内高校-211 | BI11: 否 | BN11: 外地人本地大学(常规)
A12: 85 | B12: 北京大学部 | C12: 国内大学部 | D12: 同学 | E12: 134565004 | F12: 陈伟钰 | G12: 2025-11-14 15:13:37 | H12: 钱雪冰的顾问转介绍-其他（不返现） | J12: 大三 | K12: 钱雪冰 | L12: 转介绍 | M12: 顾问转介绍-其他(不返现) | N12: 钱雪冰qianxuebing@xdf.cn | Q12: 蔡佳茵 | R12: 钱雪冰 | S12: 30761404 | T12: 正常工单 | U12: 2025-11-14 15:26 | V12: A（六个月内有报课意向工单） | W12: 考研专业课,考研VIP,考研无忧计划 | X12: 大三 | Y12: 燕京理工学院 | Z12: 文法学院 | AA12: 汉语言文学 | AB12: 蔡佳茵 | AC12: 5728268 | AD12: 谭悦 | AE12: 2025-11-15 15:18 | AF12: 钱雪冰 | AG12: 2025-11-15 15:19 | AH12: 无忧 | AK12: 国内考试 | AM12: 33650 | AO12: 钱雪冰 | AP12: 分单 | AQ12: 已交接 | AS12: BJWY1763277405 | AW12: 回访人：钱雪冰，回访时间：2025-11-14 15:26，回访内容：燕京理工学院 大三 汉语言文学专业，然后是想考郑州大学汉语言文学专业，比较在意是否有上岸的案例。比较在意上课的细节，明天过来校区听试听课程；|回访人：钱雪冰，回访时间：2025-11-15 15:18，回访内容：报名 | BB12: 87447997 | BC12: 否 | BD12: 27考季 | BE12: 无忧计划-候鸟,VIP - 伴学,考研专业课300 | BF12: 英语,政治 | BG12: 其他 | BH12: 国内高校-双非 | BI12: 否 | BN12: 本地人外地大学(归巢) | BO12: 客服
A13: 72 | B13: 北京大学部 | C13: 国内大学部 | D13: 曹泽恒 | E13: 134462228 | F13: 刘大庆 | G13: 2025-11-14 18:57:24 | H13: 续费原因：学员续费一对一，辛苦老师建单流转；该学生为保护期内续费，原顾问：国内大学部-赵星火(zhaoxinghuo@xdf.cn) | J13: 大学已毕业 | K13: 赵星火 | L13: 转介绍 | M13: 学管续费推荐 | N13: 刘大庆liudaqing1@xdf.cn | Q13: 曹泽恒 | R13: 赵星火 | S13: 30765656 | T13: 续费工单 | U13: 2025-11-15 15:30 | V13: A（六个月内有报课意向工单） | W13: 考研VIP | X13: 大学已毕业 | Y13: 北京工业大学 | Z13: 城市建设学部 | AA13: 土木工程 | AB13: 曹泽恒 | AC13: 5730320 | AD13: 赵星火 | AE13: 2025-11-18 19:32 | AF13: 赵星火 | AG13: 2025-11-18 20:40 | AH13: 集训 | AI13: LP17634655422194 | AJ13: 26考研一对一伴学（集训） | AK13: 国内考试 | AM13: 9600 | AO13: 刘大庆 | AP13: 续班 | AQ13: 已交接 | AS13: BJWY4116308585 | AU13: 2025-11-18 | AW13: 回访人：赵星火，回访时间：2025-11-15 15:30，回访内容：计划续费一对一这边看下课时跟进中；|回访人：赵星火，回访时间：2025-11-17 14:41，回访内容：跟进学生中继续维护学生考虑，看下课程考虑。；|回访人：赵星火，回访时间：2025-11-18 19:32，回访内容：系统自动签约 | BB13: 33140368 | BC13: 否 | BD13: 26考季 | BE13: VIP - 伴学 | BF13: 英语 | BG13: 其他 | BH13: 国内高校-211 | BI13: 是 | BO13: 学管续费推荐
A14: 10 | B14: 北京大学部 | C14: 国内大学部 | D14: 曾丹 | E14: 134232548 | F14: 李亚坤 | G14: 2025-11-12 17:32:45 | H14: 续费原因：家长择校完，说还是要考人大 300升级费需要交；该学生为保护期内续费，原顾问：国内大学部-谭悦(tanyue9@xdf.cn) | J14: 大三 | K14: 谭悦 | L14: 转介绍 | M14: 学管续费推荐 | N14: 李亚坤liyakun4@xdf.cn | Q14: 曾丹 | R14: 谭悦 | S14: 30729076 | T14: 续费工单 | U14: 2025-11-12 19:49 | V14: A（六个月内有报课意向工单） | W14: 考研专业课 | X14: 大三 | Y14: 中国农业大学 | Z14: 人文与发展学院 | AA14: 英语 | AB14: 曾丹 | AC14: 5696741 | AD14: 谭悦 | AE14: 2025-11-13 11:38 | AF14: 谭悦 | AG14: 2025-11-13 11:43 | AH14: 无忧 | AI14: LP1763005110401 | AJ14: 985院校升级费-无忧 | AK14: 国内考试 | AM14: 3000 | AO14: 李亚坤 | AP14: 续班 | AQ14: 未交接 | AS14: BJWY7684715389 | AU14: 2025-11-13 | AW14: 回访人：谭悦，回访时间：2025-11-12 19:49，回访内容：续费专业课 ；|回访人：谭悦，回访时间：2025-11-13 11:38，回访内容：系统自动签约 | BB14: 84876601 | BC14: 否 | BD14: 27考季 | BE14: 考研专业课300 | BF14: 专业课300 | BG14: 其他 | BH14: 国内高校-985 | BI14: 否 | BN14: 本地人本地大学(常规) | BO14: 学管续费推荐
A15: 40 | B15: 北京大学部 | C15: 国内大学部 | D15: 陈嘉硕 | E15: 133140096 | F15: 陈晶 | G15: 2025-11-03 15:46:32 | H15: 续费原因：报名专业课；该学生为保护期外续费，原顾问部门：国内大学部 | J15: 大学已毕业 | K15: 谭悦 | L15: 转介绍 | M15: 学管续费推荐 | N15: 陈晶chenjing171@xdf.cn | Q15: 陈嘉硕 | R15: 谭悦 | S15: 30652571 | T15: 续费工单 | U15: 2025-11-03 16:19 | V15: A（六个月内有报课意向工单） | W15: 考研专业课 | X15: 大学已毕业 | Y15: 西安邮电大学 | Z15: 计算机学院 | AA15: 计算机科学与技术 | AB15: 陈嘉硕 | AC15: 5691084 | AD15: 谭悦 | AE15: 2025-11-03 16:21 | AH15: 个性化 | AI15: LP1762158074916 | AJ15: 考研专业课一对一伴学班（12h/26考季） | AM15: 7200 | AO15: 陈晶 | AP15: 续班 | AQ15: 未交接 | AS15: BJWY7070266959 | AU15: 2025-11-03 | AW15: 回访人：谭悦，回访时间：2025-11-03 16:19，回访内容：报专业课 ；|回访人：谭悦，回访时间：2025-11-03 16:21，回访内容：系统自动签约 | BB15: 52706084 | BC15: 否 | BD15: 27考季 | BE15: 考研专业课150 | BF15: 专业课150 | BG15: 其他 | BH15: 国内高校-211 | BI15: 否 | BO15: 学管续费推荐
A16: 67 | B16: 北京大学部 | C16: 国内大学部 | D16: 陈嘉硕 | E16: 135330352 | F16: 陈晶 | G16: 2025-11-21 15:49:57 | H16: 续费原因：续课时，个性化；该学生为保护期内续费，原顾问：国内大学部-谭悦(tanyue9@xdf.cn) | J16: 大学已毕业 | K16: 谭悦 | L16: 转介绍 | M16: 学管续费推荐 | N16: 陈晶chenjing171@xdf.cn | Q16: 陈嘉硕 | R16: 谭悦 | S16: 30792786 | T16: 续费工单 | U16: 2025-11-21 15:58 | V16: A（六个月内有报课意向工单） | W16: 考研专业课 | X16: 大学已毕业 | Y16: 西安邮电大学 | Z16: 计算机学院 | AA16: 计算机科学与技术 | AB16: 陈嘉硕 | AC16: 5731913 | AD16: 谭悦 | AE16: 2025-11-21 16:45 | AF16: 谭悦 | AG16: 2025-11-21 16:48 | AH16: 个性化 | AI16: LP17637147081820 | AJ16: 考研初试专业课一对一（26考季/10小时） | AK16: 国内考试 | AM16: 6000 | AO16: 陈晶 | AP16: 续班 | AQ16: 已交接 | AS16: BJWY7070266959 | AU16: 2025-11-21 | AW16: 回访人：谭悦，回访时间：2025-11-21 15:58，回访内容：微信跟进中 ；|回访人：谭悦，回访时间：2025-11-21 16:45，回访内容：系统自动签约 | BB16: 52706084 | BC16: 否 | BD16: 26考季 | BE16: 考研专业课150 | BF16: 专业课150 | BG16: 其他 | BH16: 国内高校-211 | BI16: 是 | BO16: 学管续费推荐
A17: 121 | B17: 北京大学部 | C17: 国内大学部 | E17: 132605684 | G17: 2025-10-28 20:22:28 | H17: 【小红书资源】 咨询考研一对一，IP地址在北京 | J17: 大三 | K17: 李涛 | L17: 线上运营-小红书 | M17: 小红书 | Q17: 陈靓怡 | R17: 李涛 | S17: 30655508 | T17: 续费工单 | U17: 2025-11-03 11:47 | V17: A（六个月内有报课意向工单） | W17: 考研VIP | X17: 大三 | Y17: 北京信息科技大学 | Z17: 计算机学院 | AA17: 计算机科学与技术 | AB17: 陈靓怡 | AC17: 5691452 | AD17: 李涛 | AE17: 2025-11-04 15:50 | AF17: 李涛 | AG17: 2025-11-04 17:12 | AH17: 个性化 | AI17: 3201731 | AJ17: 考研督学计划 27考研英数督学计划 | AK17: 国内考试 | AM17: 80960 | AP17: 续班 | AQ17: 已交接 | AS17: BJWY7173848231 | AT17: 108320173100000001 | AU17: 2025-11-04 | AW17: 回访人：李涛，回访时间：2025-11-03 11:47，回访内容：重新下单；|回访人：李涛，回访时间：2025-11-03 18:46，回访内容：等退费 然后入班！；|回访人：李涛，回访时间：2025-11-04 15:50，回访内容：已报名 | BB17: 86751591 | BC17: 否 | BD17: 27考季 | BE17: VIP - 伴学 | BF17: 英语,政治,数学,计算机 | BH17: 国内高校-双非 | BI17: 是 | BN17: 本地人本地大学(常规)
A18: 36 | B18: 北京大学部 | C18: 国内大学部 | E18: 132519662 | G18: 2025-10-28 11:15:27 | H18: 续费原因：学生27考研，需要一对一，辛苦谭悦老师跟进；该学生为保护期内续费，原顾问：国内大学部-谭悦(tanyue9@xdf.cn) | J18: 大四 | K18: 谭悦 | L18: 转介绍 | M18: 学管续费推荐 | Q18: 陈一凡 | R18: 谭悦 | S18: 30690701 | T18: 续费工单 | U18: 2025-11-05 16:35 | V18: A（六个月内有报课意向工单） | W18: 考研VIP | X18: 大四 | Y18: 北方工业大学 | Z18: 信息学院 | AA18: 数据科学与大数据技术 | AB18: 陈一凡 | AC18: 5691927 | AD18: 谭悦 | AE18: 2025-11-05 16:35 | AF18: 系统管理员 | AG18: 2025-11-10 17:45 | AH18: 无忧 | AI18: LP1761622149221 | AJ18: 26考研一对一伴学（无忧） | AM18: -20400 | AQ18: 未交接 | AS18: BJWY8503976521 | AU18: 2025-11-05 | AW18: 回访人：系统管理员，回访时间：2025-11-05 16:35，回访内容：学生转产品转入，创建续费工单。 | BB18: 58815635 | BC18: 否 | BD18: 26考季 | BE18: VIP - 伴学 | BF18: 英语,政治 | BH18: 国内高校-211 | BI18: 否
A19: 37 | B19: 北京大学部 | C19: 国内大学部 | E19: 132519662 | G19: 2025-10-28 11:15:27 | H19: 续费原因：学生27考研，需要一对一，辛苦谭悦老师跟进；该学生为保护期内续费，原顾问：国内大学部-谭悦(tanyue9@xdf.cn) | J19: 大四 | K19: 谭悦 | L19: 转介绍 | M19: 学管续费推荐 | Q19: 陈一凡 | R19: 谭悦 | S19: 30690701 | T19: 续费工单 | U19: 2025-11-05 16:35 | V19: A（六个月内有报课意向工单） | W19: 考研VIP | X19: 大四 | Y19: 北方工业大学 | Z19: 信息学院 | AA19: 数据科学与大数据技术 | AB19: 陈一凡 | AC19: 5691927 | AD19: 谭悦 | AE19: 2025-11-05 16:35 | AF19: 系统管理员 | AG19: 2025-11-10 17:45 | AH19: 无忧 | AI19: LP17623311801419 | AJ19: 27考研一对一伴学(无忧) | AM19: 20400 | AQ19: 未交接 | AS19: BJWY8503976521 | AU19: 2025-11-05 | AW19: 回访人：系统管理员，回访时间：2025-11-05 16:35，回访内容：学生转产品转入，创建续费工单。 | BB19: 58815635 | BC19: 否 | BD19: 26考季 | BE19: VIP - 伴学 | BF19: 英语,政治 | BH19: 国内高校-211 | BI19: 否
A20: 38 | B20: 北京大学部 | C20: 国内大学部 | E20: 132519662 | G20: 2025-10-28 11:15:27 | H20: 续费原因：学生27考研，需要一对一，辛苦谭悦老师跟进；该学生为保护期内续费，原顾问：国内大学部-谭悦(tanyue9@xdf.cn) | J20: 大四 | K20: 谭悦 | L20: 转介绍 | M20: 学管续费推荐 | Q20: 陈一凡 | R20: 谭悦 | S20: 30690701 | T20: 续费工单 | U20: 2025-11-05 16:35 | V20: A（六个月内有报课意向工单） | W20: 考研VIP | X20: 大四 | Y20: 北方工业大学 | Z20: 信息学院 | AA20: 数据科学与大数据技术 | AB20: 陈一凡 | AC20: 5691927 | AD20: 谭悦 | AE20: 2025-11-05 16:35 | AF20: 系统管理员 | AG20: 2025-11-10 17:45 | AH20: 无忧 | AI20: LP17623311801419 | AJ20: 27考研一对一伴学(无忧) | AM20: 1200 | AQ20: 未交接 | AS20: BJWY8503976521 | AU20: 2025-11-10 | AW20: 回访人：系统管理员，回访时间：2025-11-05 16:35，回访内容：学生转产品转入，创建续费工单。 | BB20: 58815635 | BC20: 否 | BD20: 26考季 | BE20: VIP - 伴学 | BF20: 英语,政治 | BH20: 国内高校-211 | BI20: 否
A21: 39 | B21: 北京大学部 | C21: 国内大学部 | E21: 132519662 | G21: 2025-10-28 11:15:27 | H21: 续费原因：学生27考研，需要一对一，辛苦谭悦老师跟进；该学生为保护期内续费，原顾问：国内大学部-谭悦(tanyue9@xdf.cn) | J21: 大四 | K21: 谭悦 | L21: 转介绍 | M21: 学管续费推荐 | Q21: 陈一凡 | R21: 谭悦 | S21: 30690701 | T21: 续费工单 | U21: 2025-11-05 16:35 | V21: A（六个月内有报课意向工单） | W21: 考研VIP | X21: 大四 | Y21: 北方工业大学 | Z21: 信息学院 | AA21: 数据科学与大数据技术 | AB21: 陈一凡 | AC21: 5691927 | AD21: 谭悦 | AE21: 2025-11-05 16:35 | AF21: 系统管理员 | AG21: 2025-11-10 17:45 | AH21: 无忧 | AI21: LP1762767548850 | AJ21: 27考研一对一伴学(无忧) | AM21: 8500 | AQ21: 未交接 | AS21: BJWY8503976521 | AU21: 2025-11-10 | AW21: 回访人：系统管理员，回访时间：2025-11-05 16:35，回访内容：学生转产品转入，创建续费工单。 | BB21: 58815635 | BC21: 否 | BD21: 26考季 | BE21: VIP - 伴学 | BF21: 英语,政治 | BH21: 国内高校-211 | BI21: 否
A22: 109 | B22: 北京大学部 | C22: 国内大学部 | D22: 陈政元 | E22: 132406074 | F22: 北京国内管理员 | G22: 2025-10-26 21:48:56 | H22: 资源录入来源：小表单 市场活动id：412422 市场活动名称：新东方集团官微【新东方】资源 活动所属学校id：10000 活动所属学校名称：总公司 线索接收人邮箱：yangjun42@xdf.cn 线索接受人类型：自定义 表单信息：表单id81512、表单名(对内)：新东方集团官微【新东方】资源、表单名（对外）：新东方课程报名、创建人邮箱：wuyue38@xdf.cn、表单链接：pages/index/index.html?scene=81512,,ucwVUGil 备注：来源:小表单;姓名:陈政元;意向课程: 【课程】考研、四六级、专升本、成人英语/北京/北京; 新老生: 新生; 提交链接:pages/index/index.html?scene=81512,,ucwVUGil;地理位置:-;渠道:新媒体运营/集团品牌官微 | I22: 2026财年小表单-新东方集团官微【新东方】资源 | J22: 未知 | K22: 杨钰杰 | L22: 线上运营-私域中台 | M22: 集团官微 | O22: 杨钰杰 | P22: 2025-10-27 10:03:33 | Q22: 陈政元 | R22: 谭悦 | S22: 30560560 | T22: 正常工单 | U22: 2025-10-27 11:30 | V22: A（六个月内有报课意向工单） | W22: 考研专业课,考研VIP | X22: 大四 | Y22: 北京工商大学 | Z22: 人工智能学院 | AA22: 机械工程 | AB22: 陈政元 | AC22: 5694099 | AD22: 谭悦 | AE22: 2025-11-09 17:00 | AF22: 谭悦 | AG22: 2025-11-09 18:01 | AH22: 个性化 | AI22: 3234557 | AJ22: 北京中心菁英计划 27考研菁英A计划（英政数） | AK22: 国内考试 | AM22: 259000 | AP22: 新签 | AQ22: 已交接 | AS22: BJWY4807692593 | AT22: 108323455700000001 | AU22: 2025-11-09 | AW22: 回访人：谭悦，回访时间：2025-10-31 16:56，回访内容：学生要等家长回来，一起过来 ；|回访人：谭悦，回访时间：2025-11-05 12:03，回访内容：微信邀约来访面谈 ；|回访人：谭悦，回访时间：2025-11-09 17:00，回访内容：面谈接待，报名了菁英计划 | BB22: 86686253 | BC22: 否 | BD22: 27考季 | BE22: VIP - 畅学,考研专业课150 | BF22: 英语,政治,数学,专业课150 | BG22: 其他 | BH22: 国内高校-双非 | BI22: 是 | BN22: 本地人本地大学(常规) | BO22: 小表单
A23: 110 | B23: 北京大学部 | C23: 国内大学部 | D23: 陈政元 | E23: 132406074 | F23: 北京国内管理员 | G23: 2025-10-26 21:48:56 | H23: 资源录入来源：小表单 市场活动id：412422 市场活动名称：新东方集团官微【新东方】资源 活动所属学校id：10000 活动所属学校名称：总公司 线索接收人邮箱：yangjun42@xdf.cn 线索接受人类型：自定义 表单信息：表单id81512、表单名(对内)：新东方集团官微【新东方】资源、表单名（对外）：新东方课程报名、创建人邮箱：wuyue38@xdf.cn、表单链接：pages/index/index.html?scene=81512,,ucwVUGil 备注：来源:小表单;姓名:陈政元;意向课程: 【课程】考研、四六级、专升本、成人英语/北京/北京; 新老生: 新生; 提交链接:pages/index/index.html?scene=81512,,ucwVUGil;地理位置:-;渠道:新媒体运营/集团品牌官微 | I23: 2026财年小表单-新东方集团官微【新东方】资源 | J23: 未知 | K23: 杨钰杰 | L23: 线上运营-私域中台 | M23: 集团官微 | O23: 杨钰杰 | P23: 2025-10-27 10:03:33 | Q23: 陈政元 | R23: 谭悦 | S23: 30560560 | T23: 正常工单 | U23: 2025-10-27 11:30 | V23: A（六个月内有报课意向工单） | W23: 考研专业课,考研VIP | X23: 大四 | Y23: 北京工商大学 | Z23: 人工智能学院 | AA23: 机械工程 | AB23: 陈政元 | AC23: 5694099 | AD23: 谭悦 | AE23: 2025-11-09 17:00 | AF23: 谭悦 | AG23: 2025-11-09 18:01 | AH23: 个性化 | AI23: 3234573 | AJ23: 北京中心菁英计划 27考研菁英计划（英政数联报专业课30h | AK23: 国内考试 | AM23: 12000 | AP23: 新签 | AQ23: 已交接 | AS23: BJWY4807692593 | AT23: 108323457300000001 | AU23: 2025-11-09 | AW23: 回访人：谭悦，回访时间：2025-10-31 16:56，回访内容：学生要等家长回来，一起过来 ；|回访人：谭悦，回访时间：2025-11-05 12:03，回访内容：微信邀约来访面谈 ；|回访人：谭悦，回访时间：2025-11-09 17:00，回访内容：面谈接待，报名了菁英计划 | BB23: 86686253 | BC23: 否 | BD23: 27考季 | BE23: VIP - 畅学,考研专业课150 | BF23: 英语,政治,数学,专业课150 | BG23: 其他 | BH23: 国内高校-双非 | BI23: 是 | BN23: 本地人本地大学(常规) | BO23: 小表单
A24: 6 | B24: 北京大学部 | C24: 国内大学部 | D24: 崔好奇 | E24: 135201274 | F24: 北京国内管理员 | G24: 2025-11-20 20:13:46 | H24: 资源录入来源：小表单 城市：北京市 市场活动id：412422 市场活动名称：新东方集团官微【新东方】资源 活动所属学校id：10000 活动所属学校名称：总公司 线索接收人邮箱：yangjun42@xdf.cn 线索接受人类型：自定义 表单信息：表单id81512、表单名(对内)：新东方集团官微【新东方】资源、表单名（对外）：新东方课程报名、创建人邮箱：wuyue38@xdf.cn、表单链接：pages/index/index.html?scene=81512,,ucwVUGil 备注：来源:小表单;姓名:崔好奇;意向课程: 【课程】考研、四六级、专升本、成人英语/北京/北京; 新老生: 新生; 提交链接:pages/index/index.html?scene=81512,,ucwVUGil;地理位置:北京市丰台区东铁匠营街道西木樨园;渠道:新媒体运营/集团品牌官微 | I24: 2026财年小表单-新东方集团官微【新东方】资源 | J24: 未知 | K24: 杨钰杰 | L24: 线上运营-私域中台 | M24: 集团官微 | O24: 杨钰杰 | P24: 2025-11-20 20:24:25 | Q24: 崔好奇 | R24: 谭悦 | S24: 30848265 | T24: 正常工单 | U24: 2025-11-21 11:51 | V24: B（需长时间跟单或只需要规划） | W24: 线上考研产品 | X24: 在职 | Y24: 北京建筑大学 | Z24: 环境与能源工程学院 | AA24: 建筑环境与能源应用工程 | AB24: 崔好奇 | AC24: 5706702 | AD24: 谭悦 | AE24: 2025-11-22 17:57 | AF24: 谭悦 | AG24: 2025-11-22 17:57 | AH24: 网课 | AI24: 86231189510 | AJ24: 2028考研管综全科在校直通车（1期） | AK24: 国内考试 | AM24: 10144 | AP24: 新签 | AQ24: 无须交接 | AU24: 2025-11-22 | AW24: 回访人：谭悦，回访时间：2025-11-21 11:51，回访内容：25年毕业， 28考研， 跟进中 ，MEM 北建筑 ；|回访人：谭悦，回访时间：2025-11-22 17:57，回访内容：1 | BA24: 长期班 | BB24: 87668013 | BC24: 是 | BD24: 27考季 | BE24: 线上直通车 | BF24: 英语,管综 | BG24: 管综 | BH24: 国内高校-双非 | BI24: 否 | BM24: 107274163 | BO24: 小表单
A25: 105 | B25: 北京大学部 | C25: 国内大学部 | D25: 崔若琳 | E25: 134062030 | F25: 张泽7 | G25: 2025-11-10 18:24:44 | H25: 续费原因：每周三加一次写作；该学生为保护期内续费，原顾问：国内大学部-赵星火(zhaoxinghuo@xdf.cn) | J25: 大四 | K25: 赵星火 | L25: 转介绍 | M25: 学管续费推荐 | N25: 张泽7zhangze7@xdf.cn | Q25: 崔若琳 | R25: 赵星火 | S25: 30746685 | T25: 续费工单 | U25: 2025-11-11 11:41 | V25: A（六个月内有报课意向工单） | W25: 考研VIP | X25: 大四 | Y25: 北京农学院 | Z25: 生物与资源环境学院 | AA25: 生物工程 | AB25: 崔若琳 | AC25: 5695111 | AD25: 赵星火 | AE25: 2025-11-11 12:04 | AF25: 赵星火 | AG25: 2025-11-11 12:07 | AH25: 个性化 | AI25: LP1762833896560 | AJ25: 考研一对一伴学班（26考季） | AK25: 国内考试 | AM25: 7800 | AO25: 张泽7 | AP25: 续班 | AQ25: 已交接 | AS25: BJWY0122570561 | AU25: 2025-11-11 | AW25: 回访人：赵星火，回访时间：2025-11-11 11:41，回访内容：签约；|回访人：赵星火，回访时间：2025-11-11 12:04，回访内容：系统自动签约 | BB25: 19355703 | BC25: 否 | BD25: 26考季 | BE25: VIP - 伴学 | BF25: 英语 | BG25: 其他 | BH25: 国内高校-双非 | BI25: 是 | BN25: 本地人本地大学(常规) | BO25: 学管续费推荐
A26: 7 | B26: 北京大学部 | C26: 国内大学部 | D26: 同学 | E26: 135004856 | F26: 吕猛 | G26: 2025-11-18 21:22:49 | H26: 咨询一对一冲刺课程 | J26: 大四 | K26: 谭悦 | L26: 线上运营-本地生活平台 | M26: 大众点评 | Q26: 丹央 | R26: 谭悦 | S26: 30788504 | T26: 正常工单 | U26: 2025-11-19 11:50 | V26: A（六个月内有报课意向工单） | W26: 线上考研产品 | X26: 大四 | Y26: 国际关系学院 | Z26: 国际安全学院 | AA26: 国际政治 | AB26: 丹央 | AC26: 5575552 | AD26: 谭悦 | AE26: 2025-11-19 11:50 | AF26: 谭悦 | AG26: 2025-11-19 11:50 | AH26: 网课 | AI26: 02698866958 | AJ26: 2026考研专业课定制一对一（20h）-B班 | AK26: 国内考试 | AM26: 12240 | AP26: 新签 | AQ26: 无须交接 | AU26: 2025-11-19 | AW26: 回访人：谭悦，回访时间：2025-11-19 11:50，回访内容：国际关系学院，本科学的是公共管理。 | BA26: 长期班 | BB26: 87647271 | BC26: 是 | BD26: 26考季 | BE26: 专业课 | BF26: 专业课300 | BG26: 其他 | BH26: 国内高校-双非 | BI26: 否 | BM26: 109203918 | BN26: 本地人本地大学(常规) | BO26: 客服
A27: 73 | B27: 北京大学部 | C27: 国内大学部 | D27: 丁浩洋 | E27: 135003471 | F27: 李雪68 | G27: 2025-11-18 18:55:45 | H27: 罗玉骏+luoyujun@xdf.cn+罗玉骏(新东方教育科技集团有限公司-产业机构-国际教育培训事业部-国际教育北京中心-运营管理部-中学区域运营中心二区-国贸中学分中心 | 学业规划师) | J27: 未知 | K27: 赵星火 | L27: 转介绍 | M27: 内部员工推荐 | N27: 罗玉骏+luoyujun@xdf.cn+罗玉骏(新东方教育科技集团有限公司-产业机构-国际教育培训事业部-国际教育北京中心-运营管理部-中学区域运营中心二区-国贸中学分中心 | 学业规划师) | Q27: 丁浩洋 | R27: 赵星火 | S27: 30787958 | T27: 正常工单 | U27: 2025-11-18 18:59 | V27: A（六个月内有报课意向工单） | W27: 考研专业课 | X27: 大一 | Y27: 澳门科技大学 | Z27: 电子与信息技术 | AA27: 电子与信息技术 | AB27: 丁浩洋 | AC27: 5730315 | AD27: 赵星火 | AE27: 2025-11-18 19:11 | AF27: 赵星火 | AG27: 2025-11-18 19:29 | AH27: 个性化 | AI27: LP17634642652171 | AJ27: 考研初试专业课一对一（27考研/30小时） | AK27: 国内考试 | AM27: 18300 | AO27: 罗玉骏+luoyujun@xdf.cn+罗玉骏(新东方教育科技集团有限公司-产业机构-国际教育培训事业部-国际教育北京中心-运营管理部-中学区域运营中心二区-国贸中学分中心 | 学业规划师) | AP27: 新签 | AQ27: 已交接 | AS27: BJWY8381978400 | AU27: 2025-11-18 | AW27: 回访人：赵星火，回访时间：2025-11-18 18:59，回访内容：跟进中这边看下情况；|回访人：赵星火，回访时间：2025-11-18 19:11，回访内容：系统自动签约 | BB27: 87647140 | BC27: 否 | BD27: 27考季 | BE27: 考研专业课150 | BF27: 专业课150 | BG27: 其他 | BH27: 国内高校-双非 | BI27: 是 | BN27: 本地人外地大学(归巢) | BO27: 客服
A28: 28 | B28: 北京大学部 | C28: 国内大学部 | E28: 136043660 | G28: 2025-11-29 16:30:24 | H28: 续费原因：4h定制1v1，指定刘瑶；该学生为保护期内续费，原顾问：国内大学部-谭悦(tanyue9@xdf.cn) | J28: 大学已毕业 | K28: 谭悦 | L28: 转介绍 | M28: 学管续费推荐 | Q28: 冯晨阳 | R28: 谭悦 | S28: 30958049 | T28: 续费工单 | U28: 2025-12-01 20:15 | V28: A（六个月内有报课意向工单） | W28: 考研VIP | X28: 大学已毕业 | Y28: 首都医科大学 | Z28: 临床医学院 | AA28: 临床医学 | AB28: 冯晨阳 | AC28: 5713519 | AD28: 谭悦 | AE28: 2025-12-01 20:15 | AF28: 系统管理员 | AG28: 2025-12-01 20:15 | AH28: 个性化 | AI28: LP17644170743890 | AJ28: 考研一对一伴学班（定制/26考季） | AM28: -7200 | AQ28: 未交接 | AS28: BJWY9774040881 | AU28: 2025-12-01 | AW28: 回访人：系统管理员，回访时间：2025-12-01 20:15，回访内容：学生转产品转入，创建续费工单。 | BB28: 51853027 | BC28: 否 | BD28: 26考季 | BE28: VIP - 伴学 | BF28: 英语 | BH28: 国内高校-双非 | BI28: 否
A29: 29 | B29: 北京大学部 | C29: 国内大学部 | E29: 136043660 | G29: 2025-11-29 16:30:24 | H29: 续费原因：4h定制1v1，指定刘瑶；该学生为保护期内续费，原顾问：国内大学部-谭悦(tanyue9@xdf.cn) | J29: 大学已毕业 | K29: 谭悦 | L29: 转介绍 | M29: 学管续费推荐 | Q29: 冯晨阳 | R29: 谭悦 | S29: 30958049 | T29: 续费工单 | U29: 2025-12-01 20:15 | V29: A（六个月内有报课意向工单） | W29: 考研VIP | X29: 大学已毕业 | Y29: 首都医科大学 | Z29: 临床医学院 | AA29: 临床医学 | AB29: 冯晨阳 | AC29: 5713519 | AD29: 谭悦 | AE29: 2025-12-01 20:15 | AF29: 系统管理员 | AG29: 2025-12-01 20:15 | AH29: 无忧 | AI29: LP17645908628004 | AJ29: 26考研一对一伴学（定制/无忧） | AM29: 7200 | AQ29: 未交接 | AS29: BJWY9774040881 | AU29: 2025-12-01 | AW29: 回访人：系统管理员，回访时间：2025-12-01 20:15，回访内容：学生转产品转入，创建续费工单。 | BB29: 51853027 | BC29: 否 | BD29: 26考季 | BE29: VIP - 伴学 | BF29: 英语 | BH29: 国内高校-双非 | BI29: 否
A30: 46 | B30: 北京大学部 | C30: 国内大学部 | D30: 冯晨阳 | E30: 136043660 | F30: 许庆典 | G30: 2025-11-29 16:30:24 | H30: 续费原因：4h定制1v1，指定刘瑶；该学生为保护期内续费，原顾问：国内大学部-谭悦(tanyue9@xdf.cn) | J30: 大学已毕业 | K30: 谭悦 | L30: 转介绍 | M30: 学管续费推荐 | N30: 许庆典xuqingdian@xdf.cn | Q30: 冯晨阳 | R30: 谭悦 | S30: 30914217 | T30: 续费工单 | U30: 2025-11-29 19:45 | V30: A（六个月内有报课意向工单） | W30: 考研VIP | X30: 大学已毕业 | Y30: 首都医科大学 | Z30: 临床医学院 | AA30: 临床医学 | AB30: 冯晨阳 | AC30: 5737100 | AD30: 谭悦 | AE30: 2025-11-29 19:51 | AF30: 谭悦 | AG30: 2025-11-29 19:59 | AH30: 个性化 | AI30: LP17644170743890 | AJ30: 考研一对一伴学班（定制/26考季） | AK30: 国内考试 | AM30: 7200 | AO30: 许庆典 | AP30: 续班 | AQ30: 已交接 | AS30: BJWY9774040881 | AU30: 2025-11-29 | AW30: 回访人：谭悦，回访时间：2025-11-29 19:45，回访内容：1；|回访人：谭悦，回访时间：2025-11-29 19:51，回访内容：系统自动签约 | BB30: 51853027 | BC30: 否 | BD30: 26考季 | BE30: VIP - 伴学 | BF30: 英语 | BG30: 其他 | BH30: 国内高校-双非 | BI30: 是 | BO30: 学管续费推荐
A31: 60 | B31: 北京大学部 | C31: 国内大学部 | D31: 北京市5117 | E31: 135574278 | F31: 王静静 | G31: 2025-11-24 11:09:52 | H31: 考季：26 年级：在职 课程形式：考研VIP 学生情况：今年考研，咨询考研英语和政治的一对一【系统里有签约】；渠道录入来源：新东方官网M站-客服 意向城市：北京访客省/城市：北京市 访客静态ID：01000003465900269897988572415117 接待分组ID：70455 搜索引擎： 搜索词： 关键词： 设备类型：phone 访客IP：124.127.68.131 对话详细内容：AI-Lbo0rDBXCyBY 2025-11-09 22:36:20_x000D_ 您好同学,欢迎访问北京新东方考研四六级中心. 考研线下课程26/27考季【考研全年集训营】【考研半年集训营】【考研全科线下走读班】【考研寒/暑假集训营】【考研一对一】【考研专业课】【四/六级课程】，热门课程火热报名中,咨询即可领取专享优惠。 **【考研全年集训营】=ff761f# **【考研半年集训营】=ff6b6b# **【考研全科线下走读班】=ffc158# **【考研寒/暑假集训营】=ffc158# **【考研一对一】=ff761f# **【考研专业课】=ff6caa# **【四/六级课程】=ff6caa# **【考研冲刺班】=60e27e#_x000D_ _x000D_ AI-Lbo0rDBXCyBY 2025-11-09 22:36:23_x000D_ 您是想咨询【线下课程】【线上课程】【考研规划】还是【在职考研】呢？**【线下课程】# **【线上课程】#**【考研规划】#**【在职考研】#_x000D_ _x000D_ 01000003465900269897988572415117 2025-11-09 22:36:30_x000D_ 【线下课程】_x000D_ _x000D_ AI-Lbo0rDBXCyBY 2025-11-09 22:36:34_x000D_ 同学，你现在是在校还是在职呢？_x000D_ _x000D_ 01000003465900269897988572415117 2025-11-09 22:36:42_x000D_ 在校_x000D_ _x000D_ AI-Lbo0rDBXCyBY 2025-11-09 22:36:45_x000D_ 具体是想报考什么学校和专业呢？_x000D_ _x000D_ 01000003465900269897988572415117 2025-11-09 22:37:05_x000D_ 【考研一对一】_x000D_ _x000D_ AI-Lbo0rDBXCyBY 2025-11-09 22:37:09_x000D_ 好的，我这边安排专业老师给您回电，详细沟通一下，请问您的电话是多少呢？_x000D_ _x000D_ 01000003465900269897988572415117 2025-11-09 22:37:20_x000D_ 17338157357_x000D_ _x000D_ AI-Lbo0rDBXCyBY 2025-11-09 22:37:24_x000D_ 好的，确认一下你的号码是否正确呢~_x000D_ _x000D_ 01000003465900269897988572415117 2025-11-09 22:37:34_x000D_ 正确_x000D_ _x000D_ AI-Lbo0rDBXCyBY 2025-11-09 22:37:38_x000D_ 同学怎么称呼呢？_x000D_ _x000D_ 01000003465900269897988572415117 2025-11-09 22:37:45_x000D_ 冯_x000D_ _x000D_ AI-Lbo0rDBXCyBY 2025-11-09 22:37:49_x000D_ 好的，由于今天课程规划老师已经下班了，这边安排老师明天上午9点后给您回电请注意接听~_x000D_ _x000D_ 01000003465900269897988572415117 2025-11-09 22:38:23_x000D_ 上午十一点到十二点打吧_x000D_ _x000D_ AI-Lbo0rDBXCyBY 2025-11-09 22:38:26_x000D_ 好的，这个也是您的微信号吗？_x000D_ _x000D_ 01000003465900269897988572415117 2025-11-09 22:38:33_x000D_ 对_x000D_ _x000D_ AI-Lbo0rDBXCyBY 2025-11-09 22:38:36_x000D_ 稍后老师会联系哈_x000D_ _x000D_ 01000003465900269897988572415117 2025-11-09 22:38:48_x000D_ 直接加微信说吧_x000D_ _x000D_ AI-Lbo0rDBXCyBY 2025-11-09 22:38:52_x000D_ 可以的，你的微信是多少呢？_x000D_ _x000D_ 01000003465900269897988572415117 2025-11-09 22:39:05_x000D_ 就这个手机号_x000D_ _x000D_ AI-Lbo0rDBXCyBY 2025-11-09 22:39:08_x000D_ 好的，请问还有其他问题需要咨询吗？_x000D_ _x000D_ 01000003465900269897988572415117 2025-11-09 22:39:18_x000D_ 没_x000D_ _x000D_ AI-Lbo0rDBXCyBY 2025-11-09 22:39:21_x000D_ 联系方式已收到，第二天上午9点后与您联系的，感谢您的访问 祝您生活愉快！您可以关闭对话早点休息了。晚安~_x000D_ _x000D_ _x000D_ 来源页：https://group-live2.easyliao.com/live/chat.do?c=34659&g=70455&config=102466 备注： 外呼主题：2026财年第6财月易聊新东方官网M站 离职顾问：栗晓环(资源备注人:程远;资源备注时间:2025-11-10 10:00)（TMK主管分配TMK） | I31: 2026财年第6财月易聊新东方官网M站 | J31: 在职 | K31: 段同飞 | L31: 新东方官网 | M31: 新东方官网M站 | O31: 段同飞 | P31: 2025-11-24 12:15:58 | Q31: 冯晨阳 | R31: 谭悦 | S31: 30861560 | T31: 续费工单 | U31: 2025-11-24 14:15 | V31: A（六个月内有报课意向工单） | W31: 考研VIP | X31: 在职 | Y31: 首都医科大学 | Z31: 临床医学院 | AA31: 临床医学 | AB31: 冯晨阳 | AC31: 5576878 | AD31: 谭悦 | AE31: 2025-11-24 14:39 | AF31: 谭悦 | AG31: 2025-11-24 14:40 | AH31: 无忧 | AI31: LP1763966340551 | AJ31: 26考研一对一伴学（定制/无忧） | AK31: 国内考试 | AM31: 5200 | AP31: 续班 | AQ31: 已交接 | AS31: BJWY9774040881 | AU31: 2025-11-24 | AW31: 回访人：谭悦，回访时间：2025-11-24 14:15，回访内容：1；|回访人：谭悦，回访时间：2025-11-24 14:39，回访内容：系统自动签约 | BB31: 51853027 | BC31: 否 | BD31: 26考季 | BE31: VIP - 伴学 | BF31: 英语 | BG31: 其他 | BH31: 国内高校-双非 | BI31: 是
A32: 8 | B32: 北京大学部 | C32: 国内大学部 | D32: 沈 | E32: 134829313 | F32: 仇舰宁 | G32: 2025-11-17 15:20:49 | H32: 市场人员：刘子奇 备注：家长给孩子咨询26考研冲刺1对1辅导 | I32: 2026财年第6财月91校代系统资源活动 | K32: 李涛 | L32: 校代 | M32: 线上校代 | Q32: 冯靖桐 | R32: 李涛 | S32: 30833624 | T32: 正常工单 | U32: 2025-11-17 16:32 | V32: A（六个月内有报课意向工单） | W32: 考研VIP | X32: 大四 | Y32: 青岛农业大学 | Z32: 动漫与传媒学院 | AA32: 传播学（影视与网络） | AB32: 冯靖桐 | AC32: 5729816 | AD32: 李涛 | AE32: 2025-11-17 19:04 | AF32: 李涛 | AG32: 2025-11-17 19:05 | AH32: 网课 | AI32: 99860229334 | AJ32: 2026考研专业课定制一对一（20h）-A班 | AK32: 国内考试 | AM32: 9450 | AP32: 新签 | AQ32: 无须交接 | AU32: 2025-11-17 | AW32: 回访人：李涛，回访时间：2025-11-17 16:32，回访内容：想考山东师范大学 历史学！ 本科新闻传播学！ 现在主要是需要专业课的辅导！介绍一对一课程！；|回访人：李涛，回访时间：2025-11-17 19:04，回访内容：系统自动签约 | AY32: 9450.0 | AZ32: 2025-11-30 | BA32: 长期班 | BB32: 87568856 | BC32: 是 | BD32: 27考季 | BE32: VIP - 伴学 | BF32: 专业课150 | BG32: 其他 | BH32: 国内高校-双非 | BI32: 否 | BM32: 111185342 | BN32: 外地人外地大学(常规) | BO32: 新东方91校园大使
A33: 127 | B33: 北京大学部 | C33: 国内大学部 | D33: 成都市8577 | E33: 133164484 | F33: 张亚男 | G33: 2025-11-02 12:39:40 | H33: 渠道录入来源：北京中心-百度投放 意向城市：北京访客省/城市：成都市 访客静态ID：01000000034659205819616495768577 接待分组ID：82148 搜索引擎： 搜索词： 关键词： 设备类型：pc 访客IP：171.221.137.205 对话详细内容：AI-Lbo0rDBXCy 2025-11-02 12:36:38_x000D_ 您好同学,欢迎访问北京新东方考研四六级中心. 考研线下课程26/27考季【考研全年集训营】【考研半年集训营】【考研全科线下走读班】【考研寒/暑假集训营】【考研一对一】【考研专业课】【四/六级课程】，热门课程火热报名中,咨询即可领取专享优惠。 **【考研全年集训营】=ff761f# **【考研半年集训营】=ff6b6b# **【考研全科线下走读班】=ffc158# **【考研寒/暑假集训营】=ffc158# **【考研一对一】=ff761f# **【考研专业课】=ff6caa# **【四/六级课程】=ff6caa# **【考研冲刺班】=60e27e#_x000D_ _x000D_ AI-Lbo0rDBXCy 2025-11-02 12:36:41_x000D_ 您是想咨询【线下课程】【线上课程】【考研规划】还是【在职考研】呢？**【线下课程】# **【线上课程】#**【考研规划】#**【在职考研】#_x000D_ _x000D_ 01000000034659205819616495768577 2025-11-02 12:36:54_x000D_ 【考研一对一】_x000D_ _x000D_ AI-Lbo0rDBXCy 2025-11-02 12:36:57_x000D_ 同学，你现在是在校还是在职呢？_x000D_ _x000D_ 01000000034659205819616495768577 2025-11-02 12:37:04_x000D_ 在职_x000D_ _x000D_ AI-Lbo0rDBXCy 2025-11-02 12:37:07_x000D_ 具体是想报考什么学校和专业呢？_x000D_ _x000D_ 01000000034659205819616495768577 2025-11-02 12:37:19_x000D_ 清华大学 新闻与传播_x000D_ _x000D_ AI-Lbo0rDBXCy 2025-11-02 12:37:23_x000D_ 好的，我这边安排专业老师给您回电，详细沟通一下，请问您的电话是多少呢？_x000D_ _x000D_ 01000000034659205819616495768577 2025-11-02 12:37:39_x000D_ 13564410235_x000D_ _x000D_ AI-Lbo0rDBXCy 2025-11-02 12:37:43_x000D_ 好的，确认一下你的号码是否正确呢~_x000D_ _x000D_ 01000000034659205819616495768577 2025-11-02 12:37:53_x000D_ 确认_x000D_ _x000D_ AI-Lbo0rDBXCy 2025-11-02 12:37:56_x000D_ 同学怎么称呼呢？_x000D_ _x000D_ 01000000034659205819616495768577 2025-11-02 12:38:02_x000D_ 傅_x000D_ _x000D_ AI-Lbo0rDBXCy 2025-11-02 12:38:06_x000D_ 这边马上安排顾问老师联系您，预计半个小时左右给您回电请注意接听~_x000D_ _x000D_ 来源页：https://cn.bing.com/ 备注： | I33: 2026财年第6财月易聊百度投放 | K33: 谭悦 | L33: 线上运营-投放 | M33: 百度投放 | Q33: 傅寅杰 | R33: 谭悦 | S33: 30650543 | T33: 正常工单 | U33: 2025-11-03 10:25 | V33: A（六个月内有报课意向工单） | W33: 考研专业课 | X33: 在职 | Y33: 清华大学 | Z33: 新闻与传播学院 | AA33: 新闻学 | AB33: 傅寅杰 | AC33: 5690879 | AD33: 谭悦 | AE33: 2025-11-03 11:36 | AF33: 谭悦 | AG33: 2025-11-03 12:28 | AH33: 个性化 | AI33: LP1762140978258 | AJ33: 考研初试专业课一对一（27考研/50小时） | AK33: 国内考试 | AM33: 28800 | AP33: 新签 | AQ33: 已交接 | AS33: BJWY5387442298 | AU33: 2025-11-03 | AW33: 回访人：谭悦，回访时间：2025-11-03 10:25，回访内容：毕业几年了，24考研考的上海的新传，差20分， 今年考清华的学硕新传， 准备报专业课 ；|回访人：谭悦，回访时间：2025-11-03 11:36，回访内容：系统自动签约 | BB33: 86931058 | BC33: 否 | BD33: 27考季 | BE33: 考研专业课300 | BF33: 专业课300 | BG33: 其他 | BH33: 国内高校-C9 | BI33: 是 | BO33: 易聊在线咨询
A34: 128 | B34: 北京大学部 | C34: 国内大学部 | D34: 成都市8577 | E34: 133164484 | F34: 张亚男 | G34: 2025-11-02 12:39:40 | H34: 渠道录入来源：北京中心-百度投放 意向城市：北京访客省/城市：成都市 访客静态ID：01000000034659205819616495768577 接待分组ID：82148 搜索引擎： 搜索词： 关键词： 设备类型：pc 访客IP：171.221.137.205 对话详细内容：AI-Lbo0rDBXCy 2025-11-02 12:36:38_x000D_ 您好同学,欢迎访问北京新东方考研四六级中心. 考研线下课程26/27考季【考研全年集训营】【考研半年集训营】【考研全科线下走读班】【考研寒/暑假集训营】【考研一对一】【考研专业课】【四/六级课程】，热门课程火热报名中,咨询即可领取专享优惠。 **【考研全年集训营】=ff761f# **【考研半年集训营】=ff6b6b# **【考研全科线下走读班】=ffc158# **【考研寒/暑假集训营】=ffc158# **【考研一对一】=ff761f# **【考研专业课】=ff6caa# **【四/六级课程】=ff6caa# **【考研冲刺班】=60e27e#_x000D_ _x000D_ AI-Lbo0rDBXCy 2025-11-02 12:36:41_x000D_ 您是想咨询【线下课程】【线上课程】【考研规划】还是【在职考研】呢？**【线下课程】# **【线上课程】#**【考研规划】#**【在职考研】#_x000D_ _x000D_ 01000000034659205819616495768577 2025-11-02 12:36:54_x000D_ 【考研一对一】_x000D_ _x000D_ AI-Lbo0rDBXCy 2025-11-02 12:36:57_x000D_ 同学，你现在是在校还是在职呢？_x000D_ _x000D_ 01000000034659205819616495768577 2025-11-02 12:37:04_x000D_ 在职_x000D_ _x000D_ AI-Lbo0rDBXCy 2025-11-02 12:37:07_x000D_ 具体是想报考什么学校和专业呢？_x000D_ _x000D_ 01000000034659205819616495768577 2025-11-02 12:37:19_x000D_ 清华大学 新闻与传播_x000D_ _x000D_ AI-Lbo0rDBXCy 2025-11-02 12:37:23_x000D_ 好的，我这边安排专业老师给您回电，详细沟通一下，请问您的电话是多少呢？_x000D_ _x000D_ 01000000034659205819616495768577 2025-11-02 12:37:39_x000D_ 13564410235_x000D_ _x000D_ AI-Lbo0rDBXCy 2025-11-02 12:37:43_x000D_ 好的，确认一下你的号码是否正确呢~_x000D_ _x000D_ 01000000034659205819616495768577 2025-11-02 12:37:53_x000D_ 确认_x000D_ _x000D_ AI-Lbo0rDBXCy 2025-11-02 12:37:56_x000D_ 同学怎么称呼呢？_x000D_ _x000D_ 01000000034659205819616495768577 2025-11-02 12:38:02_x000D_ 傅_x000D_ _x000D_ AI-Lbo0rDBXCy 2025-11-02 12:38:06_x000D_ 这边马上安排顾问老师联系您，预计半个小时左右给您回电请注意接听~_x000D_ _x000D_ 来源页：https://cn.bing.com/ 备注： | I34: 2026财年第6财月易聊百度投放 | K34: 谭悦 | L34: 线上运营-投放 | M34: 百度投放 | Q34: 傅寅杰 | R34: 谭悦 | S34: 30650543 | T34: 正常工单 | U34: 2025-11-03 10:25 | V34: A（六个月内有报课意向工单） | W34: 考研专业课 | X34: 在职 | Y34: 清华大学 | Z34: 新闻与传播学院 | AA34: 新闻学 | AB34: 傅寅杰 | AC34: 5690879 | AD34: 谭悦 | AE34: 2025-11-03 11:36 | AF34: 谭悦 | AG34: 2025-11-03 12:28 | AH34: 个性化 | AI34: LP1762140978259 | AJ34: 清北院校升级费 | AK34: 国内考试 | AM34: 5000 | AP34: 新签 | AQ34: 已交接 | AS34: BJWY5387442298 | AU34: 2025-11-03 | AW34: 回访人：谭悦，回访时间：2025-11-03 10:25，回访内容：毕业几年了，24考研考的上海的新传，差20分， 今年考清华的学硕新传， 准备报专业课 ；|回访人：谭悦，回访时间：2025-11-03 11:36，回访内容：系统自动签约 | BB34: 86931058 | BC34: 否 | BD34: 27考季 | BE34: 考研专业课300 | BF34: 专业课300 | BG34: 其他 | BH34: 国内高校-C9 | BI34: 是 | BO34: 易聊在线咨询
A35: 84 | B35: 北京大学部 | C35: 国内大学部 | D35: 郭宸宇 | E35: 134712043 | F35: 徐岩 | G35: 2025-11-15 21:13:52 | H35: 续费原因：续费10小时数学课 辛苦流转谭悦；该学生为保护期内续费，原顾问：国内大学部-谭悦(tanyue9@xdf.cn) | J35: 大二 | K35: 谭悦 | L35: 转介绍 | M35: 学管续费推荐 | N35: 徐岩xuyan91@xdf.cn | Q35: 郭宸宇 | R35: 谭悦 | S35: 30767603 | T35: 续费工单 | U35: 2025-11-16 09:26 | V35: A（六个月内有报课意向工单） | W35: 六级 | X35: 大二 | Y35: 对外经济贸易大学 | Z35: 金融学院 | AA35: 金融学 | AB35: 郭宸宇 | AC35: 5574845 | AD35: 谭悦 | AE35: 2025-11-16 09:30 | AF35: 谭悦 | AG35: 2025-11-16 09:38 | AH35: 四六级 | AI35: LP17632566543722 | AJ35: 大学数学一对一伴学班（定制） | AK35: 国内考试 | AM35: 12000 | AO35: 徐岩 | AP35: 续班 | AQ35: 已交接 | AS35: BJWY5305138836 | AU35: 2025-11-16 | AW35: 回访人：谭悦，回访时间：2025-11-16 09:26，回访内容：报名数学一对一 ；|回访人：谭悦，回访时间：2025-11-16 09:30，回访内容：系统自动签约 | BB35: 59798822 | BC35: 否 | BD35: 25下考季 | BE35: 六级一对一 | BH35: 国内高校-211 | BI35: 是 | BN35: 本地人本地大学(常规) | BO35: 学管续费推荐
A36: 11 | B36: 北京大学部 | C36: 国内大学部 | D36: 107044026 | E36: 133903723 | F36: 张亚男 | G36: 2025-11-09 10:13:22 | H36: 渠道录入来源：抖音新东方考研直播间 koouserID：107044026 城市：北京 产品分组：考研 线索来源：直播间小风车收资-大学生-线下面授 市场人员： 是否兼职： 备注信息：请选择当前所属阶段：:大三;请选择倾向的备考方式：:线下面授;请选择备考城市：:北京 | I36: 2026财年第6财月抖音新东方考研直播间 | K36: 乔文娇 | L36: 线上运营-抖音 | M36: 抖音新东方考研直播间 | O36: 乔文娇 | P36: 2025-11-09 12:29:40 | Q36: 何年 | R36: 谭悦 | S36: 30708914 | T36: 正常工单 | U36: 2025-11-09 17:34 | V36: A（六个月内有报课意向工单） | W36: 线上考研产品 | X36: 大三 | Y36: 大连海事大学 | Z36: 法学院 | AA36: 法学（海商法） | AB36: 何年 | AC36: 5695630 | AD36: 谭悦 | AE36: 2025-11-11 21:14 | AF36: 谭悦 | AG36: 2025-11-11 22:53 | AH36: 网课 | AI36: 46455177697 | AJ36: 2027考研英语一无忧计划·7期,2027考研直通车VIP【法律硕士（法学）】,2027考研政治无忧计划·6期 | AK36: 国内考试 | AM36: 19685.6 | AP36: 新签 | AQ36: 无须交接 | AU36: 2025-11-11 | AW36: 回访人：谭悦，回访时间：2025-11-09 17:34，回访内容：法硕 面谈了， 大连海事想考北大法硕法学， 家长一起来的 ；|回访人：谭悦，回访时间：2025-11-11 18:45，回访内容：学生不回复消息，不怎么说话 ；|回访人：谭悦，回访时间：2025-11-11 21:14，回访内容：系统自动签约 | BA36: 长期班,长期班,长期班 | BB36: 87225932 | BC36: 是 | BD36: 27考季 | BE36: 线上直通车 | BF36: 政治,英语 | BG36: 其他 | BH36: 国内高校-211 | BI36: 否 | BM36: 107044026 | BN36: 外地人外地大学(常规) | BO36: 抖音新东方考研直播间
A37: 82 | B37: 北京大学部 | C37: 国内大学部 | E37: 134447281 | G37: 2025-11-14 09:47:52 | H37: 课程形式：考博英语一对一 学生情况：学生咨询考博英语，非医学专业，告知目前只有一对一辅导，也说了价格，可以了解一下，方便电话 | J37: 研究生以上 | K37: 赵星火 | L37: 电话 | M37: 大客服呼入 | Q37: 何晓涛 | R37: 赵星火 | S37: 30806542 | T37: 续费工单 | U37: 2025-11-17 10:13 | V37: A（六个月内有报课意向工单） | W37: 考博 | X37: 研究生以上 | Y37: 中国人民大学 | Z37: 信息学院 | AA37: 计算机科学与技术 | AB37: 何晓涛 | AC37: 5703459 | AD37: 赵星火 | AE37: 2025-11-17 10:20 | AF37: 赵星火 | AG37: 2025-11-17 10:27 | AH37: 个性化 | AI37: LP176334603072 | AJ37: 考博一对一伴学班 | AK37: 国内考试 | AM37: 18000 | AP37: 续班 | AQ37: 已交接 | AS37: BJWY4055776168 | AU37: 2025-11-17 | AW37: 回访人：赵星火，回访时间：2025-11-17 10:13，回访内容：1；|回访人：赵星火，回访时间：2025-11-17 10:20，回访内容：系统自动签约 | BB37: 87403705 | BC37: 否 | BH37: 国内高校-985 | BI37: 是
A38: 86 | B38: 北京大学部 | C38: 国内大学部 | D38: 考博 | E38: 134504635 | F38: 杨欢欢 | G38: 2025-11-14 09:19:17 | J38: 研究生以上 | K38: 杨欢欢 | L38: 电话 | M38: 大客服呼入 | O38: 杨欢欢 | P38: 2025-11-14 09:47:52 | Q38: 何晓涛 | R38: 赵星火 | S38: 30780026 | T38: 正常工单 | U38: 2025-11-14 10:24 | V38: A（六个月内有报课意向工单） | W38: 考博 | X38: 研究生以上 | Y38: 中国人民大学 | Z38: 信息学院 | AA38: 计算机科学与技术 | AB38: 何晓涛 | AC38: 5727982 | AD38: 赵星火 | AE38: 2025-11-15 10:38 | AF38: 赵星火 | AG38: 2025-11-15 10:47 | AH38: 个性化 | AI38: LP1763174337311 | AJ38: 考博一对一伴学班 | AK38: 国内考试 | AM38: 1800 | AP38: 新签 | AQ38: 已交接 | AS38: BJWY4055776168 | AU38: 2025-11-15 | AW38: 回访人：赵星火，回访时间：2025-11-14 10:24，回访内容：需要了解人大信息学院的考博的 内容近期想要上课，这边跟进中。；|回访人：赵星火，回访时间：2025-11-15 10:38，回访内容：系统自动签约 | BB38: 87403705 | BC38: 否 | BH38: 国内高校-985 | BI38: 是 | BO38: 客服
A39: 125 | B39: 北京大学部 | C39: 国内大学部 | D39: 贺其永歌 | E39: 133318501 | F39: 舒志豪 | G39: 2025-11-04 12:02:17 | H39: 续费原因：学员有续费英语六级需求；该学生为保护期内续费，原顾问：国内大学部-谭悦(tanyue9@xdf.cn) | J39: 大三 | K39: 谭悦 | L39: 转介绍 | M39: 学管续费推荐 | N39: 舒志豪shuzhihao1@xdf.cn | Q39: 贺其永歌 | R39: 谭悦 | S39: 30684897 | T39: 续费工单 | U39: 2025-11-04 12:13 | V39: A（六个月内有报课意向工单） | W39: 六级 | X39: 大三 | Y39: 首都师范大学 | Z39: 文学院 | AA39: 汉语言文学 | AB39: 贺其永歌 | AC39: 5571639 | AD39: 谭悦 | AE39: 2025-11-04 12:18 | AF39: 谭悦 | AG39: 2025-11-04 15:07 | AH39: 四六级 | AI39: LP1762229887473 | AJ39: 六级一对一伴学班 | AK39: 国内考试 | AM39: 9800 | AO39: 舒志豪 | AP39: 续班 | AQ39: 已交接 | AS39: BJWY9822893615 | AU39: 2025-11-04 | AW39: 回访人：谭悦，回访时间：2025-11-04 12:13，回访内容：六级一对一 ；|回访人：谭悦，回访时间：2025-11-04 12:18，回访内容：系统自动签约 | BB39: 53001132 | BC39: 否 | BD39: 25下考季 | BE39: 六级一对一 | BH39: 国内高校-双一流(非985/211) | BI39: 是 | BN39: 本地人本地大学(常规) | BO39: 学管续费推荐
A40: 2 | B40: 北京大学部 | C40: 国内大学部 | D40: 贺暄恒 | E40: 136464256 | F40: 郭又华 | G40: 2025-12-02 15:34:55 | H40: 续费原因：专业课还想再上2次；该学生为保护期内续费，原顾问：国内大学部-谭悦(tanyue9@xdf.cn) | J40: 大四 | K40: 谭悦 | L40: 转介绍 | M40: 学管续费推荐 | N40: 郭又华guoyouhua@xdf.cn | Q40: 贺暄恒 | R40: 谭悦 | S40: 30984866 | T40: 续费工单 | U40: 2025-12-02 17:28 | V40: A（六个月内有报课意向工单） | W40: 考研专业课 | X40: 大四 | Y40: 北京建筑大学 | Z40: 建筑与城市规划学院 | AA40: 建筑学 | AB40: 贺暄恒 | AC40: 5713857 | AD40: 谭悦 | AE40: 2025-12-02 17:37 | AF40: 谭悦 | AG40: 2025-12-02 17:44 | AH40: 无忧 | AI40: LP17646682272950 | AJ40: 考研初试专业课一对一（26考研/无忧） | AK40: 国内考试 | AM40: 2800 | AO40: 郭又华 | AP40: 续班 | AQ40: 已交接 | AS40: BJWY9142571360 | AU40: 2025-12-02 | AW40: 回访人：谭悦，回访时间：2025-12-02 17:28，回访内容：1；|回访人：谭悦，回访时间：2025-12-02 17:37，回访内容：系统自动签约 | BB40: 66477823 | BC40: 否 | BD40: 26考季 | BE40: 考研专业课150 | BF40: 专业课150 | BG40: 其他 | BH40: 国内高校-双非 | BI40: 是 | BN40: 本地人本地大学(常规) | BO40: 学管续费推荐
A41: 27 | B41: 北京大学部 | C41: 国内大学部 | D41: 贺暄恒 | E41: 132960286 | F41: 郭又华 | G41: 2025-11-01 11:27:06 | H41: 续费原因：学生专业课想再讲讲题，加4小时；该学生为保护期内续费，原顾问：国内大学部-谭悦(tanyue9@xdf.cn) | J41: 大四 | K41: 谭悦 | L41: 转介绍 | M41: 学管续费推荐 | N41: 郭又华guoyouhua@xdf.cn | Q41: 贺暄恒 | R41: 谭悦 | S41: 30576201 | T41: 续费工单 | U41: 2025-11-01 11:37 | V41: A（六个月内有报课意向工单） | W41: 考研专业课 | X41: 大四 | Y41: 北京建筑大学 | Z41: 建筑与城市规划学院 | AA41: 建筑学 | AB41: 贺暄恒 | AC41: 5570914 | AD41: 谭悦 | AE41: 2025-11-01 12:29 | AF41: 谭悦 | AG41: 2025-11-01 14:40 | AH41: 无忧 | AI41: LP17619713684250 | AJ41: 考研初试专业课一对一（26考研/无忧） | AK41: 国内考试 | AM41: 2800 | AO41: 郭又华 | AP41: 续班 | AQ41: 已交接 | AS41: BJWY9142571360 | AU41: 2025-11-01 | AW41: 回访人：谭悦，回访时间：2025-11-01 11:37，回访内容：续费；|回访人：谭悦，回访时间：2025-11-01 11:51，回访内容：专业课续费跟进；|回访人：谭悦，回访时间：2025-11-01 12:29，回访内容：系统自动签约 | BB41: 66477823 | BC41: 否 | BD41: 26考季 | BE41: 考研专业课150 | BF41: 专业课150 | BG41: 其他 | BH41: 国内高校-双非 | BI41: 是 | BN41: 本地人本地大学(常规) | BO41: 学管续费推荐
A42: 75 | B42: 北京大学部 | C42: 国内大学部 | D42: 贺暄恒 | E42: 134915707 | F42: 郭又华 | G42: 2025-11-18 11:25:29 | H42: 续费原因：学生专业课还想再加8小时讲讲真题；该学生为保护期内续费，原顾问：国内大学部-谭悦(tanyue9@xdf.cn) | J42: 大四 | K42: 谭悦 | L42: 转介绍 | M42: 学管续费推荐 | N42: 郭又华guoyouhua@xdf.cn | Q42: 贺暄恒 | R42: 谭悦 | S42: 30810914 | T42: 续费工单 | U42: 2025-11-18 11:45 | V42: A（六个月内有报课意向工单） | W42: 考研专业课 | X42: 大四 | Y42: 北京建筑大学 | Z42: 建筑与城市规划学院 | AA42: 建筑学 | AB42: 贺暄恒 | AC42: 5730051 | AD42: 谭悦 | AE42: 2025-11-18 11:52 | AF42: 谭悦 | AG42: 2025-11-18 11:55 | AH42: 无忧 | AI42: LP1763437959325 | AJ42: 考研初试专业课一对一（26考研/无忧） | AK42: 国内考试 | AM42: 5600 | AO42: 郭又华 | AP42: 续班 | AQ42: 已交接 | AS42: BJWY9142571360 | AU42: 2025-11-18 | AW42: 回访人：谭悦，回访时间：2025-11-18 11:45，回访内容：加8小时专业课 ；|回访人：谭悦，回访时间：2025-11-18 11:52，回访内容：系统自动签约 | BB42: 66477823 | BC42: 否 | BD42: 26考季 | BE42: 考研专业课150 | BF42: 专业课150 | BG42: 其他 | BH42: 国内高校-双非 | BI42: 否 | BN42: 本地人本地大学(常规) | BO42: 学管续费推荐
...

Sheet 退费明细
A1: 提交日期 | B1: OA流水号 | C1: 学管姓名 | D1: 学管是否代办 | E1: 顾问姓名 | F1: 顾问是否代办 | G1: 91系统-最新报名二级渠道 | H1: 原班所属项目 | I1: 新报入班级所属项目 | J1: 退费阶段 | K1: 退费一级原因（开课前） | L1: 退费一级原因 (开课后) | M1: 退费二级原因（专业课师资匹配原因） | N1: 退费二级原因（学员意愿转变_开课后） | O1: 退费三级原因（完全匹配不上）-院校、学院、专业、专业课代码及名称 | P1: 退费详细原因说明（与OA退费详细说明保持一致） | Q1: 预计报名新班学费金额 | R1: 转班金额（请学管填写所在班级实际金额） | S1: 转班详细原因说明 | T1: 提交时间 | U1: 学校 | V1: 学院 | W1: 年级 | X1: 专业 | Y1: 您所办理的业务类型 | Z1: 提交人 | AA1: 退费类型 | AB1: 学员姓名 | AC1: 学员编码 | AD1: 退费金额 | AE1: 办理日期-客服 | AF1: 退费方式-客服 | AG1: 需要跟进的顾问/学管 | AH1: 退费/转班特殊情况备注（若需要学管提供银行卡信息，可将需求填写在此处）-客服 | AI1: 是否完成退费/转班-客服 | AJ1: 父记录 | AK1: 父记录
A2: 2025/11/03 | B2: 2025110300814 | C2: 葛铭 | E2: 李涛48 | G2: 小红书 | H2: 无忧项目-VIP | I2: VIP项目 | J2: 开课前退费 | K2: 中心原因_开课前 | P2: 学员退出改报一对一督学 | Q2: ¥80000.00 | T2: 2025-11-03 | U2: 北京信息科技大学 | V2: 计算机 | W2: 大三 | X2: 计算机技术 | Y2: 退费 | Z2: 葛铭 | AA2: 转项目/转班/退出重报等未产生实际退费 | AB2: 陈靓怡 | AC2: BJWY7173848231 | AD2: 80000 | AE2: 2025/11/04 | AF2: 11.4，退回账户余额 11.4未办理，oa未到前台@葛铭@李涛48 (李涛) [图片] | AI2: TRUE
A3: 2025/11/11 | B3: 2025110402621 | C3: 王天义56 | E3: 李涛48 | G3: 新东方PC官网 | H3: VIP项目-专业课 | J3: 开课后退费 | L3: 学员意愿转变_开课后 | N3: 认为课程用处不大/不适合自己 | P3: 退费原因：1、学生觉得信息差导致焦虑报名课程，研究生第一次授课后学员觉得溢价，并提到“经过学长提点”；2、学院家庭条件不太富裕；3、目标院校的学习通上可以下载专业课的知识点，并从二手群收购资料。引导学生专业课的复习不光是知识点的掌握，更是结合时政热点，学长手里也有实时的解题思路、模板和规划，会节约复习时间等，学生坚持退费。 退费金额：报名金额-课消金额-研究生匹配费=18800-2*700-500=16900元 | T3: 2025-11-11 | U3: 上海交通大学 | V3: 经济学院 | W3: 2022 | X3: 金融学 | Y3: 退费 | Z3: 王天义56 | AA3: 真实产生的退费 | AB3: 熊新 | AC3: BJWY2441731275 | AD3: 16900 | AE3: 2025/11/13 | AF3: 11.13支付宝退回16900———————— 11.12未办理：未查询到顾问的挽单记录@王天义56 (王天义) | AI3: TRUE
AD4: =SUM(AD2:AD3) -> 96900
A5: 2025/10/30 | B5: 18967906 | C5: 余韵7 | E5: 谭悦9 | G5: 大众点评 | H5: 无忧项目-班课 | J5: 开课后退费 | L5: 学员意愿转变_开课后 | N5: 认为课程用处不大/不适合自己 | P5: 学生姓名：许凯贤 学员编号：BJWY0058842315 报名班级：无忧英语政治 报名手机号：18611288017 考勤截至日期：10月19号 实际课消：英语2次课共4课时 退费明细：资料费用68.2元 其中已开课班次WYE27019退4184-（2/108）*21800-68.2元=3712.1元 其他未开课班次WYP27016，WYP27017，WYP27018，WYE27022，WYE27023退23116元 总退费金额：3712.1+23116=26828.1元 | T5: 2025-10-30 | U5: 首都体育学院 | V5: 体育教育训练学院 | W5: 在职 | X5: 体育教育 | Y5: 退费 | Z5: 余韵7 | AA5: 真实产生的退费 | AB5: 许凯贤 | AC5: BJWY0058842315 | AD5: 0 | AE5: 2025/11/01 | AF5: 11.11退款已到账 11.11已确认，退款中 [图片] 11.10已转手工（26828.1已经申请提现，务必提醒学生进入短信链接确认（注意不是短信回复验证码），自确认之日起7-15个工作日到账。）：@余韵7 (余韵) 户 名：许凯贤 卡 号：6214680096962319 开户行：北京银行中关村石景山园支行 11.9银联扫码退款失败 11.8头寸不足，退回失败，是否需要转手工退回，如否继续等待，如是，需提供学员本人银行卡信息@余韵7 (余韵)———————————— 11.7头寸不足@余韵7 (余韵) 11.6头寸不足@余韵7 (余韵) 11.5头寸不足@余韵7 (余韵) 11.4头寸不足@余韵7 (余韵) [图片] 11.1已提交退款，目前显示退款失败商户头寸不足，原因如下图，辛苦老师确认@余韵7 (余韵)[图片] 10.31暂退学生账户，学生另一个班级课消有误@余韵7 (余韵) 10.30未办理，oa未到前台@余韵7 (余韵) | AI5: TRUE | AJ5: 花园桥取消班，不计算顾问退费，因学管操作，上月未及时推出 | AK5: 3712.1
A6: 2025/11/02 | C6: 黄小妹7 | E6: 谭悦9 | G6: 巨量广告 | H6: 无忧项目-班课 | R6: 3891.1 | S6: 学生需要往后转班3月花园桥上课，持续转班 | T6: 2025-11-02 | Y6: 转班 | Z6: 黄小妹7 | AB6: 郑雅洁 | AC6: BJWY5564317069 | AD6: =R6 -> 3891.1 | AE6: 2025/11/02 | AF6: 已转班 | AI6: TRUE
A7: 2025/11/13 | B7: NO.2025111000162 | C7: 张泽7 | E7: 谭悦9 | G7: 学管续费推荐 | H7: VIP项目-VIP | J7: 开课前退费 | K7: 学员意愿转变_开课前 | P7: 学员家长给学员报名一对一课程，经多次沟通学员均拒绝上课，家长沟通无果决定退出费用，目前没有其他课程需要了 | T7: 2025-11-13 | U7: 北京航空航天 | V7: 信息 | W7: 大三 | X7: 计算机 | Y7: 退费 | Z7: 张泽7 | AA7: 真实产生的退费 | AB7: 赵一泽 | AC7: BJWY5334447793 | AD7: 18000 | AE7: 2025/11/19 | AF7: 微信退回 未办理：OA未到前台（11.18）@张泽7 (张泽) 未办理：OA未到前台（11.17）@张泽7 (张泽)—————————— 11.15未办理：OA未到前台，无顾问挽单记录@张泽7 (张泽) 11.14未办理：OA未到前台 11.13未办理：OA未到前台 | AI7: TRUE
A8: 2025/11/30 | B8: 19012339 | C8: 黄小妹7 | E8: 谭悦9 | G8: 内部员工推荐 | H8: 无忧项目-班课 | J8: 开课后退费 | L8: 学员意愿转变_开课后 | N8: 认为课程用处不大/不适合自己 | P8: 【开课前退费】学生表示个人原因，不透露其他，说有需求会再联系。 | T8: 2025-11-30 | U8: 北京建筑大学 | V8: 机电与车辆工程学院 | W8: 大三 | X8: 机械工程 | Y8: 退费 | Z8: 黄小妹7 | AA8: 真实产生的退费 | AB8: 温宇飞 | AC8: BJWY4724508572 | AD8: 42857 | AE8: 2025/11/30 | AF8: 12.2支付宝退42857———————— [图片] 12.01需要等专业课退费后合并提现 暂退至学员账户，待专业课退费后合并提现 | AI8: TRUE
A9: 2025/11/30 | B9: 19012035 | C9: 黄小妹7 | E9: 谭悦9 | G9: 内部员工推荐 | H9: 无忧项目-班课 | J9: 开课后退费 | L9: 学员意愿转变_开课后 | N9: 认为课程用处不大/不适合自己 | P9: 【开课后退费】学生表示个人原因，不透露其他，说有需求会再联系。 | T9: 2025-11-30 | U9: 北京建筑大学 | V9: 机电与车辆工程学院 | W9: 大三 | X9: 机械工程 | Y9: 退费 | Z9: 黄小妹7 | AA9: 真实产生的退费 | AB9: 温宇飞 | AC9: BJWY4724508572 | AD9: 3988.8 | AE9: 2025/11/30 | AF9: 12.2支付宝退3988.8元———————————— [图片] 12.01需要等专业课退费后合并提现 暂退至学员账户，待专业课退费后合并提现 | AI9: TRUE
A10: 2025/11/26 | B10: 19008961 | C10: 焦子瑞 | E10: 谭悦9 | G10: 新东方PC官网 | H10: 集训营项目-专业课 | J10: 开课后退费 | L10: 计划冲突_开课后 | P10: 退费方式：开课后退费，费用原路退回。退费原因：学生学校事情太多，无法继续参加后续的线下课程了，申请退费。 | T10: 2025-11-26 | U10: 青岛农业大学 | V10: 生命科学学院 | W10: 大四 | X10: 生物科学 | Y10: 退费 | Z10: 焦子瑞 | AA10: 真实产生的退费 | AB10: 刘晓瑜 | AC10: BJWY4340261185 | AD10: =AK10/2 -> 2880 | AE10: 2025/11/28 | AF10: 邮件已审批，合计18912微信退回 11.28邮件和审核对不上，已重新群内审核，需要重新发邮件 11.27未办理：退费群内无审核记录@焦子瑞[图片] [图片] | AI10: TRUE | AJ10: 谭悦星火分单，18912 | AK10: 5760
A11: 2025/11/26 | B11: 19008870 | C11: 焦子瑞 | E11: 谭悦9 | G11: 新东方PC官网 | H11: 集训营项目-专业课 | J11: 开课后退费 | L11: 计划冲突_开课后 | P11: 退费方式：开课后退费，费用原路退回。 退费原因：学生学校事情太多，无法继续参加后续的线下课程了，申请退费。 | T11: 2025-11-26 | U11: 青岛农业大学 | V11: 生命科学学院 | W11: 大四 | X11: 生物科学 | Y11: 退费 | Z11: 焦子瑞 | AA11: 真实产生的退费 | AB11: 刘晓瑜 | AC11: BJWY4340261185 | AD11: =AK11/2 -> 3315.35 | AE11: 2025/11/28 | AF11: 邮件已审批，合计18912微信退回 11.28邮件和审核对不上，已重新群内审核，需要重新发邮件 11.27未办理：退费群内无审核记录@焦子瑞[图片] [图片] | AI11: TRUE | AK11: 6630.7
A12: 2025/11/27 | B12: 19010532 | C12: 焦子瑞 | E12: 谭悦9 | G12: 新东方PC官网 | H12: 集训营项目-班课 | J12: 开课后退费 | L12: 计划冲突_开课后 | P12: 退费方式：开课后退费，费用原路退回。 退费原因：学生学校事情太多，无法继续参加后续的线下课程了，申请退费。 | T12: 2025-11-27 | U12: 青岛农业大学 | V12: 生命科学学院 | W12: 大四 | X12: 生物科学 | Y12: 退费 | Z12: 焦子瑞 | AA12: 真实产生的退费 | AB12: 刘晓瑜 | AC12: BJWY4340261185 | AD12: =AK12/2 -> 3260.65 | AE12: 2025/11/28 | AF12: 邮件已审批，合计18912微信退回 11.28邮件和审核对不上，已重新群内审核，需要重新发邮件 | AI12: TRUE | AK12: 6521.3
AA13: 无忧408第一次转班 | AB13: 安思羽 | AC13: 安思羽 | AD13: 9000
AA14: 无忧408第一次转班 | AB14: 孙嘉珩 | AC14: 孙嘉珩 | AD14: 9000
AA15: 无忧408第一次转班 | AB15: 余欣然 | AC15: 余欣然 | AD15: 9000
AD16: =SUM(AD5:AD15) -> 105192.9
A17: 2025/11/01 | B17: 2025102800224 | C17: 王天义56 | E17: 赵星火 | G17: 学管续费推荐 | H17: VIP项目-专业课 | J17: 开课前退费 | K17: 专业课师资匹配原因 | M17: 对专业课教师资质不满意 | P17: 师资无法匹配，辅导科目比较难： 1、大部分是数学专业内容，计算机专业无法授课，数学专业又无法讲解计算机部分； 2、匹配到了学生本校研究生，研究生反馈这门课网上没有课件，及格都比较难，当时找学校领导反应过太难，学不会，相应的专业研究生很难辅导； 3、匹配到可以带的 211 研究生，家长不满意研究生院校，想要北京的师资。 引导家长放宽匹配范围，家长要求退款，由于学生有四六级、数学课时包，所以引导家长学习考研预科，挖掘考研需求，家长不考虑。 | T17: 2025-11-01 | U17: 西安电子科技大学 | V17: 网络与信息安全学院 | W17: 2024 | X17: 信息安全 | Y17: 退费 | Z17: 王天义56 | AA17: 真实产生的退费 | AB17: 郭泽恩 | AC17: BJWY2399718106 | AD17: 15800 | AE17: 2025/11/01 | AF17: 11.1已原路退回@王天义56 (王天义)[图片] | AI17: TRUE
A18: 2025/11/11 | B18: 2025110601399 | C18: 徐岩91 | E18: 赵星火 | G18: 学管续费推荐 | H18: 四六级项目-VIP | J18: 开课后退费 | L18: 学员意愿转变_开课后 | N18: 找到工作 | P18: 学员已经毕业 工作了 四六级都过了 大学挂科的也都过了 么有需要了 申请退费 | T18: 2025-11-11 | U18: 北方工业大学 | V18: 信息学院 | W18: 毕业 | X18: 数字媒体技术 | Y18: 退费 | Z18: 徐岩91 | AA18: 真实产生的退费 | AB18: 罗浩轩 | AC18: BJWY8238689300 | AD18: 2300 | AE18: 2025/11/13 | AF18: 11.14退款完成 11.14退款中 11.13银联商务POS退回，退款中@徐岩91 (徐岩)[图片] 11.12未办理：需提供下学管端口挽单截图@徐岩91 (徐岩)[图片] | AI18: TRUE
A19: 2025/11/14 | B19: 18994744 | C19: 郑雪新 | E19: 赵星火 | G19: 学管转介绍 | H19: 集训营项目-班课 | J19: 开课前退费 | K19: 学员意愿转变_开课前 | P19: 姓名：赵梓伊学员编号:BJWY8307774892退费计算过程：退费班级：20264047；KYHSJX2702Z；KYHSJXY2702；KYHSJXZ2702报名实缴费45800（课前退费）；共计应退费用：25500+6900+7000+6400=45800元1】20264047；27考研一对一伴学(30小时/集训)；255002】KYHSJX2702Z；27考研寒暑集训营（住宿费）；69003】KYHSJXY2702；27考研寒暑集训营英语；70004】KYHSJXZ2702；27考研寒暑集训营政治；6400 | T19: 2025-11-14 | U19: 北京邮电大学世纪学院 | V19: 艺术与传媒学院 | W19: 大三 | X19: 传播学（数字媒体策划与传播） | Y19: 退费 | Z19: 郑雪新 | AA19: 真实产生的退费 | AB19: 赵梓伊 | AC19: BJWY8307774892 | AD19: 20300 | AE19: 2025/11/18 | AF19: 11.24退款成功 (11.22)原路径退还65800，银联扫码退款中：@郑雪新@王天一55 (王天一) [图片] 暂退至学员账户 未办理：无顾问、学管挽单记录（11.18）@郑雪新 未办理：无顾问、学管挽单记录（11.17）@郑雪新 | AI19: TRUE
A20: 2025/11/14 | B20: NO.5764607523035810600 | C20: 王天一55 | E20: 赵星火 | G20: 学管转介绍 | H20: 集训营项目-专业课 | J20: 开课前退费 | K20: 学员意愿转变_开课前 | P20: 学生跟家长商量后决定不考研了，想要直接工作，退费意愿强烈 | T20: 2025-11-14 | U20: 北京邮电大学世纪学院 | V20: 艺术与传媒学院 | W20: 大三 | X20: 传播学 | Y20: 退费 | Z20: 王天一55 | AA20: 真实产生的退费 | AB20: 赵梓伊 | AC20: BJWY8307774892 | AD20: 20000 | AE20: 2025/11/19 | AF20: 11.24退款成功 (11.22)原路径退还65800，银联扫码退款中：@郑雪新@王天一55 (王天一) [图片] 暂退至学员账户 未办理：无顾问、学管挽单记录（11.18）@郑雪新 未办理：无顾问、学管挽单记录（11.17）@郑雪新 | AI20: TRUE
A21: 2025/11/06 | B21: NO.4323455642277300862 | C21: 郭又华 | E21: 赵星火 | G21: 大众点评 | H21: 无忧项目-专业课 | J21: 开课后退费 | L21: 学员意愿转变_开课后 | N21: 认为课程用处不大/不适合自己 | P21: 学生从24年就报名了，但是本人是公司老板，一直没有时间学习，感觉课程设计不太合适，今年考研也没有报名，想要全科退费，目前没有其他课程需要了 | T21: 2025-11-06 | U21: 学生不愿告知 | V21: 学生不愿告知 | W21: 在职 | X21: 学生不愿告知 | Y21: 退费 | Z21: 郭又华 | AA21: 真实产生的退费 | AB21: 唐庆银 | AC21: BJWY4636639194 | AD21: 4486.7 | AE21: 2025/11/10 | AF21: 11.26退款成功。 11.25合计提现24569.5，已转手工退至原汇款账户，待短信确认：北京从云科技有限公司632967667中国民生银行股份有限公司北京魏公村支行@许庆典 [图片] [图片] 11.10已退回账户余4486.7，待公共课办理后一起提现（11.17）——————————@郭又华 [图片] 未办理：OA未到客服（11.9） 未办理：OA未到客服（11.8）—————————— 11.6未办理，oa未到前台 | AI21: TRUE
A22: 2025/11/15 | B22: 18986796 | C22: 史文涵1 | E22: 赵星火 | G22: 大众点评 | H22: 无忧项目-班课 | J22: 开课后退费 | L22: 学员意愿转变_开课后 | N22: 认为课程用处不大/不适合自己 | P22: 学员因自己前期没怎么上课，威胁投诉，要求退还剩余费用，已申请特批退款,邮件已抄送客服 | T22: 2025-11-15 | U22: 北京交通大学 | V22: 计算机 | W22: 在职 | X22: 计算机 | Y22: 退费 | Z22: 史文涵1 | AA22: 真实产生的退费 | AB22: 唐庆银 | AC22: BJWY4636639194 | AD22: 2967.8 | AE22: 2025/11/25 | AF22: 11.26退款成功。 11.25合计提现24569.5，已转手工退至原汇款账户，待短信确认：北京从云科技有限公司632967667中国民生银行股份有限公司北京魏公村支行@许庆典 [图片] [图片] 11.25未办理，暂时没有收到邮件 未办理：邮件还未审核完成（11.24）@史文涵1 (史文涵)@梁小东2 (梁小东) 未办理：邮件还未审核完成（11.23）@史文涵1 (史文涵)@梁小东2 (梁小东) 未办理：邮件还未审核完成（11.22） 未办理：辛苦老师将邮件完整的审批记录抄送至【大学事业部北京中心客户服务部前台客服部】（11.21）@史文涵1 (史文涵) 未办理：邮件审批流程未完成（11.20）@史文涵1 (史文涵) 未办理：邮件审批流程未完成（11.19）@史文涵1 (史文涵)[图片] 未办理：邮件审批流程未完成（11.18） 未办理：邮件审批流程未完成（11.17） | AG22: 许庆典 | AI22: TRUE
A23: 2025/11/15 | B23: 18990802 | C23: 史文涵1 | E23: 赵星火 | G23: 大众点评 | H23: 无忧项目-班课 | J23: 开课后退费 | L23: 学员意愿转变_开课后 | N23: 认为课程用处不大/不适合自己 | P23: 学员因自己前期没怎么上课，威胁投诉，要求退还剩余费用，已申请特批退款,邮件已抄送客服 | T23: 2025-11-15 | U23: 北京交通大学 | V23: 计算机 | W23: 在职 | X23: 计算机 | Y23: 退费 | Z23: 史文涵1 | AA23: 真实产生的退费 | AB23: 唐庆银 | AC23: BJWY4636639194 | AD23: 3298.8 | AE23: 2025/11/25 | AF23: 11.26退款成功。 11.25合计提现24569.5，已转手工退至原汇款账户，待短信确认：北京从云科技有限公司632967667中国民生银行股份有限公司北京魏公村支行@许庆典 [图片] [图片] 11.25未办理，暂时没有收到邮件 未办理：邮件还未审核完成（11.24）@史文涵1 (史文涵)@梁小东2 (梁小东) 未办理：邮件还未审核完成（11.23）@史文涵1 (史文涵)@梁小东2 (梁小东) 未办理：邮件还未审核完成（11.22） 未办理：辛苦老师将邮件完整的审批记录抄送至【大学事业部北京中心客户服务部前台客服部】（11.21）@史文涵1 (史文涵) 未办理：邮件审批流程未完成（11.20）@史文涵1 (史文涵) 未办理：邮件审批流程未完成（11.19）@史文涵1 (史文涵)[图片] 未办理：邮件审批流程未完成（11.18） 未办理：邮件审批流程未完成（11.17） | AI23: TRUE
A24: 2025/11/15 | B24: 18990954 | C24: 史文涵1 | E24: 赵星火 | G24: 大众点评 | H24: 无忧项目-班课 | J24: 开课后退费 | L24: 学员意愿转变_开课后 | N24: 认为课程用处不大/不适合自己 | P24: 学员因自己前期没怎么上课，威胁投诉，要求退还剩余费用，已申请特批退款,邮件已抄送客服 | T24: 2025-11-15 | U24: 北京交通大学 | V24: 计算机 | W24: 在职 | X24: 计算机 | Y24: 退费 | Z24: 史文涵1 | AA24: 真实产生的退费 | AB24: 唐庆银 | AC24: BJWY4636639194 | AD24: 1592.3 | AE24: 2025/11/25 | AF24: 11.26退款成功。 11.25合计提现24569.5，已转手工退至原汇款账户，待短信确认：北京从云科技有限公司632967667中国民生银行股份有限公司北京魏公村支行@许庆典 [图片] [图片] 11.25未办理，暂时没有收到邮件 未办理：邮件还未审核完成（11.24）@史文涵1 (史文涵)@梁小东2 (梁小东) 未办理：邮件还未审核完成（11.23）@史文涵1 (史文涵)@梁小东2 (梁小东) 未办理：邮件还未审核完成（11.22） 未办理：辛苦老师将邮件完整的审批记录抄送至【大学事业部北京中心客户服务部前台客服部】（11.21）@史文涵1 (史文涵) 未办理：邮件审批流程未完成（11.20）@史文涵1 (史文涵) 未办理：邮件审批流程未完成（11.19）@史文涵1 (史文涵)[图片] 未办理：邮件审批流程未完成（11.18） 未办理：邮件审批流程未完成（11.17） | AI24: TRUE
A25: 2025/11/15 | B25: 18990973 | C25: 史文涵1 | E25: 赵星火 | G25: 大众点评 | H25: 无忧项目-班课 | J25: 开课后退费 | L25: 学员意愿转变_开课后 | N25: 认为课程用处不大/不适合自己 | P25: 学员因自己前期没怎么上课，威胁投诉，要求退还剩余费用，已申请特批退款,邮件已抄送客服 | T25: 2025-11-15 | U25: 北京交通大学 | V25: 计算机 | W25: 在职 | X25: 计算机 | Y25: 退费 | Z25: 史文涵1 | AA25: 真实产生的退费 | AB25: 唐庆银 | AC25: BJWY4636639194 | AD25: 5341.1 | AE25: 2025/11/25 | AF25: 11.26退款成功。 11.25合计提现24569.5，已转手工退至原汇款账户，待短信确认：北京从云科技有限公司632967667中国民生银行股份有限公司北京魏公村支行@许庆典 [图片] [图片] 11.25未办理，暂时没有收到邮件 未办理：邮件还未审核完成（11.24）@史文涵1 (史文涵)@梁小东2 (梁小东) 未办理：邮件还未审核完成（11.23）@史文涵1 (史文涵)@梁小东2 (梁小东) 未办理：邮件还未审核完成（11.22） 未办理：辛苦老师将邮件完整的审批记录抄送至【大学事业部北京中心客户服务部前台客服部】（11.21）@史文涵1 (史文涵) 未办理：邮件审批流程未完成（11.20）@史文涵1 (史文涵) 未办理：邮件审批流程未完成（11.19）@史文涵1 (史文涵)[图片] 未办理：邮件审批流程未完成（11.18） 未办理：邮件审批流程未完成（11.17） | AI25: TRUE
A26: 2025/11/15 | B26: 18991963 | C26: 史文涵1 | E26: 赵星火 | G26: 大众点评 | H26: 无忧项目-班课 | J26: 开课后退费 | L26: 学员意愿转变_开课后 | N26: 认为课程用处不大/不适合自己 | P26: 学员因自己前期没怎么上课，威胁投诉，要求退还剩余费用，已申请特批退款,邮件已抄送客服 | T26: 2025-11-15 | U26: 北京交通大学 | V26: 计算机 | W26: 在职 | X26: 计算机 | Y26: 退费 | Z26: 史文涵1 | AA26: 真实产生的退费 | AB26: 唐庆银 | AC26: BJWY4636639194 | AD26: 3770.2 | AE26: 2025/11/25 | AF26: 11.26退款成功。 11.25合计提现24569.5，已转手工退至原汇款账户，待短信确认：北京从云科技有限公司632967667中国民生银行股份有限公司北京魏公村支行@许庆典 [图片] [图片] 11.25未办理，暂时没有收到邮件 未办理：邮件还未审核完成（11.24）@史文涵1 (史文涵)@梁小东2 (梁小东) 未办理：邮件还未审核完成（11.23）@史文涵1 (史文涵)@梁小东2 (梁小东) 未办理：邮件还未审核完成（11.22） 未办理：辛苦老师将邮件完整的审批记录抄送至【大学事业部北京中心客户服务部前台客服部】（11.21）@史文涵1 (史文涵) 未办理：邮件审批流程未完成（11.20）@史文涵1 (史文涵) 未办理：邮件审批流程未完成（11.19）@史文涵1 (史文涵)[图片] 未办理：邮件审批流程未完成（11.18） 未办理：邮件审批流程未完成（11.17） | AI26: TRUE
A27: 2025/11/15 | B27: 18991941 | C27: 史文涵1 | E27: 赵星火 | G27: 大众点评 | H27: 无忧项目-班课 | J27: 开课后退费 | L27: 学员意愿转变_开课后 | N27: 认为课程用处不大/不适合自己 | P27: 学员因自己前期没怎么上课，威胁投诉，要求退还剩余费用，已申请特批退款,邮件已抄送客服 | T27: 2025-11-15 | U27: 北京交通大学 | V27: 计算机 | W27: 在职 | X27: 计算机 | Y27: 退费 | Z27: 史文涵1 | AA27: 真实产生的退费 | AB27: 唐庆银 | AC27: BJWY4636639194 | AD27: 3112.6 | AE27: 2025/11/25 | AF27: 11.26退款成功。 11.25合计提现24569.5，已转手工退至原汇款账户，待短信确认：北京从云科技有限公司632967667中国民生银行股份有限公司北京魏公村支行@许庆典 [图片] [图片] 11.25未办理，暂时没有收到邮件 未办理：邮件还未审核完成（11.24）@史文涵1 (史文涵)@梁小东2 (梁小东) 未办理：邮件还未审核完成（11.23）@史文涵1 (史文涵)@梁小东2 (梁小东) 未办理：邮件还未审核完成（11.22） 未办理：辛苦老师将邮件完整的审批记录抄送至【大学事业部北京中心客户服务部前台客服部】（11.21）@史文涵1 (史文涵) 未办理：邮件审批流程未完成（11.20）@史文涵1 (史文涵) 未办理：邮件审批流程未完成（11.19）@史文涵1 (史文涵)[图片] 未办理：邮件审批流程未完成（11.18） 未办理：邮件审批流程未完成（11.17） | AI27: TRUE
A28: 2025/11/15 | B28: 18990927 | C28: 史文涵1 | E28: 赵星火 | G28: 大众点评 | H28: 无忧项目-班课 | J28: 开课后退费 | L28: 学员意愿转变_开课后 | N28: 认为课程用处不大/不适合自己 | P28: 学员因自己前期没怎么上课，威胁投诉，要求退还剩余费用，已申请特批退款,邮件已抄送客服 | T28: 2025-11-15 | U28: 北京交通大学 | V28: 计算机 | W28: 在职 | X28: 计算机 | Y28: 退费 | Z28: 史文涵1 | AA28: 真实产生的退费 | AB28: 唐庆银 | AC28: BJWY4636639194 | AD28: 0 | AE28: 2025/11/25 | AF28: 0元离班 11.25未办理，暂时没有收到邮件 未办理：邮件还未审核完成（11.24）@史文涵1 (史文涵)@梁小东2 (梁小东) 未办理：邮件还未审核完成（11.23）@史文涵1 (史文涵)@梁小东2 (梁小东) 未办理：邮件还未审核完成（11.22） 未办理：辛苦老师将邮件完整的审批记录抄送至【大学事业部北京中心客户服务部前台客服部】（11.21）@史文涵1 (史文涵) 未办理：邮件审批流程未完成（11.20）@史文涵1 (史文涵) 未办理：邮件审批流程未完成（11.19）@史文涵1 (史文涵)[图片] 未办理：邮件审批流程未完成（11.18） 未办理：邮件审批流程未完成（11.17） | AI28: TRUE
A29: 2025/11/15 | B29: 18991920 | C29: 史文涵1 | E29: 赵星火 | G29: 大众点评 | H29: 无忧项目-班课 | J29: 开课后退费 | L29: 学员意愿转变_开课后 | N29: 认为课程用处不大/不适合自己 | P29: 学员因自己前期没怎么上课，威胁投诉，要求退还剩余费用，已申请特批退款,邮件已抄送客服 | T29: 2025-11-15 | U29: 北京交通大学 | V29: 计算机 | W29: 大四 | X29: 计算机 | Y29: 退费 | Z29: 史文涵1 | AA29: 真实产生的退费 | AB29: 唐庆银 | AC29: BJWY4636639194 | AD29: 0 | AE29: 2025/11/25 | AF29: 0元离班 11.25未办理，暂时没有收到邮件 未办理：邮件还未审核完成（11.24）@史文涵1 (史文涵)@梁小东2 (梁小东) 未办理：邮件还未审核完成（11.23）@史文涵1 (史文涵)@梁小东2 (梁小东) 未办理：邮件还未审核完成（11.22） 未办理：辛苦老师将邮件完整的审批记录抄送至【大学事业部北京中心客户服务部前台客服部】（11.21）@史文涵1 (史文涵) 未办理：邮件审批流程未完成（11.20）@史文涵1 (史文涵) 未办理：邮件审批流程未完成（11.19）@史文涵1 (史文涵)[图片] 未办理：邮件审批流程未完成（11.18） 未办理：邮件审批流程未完成（11.17） | AI29: TRUE
