Workbook

Sheet 业绩奖金
A1: 业绩奖金表（一人可多条，需写清类别）
A2: 序号 | B2: 机构 | C2: 年月 | D2: 工号 | E2: 姓名 | F2: 部门 | G2: 薪资项目 | H2: 金额 | I2: 备注
A3: 1 | B3: 北京中心 | C3: 2025.07 | D3: 258756 | E3: 刘文君 | F3: B级学习顾问 | G3: 管理绩效 | H3: 4000 | J3: OK
A4: 2 | B4: 北京中心 | C4: 2025.07 | D4: 258756 | E4: 刘文君 | F4: B级学习顾问 | G4: 岗位补贴 | H4: 4000 | J4: OK
A5: 3 | B5: 北京中心 | C5: 2025.07 | D5: 004192 | E5: 刘晓娟 | F5: B级学习顾问 | G5: 月度绩效 | H5: 2000 | J5: ok
A6: 4 | B6: 北京中心 | C6: 2025.07 | D6: 004192 | E6: 刘晓娟 | F6: B级学习顾问 | G6: 顾问签约奖金 | H6: 71254
A7: 5 | B7: 北京中心 | C7: 2025.07 | D7: 004192 | E7: 刘晓娟 | F7: B级学习顾问 | G7: 其它奖金 | H7: 2000 | I7: 过渡性补贴2000 | J7: OK
A8: 6 | B8: 北京中心 | C8: 2025.07 | D8: 004192 | E8: 刘晓娟 | F8: B级学习顾问 | G8: 顾问pk赛 | H8: 3000 | J8: OK
A9: 7 | B9: 北京中心 | C9: 2025.07 | D9: 004192 | E9: 刘晓娟 | F9: B级学习顾问 | G9: 积分pk赛 | H9: 1000 | J9: 未公示，先不发放
A10: 8 | B10: 北京中心 | C10: 2025.07 | D10: 590299 | E10: 徐健坤 | F10: B级学习顾问 | G10: 月度绩效 | H10: 1580 | J10: ok
A11: 9 | B11: 北京中心 | C11: 2025.07 | D11: 590299 | E11: 徐健坤 | F11: B级学习顾问 | G11: 顾问签约奖金 | H11: 0
A12: 10 | B12: 北京中心 | C12: 2025.07 | D12: 590299 | E12: 徐健坤 | F12: B级学习顾问 | G12: 其它奖金 | H12: 1097 | I12: 过渡性补贴2000，7.17最后一天出勤在岗，绩效核算：2000*（17/31） | J12: OK
A13: 11 | B13: 北京中心 | C13: 2025.07 | D13: 594606 | E13: 房国超 | F13: B级学习顾问 | G13: 月度绩效 | H13: 2000 | J13: ok
A14: 12 | B14: 北京中心 | C14: 2025.07 | D14: 594606 | E14: 房国超 | F14: B级学习顾问 | G14: 顾问签约奖金 | H14: 35781
A15: 13 | B15: 北京中心 | C15: 2025.07 | D15: 594606 | E15: 房国超 | F15: B级学习顾问 | G15: 其它奖金 | H15: 2000 | I15: 过渡性补贴2000 | J15: OK
A16: 14 | B16: 北京中心 | C16: 2025.07 | D16: 594606 | E16: 房国超 | F16: B级学习顾问 | G16: 顾问pk赛 | H16: 2000 | J16: OK
A17: 15 | B17: 北京中心 | C17: 2025.07 | D17: 594605 | E17: 李政 | F17: B级学习顾问 | G17: 月度绩效 | H17: 0 | J17: ok
A18: 16 | B18: 北京中心 | C18: 2025.07 | D18: 594605 | E18: 李政 | F18: B级学习顾问 | G18: 顾问签约奖金 | H18: 0
A19: 17 | B19: 北京中心 | C19: 2025.07 | D19: 594605 | E19: 李政 | F19: B级学习顾问 | G19: 其它奖金 | H19: 2000 | I19: 过渡性补贴2000 | J19: OK
A20: 18 | B20: 北京中心 | C20: 2025.07 | D20: 608630 | E20: 宋增辉 | F20: B级学习顾问 | G20: 月度绩效 | H20: 2000 | I20: 新人第三个月，打满 | J20: ok
A21: 19 | B21: 北京中心 | C21: 2025.07 | D21: 608630 | E21: 宋增辉 | F21: B级学习顾问 | G21: 顾问签约奖金 | H21: 29204
A22: 20 | B22: 北京中心 | C22: 2025.07 | D22: 608630 | E22: 宋增辉 | F22: B级学习顾问 | G22: 其它奖金 | H22: 2000 | I22: 过渡性补贴2000 | J22: OK
A23: 21 | B23: 北京中心 | C23: 2025.07 | D23: 608630 | E23: 宋增辉 | F23: B级学习顾问 | G23: 顾问pk赛 | H23: 1000 | J23: OK
A24: 22 | B24: 北京中心 | C24: 2025.07 | D24: 608617 | E24: 田一禾 | F24: B级学习顾问 | G24: 月度绩效 | H24: 2000 | I24: 新人第三个月，打满 | J24: ok
A25: 23 | B25: 北京中心 | C25: 2025.07 | D25: 608617 | E25: 田一禾 | F25: B级学习顾问 | G25: 顾问签约奖金 | H25: 28682
A26: 24 | B26: 北京中心 | C26: 2025.07 | D26: 608617 | E26: 田一禾 | F26: B级学习顾问 | G26: 其它奖金 | H26: 2000 | I26: 过渡性补贴2000 | J26: OK
A27: 25 | B27: 北京中心 | C27: 2025.07 | D27: 608617 | E27: 田一禾 | F27: B级学习顾问 | G27: 顾问pk赛 | H27: 500 | J27: OK
A28: 26 | B28: 北京中心 | C28: 2025.07 | D28: 608681 | E28: 张博奥 | F28: B级学习顾问 | G28: 月度绩效 | H28: 2000 | I28: 新人第三个月，打满 | J28: ok
A29: 27 | B29: 北京中心 | C29: 2025.07 | D29: 608681 | E29: 张博奥 | F29: B级学习顾问 | G29: 顾问签约奖金 | H29: 3056
A30: 28 | B30: 北京中心 | C30: 2025.07 | D30: 608681 | E30: 张博奥 | F30: B级学习顾问 | G30: 其它奖金 | H30: 2000 | I30: 过渡性补贴2000 | J30: OK
A31: 29 | B31: 北京中心 | C31: 2025.07 | D31: 343549 | E31: 黄智超 | F31: B级学习顾问 | G31: 月度绩效 | H31: 2000 | I31: 新人第二个月，打满 | J31: ok
A32: 30 | B32: 北京中心 | C32: 2025.07 | D32: 343549 | E32: 黄智超 | F32: B级学习顾问 | G32: 顾问签约奖金 | H32: 49696
A33: 31 | B33: 北京中心 | C33: 2025.07 | D33: 343549 | E33: 黄智超 | F33: B级学习顾问 | G33: 其它奖金 | H33: 2000 | I33: 过渡性补贴2000 | J33: OK
A34: 32 | B34: 北京中心 | C34: 2025.07 | D34: 343549 | E34: 黄智超 | F34: B级学习顾问 | G34: 往月补发 | H34: 3000 | I34: 保障性收入部分：入职次月即第一个完整的考勤月，额外发放3000元保薪提成。（6月） | J34: OK
A35: 33 | B35: 北京中心 | C35: 2025.07 | D35: 343549 | E35: 黄智超 | F35: B级学习顾问 | G35: 顾问pk赛 | H35: 1500 | J35: OK
A36: 34 | B36: 北京中心 | C36: 2025.07 | D36: 合计 | H36: =SUM(H3:H34) -> 264850
A38: 备注
A39: 此张表格中的绩效奖金包含提成奖金、月度绩效、季度绩效、其他业绩奖金

Sheet 业绩核算明细
A1: 国内顾问业绩汇总（7月）
A2: 排名 | B2: 组别 | C2: 顾问 | D2: 月度数据
D3: 本月目标 | E3: 总进账 | F3: 线下退费 | G3: 手动加 | H3: 综合业绩 | I3: 月度完成率 | J3: 转介绍总业绩 | K3: 考研转介绍金额 | L3: 四六级转介绍金额 | M3: 对应提点 | N3: 提点奖金 | O3: 减去转介绍的剩余业绩 | P3: 对应提点 | Q3: 提点奖金 | R3: 总计奖金 | T3: 加考研
A4: 四六级 | C4: 刘晓娟 | D4: 650000 | E4: 1396995.6 | F4: 192383.4 | H4: =E4-F4+G4 -> 1204612.2 | I4: =H4/D4 -> 1.8532496 | J4: 187809.15 | K4: 107294.6 | L4: =J4-K4 -> 80514.55 | M4: 0.052 | N4: =L4*M4 -> 4186.7566 | O4: =H4-L4 -> 1124097.7 | P4: 0.05 | Q4: =O4*P4 -> 56204.885 | R4: =N4+Q4 -> 60391.642 | T4: =L18+R4 -> 71253.993 | V4: =VLOOKUP(C4,[1]汇总!$B:$W,22,0) -> 1543401.8 | W4: =VLOOKUP(C4,[1]汇总!$B$6:$T$53,19,0) -> 1804234.4 | X4: =W4-E4 -> 407238.8 | Y4: =V4-H4 -> 338789.5
C5: 徐健坤 | D5: 650000 | E5: 352973.3 | F5: 197846.4 | G5: 15540 | H5: =E5-F5+G5 -> 170666.9 | I5: =H5/D5 -> 0.26256446 | J5: 38550 | K5: 0 | L5: =J5-K5 -> 38550 | O5: =H5-L5 -> 132116.9 | Q5: =O5*P5 -> 0 | R5: =N5+Q5 -> 0 | V5: =VLOOKUP(C5,[1]汇总!$B:$W,22,0) -> 225898.3 | W5: =VLOOKUP(C5,[1]汇总!$B$6:$T$53,19,0) -> 353519 | X5: =W5-E5 -> 545.7 | Y5: =V5-H5 -> 55231.4
C6: 房国超 | D6: 650000 | E6: 976589.7 | F6: 86550.8 | H6: =E6-F6+G6 -> 890038.9 | I6: =H6/D6 -> 1.3692906 | J6: 89520 | K6: 0 | L6: =J6-K6 -> 89520 | M6: 0.042 | N6: =L6*M6 -> 3759.84 | O6: =H6-L6 -> 800518.9 | P6: 0.04 | Q6: =O6*P6 -> 32020.756 | R6: =N6+Q6 -> 35780.596 | V6: =VLOOKUP(C6,[1]汇总!$B:$W,22,0) -> 891090.4 | W6: =VLOOKUP(C6,[1]汇总!$B$6:$T$53,19,0) -> 973115.5 | X6: =W6-E6 -> -3474.2 | Y6: =V6-H6 -> 1051.5
C7: 李政 | D7: 650000 | E7: 396210 | F7: 82238.7 | H7: =E7-F7+G7 -> 313971.3 | I7: =H7/D7 -> 0.48303277 | J7: 31780 | K7: 0 | L7: =J7-K7 -> 31780 | O7: =H7-L7 -> 282191.3 | Q7: =O7*P7 -> 0 | R7: =N7+Q7 -> 0 | V7: =VLOOKUP(C7,[1]汇总!$B:$W,22,0) -> 329988 | W7: =VLOOKUP(C7,[1]汇总!$B$6:$T$53,19,0) -> 396455.7 | X7: =W7-E7 -> 245.7 | Y7: =V7-H7 -> 16016.7
C8: 宋增辉 | D8: 520000 | E8: 878316.7 | F8: 156062.2 | H8: =E8-F8+G8 -> 722254.5 | I8: =H8/D8 -> 1.388951 | J8: 157010 | K8: 0 | L8: =J8-K8 -> 157010 | M8: 0.042 | N8: =L8*M8 -> 6594.42 | O8: =H8-L8 -> 565244.5 | P8: 0.04 | Q8: =O8*P8 -> 22609.78 | R8: =N8+Q8 -> 29204.2 | V8: =VLOOKUP(C8,[1]汇总!$B:$W,22,0) -> 709013.5 | W8: =VLOOKUP(C8,[1]汇总!$B$6:$T$53,19,0) -> 825816.7 | X8: =W8-E8 -> -52500 | Y8: =V8-H8 -> -13241
C9: 田一禾 | D9: 520000 | E9: 758217.95 | F9: 42550.5 | H9: =E9-F9+G9 -> 715667.45 | I9: =H9/D9 -> 1.3762836 | J9: 27540 | K9: 0 | L9: =J9-K9 -> 27540 | M9: 0.042 | N9: =L9*M9 -> 1156.68 | O9: =H9-L9 -> 688127.45 | P9: 0.04 | Q9: =O9*P9 -> 27525.098 | R9: =N9+Q9 -> 28681.778 | V9: =VLOOKUP(C9,[1]汇总!$B:$W,22,0) -> 703067.75 | W9: =VLOOKUP(C9,[1]汇总!$B$6:$T$53,19,0) -> 752324.65 | X9: =W9-E9 -> -5893.3 | Y9: =V9-H9 -> -12599.7
C10: 张博奥 | D10: 520000 | E10: 418279 | F10: 36239 | H10: =E10-F10+G10 -> 382040 | I10: =H10/D10 -> 0.73469231 | O10: =H10-L10 -> 382040 | P10: 0.008 | Q10: =O10*P10 -> 3056.32 | R10: =N10+Q10 -> 3056.32 | V10: =VLOOKUP(C10,[1]汇总!$B:$W,22,0) -> 396599 | W10: =VLOOKUP(C10,[1]汇总!$B$6:$T$53,19,0) -> 418279 | X10: =W10-E10 -> 0 | Y10: =V10-H10 -> 14559
C11: 黄智超 | D11: 325000 | E11: 1225176.4 | F11: 234032.3 | H11: =E11-F11+G11 -> 991144.1 | I11: =H11/D11 -> 3.0496742 | J11: 69539 | K11: 0 | L11: =J11-K11 -> 69539 | M11: 0.052 | N11: =L11*M11 -> 3616.028 | O11: =H11-L11 -> 921605.1 | P11: 0.05 | Q11: =O11*P11 -> 46080.255 | R11: =N11+Q11 -> 49696.283 | V11: =VLOOKUP(C11,[1]汇总!$B:$W,22,0) -> 1005022.7 | W11: =VLOOKUP(C11,[1]汇总!$B$6:$T$53,19,0) -> 1208212.3 | X11: =W11-E11 -> -16964.1 | Y11: =V11-H11 -> 13878.6
C12: 小组合计 | D12: =SUM(D4:D11) -> 4485000 | E12: =SUM(E4:E11) -> 6402758.7 | F12: =SUM(F4:F11) -> 1027903.3 | G12: =SUM(G4:G7) -> 15540 | H12: =SUM(H4:H11) -> 5390395.4 | I12: =H12/D12 -> 1.2018719 | N12: =SUM(N4:N11) -> 19313.725 | Q12: =SUM(Q4:Q11) -> 187497.09 | R12: =SUM(R4:R11) -> 206810.82
A16: 排名 | B16: 组别 | C16: 顾问 | D16: 月度数据
D17: 总进账 | E17: 考研转介绍 | F17: 对应提点 | G17: 提点奖金 | H17: 减去转介绍的剩余业绩 | I17: 对应提点 | J17: 提点奖金 | K17: 退费扣除金额 | L17: 考研净奖金
A18: 考研 | C18: 刘晓娟 | D18: 358705.4 | E18: 107294.6 | F18: 0.032 | G18: =E18*F18 -> 3433.4272 | H18: =D18-E18 -> 251410.8 | I18: 0.03 | J18: =H18*I18 -> 7542.324 | K18: 113.4 | L18: =G18+J18-K18 -> 10862.351

Sheet 绩效明细
A1: 四六级 | D1: 资源处理时效（10） | H1: 老带新签约人头（30） | L1: 6月新增资源签约率（60） | P1: 合计得分 | Q1: 发放比例 | R1: 月度绩效标准 | S1: 月绩效应发
A2: 工号 | B2: 顾问 | C2: 备注 | D2: 目标 | E2: 数据 | F2: 完成率 | G2: 得分 | H2: 目标 | I2: 完成 | J2: 完成率 | K2: 得分 | L2: 目标 | M2: 完成情况 | N2: 完成率 | O2: 得分
A3: 004192 | B3: 刘晓娟 | C3: / | D3: 60min | E3: 60.03 | F3: 完成 | G3: 10 | H3: 7 | I3: 16 | J3: =I3/H3 -> 2.2857143 | K3: =30*J3 -> 68.571429 | L3: 0.27 | M3: 0.328 | N3: 1 | O3: 60 | P3: =G3+K3+O3 -> 138.57143 | Q3: 1 | R3: 2000 | S3: =R3*Q3 -> 2000
A4: 590299 | B4: 徐健坤 | C4: / | D4: 60min | E4: 24.26 | F4: 完成 | G4: 10 | H4: 7 | I4: 2 | J4: =I4/H4 -> 0.28571429 | K4: =30*J4 -> 8.5714286 | L4: 0.27 | M4: 0.2727 | N4: 1 | O4: =60*N4 -> 60 | P4: =G4+K4+O4 -> 78.571429 | Q4: 0.79 | R4: 2000 | S4: =R4*Q4 -> 1580
A5: 594606 | B5: 房国超 | C5: / | D5: 60min | E5: 9.5 | F5: 完成 | G5: 10 | H5: 7 | I5: 8 | J5: =I5/H5 -> 1.1428571 | K5: =30*J5 -> 34.285714 | L5: 0.27 | M5: 0.2699 | N5: 1 | O5: =60*N5 -> 60 | P5: =G5+K5+O5 -> 104.28571 | Q5: 1 | R5: 2000 | S5: =R5*Q5 -> 2000
A6: 594605 | B6: 李政 | C6: / | D6: 60min | E6: 无数据 | F6: 完成 | G6: 10 | H6: 7 | I6: 5 | J6: =I6/H6 -> 0.71428571 | K6: =30*J6 -> 21.428571 | L6: 0.27 | M6: 0.202 | N6: 0.444 | O6: =60*N6 -> 26.64 | P6: =G6+K6+O6 -> 58.068571 | Q6: 0 | R6: 2000 | S6: =R6*Q6 -> 0
A7: 608630 | B7: 宋增辉 | C7: 新人第三个月保护期打满 | P7: 100 | Q7: 1 | R7: 2000 | S7: 2000
A8: 608617 | B8: 田一禾 | P8: 100 | Q8: 1 | R8: 2000 | S8: 2000
A9: 608681 | B9: 张博奥 | P9: 100 | Q9: 1 | R9: 2000 | S9: 2000
A10: 343549 | B10: 黄智超 | C10: 新人第二个月保护期打满 | P10: 100 | Q10: 1 | R10: 2000 | S10: 2000

Sheet 7月顾问两周pk赛
B2: 顾问pk赛
B3: 第一周 | C3: 刘晓娟 | D3: 2000
C4: 黄智超 | D4: 1000
C5: 宋增辉 | D5: 500
B6: 第二周 | C6: 房国超 | D6: 2000
C7: 刘晓娟 | D7: 1000
C8: 宋增辉 | D8: 500
C9: 黄智超 | D9: 500
C10: 田一禾 | D10: 500

Sheet 退费数据 四六级
A1: 提交日期 | B1: 您所办理的业务类型 | C1: OA流水号 | D1: 学管姓名 | E1: 学管是否代办 | F1: 顾问姓名 | G1: 顾问是否代办 | H1: 91系统-最新报名二级渠道 | I1: 原班所属项目 | J1: 新报入班级所属项目 | K1: 退费阶段 | L1: 退费一级原因（开课前） | M1: 退费一级原因 (开课后) | N1: 退费二级原因（专业课师资匹配原因） | O1: 退费二级原因（学员意愿转变_开课前） | P1: 退费二级原因（计划冲突_开课前） | Q1: 退费二级原因（中心原因_开课前） | R1: 退费二级原因（签约话术） | S1: 退费二级原因（教师） | T1: 退费二级原因（教学） | U1: 退费二级原因（课程安排） | V1: 退费二级原因（配套服务） | W1: 退费二级原因（配套学习设施） | X1: 退费二级原因（中心原因_开课后） | Y1: 退费二级原因（计划冲突_开课后） | Z1: 退费二级原因（学员意愿转变_开课后） | AA1: 退费三级原因（完全匹配不上）-院校、学院、专业、专业课代码及名称 | AB1: 退费详细原因说明（与OA退费详细说明保持一致） | AC1: 预计报名新班学费金额 | AD1: 转班金额（请学管填写所在班级实际金额） | AE1: 转班详细原因说明 | AF1: 提交时间 | AG1: 学校 | AH1: 学院 | AI1: 年级 | AJ1: 专业 | AK1: 提交人 | AL1: 退费类型 | AM1: 学员姓名 | AN1: 学员编码 | AO1: 退费金额 | AP1: 办理日期-客服 | AQ1: 退费方式-客服 | AR1: 需要跟进的顾问/学管 | AS1: 退费/转班特殊情况备注（若需要学管提供银行卡信息，可将需求填写在此处）-客服 | AT1: 是否完成退费/转班-客服 | AU1: 父记录 | AV1: 父记录 | AW1: 备注
A2: 2025/06/17 | B2: 退费 | C2: 2025061702417 | D2: 刘畅778-刘畅 | F2: 徐健坤 | H2: 学管续费推荐 | I2: 四六级项目（弃用） | K2: 开课后退费 | M2: 计划冲突_开课后 | Y2: 个人生活/工作事务和新东方时间冲突 | AB2: 最后一节课学生上不了了，之前一直从天津跑过来上线下，不考虑线上，也不考虑保留着一节课，后面有需要再报 | AF2: 2025-06-30 | AK2: 刘畅778-刘畅 | AL2: 真实产生的退费 | AM2: 穆德佳 | AN2: BJWY4754614205 | AO2: 1800 | AP2: 2025/07/09 | AQ2: 微信退1800[图片] | AT2: TRUE
A3: 2025/06/24 | B3: 退费 | C3: 2025061500283 | D3: 李润基 | F3: 徐健坤 | H3: 其他（主动） | I3: 四六级项目-VIP | K3: 开课后退费 | M3: 计划冲突_开课后 | Y3: 个人生活/工作事务和新东方时间冲突 | AB3: 学生学校课很多，不能按照规划上课，取消了五节课，37000-850×40=3000 | AF3: 2025-06-30 | AK3: 李润基 | AL3: 真实产生的退费 | AM3: 郑好 | AN3: BJWY5610701694 | AO3: 3000 | AP3: 2025/07/01 | AQ3: 微信退回 | AT3: TRUE
A4: 2025/06/30 | B4: 退费 | C4: 18739969 | D4: 罗志勇1-罗志勇 | F4: 徐健坤 | H4: 新东方PC官网 | I4: 四六级项目（弃用） | K4: 开课前退费 | L4: 计划冲突_开课前 | P4: 学校事务和新东方时间冲突 | AB4: 学生专升本，学校两年内不让考四六级 | AF4: 2025-06-30 | AK4: 罗志勇1-罗志勇 | AL4: 真实产生的退费 | AM4: 王禹尧 | AN4: BJWY2840412022 | AO4: 15500 | AP4: 2025/07/02 | AQ4: 7.2退款成功。银联扫码支付宝退回 | AT4: TRUE
A5: 2025/07/01 | B5: 退费 | C5: 18752114 | D5: 边鑫博 | F5: 刘晓娟 | H5: 客服前台 | I5: 四六级项目（弃用） | J5: 四六级项目 | K5: 开课前退费 | L5: 中心原因_开课前 | Q5: 退出重报（报错班级） | AB5: 退出重报，占座，费用退到学员账户重新入班 | AC5: ¥5680.00 | AF5: 2025-07-01 | AK5: 边鑫博 | AL5: 转项目/转班/退出重报等未产生实际退费 | AM5: 田谨睿 | AN5: BJWY5207562563 | AO5: 5680 | AP5: 2025/07/01 | AQ5: 退至学员账户 | AT5: TRUE
A6: 2025/07/01 | B6: 退费 | C6: 18753067 | D6: 罗志勇1-罗志勇 | F6: 张博奥 | H6: 抖音来客 | I6: 四六级项目（弃用） | K6: 开课前退费 | L6: 学员意愿转变_开课前 | O6: 选择出国留学 | AB6: 高考失利 去学雅思 | AF6: 2025-07-01 | AK6: 罗志勇1-罗志勇 | AL6: 真实产生的退费 | AM6: 齐子昂 | AN6: BJWY3131685015 | AO6: 15500 | AP6: 2025/07/02 | AQ6: 微信退回 | AT6: TRUE
A7: 2025/07/02 | B7: 转班 | D7: 边鑫博 | F7: 刘晓娟 | H7: 大客服呼入 | I7: 四六级项目（弃用） | AE7: 换校区上课 | AF7: 2025-07-02 | AK7: 边鑫博 | AM7: 顾雨涵 | AN7: BJWY6589289284 | AO7: 19300 | AP7: 2025/07/02 | AQ7: 已转班 | AT7: TRUE
A8: 2025/07/02 | B8: 转班 | D8: 边鑫博 | F8: 黄智超 | G8: TRUE | H8: 线上运营推荐 | I8: 四六级项目（弃用） | AE8: 学生觉得四级单词比较简单，想转去六级班去学 原班号：YKF25001，需转至班号：YKS25001。辛苦老师操作 | AF8: 2025-07-02 | AK8: 黄智超1-黄智超 | AM8: 路靖远 | AN8: BJWY9575617816 | AO8: 5434.4 | AP8: 2025/07/02 | AQ8: 已转班 | AT8: TRUE
A9: 2025/07/03 | B9: 退费 | C9: 18762286 | D9: 边鑫博 | F9: 黄智超 | G9: TRUE | H9: 内部员工推荐 | I9: 四六级项目（弃用） | K9: 开课前退费 | L9: 学员意愿转变_开课前 | O9: 认为课程用处不大/不适合自己 | AB9: 学生报名预科小班，把大班课程退出 | AF9: 2025-07-03 | AK9: 黄智超1-黄智超 | AL9: 真实产生的退费 | AM9: 于奥洋 | AN9: BJWY8894097228 | AO9: 5680 | AP9: 2025/07/04 | AQ9: 微信原渠道退回 | AT9: TRUE
A10: 2025/07/04 | B10: 转班 | D10: 罗志勇1-罗志勇 | F10: 徐健坤 | H10: 内部员工推荐 | I10: 四六级项目（弃用） | AE10: 顾问入错班 | AF10: 2025-07-04 | AK10: 罗志勇1-罗志勇 | AM10: 陈晨 | AN10: BJWY2672207145 | AO10: 5680 | AP10: 2025/07/04 | AQ10: 已转班 | AT10: TRUE
A11: 2025/07/04 | B11: 退费 | C11: 18764400 | D11: 边鑫博 | F11: 李政 | H11: 内部员工推荐 | I11: 四六级项目（弃用） | K11: 开课前退费 | L11: 计划冲突_开课前 | P11: 个人生活/工作事务和新东方时间冲突 | AB11: 孩子暑假有夏令营，时间有冲突，不考虑线上课程，其他的时间也不方便上课 | AF11: 2025-07-04 | AK11: 边鑫博 | AL11: 真实产生的退费 | AM11: 王艺霏 | AN11: BJWY6664634220 | AO11: 4880 | AP11: 2025/07/07 | AQ11: 微信退回 | AT11: TRUE
A12: 2025/07/02 | B12: 退费 | C12: 18766840 | D12: 李小龙25-李小龙 | F12: 刘晓娟 | H12: 集团资源 | I12: 四六级项目（弃用） | K12: 开课前退费 | L12: 计划冲突_开课前 | P12: 个人生活/工作事务和新东方时间冲突 | AB12: 家长给孩子报名的新东方的雅思课程，未来想保研或出国，暂时打算先准备雅思。 | AF12: 2025-07-05 | AK12: 李小龙25-李小龙 | AL12: 真实产生的退费 | AM12: 李梓侨 | AN12: BJWY3436505557 | AO12: 6180 | AP12: 2025/07/15 | AQ12: 微信退回 | AT12: TRUE
A13: 2025/07/05 | B13: 转班 | D13: 李小龙25-李小龙 | F13: 刘晓娟 | H13: 新东方官网小程序 | I13: 四六级项目（弃用） | AE13: 7.16的班级时间冲突，需要转入WYS25035 | AF13: 2025-07-05 | AK13: 李小龙25-李小龙 | AM13: 秋清耀 | AN13: BJWY5355250935 | AO13: 6180 | AP13: 2025/07/05 | AQ13: 已转班 | AT13: TRUE
A14: 2025/07/06 | B14: 退费 | C14: 18770460 | D14: 李小龙25-李小龙 | F14: 黄智超 | H14: 小红书 | I14: 四六级项目-班课 | K14: 开课前退费 | L14: 学员意愿转变_开课前 | O14: 家人不支持考研/不支持跟班学习/意见不一致 | AB14: 孩子的情况想玩不想学习，沟通家长联系孩子去说服学习，学生还是执意不学习 | AF14: 2025-07-06 | AK14: 李小龙25-李小龙 | AL14: 真实产生的退费 | AM14: 李梓妍 | AN14: BJWY9542200862 | AO14: 19300 | AP14: 2025/07/26 | AQ14: 原渠道微信退回 | AT14: TRUE
A15: 2025/07/07 | B15: 转班 | D15: 边鑫博 | F15: 黄智超 | G15: TRUE | H15: 小红书 | I15: 四六级项目-班课 | AE15: 学员报名四级小班，8.1号开课（花园桥校区），现在想转到6级班课（花园桥校区），价格一样，课程编码不同，需要从YKF25005操作转班至YKS25005～ | AF15: 2025-07-07 | AK15: 黄智超1-黄智超 | AM15: 许博铭 | AN15: BJWY4996201639 | AO15: 20300 | AP15: 2025/07/08 | AQ15: 已转班 | AT15: TRUE
A16: 2025/07/08 | B16: 转班 | D16: 李小龙25-李小龙 | F16: 刘晓娟 | H16: 学管转介绍 | I16: 四六级项目-班课 | AE16: 想学六级课 | AF16: 2025-07-08 | AK16: 李小龙25-李小龙 | AM16: 张嘉懿 | AN16: BJWY7254640234 | AO16: 19100 | AP16: 2025/07/08 | AQ16: 已转班 | AT16: TRUE
A17: 2025/07/08 | B17: 退费 | C17: 18769348 | D17: 罗志勇1-罗志勇 | F17: 房国超 | G17: TRUE | H17: 顾问转介绍-老带新 | I17: 四六级项目-班课 | K17: 开课前退费 | L17: 学员意愿转变_开课前 | O17: 家人不支持考研/不支持跟班学习/意见不一致 | AB17: 报名时是家长先占上了课程优惠， 后续和孩子沟通，学生不想学习，家长反复劝说无果，学生不学，转班不考虑，家长无奈选择退费 | AF17: 2025-07-08 | AK17: 房国超 | AL17: 真实产生的退费 | AM17: 邹先御 | AN17: BJWY7373402810 | AO17: 15300 | AP17: 2025/07/09 | AQ17: 微信退15300[图片] | AT17: TRUE
A18: 2025/07/08 | B18: 转班 | D18: 边鑫博 | F18: 黄智超 | G18: TRUE | H18: 大客服呼入 | I18: 四六级项目-班课 | AE18: 学员报名六级和高数课程 目前想把高数转成口语，价格一样 辛苦老师操作 原班级编码：YKM25001；需转至：YK25002 辛苦老师操作。 | AF18: 2025-07-08 | AK18: 黄智超1-黄智超 | AM18: 张馨予 | AN18: BJWY8390237928 | AO18: 3725.6 | AP18: 2025/07/08 | AQ18: 已转班 | AT18: TRUE
A19: 2025/07/09 | B19: 退费 | C19: 18776707 | D19: 边鑫博 | F19: 刘晓娟 | H19: 京内毛坯数据 | I19: 四六级项目-班课 | K19: 开课前退费 | L19: 计划冲突_开课前 | P19: 个人生活/工作事务和新东方时间冲突 | AB19: 由于时间问题想先取消一下课，说明年报，保留课程拒绝 | AF19: 2025-07-09 | AK19: 边鑫博 | AL19: 真实产生的退费 | AM19: 刘昊阳 | AN19: BJWY5526467904 | AO19: 19300 | AP19: 2025/07/09 | AQ19: 微信退19300[图片] | AT19: TRUE
A20: 2025/07/09 | B20: 退费 | C20: 18776823 | D20: 边鑫博 | F20: 徐健坤 | H20: 顾问转介绍-老带新 | I20: 四六级项目-班课 | J20: 四六级项目 | K20: 开课前退费 | L20: 计划冲突_开课前 | P20: 个人生活/工作事务和新东方时间冲突 | AB20: 由于时间原因转班，退费后重新报名 | AC20: ¥6480.00 | AF20: 2025-07-09 | AK20: 边鑫博 | AL20: 转项目/转班/退出重报等未产生实际退费 | AM20: 王文涵 | AN20: XDF1928799125 | AO20: 19100 | AP20: 2025/07/11 | AQ20: 退回学员账户余额 | AT20: TRUE
F21: 刘晓娟 | I21: 四六级项目-班课 | AM21: 陈松乔 | AO21: 4402.8 | AP21: 2025/07/12 | AW21: 补加
A22: 2025/07/09 | B22: 退费 | C22: 18776843 | D22: 边鑫博 | F22: 徐健坤 | H22: 大众点评 | I22: 四六级项目-班课 | J22: 四六级项目 | K22: 开课前退费 | L22: 计划冲突_开课前 | P22: 个人生活/工作事务和新东方时间冲突 | AB22: 由于时间原因转班，退费后重新报名 | AC22: ¥6480.00 | AF22: 2025-07-09 | AK22: 边鑫博 | AL22: 转项目/转班/退出重报等未产生实际退费 | AM22: 刘东熠 | AN22: BJWY0362994456 | AO22: 19300 | AP22: 2025/07/11 | AQ22: 退回学员账户余额 | AT22: TRUE
A23: 2025/07/09 | B23: 退费 | C23: 18778970 | D23: 罗志勇1-罗志勇 | F23: 房国超 | H23: 顾问转介绍-老带新 | I23: 四六级项目-班课 | K23: 开课前退费 | L23: 计划冲突_开课前 | P23: 个人生活/工作事务和新东方时间冲突 | AB23: 学习意愿低 不考了 要去实习 | AF23: 2025-07-09 | AK23: 罗志勇1-罗志勇 | AL23: 真实产生的退费 | AM23: 杜梦琪 | AN23: BJWY5148939979 | AO23: 5680 | AP23: 2025/07/23 | AQ23: 支付宝退回 | AT23: TRUE
A24: 2025/07/09 | B24: 退费 | C24: 18776785 | D24: 罗志勇1-罗志勇 | F24: 刘晓娟 | H24: 新东方PC官网 | I24: 四六级项目-班课 | K24: 开课前退费 | L24: 计划冲突_开课前 | P24: 个人生活/工作事务和新东方时间冲突 | AB24: 暑假去学习雅思了 时间冲突 拒绝转班 | AF24: 2025-07-09 | AK24: 罗志勇1-罗志勇 | AL24: 真实产生的退费 | AM24: 李伊然 | AN24: BJWY6831352125 | AO24: 15000 | AP24: 2025/07/15 | AQ24: 7.23已完成付款 7.22用户短信未确认，已重新发送 7.16已转手工，待客户短信确认@罗志勇1 (罗志勇)—————— 暂退学生账户，原渠道为汇款，需提供原卡6235735000000768596的银行卡详细信息转手工退@罗志勇1 (罗志勇)[图片] | AT24: TRUE
A25: 2025/07/09 | B25: 退费 | C25: 18779247 | D25: 罗志勇1-罗志勇 | F25: 李政 | H25: 新东方官网APP | I25: 四六级项目-班课 | J25: 四六级项目 | K25: 开课前退费 | L25: 计划冲突_开课前 | P25: 个人生活/工作事务和新东方时间冲突 | AB25: 学生去学雅思 以及要转入线下的数学班课 | AC25: ¥4000.00 | AF25: 2025-07-09 | AK25: 罗志勇1-罗志勇 | AL25: 转项目/转班/退出重报等未产生实际退费 | AM25: 黄乐容 | AN25: BJWY9725876002 | AO25: 15000 | AP25: 2025/07/11 | AQ25: 退回学员账户余额 | AT25: TRUE
A26: 2025/07/10 | B26: 转班 | D26: 边鑫博 | F26: 黄智超 | G26: TRUE | H26: 大客服呼入 | I26: 四六级项目-班课 | AE26: 老师好 学员报名花园桥二期班：需操作转班，班号YKS25002，之前这个班未开放报名 | AF26: 2025-07-10 | AK26: 黄智超1-黄智超 | AM26: 张馨予 | AN26: BJWY8390237928 | AO26: 5434.4 | AP26: 2025/07/10 | AQ26: 已转班 | AT26: TRUE
A27: 2025/07/10 | B27: 转班 | D27: 边鑫博 | F27: 黄智超 | G27: TRUE | H27: 公众号 | I27: 四六级项目-班课 | AE27: 由于预科四级二班名额之前未开放，临近开课需将预科四级一班转至预科四级二班，价格一致，原班级编码：YKF25001；需转至：YKF25002 | AF27: 2025-07-10 | AK27: 黄智超1-黄智超 | AM27: 梁睿男 | AN27: BJWY7658289293 | AO27: 5434.4 | AP27: 2025/07/11 | AQ27: 已转班 | AT27: TRUE
A28: 2025/07/10 | B28: 转班 | D28: 余平瑶 | F28: 黄智超 | H28: 内部员工推荐 | I28: 四六级项目-班课 | AE28: 改学四级 | AF28: 2025-07-10 | AK28: 余平瑶 | AM28: 黄洋 | AN28: BJWY1884260416 | AO28: 5680 | AP28: 2025/07/11 | AQ28: 已转班 | AT28: TRUE
A29: 2025/07/11 | B29: 转班 | D29: 李玉迪1-李玉迪 | F29: 徐健坤 | H29: 小红书 | I29: 四六级项目-班课 | AE29: 学员转到第二期班上课 | AF29: 2025-07-11 | AK29: 李玉迪1-李玉迪 | AM29: 李宇萱 | AN29: BJWY7288551134 | AO29: 9160 | AP29: 2025/07/11 | AQ29: 已转班 | AT29: TRUE
A30: 2025/07/11 | B30: 转班 | D30: 李玉迪1-李玉迪 | F30: 徐健坤 | H30: 新东方官网小程序 | I30: 四六级项目-班课 | AE30: 学员时间安排转回第一期课上班，加数学课，为了时间不冲突需要搭配第一套英语课 | AF30: 2025-07-11 | AK30: 李玉迪1-李玉迪 | AM30: 高靖淇 | AN30: BJWY8253848251 | AO30: 5180 | AP30: 2025/07/11 | AQ30: 已转班 | AT30: TRUE
A31: 2025/07/11 | B31: 转班 | D31: 李玉迪1-李玉迪 | F31: 徐健坤 | H31: 内部员工推荐 | I31: 四六级项目-班课 | AE31: 学员时间安排需要转到第二套班上课 | AF31: 2025-07-11 | AK31: 李玉迪1-李玉迪 | AM31: 王韵嘉 | AN31: BJWY3569894740 | AO31: 5180 | AP31: 2025/07/11 | AQ31: 已转班 | AT31: TRUE
A32: 2025/07/11 | B32: 转班 | D32: 李玉迪1-李玉迪 | F32: 田一禾 | H32: 公众号 | I32: 四六级项目-班课 | AE32: 学生基础较好，从四级班转到六级上课 | AF32: 2025-07-11 | AK32: 李玉迪1-李玉迪 | AM32: 王洛欢 | AN32: BJWY7022979955 | AO32: 4880 | AP32: 2025/07/11 | AQ32: 已转班 | AT32: TRUE
A33: 2025/07/11 | B33: 转班 | D33: 边鑫博 | F33: 黄智超 | G33: TRUE | H33: 顾问转介绍-老带新 | I33: 四六级项目-班课 | AE33: 学员跟二期班，报名时二期班未开放名额，需要操作转班，转至班号YKS25002 | AF33: 2025-07-11 | AK33: 黄智超1-黄智超 | AM33: 郑初妍 | AN33: BJWY5518228982 | AO33: 5434.4 | AP33: 2025/07/11 | AQ33: 已转班 | AT33: TRUE
A34: 2025/07/11 | B34: 转班 | D34: 李玉迪1-李玉迪 | F34: 徐健坤 | H34: TMK合作 | I34: 四六级项目-班课 | AE34: 时间不合适 需要更换到YKF25002 | AF34: 2025-07-11 | AK34: 徐健坤1-徐健坤 | AM34: 李左文 | AN34: BJWY4028539388 | AO34: 5180 | AP34: 2025/07/12 | AQ34: 已转班 | AT34: TRUE
A35: 2025/07/11 | B35: 转班 | D35: 边鑫博 | F35: 黄智超 | G35: TRUE | H35: 顾问转介绍-老带新 | I35: 四六级项目-班课 | AE35: 家长需求将四级线下课，转为四级线上直播课 原班号：YKS25001，需转至YKSJ25001 | AF35: 2025-07-11 | AK35: 黄智超1-黄智超 | AM35: 王祎 | AN35: BJWY1508600205 | AO35: 5434.4 | AP35: 2025/07/12 | AQ35: 已转班 | AT35: TRUE
A36: 2025/07/12 | B36: 转班 | D36: 边鑫博 | F36: 徐健坤 | H36: 社群、虚拟人 | I36: 四六级项目-班课 | AE36: 时间冲突，都上不了课 | AF36: 2025-07-12 | AK36: 边鑫博 | AM36: 王美琪 | AN36: BJWY6250044765 | AO36: 4880 | AP36: 2025/07/12 | AQ36: 已转班 | AT36: TRUE
A37: 2025/07/13 | B37: 转班 | D37: 李小龙25-李小龙 | F37: 刘晓娟 | H37: 直访 | I37: 四六级项目-班课 | AE37: 没报上6月的考试，先转暑假班，等秋季班安排出来，插班转秋季班 | AF37: 2025-07-13 | AK37: 李小龙25-李小龙 | AM37: 吴丰恺 | AN37: BJWY3487591469 | AO37: 4314.7 | AP37: 2025/07/13 | AQ37: 已转班 | AT37: TRUE
A38: 2025/07/13 | B38: 退费 | C38: 18788911 | D38: 李小龙25-李小龙 | F38: 刘晓娟 | H38: 公众号 | I38: 四六级项目-班课 | K38: 开课前退费 | L38: 计划冲突_开课前 | P38: 个人生活/工作事务和新东方时间冲突 | AB38: 孩子选择复读，家长报名了高考暑期班，时间冲突 | AF38: 2025-07-13 | AG38: 北京市第一五六中学 | AH38: 询问院系未告知 | AI38: 高三 | AJ38: 询问院系未告知 | AK38: 李小龙25-李小龙 | AL38: 真实产生的退费 | AM38: 熊晟源 | AN38: BJWY2545661711 | AO38: 0 | AP38: 2025/07/15 | AQ38: 7.22已退款[图片] 300微信退回，19000转手工，退款中（7.19）———————— 暂退学生账户，原渠道为现金，需提供学生本人姓名的银行卡信息转手工退@李小龙25 (李小龙)[图片] | AT38: TRUE | AW38: 不算：19300
A39: 2025/07/13 | B39: 退费 | C39: 18789074 | D39: 李小龙25-李小龙 | F39: 宋增辉 | H39: 91搜课网 | I39: 四六级项目-班课 | K39: 开课前退费 | L39: 计划冲突_开课前 | P39: 个人生活/工作事务和新东方时间冲突 | AB39: 家长给孩子报名了其他机构的雅思，由于时间过早无法延期，和孩子商量后打算先去学雅思，等后面考六级前在报名 | AF39: 2025-07-13 | AG39: 中央民族大学 | AH39: 信息工程学院 | AI39: 大二 | AJ39: 电子信息工程 | AK39: 李小龙25-李小龙 | AL39: 真实产生的退费 | AM39: 虎葆霖 | AN39: BJWY9727135037 | AO39: 6180 | AP39: 2025/07/26 | AQ39: 原渠道微信退回 | AT39: TRUE
A40: 2025/07/13 | B40: 转班 | D40: 李玉迪1-李玉迪 | F40: 房国超 | G40: TRUE | H40: 内部员工推荐 | I40: 四六级项目-班课 | AE40: 用户先报的四级小班YKF25006，YKF25006未开课，家长感觉四级对孩子简单些，申请转班到六级小班YKS25004， | AF40: 2025-07-13 | AK40: 房国超 | AM40: 王彦均 | AN40: BJWY8590362294 | AO40: 19500 | AP40: 2025/07/13 | AQ40: 已转班 | AT40: TRUE
...

Sheet 四六级退费-数据透视
A1: 顾问姓名 | B1: 求和项:退费金额
A2: 房国超 | B2: 86550.8
A3: 黄智超 | B3: 234032.3
A4: 刘晓娟 | B4: 192383.4
A5: 宋增辉 | B5: 156062.2
A6: 田一禾 | B6: 42550.5
A7: 张博奥 | B7: 36239

Sheet 考研业绩退费
A1: 提交日期 | B1: 您所办理的业务类型 | C1: OA流水号 | D1: 学管姓名 | E1: 学管是否代办 | F1: 顾问姓名 | G1: 顾问是否代办 | H1: 91系统-最新报名二级渠道 | I1: 原班所属项目 | J1: 新报入班级所属项目 | K1: 退费阶段 | L1: 退费一级原因（开课前） | M1: 退费一级原因 (开课后) | N1: 退费二级原因（专业课师资匹配原因） | O1: 退费二级原因（学员意愿转变_开课后） | P1: 退费三级原因（完全匹配不上）-院校、学院、专业、专业课代码及名称 | Q1: 退费详细原因说明（与OA退费详细说明保持一致） | R1: 预计报名新班学费金额 | S1: 转班金额（请学管填写所在班级实际金额） | T1: 转班详细原因说明 | U1: 提交时间 | V1: 学校 | W1: 学院 | X1: 年级 | Y1: 专业 | Z1: 提交人 | AA1: 退费类型 | AB1: 学员姓名 | AC1: 学员编码 | AD1: 退费金额 | AE1: 办理日期-客服 | AF1: 退费方式-客服 | AG1: 需要跟进的顾问/学管 | AH1: 退费/转班特殊情况备注（若需要学管提供银行卡信息，可将需求填写在此处）-客服 | AI1: 是否完成退费/转班-客服 | AJ1: 父记录 | AK1: 父记录
A2: 2025/07/06 | B2: 转班 | D2: 黄子琪3-黄子琪 | F2: 刘晓娟 | H2: 内部员工推荐 | I2: 无忧项目-班课 | S2: 1573.8 | T2: 从WYHE26005转WYHE26006 转班原因：学生专业变动英语一变英语二 | U2: 2025-07-06 | Z2: 黄子琪3-黄子琪 | AB2: 车子越 | AC2: BJWY2366756820 | AE2: 2025/07/06 | AF2: 已转班 | AI2: TRUE
A3: 2025/07/10 | B3: 退费 | C3: 2025071002653 | D3: 陈晶171-陈晶 | F3: 刘晓娟 | H3: 学管续费推荐 | I3: VIP项目-VIP | K3: 开课后退费 | M3: 学员意愿转变_开课后 | O3: 认为课程用处不大/不适合自己 | Q3: 学员是24考研鱼柳了课时，去年没有上课，现在已经考上研究生，不需要辅导其他内容，剩余的要办理退费 | U3: 2025-07-15 | V3: 北京化工大学 | W3: 信息学院 | X3: 大四 | Y3: 计算机 | Z3: 陈晶171-陈晶 | AA3: 真实产生的退费 | AB3: 李泽善 | AC3: BJWY9389688874 | AD3: 6300 | AE3: 2025/07/17 | AF3: 7.23已完成付款 7.22用户短信已确认，退款中@陈晶171 (陈晶) 7.21转手工退6300，待客户短信确认————@陈晶171 (陈晶) 暂退学员账户，原渠道失效，提供本人银行卡信息7.18@陈晶171 (陈晶) [图片] | AI3: TRUE
A4: 2025/07/15 | B4: 转班 | D4: 黄子琪3-黄子琪 | F4: 田一禾3-田一禾 | H4: 新东方PC官网 | I4: 无忧项目-班课 | S4: 9333.4 | T4: 姓名：梁好 学员号： BJWY4821923897 转班信息如下： WYFE26017转WYFE26019 WYFE26018转WYFE26020 转班原因：英语一转英二 已登记表格，辛苦老师办理@北京中心客服组 | U4: 2025-07-15 | Z4: 黄子琪3-黄子琪 | AB4: 梁好 | AC4: BJWY4821923897 | AE4: 2025/07/15 | AF4: 已转班 | AI4: TRUE
G8: 考研一对一续费时间 | H8: 当月提点 | M8: 扣费金额
G9: 45221 | H9: 0.018 | I9: 李泽善 | J9: 刘晓娟 | K9: 6300 | L9: ✅ | M9: =H9*K9 -> 113.4
I14: 另外两笔转班，不算进账，不算退费

Sheet 考研业绩进账
A1: 签约学生姓名 | B1: 签约单录入人 | C1: 班级名称 | D1: 报名产品 | E1: 学费 | F1: 备注
A2: 陈松乔 | B2: 刘晓娟 | C2: 考研英语无忧计划（27考研/基础） | D2: 无忧计划-啄木鸟,考研专业课300,六级无忧计划 | F2: 作废 | G2: 31.8
A3: 陈松乔 | B3: 刘晓娟 | C3: 考研数学无忧计划（27考研/冲刺） | D3: 无忧计划-啄木鸟,考研专业课300,六级无忧计划 | F3: 作废 | G3: 35.8
A4: 陈松乔 | B4: 刘晓娟 | C4: 考研数学无忧计划（27考研/基础） | D4: 无忧计划-啄木鸟,考研专业课300,六级无忧计划 | F4: 作废 | G4: 28.8
A5: 陈松乔 | B5: 刘晓娟 | C5: 考研英语无忧计划（27考研/英一冲刺） | D5: 无忧计划-啄木鸟,考研专业课300,六级无忧计划 | F5: 作废 | G5: 34.8
A6: 陈松乔 | B6: 刘晓娟 | C6: 考研政治无忧计划（27考研/强化） | D6: 无忧计划-啄木鸟,考研专业课300,六级无忧计划 | F6: 作废 | G6: 23.9
A7: 陈松乔 | B7: 刘晓娟 | C7: 考研政治无忧计划（27考研/冲刺） | D7: 无忧计划-啄木鸟,考研专业课300,六级无忧计划 | F7: 作废 | G7: 28.4
A8: 陈松乔 | B8: 刘晓娟 | C8: 考研英语无忧计划（27考研/英一强化） | D8: 无忧计划-啄木鸟,考研专业课300,六级无忧计划 | F8: 作废 | G8: 41.8
A9: 陈松乔 | B9: 刘晓娟 | C9: 考研政治无忧计划（27考研/基础） | D9: 无忧计划-啄木鸟,考研专业课300,六级无忧计划 | F9: 作废 | G9: 41.2
A10: 陈松乔 | B10: 刘晓娟 | C10: 考研数学无忧计划（27考研/强化） | D10: 无忧计划-啄木鸟,考研专业课300,六级无忧计划 | F10: 作废 | G10: 43.7
A11: 王远航8 | B11: 刘晓娟 | C11: 考研规划热线 | E11: 399
A12: 魏天奇 | B12: 刘晓娟 | C12: 2027考研政治直通车 长线2期,2027考研数学直通车 长线2期,2027考研英语直通车 长线2期 | D12: 线上直通车,考研专业课150 | E12: 11902.8
A13: 魏天奇 | B13: 刘晓娟 | C13: 2027考研专业课定制一对一（30h）-A班 | D13: 线上直通车,考研专业课150 | E13: 11900
A14: 马玄轶 | B14: 刘晓娟 | C14: 2026考研英语全程班 6班 | D14: 线上全程班 | E14: 1096.5
A15: 陈松乔 | B15: 刘晓娟 | C15: 考研英语无忧计划（27考研/基础） | D15: 无忧计划-啄木鸟,考研专业课300,六级无忧计划 | F15: 作废 | G15: 2174.2
A16: 曲俊昊 | B16: 刘晓娟 | C16: 26考研英语全程集训营（寒暑） | D16: 考研专业课150,寒暑假集训营（春秋OMO） | F16: 作废 | G16: 7019.5 | H16: 转班不算业绩
A17: 曲俊昊 | B17: 刘晓娟 | C17: 26考研政治全程集训营（寒暑） | D17: 考研专业课150,寒暑假集训营（春秋OMO） | F17: 作废 | G17: 12229.9
A18: 曲俊昊 | B18: 刘晓娟 | C18: 26考研政治全程集训营（寒暑） | D18: 考研专业课150,寒暑假集训营（春秋OMO） | F18: 作废 | G18: 12229.9
A19: 曲俊昊 | B19: 刘晓娟 | C19: 26考研英语全程集训营（寒暑） | D19: 考研专业课150,寒暑假集训营（春秋OMO） | F19: 作废 | G19: 7019.5
A20: 李秋熠 | B20: 刘晓娟 | C20: 考研数学无忧计划（27考研/强化） | D20: 无忧计划-啄木鸟 | E20: 8800
A21: 李秋熠 | B21: 刘晓娟 | C21: 考研数学无忧计划（27考研/基础） | D21: 无忧计划-啄木鸟 | E21: 5800
A22: 李秋熠 | B22: 刘晓娟 | C22: 考研数学无忧计划（27考研/冲刺） | D22: 无忧计划-啄木鸟 | E22: 6700
A23: 李昱志 | B23: 刘晓娟 | C23: 27考研大二集训营（住宿费） | D23: 暑假集训营 | E23: 2720
A24: 李昱志 | B24: 刘晓娟 | C24: 27考研英语大二集训营 | D24: 暑假集训营 | E24: 12040
A25: 李昱志 | B25: 刘晓娟 | C25: 27考研数学大二集训营 | D25: 暑假集训营 | E25: 11540
A26: 郁名栋 | B26: 刘晓娟 | C26: 考研初试专业课一对一（26考研/30小时） | D26: 考研专业课300 | E26: 18300
A27: 陈静 | B27: 刘晓娟 | C27: 27考研一对一伴学（定制） | D27: VIP - 伴学 | E27: 11500
A28: 顾逸闻 | B28: 刘晓娟 | C28: 考研英语无忧计划候鸟（27考研/英二冲刺） | D28: 考研专业课150,无忧计划-候鸟,VIP - 伴学 | E28: 721.5
A29: 顾逸闻 | B29: 刘晓娟 | C29: 考研英语无忧计划候鸟（27考研/基础强化） | D29: 考研专业课150,无忧计划-候鸟,VIP - 伴学 | E29: 4978.5
A30: 顾逸闻 | B30: 刘晓娟 | C30: 考研政治无忧计划候鸟（27考研/基础强化） | D30: 考研专业课150,无忧计划-候鸟,VIP - 伴学 | E30: 4978.5
A31: 顾逸闻 | B31: 刘晓娟 | C31: 考研政治无忧计划候鸟（27考研/冲刺） | D31: 考研专业课150,无忧计划-候鸟,VIP - 伴学 | E31: 471.5
... A55: 李宇 | B55: 刘晓娟 | C55: 考研分单 | D55: 半年集训营 | E55: 33012.5

Sheet 考研业绩进账-数据透视
A1: 签约单录入人 | B1: 求和项:学费
A2: 黄智超
A3: 刘晓娟 | B3: 358705.4
A4: 田一禾 | B4: 0
A5: (空白)
A6: 总计 | B6: 358705.4

Sheet 四六级业绩进账
A1: 序号 | B1: 学校 | C1: 部门 | D1: 资源姓名 | E1: 资源ID | F1: 资源录入人 | G1: 资源录入时间 | H1: 资源描述 | I1: 市场活动 | J1: 资源年级 | K1: 分配顾问/TMK | L1: 一级获取渠道 | M1: 二级获取渠道 | N1: 转介绍人 | O1: TMK激活人 | P1: TMK激活处理时间 | Q1: 工单姓名 | R1: 跟进顾问 | S1: 工单ID | T1: 工单类型 | U1: 工单录入时间 | V1: 工单等级 | W1: 咨询课程 | X1: 工单年级 | Y1: 学校 | Z1: 院系 | AA1: 专业 | AB1: 签约学生姓名 | AC1: 签约单ID | AD1: 签约单录入人 | AE1: 签约单录入时间 | AF1: 签约单更新人 | AG1: 签约单更新时间 | AH1: 班号 | AI1: 班级名称 | AJ1: 面询表类型 | AK1: 订金 | AL1: 学费 | AM1: 续费类型 | AN1: 推荐人 | AO1: 类型 | AP1: 是否交接 | AQ1: 操作人编号 | AR1: 学员号 | AS1: 听课证号 | AT1: 报班日期 | AU1: 学员状态 | AV1: 回访记录 | AW1: 新老生类型 | AX1: 退费金额 | AY1: 退费日期 | AZ1: 课程类型 | BA1: 客户ID | BB1: 是否新东方在线签约 | BC1: 考季 | BD1: 报名产品 | BE1: 报名科目 | BF1: 意向报考专业 | BG1: 学校班型/类型 | BH1: 是否关联协议 | BI1: 特殊备注 | BJ1: 产品品类 | BK1: 业务类型 | BL1: 签约列表在线学员ID | BM1: 大学生源类型 | BN1: 资源来源 | BO1: 备注
A2: 10 | B2: 北京大学部 | C2: 国内大学部 | E2: 115875126 | G2: 2025-06-23 19:04:25 | H2: 死单激活流转黄智超；薛小刚+运营管理部+304901+xuexiaogang@xdf.cn（TMK主管分配TMK） 外呼主题：FY25-国内6月死单回访（6.9-6.15） | J2: 大三 | K2: 刘晓娟 | L2: 毛坯数据 | M2: 毛坯数据 | Q2: 陈松乔 | R2: 刘晓娟 | S2: 29045634 | T2: 续费工单 | U2: 2025-07-12 12:10 | V2: A（六个月内有报课意向工单） | W2: 六级,考研专业课,考研无忧计划 | X2: 大三 | Y2: 北京语言大学 | Z2: 信息科学学院 | AA2: 计算机科学与技术 | AB2: 陈松乔 | AC2: 5412571 | AD2: 刘晓娟 | AE2: 2025-07-12 12:11 | AF2: 刘晓娟 | AG2: 2025-07-12 12:11 | AH2: WYSJ25033 | AI2: 六级无忧计划 | AJ2: 国内考试 | AL2: 4402.8 | AM2: 同科续费 | AO2: 续班 | AP2: 已交接 | AQ2: BJWY22035556hl | AR2: BJWY0772435935 | AS2: WYSJ250330065 | AT2: 2025-07-12 | AV2: 回访人：刘晓娟，回访时间：2025-07-12 12:10，回访内容：转班；|回访人：刘晓娟，回访时间：2025-07-12 12:11，回访内容：转班 | BA2: 43431754 | BB2: 否 | BC2: 27考季 | BD2: 无忧计划-啄木鸟,考研专业课300,六级无忧计划 | BE2: 计算机,英语,政治,数学 | BG2: 国内高校-双非 | BH2: 是 | BK2: 转出 | BM2: 本地人本地大学(常规)
A3: 11 | B3: 北京大学部 | C3: 国内大学部 | D3: 锦伊 | E3: 120656775 | F3: 程远 | G3: 2025-07-24 18:46:40 | H3: 谷婷婷+gutingting7@xdf.cn+ID+谷婷婷7(新东方教育科技集团有限公司-产业机构-前途出国-前途欧亚事业部-北京中心-语培业务部-销售部-咨询一组 | 语培顾问主管)，刘晓娟； | J3: 大二 | K3: 刘晓娟 | L3: 转介绍 | M3: 内部员工推荐 | N3: 谷婷婷+gutingting7@xdf.cn+ID+谷婷婷7(新东方教育科技集团有限公司-产业机构-前途出国-前途欧亚事业部-北京中心-语培业务部-销售部-咨询一组 | 语培顾问主管) | Q3: 张锦伊 | R3: 刘晓娟 | S3: 29295848 | T3: 正常工单 | U3: 2025-07-24 19:08 | V3: A（六个月内有报课意向工单） | W3: 专四 | X3: 大二 | Y3: 北京第二外国语学院 | Z3: 英语学院 | AA3: 英语 | AB3: 张锦伊 | AC3: 5520476 | AD3: 刘晓娟 | AE3: 2025-07-24 19:08 | AF3: 刘晓娟 | AG3: 2025-07-24 19:09 | AH3: 66275033475 | AI3: 2026英语专业四级全程班【直播 + 录播】 | AJ3: 国内考试 | AL3: 1529.15 | AN3: 谷婷婷+gutingting7@xdf.cn+ID+谷婷婷7(新东方教育科技集团有限公司-产业机构-前途出国-前途欧亚事业部-北京中心-语培业务部-销售部-咨询一组 | 语培顾问主管) | AO3: 新签 | AP3: 无须交接 | AT3: 2025-07-24 | AV3: 回访人：刘晓娟，回访时间：2025-07-24 19:08，回访内容：报名 | AZ3: 长期班 | BA3: 56558941 | BB3: 是 | BG3: 国内高校-C9 | BH3: 否 | BL3: 82855942 | BM3: 本地人本地大学(常规) | BN3: 客服
A4: 12 | B4: 北京大学部 | C4: 国内大学部 | E4: 117158030 | G4: 2025-07-02 14:13:36 | J4: 大二 | K4: 黄智超 | L4: 转介绍 | M4: 内部员工推荐 | Q4: 于奥洋 | R4: 黄智超 | S4: 29202795 | T4: 续费工单 | U4: 2025-07-18 22:47 | V4: A（六个月内有报课意向工单） | W4: 六级,大学预科 | X4: 大一 | Y4: 深圳大学 | Z4: 经济学院 | AA4: 经济学 | AB4: 于奥洋 | AC4: 5484575 | AD4: 黄智超 | AE4: 2025-07-18 22:47 | AF4: 黄智超 | AG4: 2025-08-03 12:20 | AH4: WYS25039 | AI4: 六级精英计划 | AJ4: 国内考试 | AL4: 20300 | AM4: 同科续费 | AN4: 高晶+gaojing43@xdf.cn+312057+培训学校-北京学校-高中一对一部-西南区-玉泉路分中心 | AO4: 续班 | AP4: 已交接 | AQ4: BJWY24032w1g8X | AR4: BJWY8894097228 | AS4: WYS250390005 | AT4: 2025-07-24 | AV4: 回访人：黄智超，回访时间：2025-07-18 22:47，回访内容：转班；|回访人：黄智超，回访时间：2025-07-18 22:47，回访内容：转班；|回访人：黄智超，回访时间：2025-07-23 22:27，回访内容：联系家长 添加学管老师微信 及时同步课程 | BA4: 56143849 | BB4: 否 | BC4: 25下考季 | BD4: 六级无忧计划 | BG4: 国内高校-双非 | BH4: 否 | BK4: 转出 | BM4: 本地人本地大学(常规)
A5: 13 | B5: 北京大学部 | C5: 国内大学部 | E5: 119941935 | G5: 2025-07-20 20:17:42 | H5: 准大一新生，家长咨询四级线下走读课程，离知春路校区比较近，让微信发送课程介绍，手机号即微信号；AI-37815-01a 2025-07-20 19:58:02_x000D_ 您好同学，欢迎访问新东方考研官网，【新东方考研】全新升级，课程灵活多样，【考研全年集训营】【考研半年集训营】【考研冲刺营】【线下走读班】【考研一对一】【在职考研】【四六级】火热报名中 ，现在报名更有高达3000元优惠！_x000D_ _x000D_ AI-37815-01a 2025-07-20 19:58:04_x000D_ 您是想咨询【考研走读班】【考研集训营】【考研规划】还是【在职考研】呢？_x000D_ _x000D_ 01000000037815301266328043346910 2025-07-20 19:58:42_x000D_ 新大一，四级英语课，上几次？价位？_x000D_ _x000D_ AI-37815-01a 2025-07-20 19:58:46_x000D_ 我们拥有多种授课模式，不同的学习内容价格是存在差异的，您可以留下您的姓名电话，我们会安排老师第一时间为您回电_x000D_ _x000D_ _x000D_ 01000000037815301266328043346910 2025-07-20 19:59:01_x000D_ 13552696321_x000D_ _x000D_ AI-37815-01a 2025-07-20 19:59:04_x000D_ 好的，确认一下你的号码是否正确呢~_x000D_ _x000D_ 外呼主题：2026财年第2财月百度投放新东方官网小程序 | I5: 2026财年第2财月百度投放新东方官网小程序 | J5: 大一 | K5: 田一禾 | L5: 新东方官网 | M5: 新东方官网小程序 | Q5: 陈兆骞 | R5: 田一禾 | S5: 29475921 | T5: 续费工单 | U5: 2025-08-03 11:33 | V5: A（六个月内有报课意向工单） | W5: 四级,大学预科 | X5: 大一 | Y5: 首都师范大学 | Z5: 化学系 | AA5: 化学 | AB5: 陈兆骞 | AC5: 5530644 | AD5: 田一禾 | AE5: 2025-08-03 11:36 | AF5: 田一禾 | AG5: 2025-08-03 11:37 | AH5: YKS25002 | AI5: 六级无忧计划（新大一专属） | AJ5: 国内考试 | AL5: 5680 | AM5: 同科续费 | AO5: 续班 | AP5: 已交接 | AQ5: BJWY2011wXCx1W | AR5: BJWY3877559849 | AS5: YKS250020038 | AT5: 2025-07-22 | AV5: 回访人：田一禾，回访时间：2025-08-03 11:33，回访内容：转班；|回访人：田一禾，回访时间：2025-08-03 11:36，回访内容：转班操作 | BA5: 82060903 | BB5: 否 | BC5: 25下考季 | BD5: 四级线上网课 | BG5: 国内高校-双一流(非985/211) | BH5: 是 | BK5: 转出 | BM5: 本地人本地大学(常规)
A6: 16 | B6: 北京大学部 | C6: 国内大学部 | D6: 张婧辰 | E6: 119666526 | F6: 王天义 | G6: 2025-07-18 14:48:24 | H6: 续费原因：专业课课时八月中旬消耗完，之前和家长聊过，课时不足可以续费，目的就是想让学生这次上岸；今天上午电话沟通家长说一定保证数学一周一次课，后续我会和家长初步沟通续费情况。；该学生为保护期内续费，原顾问：国内大学部-苏乾楠(suqiannan@xdf.cn) | J6: 大学已毕业 | K6: 苏乾楠 | L6: 转介绍 | M6: 学管续费推荐 | N6: 王天义wangtianyi56@xdf.cn | Q6: 张婧辰 | R6: 苏乾楠 | S6: 29197476 | T6: 续费工单 | U6: 2025-07-18 15:02 | V6: A（六个月内有报课意向工单） | W6: 考研专业课 | X6: 大学已毕业 | Y6: 北京信息科技大学 | Z6: 经济管理学院 | AA6: 会计学 | AB6: 张婧辰 | AC6: 5517645 | AD6: 刘晓娟 | AE6: 2025-07-21 19:25 | AF6: 苏乾楠 | AG6: 2025-07-21 19:26 | AJ6: 国内考试 | AL6: 3750 | AN6: 王天义 | AO6: 分单 | AP6: 已交接 | AR6: BJWY1217641283 | AV6: 回访人：苏乾楠，回访时间：2025-07-18 15:02，回访内容：学管老师先跟进 今天在校区沟通；|回访人：苏乾楠，回访时间：2025-07-21 19:21，回访内容：报名 | BA6: 52122438 | BB6: 否 | BC6: 26考季 | BD6: 考研专业课管综 | BE6: 管综 | BF6: 管综 | BG6: 国内高校-双非 | BH6: 否 | BN6: 学管续费推荐
A7: 17 | B7: 北京大学部 | C7: 国内大学部 | D7: 润欣 | E7: 118632154 | F7: 程远 | G7: 2025-07-11 14:21:04 | H7: 卢嘉雯+lujiawen3@xdf.cn+213598+培训学校 北京学校 高中一对一部 西北区 展春园分中心，黄智超； | J7: 大二 | K7: 黄智超 | L7: 转介绍 | M7: 内部员工推荐 | N7: 卢嘉雯+lujiawen3@xdf.cn+213598+培训学校 北京学校 高中一对一部 西北区 展春园分中心 | Q7: 沈润欣 | R7: 黄智超 | S7: 28983533 | T7: 正常工单 | U7: 2025-07-11 14:48 | V7: A（六个月内有报课意向工单） | W7: 六级,大学预科 | X7: 大一 | Y7: 北京建华实验亦庄学校 | Z7: 新大一 | AA7: 新大一 | AB7: 沈润欣 | AC7: 5489793 | AD7: 黄智超 | AE7: 2025-07-21 22:38 | AF7: 黄智超 | AG7: 2025-07-21 22:38 | AH7: YKSJ25001 | AI7: 六级无忧计划（线上优享/新大一专属） | AJ7: 国内考试 | AL7: 5180 | AN7: 卢嘉雯+lujiawen3@xdf.cn+213598+培训学校 北京学校 高中一对一部 西北区 展春园分中心 | AO7: 新签 | AP7: 已交接 | AQ7: BJWY2101498uW2 | AR7: BJWY7973903583 | AS7: YKSJ250010051 | AT7: 2025-07-21 | AV7: 回访人：黄智超，回访时间：2025-07-14 20:56，回访内容：家长需求微信联系 目前就是觉得线下距离远，学六级又有点早，网课又不倾向，家长明确说明微信以后沟通 别打电话，孩子是k12老生；|回访人：黄智超，回访时间：2025-07-20 12:04，回访内容：家长明确说明不要打电活联系 微信沟通 目前不确定是否报名 再缓缓；|回访人：黄智超，回访时间：2025-07-21 22:38，回访内容：已签约 5180 预科线上六级课～YKSJ25001 | BA7: 74686638 | BB7: 否 | BC7: 25下考季 | BD7: 六级无忧计划 | BG7: 普通学校-普高 | BH7: 否 | BK7: 报名 | BM7: 本地人本地大学(常规) | BN7: 客服
A8: 18 | B8: 北京大学部 | C8: 国内大学部 | D8: 王东 | E8: 108040003 | F8: 北京国内管理员 | G8: 2025-06-04 10:09:49 | H8: 来源:北京百学汇; | I8: 【2025-CRM高三资源】-北京大学部 | J8: 大一 | K8: 高晓慧 | L8: 毛坯数据 | M8: 毛坯数据 | O8: 高晓慧 | P8: 2025-07-15 16:09:16 | Q8: 王开睿 | R8: 李政(离职) | S8: 29091887 | T8: 正常工单 | U8: 2025-07-15 16:19 | V8: A（六个月内有报课意向工单） | W8: 四级,大学预科 | X8: 大一 | Y8: 不详 | Z8: 询问未告知 | AA8: 新大一 | AB8: 王开睿 | AC8: 5488602 | AD8: 李政(离职) | AE8: 2025-07-20 19:10 | AF8: 李政(离职) | AG8: 2025-07-20 19:10 | AH8: YKF25002 | AI8: 四级无忧计划（新大一专属） | AJ8: 国内考试 | AL8: 4880 | AO8: 新签 | AP8: 已交接 | AQ8: BJWY25030q8UPI | AR8: BJWY5651022809 | AS8: YKF250020045 | AT8: 2025-07-20 | AV8: 回访人：李政(离职)，回访时间：2025-07-15 16:19，回访内容：家长帮孩子咨询，不方便沟通，先都看看；|回访人：李政(离职)，回访时间：2025-07-17 14:52，回访内容：电话无人接听，询问家长的课程意向，家长无回复；|回访人：李政(离职)，回访时间：2025-07-20 19:09，回访内容：试听课来参加；|回访人：李政(离职)，回访时间：2025-07-20 19:10，回访内容：签约 | BA8: 74844973 | BB8: 否 | BC8: 25下考季 | BD8: 四级无忧计划 | BG8: 国内高校-双非 | BH8: 否 | BK8: 报名 | BM8: 本地人本地大学(常规) | BN8: 新CRM
A9: 19 | B9: 北京大学部 | C9: 国内大学部 | E9: 93426823 | G9: 2025-01-19 18:44:34 | H9: 【王朝群】咨询四六级课程 | J9: 大二 | K9: 刘晓娟 | L9: 线上运营-小红书 | M9: 小红书 | Q9: 汪宣晓 | R9: 刘晓娟 | S9: 29243397 | T9: 续费工单 | U9: 2025-07-20 16:02 | V9: A（六个月内有报课意向工单） | W9: 四级 | X9: 大二 | Y9: 武汉音乐学院 | Z9: 中国器乐系 | AA9: 古琴 | AB9: 汪宣晓 | AC9: 5488193 | AD9: 刘晓娟 | AE9: 2025-07-20 16:06 | AF9: 刘晓娟 | AG9: 2025-07-20 16:06 | AH9: WYFJ25040 | AI9: 四级无忧计划 | AJ9: 国内考试 | AL9: 5680 | AM9: 同科续费 | AO9: 续班 | AP9: 未交接 | AQ9: BJWY22035556hl | AR9: BJWY5490718239 | AS9: WYFJ250400002 | AT9: 2025-07-20 | AV9: 回访人：刘晓娟，回访时间：2025-07-20 16:02，回访内容：转班；|回访人：刘晓娟，回访时间：2025-07-20 16:06，回访内容：转班 | BA9: 66365835 | BB9: 否 | BC9: 25下考季 | BD9: 四级无忧计划 | BG9: 国内高校-双非 | BH9: 否 | BK9: 转出 | BM9: 本地人外地大学(归巢)
A10: 20 | B10: 北京大学部 | C10: 国内大学部 | E10: 117158030 | G10: 2025-07-02 14:13:36 | J10: 大二 | K10: 黄智超 | L10: 转介绍 | M10: 内部员工推荐 | Q10: 于奥洋 | R10: 黄智超 | S10: 29476388 | T10: 续费工单 | U10: 2025-08-03 12:26 | V10: A（六个月内有报课意向工单） | W10: 六级,大学预科 | X10: 大一 | Y10: 深圳大学 | Z10: 经济学院 | AA10: 经济学 | AB10: 于奥洋 | AC10: 5502967 | AD10: 黄智超 | AE10: 2025-08-03 12:26 | AF10: 黄智超 | AG10: 2025-08-03 12:27 | AH10: YKS25005 | AI10: 六级精英计划（新大一专属） | AJ10: 国内考试 | AL10: 20300 | AM10: 同科续费 | AN10: 高晶+gaojing43@xdf.cn+312057+培训学校-北京学校-高中一对一部-西南区-玉泉路分中心 | AO10: 续班 | AP10: 已交接 | AQ10: BJWY2011wXCx1W | AR10: BJWY8894097228 | AS10: YKS250050005 | AT10: 2025-07-18 | AV10: 回访人：黄智超，回访时间：2025-08-03 12:26，回访内容：转班；|回访人：黄智超，回访时间：2025-08-03 12:26，回访内容：转班 | BA10: 56143849 | BB10: 否 | BC10: 25下考季 | BD10: 六级无忧计划 | BG10: 国内高校-双非 | BH10: 是 | BK10: 转出 | BM10: 本地人本地大学(常规)
A11: 21 | B11: 北京大学部 | C11: 国内大学部 | D11: 徐子翔 | E11: 115186765 | F11: 曹伟杰2 | G11: 2025-06-19 10:56:40 | H11: 家长咨询四六级暑期班 辛苦老师分配给原顾问黄智超，合并工单，不占顺序。之前整错渠道啦 | J11: 高三 | K11: 黄智超 | L11: 转介绍 | M11: 内部员工推荐 | N11: 吕玉珠+lvyuzhu1@xdf.cn+444957+培训学校-北京学校-高中一对一部-增长中心-线上社群组 | Q11: 徐子翔 | R11: 黄智超 | S11: 28429430 | T11: 续费工单 | U11: 2025-06-19 11:35 | V11: A（六个月内有报课意向工单） | W11: 四级 | X11: 高三 | Y11: 北京市第十一中学 | Z11: 新大一 | AA11: 新大一 | AB11: 徐子翔 | AC11: 5415457 | AD11: 黄智超 | AE11: 2025-07-18 10:44 | AF11: 黄智超 | AG11: 2025-07-19 18:37 | AH11: 37912747353 | AI11: 【返学费】四级暑期直通车【2025年12考季】 | AJ11: 国内考试 | AN11: 吕玉珠+lvyuzhu1@xdf.cn+444957+培训学校-北京学校-高中一对一部-增长中心-线上社群组 | AO11: 新签 | AP11: 无须交接 | AT11: 2025-07-18 | AV11: 回访人：黄智超，回访时间：2025-07-12 16:36，回访内容：电话接不通 同事电话也不接 微信回复觉得课程价格贵；|回访人：黄智超，回访时间：2025-07-13 17:52，回访内容：家长觉得课程价格贵 就规划了新东方在线的网课，家长看到返学费的 又问了考试的事情 目前也不知道能不能给孩子报名；|回访人：黄智超，回访时间：2025-07-22 14:11，回访内容：发送四级资料维护一下 | AZ11: 长期班 | BA11: 75302707 | BB11: 是 | BC11: 25下考季 | BD11: 四级无忧计划 | BG11: 普通学校-普高 | BH11: 否 | BL11: 110560210 | BM11: 本地人本地大学(常规) | BN11: 市场 | BO11: 在线不算 | BP11: 279
A12: 22 | B12: 北京大学部 | C12: 国内大学部 | D12: 吴优 | E12: 119674385 | F12: 杨沫 | G12: 2025-07-17 19:29:32 | H12: 张鸿伟+zhanghongwei9@xdf.cn+ 162245+培训学校-北京学校-高中一对一部-学员服务管理中心-西南区 房国超 | J12: 大二 | K12: 房国超 | L12: 转介绍 | M12: 内部员工推荐 | N12: 张鸿伟+zhanghongwei9@xdf.cn+ 162245+培训学校-北京学校-高中一对一部-学员服务管理中心-西南区 | Q12: 吴优 | R12: 房国超 | S12: 29192447 | T12: 续费工单 | U12: 2025-07-17 20:07 | V12: A（六个月内有报课意向工单） | W12: 六级 | X12: 大二 | Y12: 北京工商大学 | Z12: 数学与统计学院 | AA12: 经济统计学 | AB12: 吴优 | AC12: 5415404 | AD12: 房国超 | AE12: 2025-07-18 09:04 | AF12: 房国超 | AG12: 2025-07-18 09:11 | AH12: 88527312393 | AI12: 【返学费】六级暑期直通车【2025年12考季】 | AJ12: 国内考试 | AN12: 张鸿伟+zhanghongwei9@xdf.cn+ 162245+培训学校-北京学校-高中一对一部-学员服务管理中心-西南区 | AO12: 新签 | AP12: 无须交接 | AT12: 2025-07-18 | AV12: 回访人：房国超，回访时间：2025-07-17 20:07，回访内容：家长咨询，学生四级 480多，家长想让孩子暑假学学， 推荐直播课 和小班，微信详聊 | AZ12: 长期班 | BA12: 56483959 | BB12: 是 | BC12: 25下考季 | BD12: 六级无忧计划 | BG12: 国内高校-双非 | BH12: 否 | BL12: 110559692 | BM12: 外地人本地大学(常规) | BN12: 客服 | BO12: 在线不算 | BP12: 279
A13: 23 | B13: 北京大学部 | C13: 国内大学部 | D13: 北京市3774 | E13: 116690066 | F13: 杨俊42(国内) | G13: 2025-06-30 20:08:54 | H13: 渠道录入来源：新东方官网M站-客服 意向城市：北京访客省/城市：北京市 访客静态ID：01000000034659128491454282423774 接待分组ID：70455 搜索引擎： 搜索词： 关键词： 设备类型：pc 访客IP：120.244.194.194 对话详细内容：AI-Lbo0rDBXCyBY 2025-06-30 20:05:10_x000D_ 您好同学,欢迎访问北京新东方考研四六级中心. 考研线下课程26/27考季【考研全年集训营】【考研半年集训营】【考研全科线下走读班】【考研寒/暑假集训营】【考研一对一】【考研专业课】【四/六级课程】，热门课程火热报名中,咨询即可领取专享优惠。 **【考研全年集训营】=ff761f# **【考研半年集训营】=ff6b6b# **【考研全科线下走读班】=ffc158# **【考研寒/暑假集训营】=ffc158# **【考研一对一】=ff761f# **【考研专业课】=ff6caa# **【四/六级课程】=ff6caa# **【考研冲刺班】=60e27e#_x000D_ _x000D_ AI-Lbo0rDBXCyBY 2025-06-30 20:05:13_x000D_ 您是想咨询【线下课程】【线上课程】【考研规划】还是【在职考研】呢？**【线下课程】# **【线上课程】#**【考研规划】#**【在职考研】#_x000D_ _x000D_ 01000000034659128491454282423774 2025-06-30 20:05:22_x000D_ 【线下课程】_x000D_ _x000D_ AI-Lbo0rDBXCyBY 2025-06-30 20:05:25_x000D_ 同学，你现在是在校还是在职呢？_x000D_ _x000D_ 01000000034659128491454282423774 2025-06-30 20:05:44_x000D_ 学生_x000D_ _x000D_ AI-Lbo0rDBXCyBY 2025-06-30 20:05:48_x000D_ 具体是想报考什么学校和专业呢？_x000D_ _x000D_ 01000000034659128491454282423774 2025-06-30 20:05:55_x000D_ 报考4级_x000D_ _x000D_ AI-Lbo0rDBXCyBY 2025-06-30 20:05:59_x000D_ 您目前在学的院校是哪所呢？_x000D_ _x000D_ AI-Lbo0rDBXCyBY 2025-06-30 20:06:36_x000D_ 您好，能看到我的对话吗？如有疑问，可以在此留电咨询！_x000D_ _x000D_ 01000000034659128491454282423774 2025-06-30 20:06:53_x000D_ 13641067224_x000D_ _x000D_ AI-Lbo0rDBXCyBY 2025-06-30 20:06:57_x000D_ 好的，确认一下你的号码是否正确呢~_x000D_ _x000D_ 01000000034659128491454282423774 2025-06-30 20:07:10_x000D_ 正确_x000D_ _x000D_ AI-Lbo0rDBXCyBY 2025-06-30 20:07:14_x000D_ 同学怎么称呼呢？_x000D_ _x000D_ 01000000034659128491454282423774 2025-06-30 20:07:26_x000D_ 何_x000D_ _x000D_ AI-Lbo0rDBXCyBY 2025-06-30 20:07:29_x000D_ 这边马上安排顾问老师联系您，预计半个小时左右给您回电请注意接听~_x000D_ _x000D_ 来源页：https://www.xdf.cn/beijing/ 备注： | I13: 2026财年第1财月易聊新东方官网M站 | K13: 徐利霞 | L13: 新东方官网 | M13: 新东方官网M站 | O13: 徐利霞 | P13: 2025-07-01 11:43:20 | Q13: 何格 | R13: 黄智超 | S13: 28764973 | T13: 正常工单 | U13: 2025-07-01 13:40 | V13: A（六个月内有报课意向工单） | W13: 四级,大学预科 | X13: 大一 | Y13: 北京第二外国语学院 | Z13: 中东学院 | AA13: 阿拉伯语 | AB13: 何格 | AC13: 5483208 | AD13: 黄智超 | AE13: 2025-07-17 16:14 | AF13: 黄智超 | AG13: 2025-07-18 15:48 | AH13: YKF25003 | AI13: 四级无忧计划（新大一专属） | AJ13: 国内考试 | AL13: 5180 | AO13: 新签 | AP13: 已交接 | AQ13: BJWY2101498uW2 | AR13: BJWY7411043612 | AS13: YKF250030011 | AT13: 2025-07-17 | AV13: 回访人：黄智超，回访时间：2025-07-08 17:48，回访内容：孩子上次听完试听课回家之后进行了赔偿，今天关心了一下身体，目前反馈还可以，需要等待考录取结果出来之后再决定～；|回访人：黄智超，回访时间：2025-07-11 14:18，回访内容：目前录取结果还没有出来，学生不太确定，还需要再跟进跟进，等一等时间。；|回访人：黄智超，回访时间：2025-07-14 19:27，回访内容：之前试听课过来，要等录取结果出来才能报名，现在结果出来了，学生觉得课程价格高，打算明天给走个五人团 看看能不能交钱；|回访人：黄智超，回访时间：2025-07-15 20:09，回访内容：还是在纠结 在跟家长沟通一下；|回访人：黄智超，回访时间：2025-07-16 18:17，回访内容：目前是跟孩子在沟通，特殊情况还是先不要触达家长 告知了课程团报优惠 孩子还没回复我；|回访人：黄智超，回访时间：2025-07-17 16:14，回访内容：报名暑假预科四级三班（花园桥校区）8月4号开课的班级YKF25003，之前试听课喝我们赠送的水过期了 家长当时有情绪 辛苦老师维护好学生～ | BA13: 80808745 | BB13: 否 | BC13: 25下考季 | BD13: 四级无忧计划 | BG13: 国内高校-双非 | BH13: 否 | BK13: 报名 | BM13: 本地人本地大学(常规) | BN13: 易聊在线咨询
A14: 24 | B14: 北京大学部 | C14: 国内大学部 | D14: 老带新用户 | E14: 119497203 | F14: 黄智超 | G14: 2025-07-16 23:30:44 | H14: 渠道录入来源：老带新系统 老生userid：385b6138-50b9-4f54-ba17-69594722a147 老生学号：BJWY7771366384 老生姓名：肖遥 产品类型：1 活动所属学校名称：北京大学事业部 老带新活动名称：邀好友，大家一起来省钱（班课专用）新 老带新活动id：2366032 推广邮箱：huangzhichao1@xdf.cn | I14: 2026财年第2财月老带新系统 | K14: 黄智超 | L14: 转介绍 | M14: 老带新系统顾问 | N14: 黄智超huangzhichao1@xdf.cn | Q14: 郑文予 | R14: 黄智超 | S14: 29188775 | T14: 正常工单 | U14: 2025-07-17 15:51 | V14: A（六个月内有报课意向工单） | W14: 六级 | X14: 大一 | Y14: 北京市第五十中学 | Z14: 新大一 | AA14: 新大一 | AB14: 郑文予 | AC14: 5415253 | AD14: 黄智超 | AE14: 2025-07-17 16:10 | AF14: 黄智超 | AG14: 2025-07-25 13:36 | AH14: YKS25002 | AI14: 六级无忧计划（新大一专属） | AJ14: 国内考试 | AL14: 5480 | AN14: 黄智超 | AO14: 新签 | AP14: 已交接 | AQ14: WebReg | AR14: BJWY3837265523 | AS14: YKS250020026 | AT14: 2025-07-17 | AV14: 回访人：黄智超，回访时间：2025-07-17 15:51，回访内容：准备和肖遥同学一起报名暑假6级预科二班；|回访人：黄智超，回访时间：2025-07-17 16:10，回访内容：报名暑假预科六级二班（肖遥的同学）YKS25002 | BA14: 81849719 | BB14: 否 | BC14: 25下考季 | BD14: 六级无忧计划 | BG14: 普通学校-普高 | BH14: 否 | BK14: 报名 | BM14: 本地人本地大学(常规) | BN14: 老带新系统
A15: 25 | B15: 北京大学部 | C15: 国内大学部 | D15: 吴昭睿 | E15: 117589255 | F15: 曹伟杰2 | G15: 2025-07-04 14:07:49 | H15: 家长咨询暑期6级线上，报过价格【张志威公众号】 | J15: 大二 | K15: 徐健坤 | L15: 线上运营-私域中台 | M15: 公众号 | Q15: 吴昭睿 | R15: 黄智超 | S15: 28804436 | T15: 正常工单 | U15: 2025-07-16 14:32 | V15: A（六个月内有报课意向工单） | W15: 六级 | X15: 大一 | Y15: 新大一 | Z15: 新大一 | AA15: 新大一 | AB15: 吴昭睿 | AC15: 5414679 | AD15: 黄智超 | AE15: 2025-07-16 14:35 | AF15: 黄智超 | AG15: 2025-07-16 14:36 | AH15: 85308838525 | AI15: 【返学费】六级暑期直通车【2025年12考季】 | AJ15: 国内考试 | AO15: 新签 | AP15: 无须交接 | AT15: 2025-07-16 | AV15: 回访人：徐健坤，回访时间：2025-07-09 22:24，回访内容：电话没有接听 留言；|回访人：刘文君，回访时间：2025-07-13 21:11，回访内容：两遍没接；|回访人：刘文君，回访时间：2025-07-16 12:11，回访内容：2、3k 不在意录播 与其他班型推荐一下 看看试听课 ；|回访人：黄智超，回访时间：2025-07-16 14:35，回访内容：签约 279线上网课 | AZ15: 长期班 | BA15: 56358343 | BB15: 是 | BC15: 25下考季 | BD15: 六级无忧计划 | BG15: 普通学校-普高 | BH15: 否 | BL15: 110549969 | BM15: 本地人本地大学(常规) | BN15: 市场 | BO15: 在线不算 | BP15: 279
A16: 27 | B16: 北京大学部 | C16: 国内大学部 | D16: 张敏 | E16: 118960010 | F16: 杨沫 | G16: 2025-07-14 09:42:07 | H16: 黄智超 | J16: 大学已毕业 | K16: 黄智超 | L16: 转介绍 | M16: 顾问转介绍-新带新 | N16: 张晴 | Q16: 张敏 | R16: 黄智超 | S16: 28993241 | T16: 正常工单 | U16: 2025-07-14 09:54 | V16: A（六个月内有报课意向工单） | W16: 专升本 | X16: 大学已毕业 | Y16: 北京工业职业技术学院 | Z16: 电子科技 | AA16: 电子信息 | AB16: 张敏 | AC16: 5479462 | AD16: 黄智超 | AE16: 2025-07-14 11:44 | AF16: 黄智超 | AG16: 2025-07-14 11:53 | AH16: 24419587709 | AI16: 26通用专升本慧学班-英语 | AJ16: 国内考试 | AL16: 1999 | AN16: 张晴 | AO16: 新签 | AP16: 无须交接 | AT16: 2025-07-14 | AV16: 回访人：黄智超，回访时间：2025-07-14 09:54，回访内容： 张晴同学的表姐，专升本的推荐一对一和网课，预计报名英语网课；|回访人：黄智超，回访时间：2025-07-19 08:09，回访内容：给学生邮寄了4级单词书，维护一下，学生非常开心。 | AZ16: 长期班 | BA16: 81656739 | BB16: 是 | BC16: 26考季 | BD16: 专升本全科全程班 | BE16: 英语 | BG16: 国内高校-大专 | BH16: 否 | BL16: 110536506 | BN16: 客服
A17: 28 | B17: 北京大学部 | C17: 国内大学部 | E17: 116382146 | G17: 2025-06-26 20:00:26 | H17: 【四级】家长咨询，孩子刚高考完，咨询四级线上课程，方便电话；线上四级 | J17: 高三 | K17: 刘晓娟 | L17: 电话 | M17: 大客服呼入 | Q17: 王钧浩 | R17: 刘晓娟 | S17: 29101013 | T17: 续费工单 | U17: 2025-07-14 23:17 | V17: A（六个月内有报课意向工单） | W17: 六级,大学预科 | X17: 大一 | Y17: 北京市第十九中学 | Z17: 新大一 | AA17: 新大一 | AB17: 王钧浩 | AC17: 5413943 | AD17: 刘晓娟 | AE17: 2025-07-14 23:18 | AF17: 刘晓娟 | AG17: 2025-07-14 23:18 | AH17: YKFJ25001 | AI17: 四级无忧计划（线上优享/新大一专属） | AJ17: 国内考试 | AL17: 5680 | AM17: 扩科续费 | AO17: 续班 | AP17: 无须交接 | AQ17: BJWY22035556hl | AR17: BJWY5992971962 | AS17: YKFJ250010059 | AT17: 2025-07-14 | AV17: 回访人：刘晓娟，回访时间：2025-07-14 23:17，回访内容：转班；|回访人：刘晓娟，回访时间：2025-07-14 23:18，回访内容：转班 | BA17: 80589207 | BB17: 否 | BC17: 25下考季 | BD17: 六级无忧计划 | BG17: 普通学校-普高 | BH17: 否 | BK17: 转出 | BM17: 本地人本地大学(常规)
A18: 29 | B18: 北京大学部 | C18: 国内大学部 | E18: 95427640 | G18: 2025-02-24 11:38:58 | H18: （吴丰恺）魏公村直访，刘晓娟接待； | J18: 大一 | K18: 刘晓娟 | L18: 直访 | M18: 直访 | Q18: 吴丰恺 | R18: 刘晓娟 | S18: 29059531 | T18: 续费工单 | U18: 2025-07-13 18:23 | V18: A（六个月内有报课意向工单） | W18: 六级 | X18: 大二 | Y18: 中央财经大学 | Z18: 财政税务学院 | AA18: 财政学 | AB18: 吴丰恺 | AC18: 5478903 | AD18: 刘晓娟 | AE18: 2025-07-13 18:24 | AF18: 刘晓娟 | AG18: 2025-07-13 18:24 | AH18: WYS25042 | AI18: 六级无忧计划 | AJ18: 国内考试 | AL18: 4314.7 | AM18: 同科续费 | AO18: 续班 | AP18: 未交接 | AQ18: BJWY24032w1g8X | AR18: BJWY3487591469 | AS18: WYS250420001 | AT18: 2025-07-13 | AV18: 回访人：刘晓娟，回访时间：2025-07-13 18:23，回访内容：转班；|回访人：刘晓娟，回访时间：2025-07-13 18:24，回访内容：转班 | BA18: 67227543 | BB18: 否 | BC18: 25下考季 | BD18: 六级无忧计划 | BG18: 国内高校-211 | BH18: 否 | BK18: 转出 | BM18: 外地人本地大学(常规)
A19: 30 | B19: 北京大学部 | C19: 国内大学部 | D19: 未知 | E19: 116992462 | F19: 吕猛 | G19: 2025-07-01 18:56:54 | H19: 咨询六级线下课程 渠道录入来源：大众点评 事件名称：在线咨询 大众点评门店名称：新东方考研四六级(惠新东街校区) 店铺绑定的校区：临时教学校区 店铺管理员邮箱：lvmeng2@xdf.cn 备注：2025-07-01 18:56:52,用户在大众点评新东方考研四六级(惠新东街校区)在线咨询 | I19: 2026财年第2财月大众点评在线咨询 | J19: 未知 | K19: 黄智超 | L19: 线上运营-本地生活平台 | M19: 大众点评 | Q19: 何嘉蔚 | R19: 黄智超 | S19: 28751369 | T19: 正常工单 | U19: 2025-07-01 20:31 | V19: A（六个月内有报课意向工单） | W19: 六级 | X19: 大二 | Y19: 北京工业大学 | Z19: 经济与管理学院 | AA19: 经济统计学 | AB19: 何嘉蔚 | AC19: 5478861 | AD19: 黄智超 | AE19: 2025-07-13 18:10 | AF19: 黄智超 | AG19: 2025-07-17 12:55 | AH19: WYS25035 | AI19: 六级无忧计划 | AJ19: 国内考试 | AL19: 6180 | AO19: 新签 | AP19: 已交接 | AQ19: BJWY2011wXCx1W | AR19: BJWY0320886291 | AS19: WYS250350036 | AT19: 2025-07-13 | AV19: 回访人：黄智超，回访时间：2025-07-05 09:46，回访内容：问问家长和孩子沟通的结果，家长暂未回微信。；|回访人：黄智超，回访时间：2025-07-07 21:26，回访内容：目前孩子的时间冲突，所以还在观望中，孩子目前只能接受纯8月开课的。；|回访人：黄智超，回访时间：2025-07-09 17:08，回访内容：家长只接受8月份的班 目前也没时间 还需要沟通孩子；|回访人：黄智超，回访时间：2025-07-13 18:10，回访内容：报名六级二班，WYS25035昨天交了5680今天补500 6180入班 | BA19: 56508496 | BB19: 否 | BC19: 25下考季 | BD19: 六级无忧计划 | BG19: 国内高校-211 | BH19: 是 | BK19: 报名 | BM19: 本地人本地大学(常规) | BN19: 新媒体管家-点评
A20: 31 | B20: 北京大学部 | C20: 国内大学部 | D20: 许致浩 | E20: 118802764 | F20: 方勃文 | G20: 2025-07-12 21:43:13 | H20: 学生在辽宁，咨询四级线上课，加微信发送课程【已在群内反馈】 | J20: 大三 | K20: 黄智超 | L20: 线上运营-私域中台 | M20: 社群、虚拟人 | Q20: 许致浩 | R20: 黄智超 | S20: 29055010 | T20: 正常工单 | U20: 2025-07-13 13:21 | V20: A（六个月内有报课意向工单） | W20: 四级 | X20: 大三 | Y20: 北京科技大学 | Z20: 土木与资源工程学院 | AA20: 建筑设备与能源应用工程 | AB20: 许致浩 | AC20: 5478547 | AD20: 黄智超 | AE20: 2025-07-13 16:02 | AF20: 黄智超 | AG20: 2025-07-13 16:51 | AH20: 17096309135 | AI20: 【返学费】四级暑期直通车【2025年12考季】 | AJ20: 国内考试 | AO20: 新签 | AP20: 无须交接 | AT20: 2025-07-13 | AV20: 回访人：黄智超，回访时间：2025-07-13 13:21，回访内容：学生在忙 微信通过后沟通 目前考虑网课 但是我们的5980课程价格高 学生不能接受 推荐在线网课 看看孩子的反馈；|回访人：黄智超，回访时间：2025-07-19 08:12，回访内容：给学生邮寄了4级词汇书，祝愿他4级顺利通过吧～ | AZ20: 长期班 | BA20: 81621863 | BB20: 是 | BC20: 27下考季 | BD20: 四级无忧计划 | BG20: 国内高校-211 | BH20: 否 | BL20: 109227936 | BM20: 外地人本地大学(常规) | BN20: 市场 | BO20: 在线不算 | BP20: 279
A21: 35 | B21: 北京大学部 | C21: 国内大学部 | D21: 顾芳丞 | E21: 113731966 | F21: 陈自强 | G21: 2025-06-11 15:19:56 | H21: 高三家长资源，按毛坯数据话术回访即可，重点沟通大学预科以及四六级课程暑期学习重要性，引导了解 | I21: 批量导入-京内-渠道推荐-高三-陈自强-250611 | J21: 高三 | K21: 曹健 | L21: 市场活动 | M21: 京内会销/讲座 | O21: 曹健 | P21: 2025-06-19 18:22:38 | Q21: 顾芳丞 | R21: 刘晓娟 | S21: 28497327 | T21: 正常工单 | U21: 2025-06-19 19:19 | V21: A（六个月内有报课意向工单） | W21: 六级,大学预科 | X21: 大一 | Y21: 北京西城区裕中中学 | Z21: 新大一 | AA21: 新大一 | AB21: 顾芳丞 | AC21: 5477552 | AD21: 刘晓娟 | AE21: 2025-07-12 18:06 | AF21: 刘晓娟 | AG21: 2025-07-14 23:16 | AH21: YKS25002 | AI21: 六级无忧计划（新大一专属） | AJ21: 国内考试 | AL21: 4880 | AO21: 新签 | AP21: 已交接 | AQ21: BJWY2101498uW2 | AR21: BJWY7653144964 | AS21: YKS250020021 | AT21: 2025-07-12 | AV21: 回访人：刘晓娟，回访时间：2025-07-03 14:59，回访内容：邀约讲座；|回访人：刘晓娟，回访时间：2025-07-10 19:14，回访内容：邀约讲座；|回访人：刘晓娟，回访时间：2025-07-12 18:06，回访内容：报名 | BA21: 74585485 | BB21: 否 | BC21: 25下考季 | BD21: 六级无忧计划 | BG21: 普通学校-普高 | BH21: 是 | BK21: 报名 | BM21: 本地人本地大学(常规) | BN21: 市场
A22: 36 | B22: 北京大学部 | C22: 国内大学部 | E22: 116612399 | G22: 2025-06-29 13:38:30 | H22: 孩子高一，家长意向8月4- 8月16四级，加微信联系，备注曹老师推荐【张志威公众号】 | J22: 高一 | K22: 田一禾 | L22: 线上运营-私域中台 | M22: 公众号 | Q22: 王洛欢 | R22: 田一禾 | S22: 29362963 | T22: 续费工单 | U22: 2025-08-03 11:44 | V22: B（需长时间跟单或只需要规划） | W22: 四级,大学预科 | X22: 大一 | Y22: 询问院校未告知 | Z22: 询问院系未告知 | AA22: 询问专业未告知 | AB22: 王洛欢 | AC22: 5530669 | AD22: 田一禾 | AE22: 2025-08-03 11:45 | AF22: 田一禾 | AG22: 2025-08-03 11:46 | AH22: YKS25003 | AI22: 六级无忧计划（新大一专属） | AJ22: 国内考试 | AL22: 4880 | AM22: 扩科续费 | AO22: 续班 | AP22: 已交接 | AQ22: BJWY2101498uW2 | AR22: BJWY7022979955 | AS22: YKS250030004 | AT22: 2025-07-11 | AV22: 回访人：田一禾，回访时间：2025-08-03 11:44，回访内容：转班；|回访人：田一禾，回访时间：2025-08-03 11:45，回访内容：转班操作 | BA22: 80712352 | BB22: 否 | BC22: 28下考季 | BD22: 四级无忧计划 | BG22: 普通学校-普高 | BH22: 是 | BK22: 转出
A23: 37 | B23: 北京大学部 | C23: 国内大学部 | D23: Sunshine | E23: 116905889 | F23: 王朝群 | G23: 2025-07-01 23:50:32 | H23: 【王朝群】咨询大学预科 | I23: 2026财年第2财月小红书 | J23: 大一 | K23: 黄智超 | L23: 线上运营-小红书 | M23: 小红书 | Q23: 田沐家 | R23: 黄智超 | S23: 28756058 | T23: 正常工单 | U23: 2025-07-02 14:05 | V23: A（六个月内有报课意向工单） | W23: 六级,大学预科 | X23: 大一 | Y23: 北师大二附中海淀校区 | Z23: 询问院系未告知 | AA23: 询问专业未告知 | AB23: 田沐家 | AC23: 5411942 | AD23: 黄智超 | AE23: 2025-07-10 21:38 | AF23: 黄智超 | AG23: 2025-07-13 15:53 | AH23: YK25002 | AI23: 大学口语特训营 | AJ23: 国内考试 | AL23: 3998.9 | AO23: 新签 | AP23: 已交接 | AQ23: WebReg | AR23: BJWY7835063861 | AS23: YK250020016 | AT23: 2025-07-10 | AV23: 回访人：黄智超，回访时间：2025-07-02 14:05，回访内容：孩子英语基础不错 130分左右 建议学六级小班 也咨询了六级大班的课程安排 微信电话沟通 目前意向比较高 持续联系 邀约试听课；|回访人：黄智超，回访时间：2025-07-04 23:31，回访内容：问问家长和孩子沟通的情况如何 目前暂未回复；|回访人：黄智超，回访时间：2025-07-08 21:32，回访内容：准备报名了 家长还未付款 明天重新发送；|回访人：黄智超，回访时间：2025-07-09 16:34，回访内容：电话不接 缴费码都发了 还没交钱；|回访人：黄智超，回访时间：2025-07-10 21:38，回访内容：已签约，预科六级全科（魏公村）；|回访人：黄智超，回访时间：2025-07-15 21:55，回访内容：告知线上线下的课程区别，鼓励孩子尽可能来线下学习 | BA23: 67717559 | BB23: 否 | BC23: 25下考季 | BD23: 六级无忧计划 | BG23: 普通学校-普高 | BH23: 是 | BK23: 报名 | BM23: 本地人本地大学(常规) | BN23: 小红书
A24: 38 | B24: 北京大学部 | C24: 国内大学部 | D24: Sunshine | E24: 116905889 | F24: 王朝群 | G24: 2025-07-01 23:50:32 | H24: 【王朝群】咨询大学预科 | I24: 2026财年第2财月小红书 | J24: 大一 | K24: 黄智超 | L24: 线上运营-小红书 | M24: 小红书 | Q24: 田沐家 | R24: 黄智超 | S24: 28756058 | T24: 正常工单 | U24: 2025-07-02 14:05 | V24: A（六个月内有报课意向工单） | W24: 六级,大学预科 | X24: 大一 | Y24: 北师大二附中海淀校区 | Z24: 询问院系未告知 | AA24: 询问专业未告知 | AB24: 田沐家 | AC24: 5411942 | AD24: 黄智超 | AE24: 2025-07-10 21:38 | AF24: 黄智超 | AG24: 2025-07-13 15:53 | AH24: YKS25001 | AI24: 六级无忧计划（新大一专属） | AJ24: 国内考试 | AL24: 4802.1 | AO24: 新签 | AP24: 已交接 | AQ24: WebReg | AR24: BJWY7835063861 | AS24: YKS250010047 | AT24: 2025-07-10 | AV24: 回访人：黄智超，回访时间：2025-07-02 14:05，回访内容：孩子英语基础不错 130分左右 建议学六级小班 也咨询了六级大班的课程安排 微信电话沟通 目前意向比较高 持续联系 邀约试听课；|回访人：黄智超，回访时间：2025-07-04 23:31，回访内容：问问家长和孩子沟通的情况如何 目前暂未回复；|回访人：黄智超，回访时间：2025-07-08 21:32，回访内容：准备报名了 家长还未付款 明天重新发送；|回访人：黄智超，回访时间：2025-07-09 16:34，回访内容：电话不接 缴费码都发了 还没交钱；|回访人：黄智超，回访时间：2025-07-10 21:38，回访内容：已签约，预科六级全科（魏公村）；|回访人：黄智超，回访时间：2025-07-15 21:55，回访内容：告知线上线下的课程区别，鼓励孩子尽可能来线下学习 | BA24: 67717559 | BB24: 否 | BC24: 25下考季 | BD24: 六级无忧计划 | BG24: 普通学校-普高 | BH24: 是 | BK24: 报名 | BM24: 本地人本地大学(常规) | BN24: 小红书
A25: 39 | B25: 北京大学部 | C25: 国内大学部 | D25: Sunshine | E25: 116905889 | F25: 王朝群 | G25: 2025-07-01 23:50:32 | H25: 【王朝群】咨询大学预科 | I25: 2026财年第2财月小红书 | J25: 大一 | K25: 黄智超 | L25: 线上运营-小红书 | M25: 小红书 | Q25: 田沐家 | R25: 黄智超 | S25: 28756058 | T25: 正常工单 | U25: 2025-07-02 14:05 | V25: A（六个月内有报课意向工单） | W25: 六级,大学预科 | X25: 大一 | Y25: 北师大二附中海淀校区 | Z25: 询问院系未告知 | AA25: 询问专业未告知 | AB25: 田沐家 | AC25: 5411942 | AD25: 黄智超 | AE25: 2025-07-10 21:38 | AF25: 黄智超 | AG25: 2025-07-13 15:53 | AH25: YKM25001 | AI25: 大学预科数学（新大一专属） | AJ25: 国内考试 | AL25: 3999 | AO25: 新签 | AP25: 已交接 | AQ25: WebReg | AR25: BJWY7835063861 | AS25: YKM250010042 | AT25: 2025-07-10 | AV25: 回访人：黄智超，回访时间：2025-07-02 14:05，回访内容：孩子英语基础不错 130分左右 建议学六级小班 也咨询了六级大班的课程安排 微信电话沟通 目前意向比较高 持续联系 邀约试听课；|回访人：黄智超，回访时间：2025-07-04 23:31，回访内容：问问家长和孩子沟通的情况如何 目前暂未回复；|回访人：黄智超，回访时间：2025-07-08 21:32，回访内容：准备报名了 家长还未付款 明天重新发送；|回访人：黄智超，回访时间：2025-07-09 16:34，回访内容：电话不接 缴费码都发了 还没交钱；|回访人：黄智超，回访时间：2025-07-10 21:38，回访内容：已签约，预科六级全科（魏公村）；|回访人：黄智超，回访时间：2025-07-15 21:55，回访内容：告知线上线下的课程区别，鼓励孩子尽可能来线下学习 | BA25: 67717559 | BB25: 否 | BC25: 25下考季 | BD25: 六级无忧计划 | BG25: 普通学校-普高 | BH25: 是 | BK25: 报名 | BM25: 本地人本地大学(常规) | BN25: 小红书
A26: 40 | B26: 北京大学部 | C26: 国内大学部 | D26: 李嘉泽 | E26: 117825382 | F26: 曹伟杰2 | G26: 2025-07-06 17:19:07 | H26: 家长咨询暑期四级【tmk合作徐树萌老师】 | J26: 大一 | K26: 徐树萌 | L26: 线上运营-私域中台 | M26: TMK合作 | O26: 徐树萌 | P26: 2025-07-06 17:33:18 | Q26: 李左文 | R26: 徐健坤 | S26: 28893730 | T26: 正常工单 | U26: 2025-07-06 18:30 | V26: A（六个月内有报课意向工单） | W26: 四级,大学预科 | X26: 大一 | Y26: 清华大学附属中学（奥森校区） | Z26: 新大一 | AA26: 新大一 | AB26: 李左文 | AC26: 5473056 | AD26: 徐健坤 | AE26: 2025-07-08 22:19 | AF26: 徐健坤 | AG26: 2025-07-15 16:36 | AH26: YKF25001 | AI26: 四级无忧计划（新大一专属） | AJ26: 国内考试 | AL26: 5180 | AO26: 新签 | AP26: 已交接 | AQ26: BJWY25030q8UPI | AR26: BJWY4028539388 | AS26: YKF250010053 | AT26: 2025-07-08 | AV26: 回访人：徐健坤，回访时间：2025-07-06 18:30，回访内容：英语99 基础薄弱 小班；|回访人：徐健坤，回访时间：2025-07-07 22:01，回访内容：看了课表；|回访人：徐健坤，回访时间：2025-07-08 22:19，回访内容：签约 | BA26: 59777577 | BB26: 否 | BC26: 25下考季 | BD26: 四级无忧计划 | BG26: 普通学校-普高 | BH26: 否 | BK26: 报名 | BM26: 本地人本地大学(常规) | BN26: 市场
A27: 41 | B27: 北京大学部 | C27: 国内大学部 | D27: 头头 | E27: 114348125 | F27: 王朝群 | G27: 2025-06-14 17:03:28 | H27: 【王朝群】咨询四六级暑期班 | I27: 2026财年第1财月小红书 | J27: 大二 | K27: 黄智超 | L27: 线上运营-小红书 | M27: 小红书 | Q27: 许博铭 | R27: 黄智超 | S27: 28358094 | T27: 续费工单 | U27: 2025-06-14 18:01 | V27: A（六个月内有报课意向工单） | W27: 六级,大学预科 | X27: 高三 | Y27: 北京市八一中学 | Z27: 新大一 | AA27: 新大一 | AB27: 许博铭 | AC27: 5470637 | AD27: 黄智超 | AE27: 2025-07-06 22:48 | AF27: 黄智超 | AG27: 2025-07-09 15:39 | AH27: YKS25004 | AI27: 六级精英计划（新大一专属） | AJ27: 国内考试 | AL27: 20300 | AO27: 新签 | AP27: 已交接 | AQ27: BJWY2101498uW2 | AR27: BJWY4996201639 | AS27: YKS250040007 | AT27: 2025-07-08 | AV27: 回访人：黄智超，回访时间：2025-07-02 22:13，回访内容：高考志愿填报结束 邀约试听课 看看能不能来 再持续沟通；|回访人：黄智超，回访时间：2025-07-04 19:40，回访内容：明天来线下试听课 跟孩子一起过来；|回访人：黄智超，回访时间：2025-07-05 23:56，回访内容：试听课邀约现场；|回访人：黄智超，回访时间：2025-07-06 22:48，回访内容：签约，四级暑假小班2期，20300 | BA27: 74677393 | BB27: 否 | BC27: 25下考季 | BD27: 六级无忧计划 | BG27: 国内高校-双非 | BH27: 否 | BK27: 转出 | BN27: 小红书
A28: 42 | B28: 北京大学部 | C28: 国内大学部 | D28: 张雅冬同学 | E28: 117632295 | F28: 吴凯龙 | G28: 2025-07-04 19:26:26 | H28: 徐健坤1的内部员工推荐工单 | J28: 高三 | K28: 徐健坤 | L28: 转介绍 | M28: 内部员工推荐 | N28: 郑威+zhengwei16@xdf.cn+ID+培训学校-北京学校-高中一对一部-东南区-蒲黄榆分中心 | Q28: 张雅冬 | R28: 徐健坤 | S28: 28864952 | T28: 正常工单 | U28: 2025-07-04 22:30 | V28: A（六个月内有报课意向工单） | W28: 六级,大学预科 | X28: 高三 | Y28: 香港科技大学 | Z28: 询问院系未告知 | AA28: 询问专业未告知 | AB28: 张雅冬 | AC28: 5442109 | AD28: 徐健坤 | AE28: 2025-07-07 10:20 | AF28: 徐健坤 | AG28: 2025-07-07 23:01 | AH28: LP1751854837306 | AI28: 大学英语一对一（30H） | AJ28: 国内考试 | AL28: 25000 | AN28: 郑威+zhengwei16@xdf.cn+ID+培训学校-北京学校-高中一对一部-东南区-蒲黄榆分中心 | AO28: 新签 | AP28: 已交接 | AR28: BJWY8096770861 | AT28: 2025-07-07 | AV28: 回访人：徐健坤，回访时间：2025-07-04 22:30，回访内容：高考英语133 基础不错 听力口语稍差 一对一方式 总结：您与北京新东方徐老师建立了联系，徐老师负责多种国内考试咨询，并邀请您参加明天的试听课。试听课由韩老师主讲四六级内容，口语部分由娜扎老师负责，她是北外英语演讲比赛的评委，发音纯正。您已预约试听课，并表示如有变动会提前通知。 下次回访建议：建议在试听课后跟进，了解您对课程内容和教师教学的反馈，同时询问是否有进一步的学习需求或问题，以便提供更个性化的教育咨询服务。；|回访人：徐健坤，回访时间：2025-07-06 23:04，回访内容：已经支付 明天交接 总结：北京新东方徐老师通过微信联系，提供大学预科、专升本、四六级、考研等国内考试咨询服务。双方讨论了试听课的安排，确认了授课老师（韩老师和娜扎老师）及课程内容（四六级和口语）。家长为孩子（张雅冬）报名了四六级VIP课程，并签署了培训协议，完成了支付流程。徐老师将后续安排入班对接。 下次回访建议： 1. 确认张雅冬同学的上课时间和地点是否已协调妥当，尤其是娜扎老师在国贸的课程安排。 2. 跟进学生对试听课的反馈，了解其学习需求和目标，以便进一步调整课程计划。 3. 提醒家长和学生关于课程进度和后续安排，确保学习计划顺利推进。 4. 如有其他优惠活动或课程推荐，可适时告知家长，增加合作机会。 | BA28: 75637628 | BB28: 否 | BC28: 25下考季 | BD28: 六级一对一 | BG28: 海外学校-国外大学-其他 | BH28: 是 | BM28: 本地人外地大学(归巢) | BN28: 客服
A29: 45 | B29: 北京大学部 | C29: 国内大学部 | D29: 未知 | E29: 114207297 | F29: 李雪68 | G29: 2025-06-13 17:22:01 | H29: 激活 | J29: 大四 | K29: 刘晓娟 | L29: 转介绍 | M29: 顾问转介绍-老带新 | N29: 激活 | Q29: 张裾扬 | R29: 刘晓娟 | S29: 28327261 | T29: 正常工单 | U29: 2025-06-13 17:38 | V29: A（六个月内有报课意向工单） | W29: 专八 | X29: 大四 | Y29: 中国石油大学(北京) | Z29: 英语 | AA29: 英语 | AB29: 张裾扬 | AC29: 5439737 | AD29: 刘晓娟 | AE29: 2025-07-05 15:42 | AF29: 刘晓娟 | AG29: 2025-07-05 15:42 | AH29: 16684991291 | AI29: 2026英语专业八级全程班【直播 + 录播】 | AJ29: 国内考试 | AL29: 1529.15 | AN29: 激活 | AO29: 新签 | AP29: 无须交接 | AT29: 2025-07-05 | AV29: 回访人：刘晓娟，回访时间：2025-06-27 18:19，回访内容：等放假再报；|回访人：刘晓娟，回访时间：2025-07-04 18:31，回访内容：确认放假时间，等回复；|回访人：刘晓娟，回访时间：2025-07-05 15:42，回访内容：报名 | AZ29: 长期班 | BA29: 67366752 | BB29: 是 | BG29: 国内高校-211 | BH29: 否 | BL29: 110483407 | BM29: 本地人本地大学(常规) | BN29: 客服
A30: 46 | B30: 北京大学部 | C30: 国内大学部 | D30: 家长 | E30: 117067786 | F30: 乔文娇 | G30: 2025-07-02 10:11:27 | H30: 新大一，高考英语130多分，学四六级，告知还有口语特训 | J30: 大一 | K30: 乔文娇 | L30: 电话 | M30: 大客服呼入 | O30: 乔文娇 | P30: 2025-07-02 10:29:10 | Q30: 张馨予 | R30: 黄智超 | S30: 28782116 | T30: 正常工单 | U30: 2025-07-02 21:57 | V30: A（六个月内有报课意向工单） | W30: 六级,大学预科 | X30: 大一 | Y30: 新大一 | Z30: 新大一 | AA30: 新大一 | AB30: 张馨予 | AC30: 5409352 | AD30: 黄智超 | AE30: 2025-07-05 22:44 | AF30: 黄智超 | AG30: 2025-07-08 16:37 | AH30: YKM25001 | AI30: 大学预科数学（新大一专属） | AJ30: 国内考试 | AL30: 3725.6 | AO30: 新签 | AP30: 已交接 | AQ30: BJWY2011wXCx1W | AR30: BJWY8390237928 | AS30: YKM250010029 | AT30: 2025-07-05 | AV30: 回访人：黄智超，回访时间：2025-07-02 21:57，回访内容：家长给孩子咨询暑假课程 推荐了预科联报的课程 邀约试听课 家长来添加我的微信 ；|回访人：黄智超，回访时间：2025-07-04 23:11，回访内容：确认邀明天试听课 跟孩子一起来；|回访人：黄智超，回访时间：2025-07-05 22:44，回访内容：签约 大学预科花园桥校区2期班 9160：YKS25002+YKM25002 | BA30: 80891575 | BB30: 否 | BC30: 25下考季 | BD30: 六级无忧计划 | BG30: 国内高校-双非 | BH30: 否 | BI30: 老师好 学员需要报名花园桥二期班：需操作转班，班号YKS25002+YKM25002 | BK30: 报名 | BM30: 本地人本地大学(常规) | BN30: 客服
A31: 47 | B31: 北京大学部 | C31: 国内大学部 | D31: 家长 | E31: 117067786 | F31: 乔文娇 | G31: 2025-07-02 10:11:27 | H31: 新大一，高考英语130多分，学四六级，告知还有口语特训 | J31: 大一 | K31: 乔文娇 | L31: 电话 | M31: 大客服呼入 | O31: 乔文娇 | P31: 2025-07-02 10:29:10 | Q31: 张馨予 | R31: 黄智超 | S31: 28782116 | T31: 正常工单 | U31: 2025-07-02 21:57 | V31: A（六个月内有报课意向工单） | W31: 六级,大学预科 | X31: 大一 | Y31: 新大一 | Z31: 新大一 | AA31: 新大一 | AB31: 张馨予 | AC31: 5409352 | AD31: 黄智超 | AE31: 2025-07-05 22:44 | AF31: 黄智超 | AG31: 2025-07-08 16:37 | AH31: YKS25001 | AI31: 六级无忧计划（新大一专属） | AJ31: 国内考试 | AL31: 5434.4 | AO31: 新签 | AP31: 已交接 | AQ31: BJWY2011wXCx1W | AR31: BJWY8390237928 | AS31: YKS250010027 | AT31: 2025-07-05 | AV31: 回访人：黄智超，回访时间：2025-07-02 21:57，回访内容：家长给孩子咨询暑假课程 推荐了预科联报的课程 邀约试听课 家长来添加我的微信 ；|回访人：黄智超，回访时间：2025-07-04 23:11，回访内容：确认邀明天试听课 跟孩子一起来；|回访人：黄智超，回访时间：2025-07-05 22:44，回访内容：签约 大学预科花园桥校区2期班 9160：YKS25002+YKM25002 | BA31: 80891575 | BB31: 否 | BC31: 25下考季 | BD31: 六级无忧计划 | BG31: 国内高校-双非 | BH31: 否 | BI31: 老师好 学员需要报名花园桥二期班：需操作转班，班号YKS25002+YKM25002 | BK31: 报名 | BM31: 本地人本地大学(常规) | BN31: 客服
