Workbook

Sheet 业绩奖金
A1: 业绩奖金表（一人可多条，需写清类别）
A2: 序号 | B2: 机构 | C2: 年月 | D2: 工号 | E2: 姓名 | F2: 部门 | G2: 薪资项目 | H2: 金额 | I2: 备注
A3: 1 | B3: 北京中心 | C3: 2026.12 | D3: 004192 | E3: 刘晓娟 | F3: B级学习顾问 | G3: 月度绩效 | H3: 2000 | I3: 人力：更正为1700
A4: 2 | B4: 北京中心 | C4: 2026.12 | D4: 004192 | E4: 刘晓娟 | F4: B级学习顾问 | G4: 顾问签约奖金 | H4: 28110.618
A5: 3 | B5: 北京中心 | C5: 2026.12 | D5: 004192 | E5: 刘晓娟 | F5: B级学习顾问 | G5: 其它奖金 | H5: 2000 | I5: 过渡性补贴2000
A6: 4 | B6: 北京中心 | C6: 2026.12 | D6: 004192 | E6: 刘晓娟 | F6: B级学习顾问 | G6: 季度奖金 | H6: 8000
A7: 5 | B7: 北京中心 | C7: 2026.12 | D7: 594606 | E7: 房国超 | F7: B级学习顾问 | G7: 月度绩效 | H7: 1640
A8: 6 | B8: 北京中心 | C8: 2026.12 | D8: 594606 | E8: 房国超 | F8: B级学习顾问 | G8: 顾问签约奖金 | H8: 4515.4087
A9: 7 | B9: 北京中心 | C9: 2026.12 | D9: 594606 | E9: 房国超 | F9: B级学习顾问 | G9: 其它奖金 | H9: 2000 | I9: 过渡性补贴2000
A10: 8 | B10: 北京中心 | C10: 2026.12 | D10: 608630 | E10: 宋增辉 | F10: B级学习顾问 | G10: 月度绩效 | H10: 0
A11: 9 | B11: 北京中心 | C11: 2026.12 | D11: 608630 | E11: 宋增辉 | F11: B级学习顾问 | G11: 顾问签约奖金 | H11: 1644.576
A12: 10 | B12: 北京中心 | C12: 2026.12 | D12: 608630 | E12: 宋增辉 | F12: B级学习顾问 | G12: 其它奖金 | H12: 2000 | I12: 过渡性补贴2000
A13: 11 | B13: 北京中心 | C13: 2026.12 | D13: 608617 | E13: 田一禾 | F13: B级学习顾问 | G13: 月度绩效 | H13: 0
A14: 12 | B14: 北京中心 | C14: 2026.12 | D14: 608617 | E14: 田一禾 | F14: B级学习顾问 | G14: 顾问签约奖金 | H14: 14874.12
A15: 13 | B15: 北京中心 | C15: 2026.12 | D15: 608617 | E15: 田一禾 | F15: B级学习顾问 | G15: 其它奖金 | H15: 2000 | I15: 过渡性补贴2000
A16: 14 | B16: 北京中心 | C16: 2026.12 | D16: 608617 | E16: 田一禾 | F16: B级学习顾问 | G16: 季度奖金 | H16: 8000
A17: 15 | B17: 北京中心 | C17: 2026.12 | D17: 343549 | E17: 黄智超 | F17: B级学习顾问 | G17: 季度奖金 | H17: 8000
A18: 16 | B18: 北京中心 | C18: 2026.12 | D18: 343549 | E18: 黄智超 | F18: B级学习顾问 | G18: 月度绩效 | H18: 2000
A19: 17 | B19: 北京中心 | C19: 2026.12 | D19: 343549 | E19: 黄智超 | F19: B级学习顾问 | G19: 顾问签约奖金 | H19: 25944.588
A20: 18 | B20: 北京中心 | C20: 2026.12 | D20: 343549 | E20: 黄智超 | F20: B级学习顾问 | G20: 其它奖金 | H20: 2000 | I20: 过渡性补贴2000
A21: 19 | B21: 北京中心 | C21: 2026.12 | D21: 343549 | E21: 黄智超 | F21: B级学习顾问 | G21: 其它奖金 | H21: 1000 | I21: 本月积分超过5分，奖励1000元
A22: 20 | B22: 北京中心 | C22: 2026.12 | D22: 639094 | E22: 徐一城 | F22: B级学习顾问 | G22: 月度绩效 | H22: 1520
A23: 21 | B23: 北京中心 | C23: 2026.12 | D23: 639094 | E23: 徐一城 | F23: B级学习顾问 | G23: 顾问签约奖金 | H23: 9912.688
A24: 22 | B24: 北京中心 | C24: 2026.12 | D24: 639094 | E24: 徐一城 | F24: B级学习顾问 | G24: 其它奖金 | H24: 2000 | I24: 过渡性补贴2000
B25: 北京中心 | C25: 2026.12 | D25: 258756 | E25: 刘文君 | F25: 销售主管 | G25: 季度绩效 | H25: 6133
B26: 北京中心 | C26: 2026.12 | D26: 合计 | H26: =SUM(H3:H25) -> 135295
A28: 备注
A29: 此张表格中的绩效奖金包含提成奖金、月度绩效、季度绩效、其他业绩奖金

Sheet 业绩核算明细
A1: 国内顾问业绩汇总（11月）
A2: 排名 | B2: 组别 | C2: 顾问 | D2: 月度数据 | I2: 转介绍总业绩奖金 | S2: 四六级总业绩奖金 | V2: 考研减去转介绍剩余业绩奖金
D3: 本月目标 | E3: 总进账 | F3: 线下退费 | G3: 综合业绩 | H3: 月度完成率 | I3: 转介绍目标 | J3: 转介绍总业绩 | K3: 考研转介绍金额 | L3: 四六级转介绍金额 | M3: 转介绍完成率 | N3: 四六级顾问对应提点 | O3: 四六级转介绍提点奖金 | P3: 考研顾问转介绍提点 | Q3: 考研转介绍奖金 | R3: 总转介绍奖金 | S3: 减去转介绍的剩余业绩 | T3: 对应提点 | U3: 四六级提点奖金 | V3: 考研减去转介绍剩余业绩 | W3: 对应提点 | X3: 考研提点奖金 | Y3: 总计奖金
A4: 四六级 | C4: 刘晓娟 | D4: 290000 | E4: =四六级进账!D3 -> 592469.15 | F4: =四六级进账!E3 -> 90192 | G4: =E4-F4 -> 502277.15 | H4: =G4/D4 -> 1.7319902 | I4: 25000 | J4: =K4+L4 -> 65920 | K4: 62800 | L4: 3120 | M4: =L4/I4 -> 0.1248 | N4: =IF(ISNUMBER(IF(H4>=150%,5%,IF(H4>=120%,4%,IF(H4>=100%,3%,IF(H4>=80%,1.8%,IF(H4>=70%,0.8%,"未达提点门槛")))))),IF(H4>=150%,5%,IF(H4>=120%,4%,IF(H4>=100%,3%,IF(H4>=80%,1.8%,IF(H4>=70%,0.8%,"未达提点门槛")))))+IF(M4>=100%,0.2%,IF(M4<70%,-0.2%,0)),"未达提点门槛") -> 0.048 | O4: =L4*N4 -> 149.76 | P4: =IF(ISNUMBER(IF(H4>=150%,5%,IF(H4>=120%,4%,IF(H4>=100%,3%,IF(H4>=80%,1.8%,IF(H4>=70%,0.8%,"未达提点门槛")))))),MIN(IF(H4>=150%,5%,IF(H4>=120%,4%,IF(H4>=100%,3%,IF(H4>=80%,1.8%,0.8%)))+IF(M4>=100%,0.2%,IF(M4<70%,-0.2%,0))),3%),"未达提点门槛") -> 0.03 | Q4: =K4*P4 -> 1884 | R4: =O4+Q4 -> 2033.76 | S4: =G4-L4 -> 499157.15 | T4: =IF(H4>=150%,5%,IF(H4>=120%,4%,IF(H4>=100%,3%,IF(H4>=80%,1.8%,IF(H4>=70%,0.8%,"未达提点门槛"))))) -> 0.05 | U4: =S4*T4 -> 24957.858 | V4: =SUMIF(考研进账!P:P,C4,考研进账!H:H)-K4 -> 37300 | W4: =IF(H4>=100%,3%,IF(H4>=80%,1.8%,IF(H4>=70%,0.8%,"未达提点门槛"))) -> 0.03 | X4: =V4*W4 -> 1119 | Y4: =X4+U4+R4 -> 28110.618
C5: 房国超 | D5: 290000 | E5: =四六级进账!D4 -> 278067.15 | F5: =四六级进账!E4 -> 25340 | G5: =E5-F5 -> 252727.15 | H5: =G5/D5 -> 0.87147293 | I5: 25000 | J5: =K5+L5 -> 16840 | K5: 0 | L5: 16840 | M5: =L5/I5 -> 0.6736 | N5: =IF(ISNUMBER(IF(H5>=150%,5%,IF(H5>=120%,4%,IF(H5>=100%,3%,IF(H5>=80%,1.8%,IF(H5>=70%,0.8%,"未达提点门槛")))))),IF(H5>=150%,5%,IF(H5>=120%,4%,IF(H5>=100%,3%,IF(H5>=80%,1.8%,IF(H5>=70%,0.8%,"未达提点门槛")))))+IF(M5>=100%,0.2%,IF(M5<70%,-0.2%,0)),"未达提点门槛") -> 0.016 | O5: =L5*N5 -> 269.44 | P5: =IF(ISNUMBER(IF(H5>=150%,5%,IF(H5>=120%,4%,IF(H5>=100%,3%,IF(H5>=80%,1.8%,IF(H5>=70%,0.8%,"未达提点门槛")))))),MIN(IF(H5>=150%,5%,IF(H5>=120%,4%,IF(H5>=100%,3%,IF(H5>=80%,1.8%,0.8%)))+IF(M5>=100%,0.2%,IF(M5<70%,-0.2%,0))),3%),"未达提点门槛") -> 0.016 | Q5: =K5*P5 -> 0 | R5: =O5+Q5 -> 269.44 | S5: =G5-L5 -> 235887.15 | T5: =IF(H5>=150%,5%,IF(H5>=120%,4%,IF(H5>=100%,3%,IF(H5>=80%,1.8%,IF(H5>=70%,0.8%,"未达提点门槛"))))) -> 0.018 | U5: =S5*T5 -> 4245.9687 | V5: =SUMIF(考研进账!P:P,C5,考研进账!H:H)-K5 -> 0 | W5: =IF(H5>=100%,3%,IF(H5>=80%,1.8%,IF(H5>=70%,0.8%,"未达提点门槛"))) -> 0.018 | X5: =V5*W5 -> 0 | Y5: =X5+U5+R5 -> 4515.4087
C6: 宋增辉 | D6: 320000 | E6: =四六级进账!D5 -> 249852 | F6: =四六级进账!E5 -> 44280 | G6: =E6-F6 -> 205572 | H6: =G6/D6 -> 0.6424125 | I6: 25000 | J6: =K6+L6 -> 0 | K6: 0 | L6: 0 | M6: =L6/I6 -> 0 | N6: 0.008 | O6: 0 | P6: =IF(ISNUMBER(IF(H6>=150%,5%,IF(H6>=120%,4%,IF(H6>=100%,3%,IF(H6>=80%,1.8%,IF(H6>=70%,0.8%,"未达提点门槛")))))),MIN(IF(H6>=150%,5%,IF(H6>=120%,4%,IF(H6>=100%,3%,IF(H6>=80%,1.8%,0.8%)))+IF(M6>=100%,0.2%,IF(M6<70%,-0.2%,0))),3%),"未达提点门槛") -> 未达提点门槛 | Q6: 0 | R6: =O6+Q6 -> 0 | S6: =G6-L6 -> 205572 | T6: 0.008 | U6: =S6*T6 -> 1644.576 | V6: =SUMIF(考研进账!P:P,C6,考研进账!H:H)-K6 -> 0 | W6: 0 | X6: =V6*W6 -> 0 | Y6: =X6+U6+R6 -> 1644.576
C7: 田一禾 | D7: 290000 | E7: =四六级进账!D6 -> 460819 | F7: =四六级进账!E6 -> 97516 | G7: =E7-F7 -> 363303 | H7: =G7/D7 -> 1.252769 | I7: 25000 | J7: =K7+L7 -> 0 | K7: 0 | L7: 0 | M7: =L7/I7 -> 0 | N7: =IF(ISNUMBER(IF(H7>=150%,5%,IF(H7>=120%,4%,IF(H7>=100%,3%,IF(H7>=80%,1.8%,IF(H7>=70%,0.8%,"未达提点门槛")))))),IF(H7>=150%,5%,IF(H7>=120%,4%,IF(H7>=100%,3%,IF(H7>=80%,1.8%,IF(H7>=70%,0.8%,"未达提点门槛")))))+IF(M7>=100%,0.2%,IF(M7<70%,-0.2%,0)),"未达提点门槛") -> 0.038 | O7: =L7*N7 -> 0 | P7: =IF(ISNUMBER(IF(H7>=150%,5%,IF(H7>=120%,4%,IF(H7>=100%,3%,IF(H7>=80%,1.8%,IF(H7>=70%,0.8%,"未达提点门槛")))))),MIN(IF(H7>=150%,5%,IF(H7>=120%,4%,IF(H7>=100%,3%,IF(H7>=80%,1.8%,0.8%)))+IF(M7>=100%,0.2%,IF(M7<70%,-0.2%,0))),3%),"未达提点门槛") -> 0.03 | Q7: =K7*P7 -> 0 | R7: =O7+Q7 -> 0 | S7: =G7-L7 -> 363303 | T7: =IF(H7>=150%,5%,IF(H7>=120%,4%,IF(H7>=100%,3%,IF(H7>=80%,1.8%,IF(H7>=70%,0.8%,"0"))))) -> 0.04 | U7: =S7*T7 -> 14532.12 | V7: =SUMIF(考研进账!P:P,C7,考研进账!H:H)-K7 -> 11400 | W7: =IF(H7>=100%,3%,IF(H7>=80%,1.8%,IF(H7>=70%,0.8%,"未达提点门槛"))) -> 0.03 | X7: =V7*W7 -> 342 | Y7: =X7+U7+R7 -> 14874.12
C8: 黄智超 | D8: 290000 | E8: =四六级进账!D7 -> 695660.15 | F8: =四六级进账!E7 -> 190702 | G8: =E8-F8 -> 504958.15 | H8: =G8/D8 -> 1.741235 | I8: 25000 | J8: =K8+L8 -> 66340 | K8: 0 | L8: 66340 | M8: =L8/I8 -> 2.6536 | N8: =IF(ISNUMBER(IF(H8>=150%,5%,IF(H8>=120%,4%,IF(H8>=100%,3%,IF(H8>=80%,1.8%,IF(H8>=70%,0.8%,"未达提点门槛")))))),IF(H8>=150%,5%,IF(H8>=120%,4%,IF(H8>=100%,3%,IF(H8>=80%,1.8%,IF(H8>=70%,0.8%,"未达提点门槛")))))+IF(M8>=100%,0.2%,IF(M8<70%,-0.2%,0)),"未达提点门槛") -> 0.052 | O8: =L8*N8 -> 3449.68 | P8: =IF(ISNUMBER(IF(H8>=150%,5%,IF(H8>=120%,4%,IF(H8>=100%,3%,IF(H8>=80%,1.8%,IF(H8>=70%,0.8%,"未达提点门槛")))))),MIN(IF(H8>=150%,5%,IF(H8>=120%,4%,IF(H8>=100%,3%,IF(H8>=80%,1.8%,0.8%)))+IF(M8>=100%,0.2%,IF(M8<70%,-0.2%,0))),3%),"未达提点门槛") -> 0.03 | Q8: =K8*P8 -> 0 | R8: =O8+Q8 -> 3449.68 | S8: =G8-L8 -> 438618.15 | T8: =IF(H8>=150%,5%,IF(H8>=120%,4%,IF(H8>=100%,3%,IF(H8>=80%,1.8%,IF(H8>=70%,0.8%,"未达提点门槛"))))) -> 0.05 | U8: =S8*T8 -> 21930.908 | V8: =SUMIF(考研进账!P:P,C8,考研进账!H:H)-K8 -> 18800 | W8: =IF(H8>=100%,3%,IF(H8>=80%,1.8%,IF(H8>=70%,0.8%,"未达提点门槛"))) -> 0.03 | X8: =V8*W8 -> 564 | Y8: =X8+U8+R8 -> 25944.588
C9: 徐一城 | D9: 320000 | E9: =四六级进账!D8 -> 354120 | F9: =四六级进账!E8 -> 22960 | G9: =E9-F9 -> 331160 | H9: =G9/D9 -> 1.034875 | I9: 25000 | J9: =K9+L9 -> 11056 | K9: 0 | L9: 11056 | M9: =L9/I9 -> 0.44224 | N9: =IF(ISNUMBER(IF(H9>=150%,5%,IF(H9>=120%,4%,IF(H9>=100%,3%,IF(H9>=80%,1.8%,IF(H9>=70%,0.8%,"未达提点门槛")))))),IF(H9>=150%,5%,IF(H9>=120%,4%,IF(H9>=100%,3%,IF(H9>=80%,1.8%,IF(H9>=70%,0.8%,"未达提点门槛")))))+IF(M9>=100%,0.2%,IF(M9<70%,-0.2%,0)),"未达提点门槛") -> 0.028 | O9: =L9*N9 -> 309.568 | P9: =IF(ISNUMBER(IF(H9>=150%,5%,IF(H9>=120%,4%,IF(H9>=100%,3%,IF(H9>=80%,1.8%,IF(H9>=70%,0.8%,"未达提点门槛")))))),MIN(IF(H9>=150%,5%,IF(H9>=120%,4%,IF(H9>=100%,3%,IF(H9>=80%,1.8%,0.8%)))+IF(M9>=100%,0.2%,IF(M9<70%,-0.2%,0))),3%),"未达提点门槛") -> 0.028 | Q9: =K9*P9 -> 0 | R9: =O9+Q9 -> 309.568 | S9: =G9-L9 -> 320104 | T9: =IF(H9>=150%,5%,IF(H9>=120%,4%,IF(H9>=100%,3%,IF(H9>=80%,1.8%,IF(H9>=70%,0.8%,"未达提点门槛"))))) -> 0.03 | U9: =S9*T9 -> 9603.12 | V9: =SUMIF(考研进账!P:P,C9,考研进账!H:H)-K9 -> 0 | W9: =IF(H9>=100%,3%,IF(H9>=80%,1.8%,IF(H9>=70%,0.8%,"未达提点门槛"))) -> 0.03 | X9: 0 | Y9: =X9+U9+R9 -> 9912.688
C10: 小组合计 | D10: =SUM(D4:D9) -> 1800000 | E10: =SUM(E4:E9) -> 2630987.5 | F10: =SUM(F4:F9) -> 470990 | G10: =G4+G5+G6+G7+G8+G9 -> 2159997.5 | H10: =G10/D10 -> 1.1999986 | J10: 未达签约人头目标 | U10: =SUM(U4:U9) -> 76914.55 | V10: =SUM(V4:V9) -> 67500 | W10: - | X10: =SUM(X4:X9) -> 2025 | Y10: =SUM(Y4:Y9) -> 85001.998

Sheet 12月绩效
A1: 四六级 | D1: 资源处理时效（10） | H1: 老带新签约人头（30） | L1: 9月新增资源签约率（60） | P1: 合计得分 | Q1: 发放比例 | R1: 月度绩效标准 | S1: 月绩效应发
A2: 工号 | B2: 顾问 | C2: 备注 | D2: 目标 | E2: 数据 | F2: 完成率 | G2: 得分 | H2: 目标 | I2: 完成 | J2: 完成率 | K2: 得分 | L2: 目标 | M2: 完成情况 | N2: 完成率 | O2: 得分
A3: 004192 | B3: 刘晓娟 | C3: / | D3: 30min | E3: 12.89 | F3: 1 | G3: 10 | H3: 4 | I3: 2 | J3: =I3/H3 -> 0.5 | K3: =30*J3 -> 15 | L3: 0.28 | M3: 0.3172 | N3: =M3/L3 -> 1.1328571 | O3: 60 | P3: =G3+K3+O3 -> 85 | Q3: 1 | R3: 2000 | S3: =R3*Q3 -> 2000
A4: 594606 | B4: 房国超 | C4: / | D4: 30min | E4: 4.5 | F4: 1 | G4: 10 | H4: 4 | I4: 3 | J4: =I4/H4 -> 0.75 | K4: =30*J4 -> 22.5 | L4: 0.28 | M4: 0.2323 | N4: =M4/L4 -> 0.82964286 | O4: =60*N4 -> 49.778571 | P4: =G4+K4+O4 -> 82.278571 | Q4: 0.82 | R4: 2000 | S4: =R4*Q4 -> 1640
A5: 608630 | B5: 宋增辉 | C5: / | D5: 30min | E5: 25.83 | F5: 1 | G5: 10 | H5: 4 | I5: 0 | J5: =I5/H5 -> 0 | K5: =30*J5 -> 0 | L5: 0.28 | M5: 0.1548 | N5: =M5/L5 -> 0.55285714 | O5: =60*N5 -> 33.171429 | P5: =G5+K5+O5 -> 43.171429 | Q5: 0 | R5: 2000 | S5: =R5*Q5 -> 0
A6: 608617 | B6: 田一禾 | C6: / | D6: 30min | E6: 30.36 | F6: 1 | G6: 10 | H6: 4 | I6: 0 | J6: =I6/H6 -> 0 | K6: =30*J6 -> 0 | L6: 0.28 | M6: 0.2476 | N6: =M6/L6 -> 0.88428571 | O6: =60*N6 -> 53.057143 | P6: =G6+K6+O6 -> 63.057143 | Q6: 0 | R6: 2000 | S6: =R6*Q6 -> 0
A7: 343549 | B7: 黄智超 | C7: / | D7: 30min | E7: 5.15 | F7: 1 | G7: 10 | H7: 4 | I7: 4 | J7: =I7/H7 -> 1 | K7: =30*J7 -> 30 | L7: 0.28 | M7: 0.3828 | N7: =M7/L7 -> 1.3671429 | O7: 60 | P7: =G7+K7+O7 -> 100 | Q7: 1 | R7: 2000 | S7: =R7*Q7 -> 2000
A8: 639094 | B8: 徐一城 | C8: / | D8: 30min | E8: 新人第三个月保护期打满 | F8: 1 | G8: 10 | H8: 4 | I8: 2 | J8: =I8/H8 -> 0.5 | K8: 6 | L8: 0.28 | M8: 0.28 | N8: =M8/L8 -> 1 | O8: =60*N8 -> 60 | P8: =G8+K8+O8 -> 76 | Q8: 0.76 | R8: 2000 | S8: =R8*Q8 -> 1520
G39: a

Sheet 转介绍金额和人头
A1: 姓名 | B1: 四六级签约金额 | C1: 转介绍签约人头 | I1: 序号 | J1: 学校 | K1: 部门 | L1: 签约日期 | M1: 姓名 | N1: 面询表类型 | O1: 订金 | P1: 学费 | Q1: 续费类型 | R1: 推荐人 | S1: 类型 | T1: 特殊备注 | U1: 是否交接 | V1: 一级获取渠道 | W1: 二级获取渠道 | X1: 录入人 | Y1: 录入时间 | Z1: 更新人 | AA1: 更新时间 | AB1: 工单录入时间 | AC1: 工单等级 | AD1: 操作人编号 | AE1: 学员号 | AF1: 报班日期 | AG1: 学员状态 | AH1: 咨询课程 | AI1: 学校 | AJ1: 年级 | AK1: 院系 | AL1: 专业 | AM1: 考季 | AN1: 报名产品 | AO1: 报名科目
A2: 刘晓娟 | B2: =SUMIF(X:X,A2,P:P) -> 3120 | C2: 2 | I2: 9 | J2: 北京大学部 | K2: 国内大学部 | L2: 2025-12-31 | M2: 孙楚凝 | P2: 3120 | R2: 宋燕 | S2: 续班 | U2: 未交接 | V2: 转介绍 | W2: 顾问转介绍-其他(不返现) | X2: 刘晓娟 | Y2: 2025-12-31 12:31 | AB2: 2025-12-31 11:17:59 | AC2: A（六个月内有报课意向工单） | AE2: BJWY4423360303 | AH2: 专升本 | AI2: 北京劳动保障职业学院 | AJ2: 大二 | AK2: 法学 | AL2: 法学 | AM2: 25考季 | AN2: 专升本VIP | AO2: 英语
A3: 房国超 | B3: =SUMIF(X:X,A3,P:P) -> 16840 | C3: 3 | I3: 24 | J3: 北京大学部 | K3: 国内大学部 | L3: 2025-12-31 | M3: 徐梓熙 | N3: 国内考试 | P3: 5382 | R3: 徐一城 | S3: 新签 | U3: 已交接 | V3: 转介绍 | W3: 顾问转介绍-其他(不返现) | X3: 徐一城 | Y3: 2025-12-31 11:01 | Z3: 徐一城 | AA3: 2025-12-31 11:01 | AB3: 2025-12-29 18:03:52 | AC3: B（需长时间跟单或只需要规划） | AD3: WebReg | AE3: BJWY4022871188 | AF3: 2025-12-31 | AH3: 四级 | AI3: 询问院校未告知 | AJ3: 大一 | AK3: 询问院系未告知 | AL3: 询问专业未告知 | AM3: 26上考季 | AN3: 四级无忧计划
A4: 宋增辉 | B4: =SUMIF(X:X,A4,P:P) -> 0 | C4: 0 | I4: 97 | J4: 北京大学部 | K4: 国内大学部 | L4: 2025-12-25 | M4: 欧紫舒 | N4: 国内考试 | P4: 19600 | Q4: 同科续费 | R4: 罗昕煜 | S4: 续班 | U4: 已交接 | V4: 转介绍 | W4: 顾问转介绍-其他(不返现) | X4: 黄智超 | Y4: 2025-12-25 19:18 | Z4: 黄智超 | AA4: 2025-12-25 19:19 | AB4: 2025-12-25 19:18:25 | AC4: B（需长时间跟单或只需要规划） | AD4: BJWY22035556hl | AE4: BJWY6485401846 | AF4: 2025-12-25 | AH4: 四级 | AI4: 中国音乐学院 | AJ4: 大二 | AK4: 教育学院 | AL4: 音乐教育 | AM4: 25下考季 | AN4: 四级无忧计划
A5: 田一禾 | B5: =SUMIF(X:X,A5,P:P) -> 0 | C5: 0 | I5: 103 | J5: 北京大学部 | K5: 国内大学部 | L5: 2025-12-24 | M5: 陈锦阳 | N5: 国内考试 | P5: 15120 | R5: 姚姚妈 | S5: 新签 | U5: 已交接 | V5: 转介绍 | W5: 顾问转介绍-其他(不返现) | X5: 黄智超 | Y5: 2025-12-24 14:38 | Z5: 黄智超 | AA5: 2025-12-24 14:38 | AB5: 2025-12-24 12:52:33 | AC5: A（六个月内有报课意向工单） | AD5: WebReg | AE5: BJWY0387887950 | AF5: 2025-12-24 | AH5: 四级 | AI5: 哈尔滨商业大学 | AJ5: 大一 | AK5: 金融学院 | AL5: 金融学 | AM5: 26上考季 | AN5: 四级无忧计划
A6: 黄智超 | B6: =SUMIF(X:X,A6,P:P) -> 66340 | C6: 4 | I6: 108 | J6: 北京大学部 | K6: 国内大学部 | L6: 2025-12-24 | M6: 陈挚赫 | N6: 国内考试 | P6: 19620 | R6: 黄智超 | S6: 新签 | U6: 已交接 | V6: 转介绍 | W6: 顾问转介绍-其他(不返现) | X6: 黄智超 | Y6: 2025-12-24 13:11 | Z6: 黄智超 | AA6: 2025-12-24 13:11 | AB6: 2025-12-23 17:59:13 | AC6: A（六个月内有报课意向工单） | AD6: BJWY25030q8UPI | AE6: BJWY4414649577 | AF6: 2025-12-24 | AH6: 四级 | AI6: 北京建筑大学 | AJ6: 大一 | AK6: 机电与车辆工程学院 | AL6: 机械工程 | AM6: 26上考季 | AN6: 四级无忧计划
A7: 徐一城 | B7: =SUMIF(X:X,A7,P:P) -> 11056 | C7: 2 | I7: 122 | J7: 北京大学部 | K7: 国内大学部 | L7: 2025-12-22 | M7: 贺喜 | N7: 国内考试 | P7: 12000 | R7: 幽幽 | S7: 新签 | U7: 已交接 | V7: 转介绍 | W7: 顾问转介绍-其他(不返现) | X7: 黄智超 | Y7: 2025-12-22 14:46 | Z7: 黄智超 | AA7: 2025-12-22 14:51 | AB7: 2025-12-08 13:35:04 | AC7: B（需长时间跟单或只需要规划） | AE7: BJWY6679910353 | AH7: 大学学科辅导 | AI7: 清华大学 | AJ7: 大一 | AK7: 电机工程与应用电子技术系 | AL7: 精密仪器 | AM7: 25下考季 | AN7: 大学学科辅导 | AO7: 专业课
I8: 161 | J8: 北京大学部 | K8: 国内大学部 | L8: 2025-12-16 | M8: 王俊文 | N8: 国内考试 | P8: 5580 | Q8: 同科续费 | R8: 王骁BJWY5697728947 | S8: 续班 | U8: 已交接 | V8: 转介绍 | W8: 老带新系统顾问 | X8: 房国超 | Y8: 2025-12-16 14:47 | Z8: 房国超 | AA8: 2025-12-16 14:47 | AB8: 2025-12-16 14:46:47 | AC8: A（六个月内有报课意向工单） | AD8: BJWY2201F8pC6h | AE8: BJWY0784585325 | AF8: 2025-12-16 | AH8: 四级 | AI8: 北方工业大学 | AJ8: 大一 | AK8: 机械与材料工程学院 | AL8: 机械设计制造及其自动化 | AM8: 26上考季 | AN8: 四级无忧计划
I9: 162 | J9: 北京大学部 | K9: 国内大学部 | L9: 2025-12-16 | M9: 王骁 | N9: 国内考试 | P9: 5780 | Q9: 同科续费 | R9: 姬月 | S9: 续班 | U9: 已交接 | V9: 转介绍 | W9: 顾问续费 | X9: 房国超 | Y9: 2025-12-16 14:41 | Z9: 房国超 | AA9: 2025-12-16 14:42 | AB9: 2025-12-16 14:41:38 | AC9: A（六个月内有报课意向工单） | AD9: BJWY2201F8pC6h | AE9: BJWY5697728947 | AF9: 2025-12-16 | AH9: 六级 | AI9: 北京信息科技大学 | AJ9: 大一 | AK9: 计算机学院 | AL9: 数据科学与大数据技术 | AM9: 25下考季 | AN9: 六级无忧计划
I10: 165 | J10: 北京大学部 | K10: 国内大学部 | L10: 2025-12-16 | M10: 程梓翔 | N10: 国内考试 | P10: 5480 | Q10: 同科续费 | R10: 王骁BJWY5697728947 | S10: 续班 | U10: 已交接 | V10: 转介绍 | W10: 老带新系统顾问 | X10: 房国超 | Y10: 2025-12-16 14:48 | Z10: 房国超 | AA10: 2025-12-16 14:48 | AB10: 2025-12-16 14:48:00 | AC10: A（六个月内有报课意向工单） | AD10: BJWY2201F8pC6h | AE10: BJWY4161329609 | AF10: 2025-12-16 | AH10: 六级 | AI10: 华北电力大学 | AJ10: 大一 | AK10: 电气与电子工程学院 | AL10: 电气工程及其自动化 | AM10: 26上考季 | AN10: 六级无忧计划
I11: 188 | J11: 北京大学部 | K11: 国内大学部 | L11: 2025-12-12 | M11: 余明泽 | N11: 国内考试 | P11: 5674 | R11: 王梓冰 | S11: 新签 | U11: 已交接 | V11: 转介绍 | W11: 顾问转介绍-其他(不返现) | X11: 徐一城 | Y11: 2025-12-12 21:03 | Z11: 徐一城 | AA11: 2025-12-12 21:04 | AB11: 2025-12-09 18:56:22 | AC11: A（六个月内有报课意向工单） | AD11: BJWY24032w1g8X | AE11: BJWY3919474923 | AF11: 2025-12-12 | AH11: 六级 | AI11: 北京工业大学 | AJ11: 大一 | AK11: 环境与生命学部 | AL11: 生物技术（实验班） | AM11: 25下考季 | AN11: 六级无忧计划

Sheet 四六级进账
A1: 项目 | B1: 顾问 | C1: 月度数据
C2: 本月目标 | D2: 本月进账 | E2: 本月退费 | F2: 综合业绩 | G2: 月度完成率 | H2: 时间进度
A3: 四六级 | B3: 刘晓娟 | C3: 290000 | D3: =SUMIF(Y:Y,B3,Q:Q) -> 592469.15 | E3: =SUMIF(四六级退费合计!E:E,B3,四六级退费合计!AP:AP) -> 90192 | F3: =D3-E3 -> 502277.15 | G3: =F3/C3 -> 1.7319902 | H3: 1
B4: 房国超 | C4: 290000 | D4: =SUMIF(Y:Y,B4,Q:Q) -> 278067.15 | E4: =SUMIF(四六级退费合计!E:E,B4,四六级退费合计!AP:AP) -> 25340 | F4: =D4-E4 -> 252727.15 | G4: =F4/C4 -> 0.87147293
B5: 宋增辉 | C5: 320000 | D5: =SUMIF(Y:Y,B5,Q:Q) -> 249852 | E5: =SUMIF(四六级退费合计!E:E,B5,四六级退费合计!AP:AP) -> 44280 | F5: =D5-E5 -> 205572 | G5: =F5/C5 -> 0.6424125
B6: 田一禾 | C6: 290000 | D6: =SUMIF(Y:Y,B6,Q:Q) -> 460819 | E6: =SUMIF(四六级退费合计!E:E,B6,四六级退费合计!AP:AP) -> 97516 | F6: =D6-E6 -> 363303 | G6: =F6/C6 -> 1.252769
B7: 黄智超 | C7: 290000 | D7: =SUMIF(Y:Y,B7,Q:Q) -> 695660.15 | E7: =SUMIF(四六级退费合计!E:E,B7,四六级退费合计!AP:AP) -> 190702 | F7: =D7-E7 -> 504958.15 | G7: =F7/C7 -> 1.741235
B8: 徐一城 | C8: 320000 | D8: =SUMIF(Y:Y,B8,Q:Q) -> 354120 | E8: =SUMIF(四六级退费合计!E:E,B8,四六级退费合计!AP:AP) -> 22960 | F8: =D8-E8 -> 331160 | G8: =F8/C8 -> 1.034875
A9: 总计 | C9: =SUM(C3:C8) -> 1800000 | D9: =SUM(D3:D8) -> 2630987.5 | E9: =SUM(E3:E8) -> 470990 | F9: =SUM(F3:F8) -> 2159997.5 | G9: =F9/C9 -> 1.1999986
J11: 序号 | K11: 学校 | L11: 部门 | M11: 签约日期 | N11: 姓名 | O11: 面询表类型 | P11: 订金 | Q11: 学费 | R11: 续费类型 | S11: 推荐人 | T11: 类型 | U11: 特殊备注 | V11: 是否交接 | W11: 一级获取渠道 | X11: 二级获取渠道 | Y11: 录入人 | Z11: 录入时间 | AA11: 更新人 | AB11: 更新时间 | AC11: 工单录入时间 | AD11: 工单等级 | AE11: 操作人编号 | AF11: 学员号 | AG11: 报班日期 | AH11: 学员状态 | AI11: 咨询课程 | AJ11: 学校 | AK11: 年级 | AL11: 院系 | AM11: 专业 | AN11: 考季 | AO11: 报名产品 | AP11: 报名科目
J12: 1 | K12: 北京大学部 | L12: 国内大学部 | M12: 2025-12-28 | N12: 王乐予 | O12: 国内考试 | Q12: 5832 | T12: 新签 | V12: 已交接 | W12: 线上运营-私域中台 | X12: TMK合作 | Y12: 徐一城 | Z12: 2025-12-28 20:39 | AA12: 徐一城 | AB12: 2025-12-29 16:36 | AC12: 2025-12-21 09:22:21 | AD12: A（六个月内有报课意向工单） | AE12: WebReg | AF12: BJWY1159293703 | AG12: 2025-12-28 | AI12: 四级 | AJ12: 不详 | AK12: 大一 | AL12: 询问未告知 | AM12: 询问未告知 | AN12: 26上考季 | AO12: 四级无忧计划
J13: 3 | K13: 北京大学部 | L13: 国内大学部 | M13: 2025-12-14 | N13: 王宏章 | O13: 国内考试 | Q13: 49 | T13: 新签 | V13: 无须交接 | W13: 线上运营-小红书 | X13: 小红书 | Y13: 房国超 | Z13: 2025-12-14 22:10 | AA13: 房国超 | AB13: 2025-12-15 09:47 | AC13: 2025-12-14 20:37:29 | AD13: A（六个月内有报课意向工单） | AI13: 六级 | AJ13: 北京工业大学 | AK13: 研二 | AL13: 材料与制造学部 | AM13: 材料科学与工程 | AN13: 26上考季 | AO13: 六级无忧计划
J14: 4 | K14: 北京大学部 | L14: 国内大学部 | M14: 2025-12-14 | N14: 贾笑晗 | O14: 国内考试 | Q14: 249 | T14: 新签 | V14: 无须交接 | W14: 线上运营-私域中台 | X14: 集团官微 | Y14: 房国超 | Z14: 2025-12-14 11:50 | AA14: 房国超 | AB14: 2025-12-14 11:58 | AC14: 2025-12-14 10:32:26 | AD14: A（六个月内有报课意向工单） | AI14: 六级 | AJ14: 北京工业大学 | AK14: 大一 | AL14: 材料与制造学部 | AM14: 材料科学与工程 | AN14: 26上考季 | AO14: 六级无忧计划
J15: 5 | K15: 北京大学部 | L15: 国内大学部 | M15: 2025-12-14 | N15: 毕同 | O15: 国内考试 | Q15: 249 | T15: 续班 | V15: 无须交接 | W15: 线上运营-小红书 | X15: 小红书 | Y15: 黄智超 | Z15: 2025-12-14 12:14 | AA15: 黄智超 | AB15: 2025-12-14 12:16 | AC15: 2025-12-14 12:11:10 | AD15: B（需长时间跟单或只需要规划） | AI15: 六级 | AJ15: 北京师范大学 | AK15: 大一 | AL15: 教育学部 | AM15: 教育学 | AN15: 25下考季 | AO15: 六级无忧计划
J16: 6 | K16: 北京大学部 | L16: 国内大学部 | M16: 2025-12-08 | N16: 宋宇涵 | O16: 国内考试 | Q16: 1529.15 | T16: 新签 | V16: 无须交接 | W16: 线上运营-私域中台 | X16: 集团官微 | Y16: 黄智超 | Z16: 2025-12-08 15:20 | AA16: 黄智超 | AB16: 2025-12-08 15:20 | AC16: 2025-11-10 18:23:07 | AD16: A（六个月内有报课意向工单） | AI16: 专四 | AJ16: 北京师范大学 | AK16: 大二 | AL16: 外国语言文学学院 | AM16: 英语
J17: 7 | K17: 北京大学部 | L17: 国内大学部 | M17: 2025-12-31 | N17: 张云翔 | O17: 国内考试 | Q17: 5382 | T17: 新签 | V17: 未交接 | W17: 线上运营-本地生活平台 | X17: 地图标点 | Y17: 刘晓娟 | Z17: 2025-12-31 16:16 | AA17: 刘晓娟 | AB17: 2025-12-31 16:16 | AC17: 2025-12-27 12:24:30 | AD17: A（六个月内有报课意向工单） | AE17: WebReg | AF17: XDF1647563634 | AG17: 2025-12-31 | AI17: 四级 | AJ17: 北京林业大学 | AK17: 大一 | AL17: 林学院 | AM17: 林学 | AN17: 26上考季 | AO17: 四级无忧计划
J18: 8 | K18: 北京大学部 | L18: 国内大学部 | M18: 2025-12-31 | N18: 李多多 | Q18: 1999 | T18: 新签 | V18: 未交接 | W18: 新东方官网 | X18: 新东方PC官网 | Y18: 房国超 | Z18: 2025-12-31 23:06 | AC18: 2025-11-10 15:02:06 | AD18: A（六个月内有报课意向工单） | AI18: 专升本 | AJ18: 询问院校未告知 | AK18: 大三 | AL18: 询问院系未告知 | AM18: 询问专业未告知 | AN18: 26考季 | AO18: 专升本VIP | AP18: 英语
J19: 9 | K19: 北京大学部 | L19: 国内大学部 | M19: 2025-12-31 | N19: 孙楚凝 | Q19: 3120 | S19: 宋燕 | T19: 续班 | V19: 未交接 | W19: 转介绍 | X19: 顾问转介绍-其他(不返现) | Y19: 刘晓娟 | Z19: 2025-12-31 12:31 | AC19: 2025-12-31 11:17:59 | AD19: A（六个月内有报课意向工单） | AF19: BJWY4423360303 | AI19: 专升本 | AJ19: 北京劳动保障职业学院 | AK19: 大二 | AL19: 法学 | AM19: 法学 | AN19: 25考季 | AO19: 专升本VIP | AP19: 英语
J20: 10 | K20: 北京大学部 | L20: 国内大学部 | M20: 2025-12-31 | N20: 刘佳朋 | O20: 国内考试 | Q20: 15120 | R20: 同科续费 | S20: 罗志勇 | T20: 续班 | V20: 未交接 | W20: 转介绍 | X20: 学管续费推荐 | Y20: 刘晓娟 | Z20: 2025-12-31 10:24 | AA20: 刘晓娟 | AB20: 2025-12-31 10:24 | AC20: 2025-12-16 17:49:02 | AD20: B（需长时间跟单或只需要规划） | AE20: WebReg | AF20: BJWY9866282726 | AG20: 2025-12-31 | AI20: 六级 | AJ20: 河北农业大学 | AK20: 大三 | AL20: 机电工程学院 | AM20: 机械设计制造及其自动化 | AN20: 26上考季 | AO20: 六级寒假集训营
J21: 11 | K21: 北京大学部 | L21: 国内大学部 | M21: 2025-12-29 | N21: 深圳市33 | O21: 国内考试 | Q21: 1529.15 | T21: 新签 | V21: 未交接 | W21: 新东方官网 | X21: 新东方PC官网 | Y21: 刘晓娟 | Z21: 2025-12-29 13:19 | AA21: 刘晓娟 | AB21: 2025-12-29 13:20 | AC21: 2025-12-29 10:12:00 | AD21: A（六个月内有报课意向工单） | AI21: 专八 | AJ21: 询问院校未告知 | AK21: 大四 | AL21: 询问院系未告知 | AM21: 询问专业未告知
J22: 12 | K22: 北京大学部 | L22: 国内大学部 | M22: 2025-12-28 | N22: 孙楚凝 | Q22: 22880 | S22: 徐岩 | T22: 续班 | V22: 未交接 | W22: 转介绍 | X22: 学管续费推荐 | Y22: 刘晓娟 | Z22: 2025-12-28 15:51 | AC22: 2025-12-24 10:53:04 | AD22: A（六个月内有报课意向工单） | AF22: BJWY4423360303 | AI22: 专升本 | AJ22: 北京劳动保障职业学院 | AK22: 大二 | AL22: 法学 | AM22: 法学 | AN22: 26考季 | AO22: 专升本VIP | AP22: 英语
J23: 13 | K23: 北京大学部 | L23: 国内大学部 | M23: 2025-12-28 | N23: 张钰杭1 | Q23: 1999 | T23: 新签 | V23: 未交接 | W23: 线上运营-投放 | X23: 总部-百度投放 | Y23: 刘晓娟 | Z23: 2025-12-28 13:25 | AA23: 刘晓娟 | AB23: 2025-12-28 13:25 | AC23: 2025-12-23 10:00:55 | AD23: A（六个月内有报课意向工单） | AI23: 专升本 | AJ23: 北京经贸职业学院 | AK23: 高三 | AL23: 计算机 | AM23: 计算机 | AN23: 28考季 | AO23: 专升本全科全程班 | AP23: 英语
J24: 14 | K24: 北京大学部 | L24: 国内大学部 | M24: 2025-12-22 | N24: 李金泽 | Q24: 10000 | S24: 徐岩 | T24: 续班 | V24: 未交接 | W24: 转介绍 | X24: 学管续费推荐 | Y24: 刘晓娟 | Z24: 2025-12-22 18:35 | AC24: 2025-12-22 15:05:46 | AD24: A（六个月内有报课意向工单） | AF24: BJWY3281520680 | AI24: 大学学科辅导 | AJ24: 首都师范大学 | AK24: 大五 | AL24: 历史学院 | AM24: 历史学 | AN24: 25下考季 | AO24: 大学学科辅导 | AP24: 专业课
J25: 15 | K25: 北京大学部 | L25: 国内大学部 | M25: 2025-12-16 | N25: 林兰青 | O25: 国内考试 | Q25: 279 | T25: 新签 | V25: 未交接 | W25: 新东方官网 | X25: 新东方官网APP | Y25: 刘晓娟 | Z25: 2025-12-16 12:37 | AA25: 刘晓娟 | AB25: 2025-12-16 12:37 | AC25: 2025-12-16 12:37:24 | AD25: A（六个月内有报课意向工单） | AI25: 四级 | AJ25: 中国矿业大学（北京） | AK25: 大一 | AL25: 能源与矿业学院 | AM25: 采矿工程 | AN25: 26上考季 | AO25: 四级线上网课
J26: 16 | K26: 北京大学部 | L26: 国内大学部 | M26: 2025-12-13 | N26: 徐天佑 | Q26: 1600 | S26: 张泽7 | T26: 续班 | V26: 未交接 | W26: 转介绍 | X26: 学管续费推荐 | Y26: 刘晓娟 | Z26: 2025-12-13 16:56 | AC26: 2025-12-13 16:34:26 | AD26: A（六个月内有报课意向工单） | AF26: BJWY8809971011 | AI26: 考研VIP | AJ26: 北京交通大学 | AK26: 大四 | AL26: 语言与传播学院 | AM26: 网络与新媒体 | AN26: 26考季 | AO26: VIP - 畅学 | AP26: 管综
J27: 17 | K27: 北京大学部 | L27: 国内大学部 | M27: 2025-12-01 | N27: 何颖 | Q27: 1529.15 | T27: 新签 | V27: 未交接 | W27: 新东方官网 | X27: 新东方PC官网 | Y27: 房国超 | Z27: 2025-12-01 11:32 | AC27: 2025-11-29 16:43:27 | AD27: A（六个月内有报课意向工单） | AI27: 专八 | AJ27: 南昌应用技术师范学院 | AK27: 大学已毕业 | AL27: 教育学院 | AM27: 英语
J28: 18 | K28: 北京大学部 | L28: 国内大学部 | M28: 2025-12-31 | N28: 张墨涵 | O28: 国内考试 | Q28: 7560 | T28: 分单 | V28: 已交接 | W28: 线上运营-本地生活平台 | X28: 大众点评 | Y28: 房国超 | Z28: 2025-12-31 17:17 | AA28: 黄智超 | AB28: 2025-12-31 23:12 | AC28: 2025-12-26 20:28:26 | AD28: B（需长时间跟单或只需要规划） | AF28: BJWY0933636428 | AI28: 六级 | AJ28: 东北农业大学 | AK28: 大一 | AL28: 农学院 | AM28: 农学 | AN28: 26上考季 | AO28: 六级无忧计划
J29: 19 | K29: 北京大学部 | L29: 国内大学部 | M29: 2025-12-31 | N29: 周祖铖 | O29: 国内考试 | Q29: 5382 | T29: 新签 | V29: 已交接 | W29: 线上运营-私域中台 | X29: 视频号 | Y29: 房国超 | Z29: 2025-12-31 21:18 | AA29: 房国超 | AB29: 2025-12-31 21:18 | AC29: 2025-12-13 11:10:57 | AD29: A（六个月内有报课意向工单） | AE29: WebReg | AF29: BJWY3697560370 | AG29: 2025-12-31 | AI29: 六级 | AJ29: 中国石油大学（北京） | AK29: 大一 | AL29: 经济管理学院 | AM29: 金融学 | AN29: 26上考季 | AO29: 六级无忧计划
J30: 20 | K30: 北京大学部 | L30: 国内大学部 | M30: 2025-12-31 | N30: 李亚璇 | O30: 国内考试 | Q30: 5382 | T30: 新签 | V30: 已交接 | W30: 新东方官网 | X30: 新东方PC官网 | Y30: 黄智超 | Z30: 2025-12-31 19:54 | AA30: 黄智超 | AB30: 2025-12-31 19:54 | AC30: 2025-12-03 16:04:48 | AD30: A（六个月内有报课意向工单） | AE30: WebReg | AF30: BJWY8234509638 | AG30: 2025-12-31 | AI30: 六级 | AJ30: 中央财经大学 | AK30: 大一 | AL30: 经济学院 | AM30: 经济学 | AN30: 26上考季 | AO30: 六级无忧计划
J31: 21 | K31: 北京大学部 | L31: 国内大学部 | M31: 2025-12-31 | N31: 谢润晨 | O31: 国内考试 | Q31: 5832 | S31: 王成颖+wangchengying1@xdf.cn+产业机构-大学事业部-大学石家庄中心-考研项目部-销售管理部+顾问管理主管 | T31: 新签 | V31: 已交接 | W31: 转介绍 | X31: 内部员工推荐 | Y31: 黄智超 | Z31: 2025-12-31 19:47 | AA31: 黄智超 | AB31: 2025-12-31 19:48 | AC31: 2025-12-31 11:02:48 | AD31: A（六个月内有报课意向工单） | AE31: WebReg | AF31: BJWY5191810963 | AG31: 2025-12-31 | AI31: 四级 | AJ31: 河北东方学院 | AK31: 大二 | AL31: 文物与艺术学院 | AM31: 文物保护与修复 | AN31: 26上考季 | AO31: 四级无忧计划
J32: 22 | K32: 北京大学部 | L32: 国内大学部 | M32: 2025-12-31 | N32: 张墨涵 | O32: 国内考试 | Q32: 7560 | T32: 新签 | V32: 已交接 | W32: 线上运营-本地生活平台 | X32: 大众点评 | Y32: 黄智超 | Z32: 2025-12-31 17:17 | AA32: 黄智超 | AB32: 2025-12-31 23:12 | AC32: 2025-12-26 20:28:26 | AD32: B（需长时间跟单或只需要规划） | AE32: BJWY2101498uW2 | AF32: BJWY0933636428 | AG32: 2025-12-31 | AI32: 六级 | AJ32: 东北农业大学 | AK32: 大一 | AL32: 农学院 | AM32: 农学 | AN32: 26上考季 | AO32: 六级无忧计划
J33: 23 | K33: 北京大学部 | L33: 国内大学部 | M33: 2025-12-31 | N33: 于舒朦 | O33: 国内考试 | Q33: 5382 | T33: 新签 | V33: 已交接 | W33: 电话 | X33: 大客服呼入 | Y33: 刘晓娟 | Z33: 2025-12-31 12:33 | AA33: 刘晓娟 | AB33: 2025-12-31 12:33 | AC33: 2025-12-16 10:14:00 | AD33: A（六个月内有报课意向工单） | AE33: BJWY2101498uW2 | AF33: BJWY6218859735 | AG33: 2025-12-31 | AI33: 四级 | AJ33: 哈尔滨医科大学 | AK33: 大三 | AL33: 口腔医学院 | AM33: 口腔医学 | AN33: 26上考季 | AO33: 四级无忧计划
J34: 24 | K34: 北京大学部 | L34: 国内大学部 | M34: 2025-12-31 | N34: 徐梓熙 | O34: 国内考试 | Q34: 5382 | S34: 徐一城 | T34: 新签 | V34: 已交接 | W34: 转介绍 | X34: 顾问转介绍-其他(不返现) | Y34: 徐一城 | Z34: 2025-12-31 11:01 | AA34: 徐一城 | AB34: 2025-12-31 11:01 | AC34: 2025-12-29 18:03:52 | AD34: B（需长时间跟单或只需要规划） | AE34: WebReg | AF34: BJWY4022871188 | AG34: 2025-12-31 | AI34: 四级 | AJ34: 询问院校未告知 | AK34: 大一 | AL34: 询问院系未告知 | AM34: 询问专业未告知 | AN34: 26上考季 | AO34: 四级无忧计划
J35: 25 | K35: 北京大学部 | L35: 国内大学部 | M35: 2025-12-31 | N35: 王依雪 | O35: 国内考试 | Q35: 5832 | R35: 同科续费 | S35: 李玉迪 | T35: 续班 | V35: 已交接 | W35: 转介绍 | X35: 学管续费推荐 | Y35: 田一禾 | Z35: 2025-12-31 10:22 | AA35: 田一禾 | AB35: 2025-12-31 10:22 | AC35: 2025-12-26 17:11:21 | AD35: A（六个月内有报课意向工单） | AE35: BJWY2011wXCx1W | AF35: BJWY1668538930 | AG35: 2025-12-31 | AI35: 四级 | AJ35: 华北理工大学 | AK35: 大三 | AL35: 临床医学院 | AM35: 临床医学 | AN35: 26上考季 | AO35: 四级一对一
J36: 26 | K36: 北京大学部 | L36: 国内大学部 | M36: 2025-12-31 | N36: 杨歆 | O36: 国内考试 | Q36: 5382 | T36: 新签 | V36: 已交接 | W36: 合作 | X36: 集团资源 | Y36: 黄智超 | Z36: 2025-12-31 19:52 | AA36: 黄智超 | AB36: 2025-12-31 19:52 | AC36: 2025-12-22 19:11:00 | AD36: B（需长时间跟单或只需要规划） | AE36: WebReg | AF36: BJWY1237101581 | AG36: 2025-12-31 | AI36: 四级,英语 | AJ36: 询问院校未告知 | AK36: 大一 | AL36: 询问院系未告知 | AM36: 询问专业未告知 | AN36: 26下考季 | AO36: 四级无忧计划
J37: 27 | K37: 北京大学部 | L37: 国内大学部 | M37: 2025-12-31 | N37: 吴嘉伟 | O37: 国内考试 | Q37: 5382 | T37: 新签 | V37: 已交接 | W37: 线上运营-小红书 | X37: 小红书 | Y37: 徐一城 | Z37: 2025-12-31 23:36 | AA37: 徐一城 | AB37: 2025-12-31 23:36 | AC37: 2025-12-11 19:35:25 | AD37: A（六个月内有报课意向工单） | AE37: WebReg | AF37: BJWY4994271131 | AG37: 2025-12-31 | AI37: 六级 | AJ37: 北方民族大学 | AK37: 大二 | AL37: 法学院 | AM37: 法学 | AN37: 26上考季 | AO37: 六级无忧计划
J38: 28 | K38: 北京大学部 | L38: 国内大学部 | M38: 2025-12-31 | N38: 薛钰兰 | O38: 国内考试 | Q38: 19300 | T38: 新签 | V38: 已交接 | W38: 线上运营-私域中台 | X38: 集团官微 | Y38: 宋增辉 | Z38: 2025-12-31 22:37 | AA38: 宋增辉 | AB38: 2025-12-31 22:40 | AC38: 2025-12-28 11:23:11 | AD38: A（六个月内有报课意向工单） | AE38: WebReg | AF38: BJWY1698876738 | AG38: 2025-12-31 | AI38: 六级 | AJ38: 东北农业大学 | AK38: 大一 | AL38: 经济管理学院 | AM38: 农林经济管理 | AN38: 26上考季 | AO38: 六级无忧计划
J39: 29 | K39: 北京大学部 | L39: 国内大学部 | M39: 2025-12-31 | N39: 李梓曼 | O39: 国内考试 | Q39: 19300 | T39: 新签 | V39: 已交接 | W39: 线上运营-小红书 | X39: 小红书 | Y39: 徐一城 | Z39: 2025-12-31 21:56 | AA39: 徐一城 | AB39: 2025-12-31 21:56 | AC39: 2025-12-25 21:12:53 | AD39: A（六个月内有报课意向工单） | AE39: WebReg | AF39: BJWY7206183045 | AG39: 2025-12-31 | AI39: 四级 | AJ39: 中国传媒大学 | AK39: 大一 | AL39: 动画与数字艺术学院 | AM39: 动画 | AN39: 26上考季 | AO39: 四级无忧计划
J40: 30 | K40: 北京大学部 | L40: 国内大学部 | M40: 2025-12-31 | N40: 丁源 | O40: 国内考试 | Q40: 15120 | T40: 新签 | V40: 已交接 | W40: 线上运营-小红书 | X40: 小红书 | Y40: 徐一城 | Z40: 2025-12-31 21:48 | AA40: 徐一城 | AB40: 2025-12-31 21:49 | AC40: 2025-12-01 18:45:02 | AD40: A（六个月内有报课意向工单） | AE40: WebReg | AF40: BJWY1166696604 | AG40: 2025-12-31 | AI40: 六级 | AJ40: 大连理工大学 | AK40: 大一 | AL40: 物理学院 | AM40: 应用物理学 | AN40: 26上考季 | AO40: 六级集训营
J41: 31 | K41: 北京大学部 | L41: 国内大学部 | M41: 2025-12-31 | N41: 杨晓宇 | O41: 国内考试 | Q41: 5832 | T41: 新签 | V41: 已交接 | W41: 线上运营-本地生活平台 | X41: 百度地图 | Y41: 房国超 | Z41: 2025-12-31 21:07 | AA41: 房国超 | AB41: 2025-12-31 21:07 | AC41: 2025-12-29 18:37:06 | AD41: A（六个月内有报课意向工单） | AE41: WebReg | AF41: BJWY1721248700 | AG41: 2025-12-31 | AI41: 四级 | AJ41: 黑龙江科技大学 | AK41: 大一 | AL41: 管理学院 | AM41: 会计学 | AN41: 26上考季 | AO41: 四级无忧计划
...

Sheet 无考研退费
A1: 提交日期 | B1: OA流水号 | C1: 学管姓名 | D1: 学管是否代办 | E1: 顾问姓名 | F1: 顾问是否代办 | G1: 91系统-最新报名二级渠道 | H1: 转介绍人 | I1: 原班所属项目 | J1: 新报入班级所属项目 | K1: 退费阶段 | L1: 退费一级原因（开课前） | M1: 退费一级原因 (开课后) | N1: 退费二级原因（专业课师资匹配原因） | O1: 退费二级原因（学员意愿转变_开课前） | P1: 退费二级原因（计划冲突_开课前） | Q1: 退费二级原因（中心原因_开课前） | R1: 退费二级原因（签约话术） | S1: 退费二级原因（教师） | T1: 退费二级原因（教学） | U1: 退费二级原因（课程安排） | V1: 退费二级原因（配套服务） | W1: 退费二级原因（配套学习设施） | X1: 退费二级原因（中心原因_开课后） | Y1: 退费二级原因（计划冲突_开课后） | Z1: 退费二级原因（学员意愿转变_开课后） | AA1: 退费三级原因（完全匹配不上）-院校、学院、专业、专业课代码及名称 | AB1: 退费详细原因说明（与OA退费详细说明保持一致） | AC1: 预计报名新班学费金额 | AD1: 转班金额（请学管填写所在班级实际金额） | AE1: 转班详细原因说明 | AF1: 提交时间 | AG1: 学校 | AH1: 学院 | AI1: 年级 | AJ1: 专业 | AK1: 您所办理的业务类型 | AL1: 提交人 | AM1: 退费类型 | AN1: 学员姓名 | AO1: 学员编码 | AP1: 退费金额 | AQ1: 办理日期-客服 | AR1: 月 | AS1: 日 | AT1: 退费方式-客服 | AW1: 需要跟进的顾问/学管 | AX1: 退费/转班特殊情况备注（若需要学管提供银行卡信息，可将需求填写在此处）-客服 | AY1: 是否完成退费/转班-客服 | AZ1: 父记录 | BA1: 父记录
A2: 2025/12/26 | B2: NO.2017612633063657031 | C2: 马一鸣16 | E2: 刘晓娟 | G2: 学管续费推荐 | H2: 许庆典 | I2: 无忧项目-专业课 | J2: 无忧项目 | K2: 开课前退费 | L2: 学员意愿转变_开课前 | O2: 认为课程用处不大/不适合自己 | AB2: 学生想要从408的一对一课程转到408的班课学习，需要退到学员账户，再特批报入。 | AC2: ¥9000.00 | AF2: 2025-12-26 | AG2: 北京城市学院 | AH2: 信息学部 | AI2: 大三 | AJ2: 电子信息工程 | AK2: 退费 | AL2: 马一鸣16 | AM2: 转项目/转班/退出重报等未产生实际退费 | AN2: 王晓巍 | AO2: BJWY7037419543 | AP2: ¥9000.00 | AQ2: 2025 | AR2: 12 | AS2: 27 | AT2: 12.27 已办理，退回账户余额@马一鸣16 (马一鸣) 未办理：未找到退费审核记录@马一鸣16 (马一鸣)（12.26） [图片] | AY2: TRUE

Sheet 考研进账
A1: 序号 | B1: 学校 | C1: 部门 | D1: 签约日期 | E1: 姓名 | F1: 面询表类型 | G1: 订金 | H1: 学费 | I1: 续费类型 | J1: 推荐人 | K1: 类型 | L1: 特殊备注 | M1: 是否交接 | N1: 一级获取渠道 | O1: 二级获取渠道 | P1: 录入人 | Q1: 录入时间 | R1: 更新人 | S1: 更新时间 | T1: 工单录入时间 | U1: 工单等级 | V1: 操作人编号 | W1: 学员号 | X1: 报班日期 | Y1: 学员状态 | Z1: 咨询课程 | AA1: 学校 | AB1: 年级 | AC1: 院系 | AD1: 专业 | AE1: 考季 | AF1: 报名产品 | AG1: 报名科目 | AH1: 学校班型/类型 | AI1: 签约单ID | AJ1: 大学生源类型 | AK1: 在线学员ID | AL1: 面询表状态 | AM1: 是否关联协议 | AN1: 签署协议时间 | AO1: 协议签署金额 | AP1: 签约金额是否一致
A2: 74 | B2: 北京大学部 | C2: 国内大学部 | D2: 2025-12-28 | E2: 陶泽禹 | F2: 国内考试 | H2: 62800 | J2: 刘晓娟 | K2: 新签 | M2: 已交接 | N2: 转介绍 | O2: 老带新系统顾问 | P2: 刘晓娟 | Q2: 2025-12-28 12:36 | R2: 刘晓娟 | S2: 2025-12-28 12:36 | T2: 2025-12-18 13:37:16 | U2: A（六个月内有报课意向工单） | V2: BJWY24032w1g8X | W2: XDF062303185327611 | X2: 2025-12-28 | Z2: 考研专业课,考研集训营 | AA2: 北京信息科技大学 | AB2: 大三 | AC2: 电子商务 | AD2: 电子商务 | AE2: 27考季 | AF2: 寒暑假集训营（春秋OMO）,考研专业课150 | AG2: 英语,政治,数学,专业课150 | AH2: 国内高校-双非 | AI2: 5727330 | AJ2: 本地人本地大学(常规) | AL2: 学管主管审批通过 | AM2: 是 | AN2: 2025-12-28 10:33 | AO2: 62800 | AP2: 是
A3: 76 | B3: 北京大学部 | C3: 国内大学部 | D3: 2025-12-27 | E3: 王晓巍 | F3: 国内考试 | H3: 9000 | I3: 扩科续费 | K3: 续班 | M3: 已交接 | N3: 转介绍 | O3: 学管续费推荐 | P3: 刘晓娟 | Q3: 2025-12-27 14:32 | R3: 刘晓娟 | S3: 2025-12-27 14:32 | T3: 2025-12-27 14:31:44 | U3: A（六个月内有报课意向工单） | V3: BJWY22035556hl | W3: BJWY7037419543 | X3: 2025-12-27 | Z3: 考研专业课,考研无忧计划 | AA3: 北京城市学院 | AB3: 大三 | AC3: 信息学部 | AD3: 电子信息工程（电路与系统设计） | AE3: 27考季 | AF3: 无忧计划-啄木鸟,考研专业课150 | AG3: 英语,政治,数学,计算机 | AH3: 国内高校-双非 | AI3: 5764531 | AJ3: 本地人本地大学(常规) | AL3: 学管主管审批通过 | AM3: 是 | AN3: 2025-07-09 20:21 | AO3: 55300 | AP3: 否
A4: 119 | B4: 北京大学部 | C4: 国内大学部 | D4: 2025-12-22 | E4: 栖雅 | F4: 国内考试 | H4: 18800 | K4: 续班 | M4: 已交接 | N4: 线上运营-本地生活平台 | O4: 知了好学 | P4: 黄智超 | Q4: 2025-12-22 17:21 | R4: 黄智超 | S4: 2025-12-22 17:29 | T4: 2025-12-22 11:45:42 | U4: B（需长时间跟单或只需要规划） | W4: BJWY7021928093 | Z4: 大学学科辅导 | AA4: 外交学院 | AB4: 大一 | AC4: 国际经济学院 | AD4: 国际经济与贸易 | AE4: 26上考季 | AF4: 大学学科辅导 | AG4: 专业课
A5: 220 | B5: 北京大学部 | C5: 国内大学部 | D5: 2025-12-07 | E5: 宋德弘 | F5: 国内考试 | H5: 8000 | J5: 张泽7 | K5: 续班 | M5: 已交接 | N5: 转介绍 | O5: 学管续费推荐 | P5: 田一禾 | Q5: 2025-12-07 11:01 | R5: 田一禾 | S5: 2025-12-07 11:03 | T5: 2025-12-06 17:30:03 | U5: A（六个月内有报课意向工单） | W5: BJWY4327598123 | Z5: 四级 | AA5: 中国政法大学 | AB5: 大三 | AC5: 法学院 | AD5: 法学（法学人才培养模式改革实验班） | AE5: 25下考季 | AF5: 四级线上网课,四级一对一
A6: 235 | B6: 北京大学部 | C6: 国内大学部 | D6: 2025-12-04 | E6: 宋德弘 | F6: 国内考试 | H6: 3400 | J6: 张泽7 | K6: 续班 | M6: 已交接 | N6: 转介绍 | O6: 学管续费推荐 | P6: 田一禾 | Q6: 2025-12-04 16:59 | R6: 田一禾 | S6: 2025-12-04 17:02 | T6: 2025-12-01 11:10:42 | U6: A（六个月内有报课意向工单） | W6: BJWY4327598123 | Z6: 四级 | AA6: 中国政法大学 | AB6: 大三 | AC6: 法学院 | AD6: 法学（法学人才培养模式改革实验班） | AE6: 25下考季 | AF6: 四级无忧计划
A7: 219 | B7: 北京大学部 | C7: 国内大学部 | D7: 2025-12-07 | E7: 王梓函 | F7: 国内考试 | H7: 28300 | J7: 于明珠2+yumingzhu2@xdf.cn+ID+于明珠2(新东方教育科技集团有限公司-产业机构-国际教育培训事业部-国际教育北京中心-运营管理部-中学区域运营中心三区-望京中学分中心 | 学业规划 | K7: 新签 | M7: 已交接 | N7: 转介绍 | O7: 内部员工推荐 | P7: 刘晓娟 | Q7: 2025-12-07 13:52 | R7: 刘晓娟 | S7: 2025-12-10 14:09 | T7: 2025-11-14 20:08:57 | U7: A（六个月内有报课意向工单） | V7: WebReg | W7: BJWY4539449808 | X7: 2025-12-07 | Z7: 考研无忧计划 | AA7: 中国音乐学院 | AB7: 大四 | AC7: 作曲系 | AD7: 作曲 | AE7: 27考季 | AF7: 无忧计划-啄木鸟 | AG7: 英语,政治

Sheet 四六级退费合计
A1: 提交日期 | B1: OA流水号 | C1: 学管姓名 | D1: 学管是否代办 | E1: 顾问姓名 | F1: 顾问是否代办 | G1: 91系统-最新报名二级渠道 | H1: 转介绍人 | I1: 原班所属项目 | J1: 新报入班级所属项目 | K1: 退费阶段 | L1: 退费一级原因（开课前） | M1: 退费一级原因 (开课后) | N1: 退费二级原因（专业课师资匹配原因） | O1: 退费二级原因（学员意愿转变_开课前） | P1: 退费二级原因（计划冲突_开课前） | Q1: 退费二级原因（中心原因_开课前） | R1: 退费二级原因（签约话术） | S1: 退费二级原因（教师） | T1: 退费二级原因（教学） | U1: 退费二级原因（课程安排） | V1: 退费二级原因（配套服务） | W1: 退费二级原因（配套学习设施） | X1: 退费二级原因（中心原因_开课后） | Y1: 退费二级原因（计划冲突_开课后） | Z1: 退费二级原因（学员意愿转变_开课后） | AA1: 退费三级原因（完全匹配不上）-院校、学院、专业、专业课代码及名称 | AB1: 退费详细原因说明（与OA退费详细说明保持一致） | AC1: 预计报名新班学费金额 | AD1: 转班金额（请学管填写所在班级实际金额） | AE1: 转班详细原因说明 | AF1: 提交时间 | AG1: 学校 | AH1: 学院 | AI1: 年级 | AJ1: 专业 | AK1: 您所办理的业务类型 | AL1: 提交人 | AM1: 退费类型 | AN1: 学员姓名 | AO1: 学员编码 | AP1: 退费金额 | AQ1: 原来金额 | AR1: 办理日期-客服 | AS1: 月 | AT1: 日 | AU1: 退费方式-客服 | AX1: 需要跟进的顾问/学管 | AY1: 退费/转班特殊情况备注（若需要学管提供银行卡信息，可将需求填写在此处）-客服 | AZ1: 是否完成退费/转班-客服 | BA1: 父记录 | BB1: 父记录
A2: 2025/11/25 | B2: NO.2025112401110 | C2: 舒志豪1 | E2: 徐一城 | G2: 直访 | I2: 无忧项目-VIP | K2: 开课后退费 | M2: 学员意愿转变_开课后 | Z2: 家人不支持考研/不支持跟班学习/意见不一致 | AB2: 学员大四，11月19号上午旷课，电话不接，信息不回，家长因此与孩子有矛盾，孩子自己不愿意上课，家长也不愿意留着课时日后使用，坚持退费 | AF2: 2025-11-25 | AG2: 北京邮电大学 | AH2: 人文学院 | AI2: 大四 | AJ2: 法学 | AK2: 退费 | AL2: 舒志豪1 | AM2: 真实产生的退费 | AN2: 王牧骥 | AO2: BJWY5966881279 | AP2: =17500/2 -> 8750 | AQ2: =17500/2 -> 8750 | AR2: 17500 | AS2: 12 | AT2: 1 | AU2: 12.10显示已退款[图片] 12.9已转手工，待短信确认：吴维萍6226980700396185中信银行北京万柳支行 等财务老师转手工之后提交手工退款，卡号就是上面卡信息（原银联商务POS支付卡） 12.5银联商务POS退款中—————————— 12.03退款中 12.02退款中[图片] 12.1已办理，原渠道是刷卡，以下是两张银行卡分别对应的金额，目前退款中，待到账 [图片] 未办理：OA未到客服（11.30）@舒志豪1 (舒志豪)——————- 11.29未办理：OA未到客服 11.28未办理：OA未到客服 11.27未办理：OA未到客服 11.26未办理，oa未到客服 | AZ2: TRUE
A3: 2025/11/29 | B3: 19008184 | C3: 李玉迪1 | E3: 田一禾 | G3: 新东方PC官网 | I3: 四六级项目-班课 | K3: 开课后退费 | M3: 学员意愿转变_开课后 | Z3: 认为课程用处不大/不适合自己 | AB3: WYS25047,开课后退费，消耗22课次家长联系说孩子学校里课程结课提前，没有时间上面授，后面三周的课申请退出，建议保留可以看一下直播或者云教室，但是家长觉得孩子学校里事情都忙不完实在没时间补，不考虑留课，申请退出 | AF3: 2025-11-29 | AG3: 北京科技大学天津学院 | AH3: 法律系 | AI3: 大二 | AJ3: 法学 | AK3: 退费 | AL3: 李玉迪1 | AM3: 真实产生的退费 | AN3: 王艺璇 | AO3: BJWY8762185994 | AP3: 1667 | AQ3: 1667 | AR3: 2025 | AS3: 12 | AT3: 1 | AU3: 12.01已办理，原支付渠道是微信，已到账 [图片] 未办理：无顾问挽单记录（11.30）@李玉迪1 (李玉迪)@田一禾3 (田一禾) | AZ3: TRUE
A4: 2025/11/29 | B4: 19003684 | C4: 李玉迪1 | E4: 徐一城 | G4: 学管续费推荐 | I4: 四六级项目-班课 | K4: 开课后退费 | M4: 学员意愿转变_开课后 | Z4: 认为课程用处不大/不适合自己 | AB4: WYS25046,开课后报名，消耗8课次学员基础不好，报了班课和一对一课时包，上了两次班课觉得进度太快了，跟不上，都转成一对一上课了，着急排课已经报入新的课时包，班课办理退费退回。 属于特殊情况退费，已发送邮件同步，辛苦老师办理。 | AF4: 2025-11-29 | AG4: 中国地质大学(北京) | AH4: 地质学院 | AI4: 研三 | AJ4: 地质资源与地质工程 | AK4: 退费 | AL4: 李玉迪1 | AM4: 真实产生的退费 | AN4: 刘孟 | AO4: BJWY7540306760 | AP4: 1850 | AQ4: 1850 | AR4: 2025 | AS4: 12 | AT4: 2 | AU4: 12.2支付宝退1850————————[图片] [图片] 邮件未审批完——————[图片] 12.01未办理，新oa退费金额和退费审核不一致@李玉迪1 (李玉迪) [图片][图片] 未办理：OA提交有误，11.29已回退（11.30）@李玉迪1 (李玉迪)————————- [图片] [图片] | AZ4: TRUE
A5: 2025/11/30 | B5: NO.2025112900160 | C5: 舒志豪1 | E5: 房国超 | G5: 内部员工推荐 | I5: 四六级项目-VIP | K5: 开课前退费 | L5: 计划冲突_开课前 | P5: 专业课学习时间和新东方时间冲突 | AB5: 学员马上要参加一个考试，数学这学期也不考了，没时间学习，也不需要保留课时，转化其他科目 | AF5: 2025-11-30 | AG5: 首都师范大学 | AH5: 科德学院 | AI5: 大一 | AJ5: 心理学 | AK5: 退费 | AL5: 舒志豪1 | AM5: 真实产生的退费 | AN5: 张一冉 | AO5: BJWY7214774690 | AP5: 8500 | AQ5: 8500 | AR5: 2025 | AS5: 12 | AT5: 1 | AU5: 12.01已办理，原支付渠道是微信，已到账 [图片] | AZ5: TRUE
A6: 2025/12/05 | B6: NO.2025120401586 | C6: 舒志豪1 | E6: 田一禾 | G6: 阿里本地通 | I6: 四六级项目-VIP | K6: 开课后退费 | M6: 计划冲突_开课后 | Y6: 学校事务和新东方时间冲突 | AB6: 学员大一，报名有四级班课，一开始咨询考研数学，但是从大一开始学有点早，所以报名80H数学一对一从基础开始学，但目前孩子不打算学高数，用不到，也不愿意留存课时或者扩科，后续有需要再报名学习，已经和顾问进行了挽单操作，均挽单失败 | AF6: 2025-12-05 | AG6: 北京城市学院 | AH6: 信息学部 | AI6: 大一 | AJ6: 数据科学与大数据技术 | AK6: 退费 | AL6: 舒志豪1 | AM6: 真实产生的退费 | AN6: 李佳羲 | AO6: BJWY8658744284 | AP6: 46600 | AQ6: 46600 | AR6: 2025 | AS6: 12 | AT6: 6 | AU6: 支付宝退回 未办理：OA未到前台（12.5） | AZ6: TRUE
A7: 2025/12/06 | B7: 19014924 | C7: 边鑫博 | E7: 刘晓娟 | G7: 公众号 | I7: 四六级项目-班课 | J7: 四六级项目 | K7: 开课后退费 | M7: 计划冲突_开课后 | Y7: 个人生活/工作事务和新东方时间冲突 | AB7: 【退到账户储值】【退出转线上】【开课后退费】报名班级WYF25046，12-1号提出退费消耗0课次 | AC7: 5980 | AF7: 2025-12-06 | AG7: 北京印刷学院 | AH7: 新闻出版学 | AI7: 大二 | AJ7: 数字出版 | AK7: 退费 | AL7: 边鑫博 | AM7: 转项目/转班/退出重报等未产生实际退费 | AN7: 孙昭涵 | AO7: BJWY3666268697 | AP7: 3180 | AQ7: 3180 | AR7: 2025 | AS7: 12 | AT7: 6 | AU7: 退至学员账户 | AZ7: TRUE
A8: 2025/12/06 | B8: 19014862 | C8: 边鑫博 | E8: 黄智超 | G8: 学管转介绍 | I8: 四六级项目-班课 | J8: 四六级项目 | K8: 开课前退费 | L8: 计划冲突_开课前 | P8: 个人生活/工作事务和新东方时间冲突 | AB8: 【退到账户储值】【退出转线上】【开课前退费】报名班级WYS26001 ，12-1号提出退费消耗0课次 | AC8: 4980 | AF8: 2025-12-06 | AG8: 中国人民公安大学 | AH8: 反恐怖学院 | AI8: 大一 | AJ8: 公安情报学 | AK8: 退费 | AL8: 边鑫博 | AM8: 转项目/转班/退出重报等未产生实际退费 | AN8: 金玲旭 | AO8: BJWY3450008754 | AP8: 5480 | AQ8: 5480 | AR8: 2025 | AS8: 12 | AT8: 6 | AU8: 退回账户 | AZ8: TRUE
A9: 2025/12/09 | B9: NO.2025120401577 | C9: 舒志豪1 | E9: 田一禾 | G9: 新东方PC官网 | I9: 四六级项目-VIP | K9: 开课后退费 | M9: 计划冲突_开课后 | Y9: 专业课学习时间和新东方时间冲突 | AB9: 学生自己意愿不明确，之前上了一次课后就停课了，说是学校内课程太多，暂时没时间学习，也用不到这些课程，后面有需要再说 | AF9: 2025-12-09 | AG9: 北京中医药大学 | AH9: 中医学院 | AI9: 大一 | AJ9: 中医学 | AK9: 退费 | AL9: 舒志豪1 | AM9: 真实产生的退费 | AN9: 孙瑞 | AO9: BJWY0299423626 | AP9: 9000 | AQ9: 9000 | AR9: 2025 | AS9: 12 | AT9: 13 | AU9: 12.13，微信退还。@舒志豪1 (舒志豪)@田一禾3 (田一禾) 未办理：OA流程未到客服（12.12） 未办理：OA流程未到客服（12.10） | AZ9: TRUE
A10: 2025/12/11 | B10: 2025121100600 | C10: 徐岩91 | E10: 黄智超 | G10: 内部员工推荐 | I10: 四六级项目-VIP | J10: 四六级项目 | K10: 开课后退费 | M10: 学员意愿转变_开课后 | Z10: 自己找到老师复习 | AB10: 退到账户 转定制 | AC10: 7000 | AF10: 2025-12-11 | AG10: 北京林业大学 | AH10: 经济管理学院 | AI10: 大二 | AJ10: 工商管理 | AK10: 退费 | AL10: 徐岩91 | AM10: 转项目/转班/退出重报等未产生实际退费 | AN10: 张敬涵 | AO10: BJWY5062456767 | AP10: 7000 | AQ10: 7000 | AR10: 2025 | AS10: 12 | AT10: 11 | AU10: 退回学员账户 | AZ10: TRUE
A11: 2025/12/12 | B11: NO.2025120901880 | C11: 舒志豪1 | E11: 刘晓娟 | G11: 集团官微 | I11: 四六级项目-VIP | K11: 开课后退费 | M11: 计划冲突_开课后 | Y11: 个人生活/工作事务和新东方时间冲突 | AB11: 学生自己意愿不明确，之前上了一次课后就停课了，说是学校内课程太多，专业课学习非常紧张，暂时没时间学习，也用不到这些课程，后面有需要再说 | AF11: 2025-12-12 | AG11: 北方工业大学 | AH11: 电气与控制工程学院 | AI11: 大二 | AJ11: 自动化 | AK11: 退费 | AL11: 舒志豪1 | AM11: 真实产生的退费 | AN11: 刘桐希 | AO11: BJWY8915310304 | AP11: 8500 | AQ11: 8500 | AR11: 2025 | AS11: 12 | AT11: 15 | AU11: 微信退回 未办理：未查询到顾问挽单记录（12.14） 12.13未办理：未查询到顾问挽单记录。 未办理：OA流程未到客服（12.12） | AZ11: TRUE
A12: 2025/12/12 | C12: 李玉迪1 | E12: 黄智超 | F12: TRUE | G12: 学管续费推荐 | I12: 四六级项目-班课 | AD12: 5874 | AE12: 家长想让孩子学难度更高的课程 确定转到六级班 原班级编码：WYF26001 转至WYS26001 | AF12: 2025-12-12 | AK12: 转班 | AL12: 黄智超1 | AN12: 杨靖怡 | AO12: BJWY1315194841 | AP12: 5874 | AQ12: 5874 | AR12: 2025 | AS12: 12 | AT12: 12 | AU12: 已转班 | AZ12: TRUE
A13: 2025/12/14 | B13: 2025120700786 | C13: 徐岩91 | E13: 黄智超 | G13: 内部员工推荐 | I13: 四六级项目-VIP | K13: 开课后退费 | M13: 学员意愿转变_开课后 | Z13: 认为课程用处不大/不适合自己 | AB13: 孩子一共报名6小时 上了4小时 剩余2小时不需要了 但是确定上六级 家长想着六级不一定选择这个老师和定制老师，计划先清算这个2小时退费，等选好了六级老师，再交钱在报名 | AF13: 2025-12-14 | AG13: 未告知 | AH13: 未告知 | AI13: 未告知 | AJ13: 未告知 | AK13: 退费 | AL13: 徐岩91 | AM13: 真实产生的退费 | AN13: 郭思淇 | AO13: BJWY2569416299 | AP13: 2600 | AQ13: 2600 | AR13: 2025 | AS13: 12 | AT13: 19 | AU13: 12.19微信退2600———————— 未办理：群内无审核记录（12.19）@徐岩91 (徐岩)———————— 12.17未办理，群内无记录 [图片] 未办理：群里未查到顾问+学管的挽单记录（12.16） 未办理：群里未查到顾问+学管的挽单记录（12.15） | AZ13: TRUE
A14: 2025/12/14 | B14: 2025120700725 | C14: 徐岩91 | E14: 刘晓娟 | G14: 内部员工推荐 | I14: 四六级项目-VIP | K14: 开课前退费 | L14: 学员意愿转变_开课前 | O14: 认为课程用处不大/不适合自己 | AB14: 学员李加亦，孩子11.28续费了52小时，晚上跟孩子爸爸商量之后又决定不续费了，打算退了，先把目前的课时上完，后面要是需要再说，已经同步给家长新东方有雅思考研大学四六级课程，家长还是想先退了学员李加亦，孩子11.28续费了52小时，晚上跟孩子爸爸商量之后又决定不续费了，打算退了，先把目前的课时上完，后面要是需要再说，已经同步给家长新东方有雅思考研大学四六级课程，家长还是想先退了 | AF14: 2025-12-14 | AG14: 北京大学 | AH14: 计算机科学与技术 | AI14: 大一 | AJ14: 计算机科学与技术 | AK14: 退费 | AL14: 徐岩91 | AM14: 真实产生的退费 | AN14: 李加亦 | AO14: BJWY1362662123 | AP14: 47400 | AQ14: 47400 | AR14: 2025 | AS14: 12 | AT14: 17 | AU14: 12.23退款成功。 12.22已短信确认/退款中 12.21短信重发，学生短信未确认，辛苦老师提醒@徐岩91 (徐岩) 12.20学生短信未确认，辛苦老师提醒@徐岩91 (徐岩) 12.19转手工47400，待学员短信进行退费确认@徐岩91 (徐岩)———————— 账户名称:济南华捷仪器仪表有限公司 开户行: 招商银行济南开元支行 账号:531906647610778 12.18需要手工退款，请提供圈出来的银行卡信息@徐岩91 (徐岩) 12.17需要手工退款，请提供圈出来的银行卡信息@徐岩91 (徐岩) [图片] 未办理：群里未查到顾问的挽单记录（12.16）@徐岩91 (徐岩) 未办理：群里未查到顾问的挽单记录（12.15）@徐岩91 (徐岩) | AZ14: TRUE
A15: 2025/12/14 | B15: 2025120401585 | C15: 徐岩91 | E15: 黄智超 | G15: 集团资源 | I15: 四六级项目-VIP | K15: 开课后退费 | M15: 学员意愿转变_开课后 | Z15: 认为课程用处不大/不适合自己 | AB15: 家长觉得老师不适合孩子 一开始老师也是家长自己选的 中途沟通过觉得还是不合适 换了老师也觉得还是不行 没有达到他心里的预期 也不学其他的课程 坚持退费 特殊退费说明：学员当时提出退费，经过挽单，领导说给免费安排一节李萍老师课程，因为已经排进系统且无法解锁，所以申请特殊退费~ 学员一共报名80小时，实际消耗22小时，但当时最后一节课应该是免费给上的，所以要申请按照消耗20小时计算，特申请特殊退费，已经申请领导同意 | AF15: 2025-12-14 | AG15: 未告知 | AH15: 未告知 | AI15: 大一 | AJ15: 未告知 | AK15: 退费 | AL15: 徐岩91 | AM15: 真实产生的退费 | AN15: 冯俊扬 | AO15: BJWY1851952720 | AP15: 52000 | AQ15: 52000 | AR15: 2025 | AS15: 12 | AT15: 15 | AU15: 12.23退款成功。 12.22已短信确认/退款中 12.20短信已确认，退款中 12.20提现退52000，提醒学员进行退费短信确认@徐岩91 (徐岩)———————— *开户行: 工商银行 *开户行支行: 北京菜市口支行 *卡号:9558800200115958080 *姓名: 冯俊扬 12.18请提供户名@徐岩91 (徐岩) 12.17请提供户名@徐岩91 (徐岩) [图片] 暂退至学员账户，提供原汇款银行卡信息@徐岩91 (徐岩) [图片] | AZ15: TRUE
A16: 2025/12/15 | B16: 19019033 | C16: 边鑫博 | E16: 黄智超 | G16: 大众点评 | I16: 四六级项目-班课 | K16: 开课后退费 | M16: 学员意愿转变_开课后 | Z16: 找到工作 | AB16: 开课后退费】报名班级WYF25046 ，2025-12-2号提出退费消耗4课次,退费原因学员不考四级，备考学位英语不需要听力，报名前已沟通 | AF16: 2025-12-15 | AG16: 在职 | AH16: 在职 | AI16: 在职 | AJ16: 在职 | AK16: 退费 | AL16: 边鑫博 | AM16: 真实产生的退费 | AN16: 张鑫烨 | AO16: BJWY2188272707 | AP16: 738 | AQ16: 738 | AR16: 2025 | AS16: 12 | AT16: 15 | AU16: 12.19退款完成—————— 12.18已短信确认，退款中———————————————————— 12.17业务群里发送提现申请，待短信确认 暂退至学员账户，原支付方式为现金，需要提供本人银行卡信息转手工退费@边鑫博 [图片] 未办理：顾问+学管挽单记录不符合要求（12.15）@黄智超1 (黄智超)@边鑫博 [图片] | AZ16: TRUE
A17: 2025/12/15 | B17: 19027404 | C17: 李玉迪1 | E17: 徐一城 | G17: 媒体/线上投放 | I17: 四六级项目-班课 | J17: 四六级项目 | K17: 开课前退费 | L17: 学员意愿转变_开课前 | O17: 认为课程用处不大/不适合自己 | AB17: WYF26001，未开课，消耗0课时学员改变主意要报集训营的课，转班有差价需要退出在入班。未退费 | AC17: 15800 | AF17: 2025-12-15 | AG17: 中国政法大学 | AH17: 法学院 | AI17: 大一 | AJ17: 法学 | AK17: 退费 | AL17: 李玉迪1 | AM17: 转项目/转班/退出重报等未产生实际退费 | AN17: 张佑琳 | AO17: BJWY9140573723 | AP17: 6180 | AQ17: 6180 | AR17: 2025 | AS17: 12 | AT17: 15 | AU17: 退账户6180 | AZ17: TRUE
A18: 2025/12/16 | C18: 边鑫博 | E18: 房国超 | G18: 顾问转介绍-老带新 | I18: 四六级项目-班课 | AD18: 5580 | AE18: 放假晚转二期 | AF18: 2025-12-16 | AK18: 转班 | AL18: 边鑫博 | AN18: 王俊文 | AO18: BJWY0784585325 | AP18: 5580 | AQ18: 5580 | AR18: 2025 | AS18: 12 | AT18: 16 | AU18: 12.16已转班 | AZ18: TRUE
A19: 2025/12/16 | C19: 边鑫博 | E19: 房国超 | G19: 顾问转介绍-老带新 | I19: 四六级项目-班课 | AD19: 5480 | AE19: 放假晚，上二期课 | AF19: 2025-12-16 | AK19: 转班 | AL19: 边鑫博 | AN19: 程梓翔 | AO19: BJWY4161329609 | AP19: 5480 | AQ19: 5480 | AR19: 2025 | AS19: 12 | AT19: 16 | AU19: 12.16已转班 | AZ19: TRUE
A20: 2025/12/16 | C20: 边鑫博 | E20: 房国超 | G20: 老学员续费 | I20: 四六级项目-班课 | AD20: 5780 | AE20: 放假晚，转二期 | AF20: 2025-12-16 | AK20: 转班 | AL20: 边鑫博 | AN20: 王骁 | AO20: BJWY5697728947 | AP20: 5780 | AQ20: 5780 | AR20: 2025 | AS20: 12 | AT20: 16 | AU20: 12.16已转班 | AZ20: TRUE
A21: 2025/12/16 | C21: 边鑫博 | E21: 黄智超 | G21: 总部-巨量广告 | I21: 四六级项目-班课 | AD21: 5874 | AE21: 放假晚，转二期班 | AF21: 2025-12-16 | AK21: 转班 | AL21: 边鑫博 | AN21: 刘峰昊 | AO21: BJWY8229207548 | AP21: 5874 | AQ21: 6480 | AR21: 2025 | AS21: 12 | AT21: 16 | AU21: 12.16已转班 | AZ21: TRUE
A22: 2025/12/16 | C22: 边鑫博 | E22: 宋增辉 | G22: 线下校代 | I22: 四六级项目-班课 | AD22: 6480 | AE22: 放假晚，转二期班 | AF22: 2025-12-16 | AK22: 转班 | AL22: 边鑫博 | AN22: 赵云钐 | AO22: BJWY4726874831 | AP22: 5680 | AQ22: 6480 | AR22: 2025 | AS22: 12 | AT22: 16 | AU22: 12.16已转班 | AZ22: TRUE
A23: 2025/12/16 | C23: 边鑫博 | E23: 黄智超 | G23: 内部员工推荐 | I23: 四六级项目-班课 | AD23: 5874 | AE23: 放假晚，转二期班 | AF23: 2025-12-16 | AK23: 转班 | AL23: 边鑫博 | AN23: 李卓馨 | AO23: BJWY3271664179 | AP23: 5874 | AQ23: 6480 | AR23: 2025 | AS23: 12 | AT23: 16 | AU23: 12.16已转班 | AZ23: TRUE
A24: 2025/12/17 | C24: 边鑫博 | E24: 黄智超 | F24: TRUE | G24: 新东方PC官网 | I24: 四六级项目-班课 | AD24: 19800 | AE24: 由四级寒假小班转入至六级小班二期 WYF26002转至WYS26004 | AF24: 2025-12-17 | AK24: 转班 | AL24: 黄智超1 | AN24: 彭琦玮 | AO24: BJWY2913826463 | AP24: 19800 | AQ24: 19800 | AR24: 2025 | AS24: 12 | AT24: 17 | AU24: 已转班 | AZ24: TRUE
A25: 2025/12/22 | B25: NO.2025122000561 | C25: 舒志豪1 | E25: 黄智超 | G25: 内部员工推荐 | I25: 四六级项目-VIP | K25: 开课前退费 | L25: 学员意愿转变_开课前 | O25: 自己找到老师复习 | AB25: 12月18号报名高数课程，指定女老师，但家长未提前和孩子商量沟通，晚上和孩子沟通后才得知，孩子已经在学校内找到一位学姐补课，且效果不错，所以申请退费，目前四六级和考研都不需要，不保留课时 | AF25: 2025-12-22 | AG25: 北京物资学院 | AH25: 商学院 | AI25: 大一 | AJ25: 会计学 | AK25: 退费 | AL25: 舒志豪1 | AM25: 真实产生的退费 | AN25: 郭宣 | AO25: BJWY4466093680 | AP25: 0 | AQ25: 1800 | AR25: 2025 | AS25: 12 | AT25: 27 | AU25: 12.27 原路径退还1800 ，微信退还，已退款 未办理，oa未到客服（12.26） 12.25 未办理，oa未到客服 [图片] 12.24未办理：OA未到客服 未办理：OA未到客服（12.23） 未办理：OA未到客服（12.22） | AZ25: TRUE
A26: 2025/12/23 | C26: 李玉迪1 | E26: 刘晓娟 | G26: 大众点评 | I26: 四六级项目-班课 | AD26: 19300 | AE26: 学生时间不合适，需要转班到晚开班的班级 | AF26: 2025-12-23 | AK26: 转班 | AL26: 李玉迪1 | AN26: 朱震 | AO26: BJWY6138635718 | AP26: 19300 | AQ26: 19300 | AR26: 2025 | AS26: 12 | AT26: 23 | AU26: 已转班 | AZ26: TRUE
A27: 2025/12/23 | C27: 李玉迪1 | E27: 宋增辉 | F27: TRUE | G27: TMK合作 | I27: 四六级项目-班课 | AD27: 19300 | AE27: 刘艾琛爸爸想要孩子年前就学习完，报名的时候一期班已经满班，现在有学生转到二期空出名额，申请从27号上课的四级精英计划二期班WYF26004转入到19号四级精英计划WYF26002一期班 | AF27: 2025-12-23 | AK27: 转班 | AL27: 宋增辉 | AN27: 刘艾琛 | AO27: BJWY7023911345 | AP27: 19300 | AQ27: 19300 | AR27: 2025 | AS27: 12 | AT27: 23 | AU27: 已转班 | AZ27: TRUE
A28: 2025/12/23 | C28: 李玉迪1 | E28: 黄智超 | G28: 集团官微 | I28: 四六级项目-班课 | AD28: 18800 | AE28: 学生寒假没有时间，需要转到春季班 | AF28: 2025-12-23 | AK28: 转班 | AL28: 李玉迪1 | AN28: 陈奕奇 | AO28: BJWY8928140516 | AP28: 18800 | AQ28: 18800 | AR28: 2025 | AS28: 12 | AT28: 23 | AU28: 已转班 | AZ28: TRUE
A29: 2025/12/25 | C29: 李玉迪1 | E29: 黄智超 | G29: 顾问转介绍-老带新 | I29: 四六级项目-班课 | AD29: 19600 | AE29: 学生寒假没有时间，需要转到春季班 | AF29: 2025-12-25 | AK29: 转班 | AL29: 李玉迪1 | AN29: 欧紫舒 | AO29: BJWY6485401846 | AP29: 19600 | AQ29: 19600 | AR29: 2025 | AS29: 12 | AT29: 25 | AU29: 已转班 | AZ29: TRUE
A30: 2025/12/25 | C30: 李玉迪1 | E30: 黄智超 | G30: 集团官微 | I30: 四六级项目-班课 | AD30: 19800 | AE30: 学生寒假没有时间，需要转到春季班 | AF30: 2025-12-25 | AK30: 转班 | AL30: 李玉迪1 | AN30: 罗昕煜 | AO30: BJWY9812323348 | AP30: 19800 | AQ30: 19800 | AR30: 2025 | AS30: 12 | AT30: 25 | AU30: 已转班 | AZ30: TRUE
A31: 2025/12/26 | C31: 边鑫博 | E31: 刘晓娟 | G31: 学管续费推荐 | H31: 罗志勇 | I31: 四六级项目-班课 | AD31: 5832 | AE31: 寒假没时间转春季班 | AF31: 2025-12-26 | AK31: 转班 | AL31: 边鑫博 | AN31: 王思洁 | AO31: BJWY5182724099 | AP31: 5832 | AQ31: 5832 | AR31: 2025 | AS31: 12 | AT31: 26 | AU31: 已转班 | AZ31: TRUE
A32: 2025/12/26 | C32: 边鑫博 | E32: 田一禾 | G32: 集团官微 | I32: 四六级项目-班课 | AD32: 6067 | AE32: 寒假没时间转春季 | AF32: 2025-12-26 | AK32: 转班 | AL32: 边鑫博 | AN32: 张好 | AO32: BJWY7109755815 | AP32: 6067 | AQ32: 6067 | AR32: 2025 | AS32: 12 | AT32: 26 | AU32: 已转班 | AZ32: TRUE
A33: 2025/12/26 | C33: 边鑫博 | E33: 徐一城 | G33: 公众号 | I33: 四六级项目-班课 | AD33: 6180 | AE33: 寒假没时间转春季 | AF33: 2025-12-26 | AK33: 转班 | AL33: 边鑫博 | AN33: 徐英桓 | AO33: BJWY5425884493 | AP33: 6180 | AQ33: 6180 | AR33: 2025 | AS33: 12 | AT33: 26 | AU33: 已转班 | AZ33: TRUE
A34: 2025/12/26 | C34: 边鑫博 | E34: 刘晓娟 | G34: 学管转介绍 | H34: 李玉迪 | I34: 四六级项目-班课 | AD34: 5980 | AE34: 寒假没时间转到春季 | AF34: 2025-12-26 | AK34: 转班 | AL34: 边鑫博 | AN34: 韩绍强 | AO34: BJWY9999003313 | AP34: 5980 | AQ34: 5980 | AR34: 2025 | AS34: 12 | AT34: 26 | AU34: 已转班 | AZ34: TRUE
A35: 2025/12/29 | B35: 18989266 | C35: 李玉迪1 | E35: 黄智超 | G35: 学管续费推荐 | H35: 未知 | I35: 四六级项目-班课 | J35: 四六级项目 | K35: 开课后退费 | M35: 学员意愿转变_开课后 | Z35: 个人身体原因无法承受高强度学习 | AB35: WYF25042，开课后退费，消耗20课次学员暑假已经上过一期小班课，开学之后学校里事情非常多，本来想再跟一期大班课保持学习，但是实在兼顾不了，剩余的课次申请先退掉。引导转去数学课学习.学费退到学员账户 | AC35: 2130 | AF35: 2025-12-29 | AG35: 天津科技大学 | AH35: 计算机 | AI35: 大一 | AJ35: 计算机科学 | AK35: 退费 | AL35: 李玉迪1 | AM35: 转项目/转班/退出重报等未产生实际退费 | AN35: 张继中 | AO35: BJWY2473867563 | AP35: 2130 | AQ35: 2130 | AR35: 2025 | AS35: 12 | AT35: 30 | AU35: 退至学员账户 | AZ35: TRUE
A36: 2025/12/30 | B36: 19035541 | C36: 边鑫博 | E36: 黄智超 | G36: 顾问转介绍-老带新 | I36: 四六级项目-班课 | K36: 开课前退费 | L36: 计划冲突_开课前 | P36: 个人生活/工作事务和新东方时间冲突 | AB36: 【开课前退费】报名班级WYS26002，2025-12-22号提出退费消耗0课次,退费原因孩子明年6月四级考试 想要暑假学习六级课程 告知课程可以转班 家长觉得周期太长先退费 已告知优惠 家长知晓【有希望回流】 | AF36: 2025-12-30 | AG36: 北京工业大学 | AH36: 材料与制造学部 | AI36: 大一 | AJ36: 机械工程 | AK36: 退费 | AL36: 边鑫博 | AM36: 真实产生的退费 | AN36: 刘畅 | AO36: BJWY6608411312 | AP36: 19300 | AQ36: 19300 | AR36: 2025 | AS36: 12 | AT36: 30 | AU36: 微信退回 | AZ36: TRUE
A37: 2025/12/30 | C37: 李玉迪1 | E37: 黄智超 | G37: 小红书 | I37: 四六级项目-班课 | AD37: 5832 | AE37: 学生想直接学习六级准备四级 | AF37: 2025-12-30 | AK37: 转班 | AL37: 李玉迪1 | AN37: 赵思淳 | AO37: BJWY8860662154 | AP37: 5832 | AQ37: 5832 | AR37: 2025 | AS37: 12 | AT37: 30 | AU37: 已转班 | AZ37: TRUE
A38: 2025/12/30 | C38: 李玉迪1 | E38: 宋增辉 | G38: TMK合作 | I38: 四六级项目-班课 | AD38: 19300 | AE38: 学生时间不合适，申请转班 | AF38: 2025-12-30 | AK38: 转班 | AL38: 李玉迪1 | AN38: 刘艾琛 | AO38: BJWY7023911345 | AP38: 19300 | AQ38: 19300 | AR38: 2025 | AS38: 12 | AT38: 30 | AU38: 已转班 | AZ38: TRUE
A39: 2025/12/31 | B39: 19044338 | C39: 罗志勇1 | E39: 田一禾 | G39: 小红书 | I39: 四六级项目-班课 | J39: 四六级项目 | K39: 开课前退费 | L39: 中心原因_开课前 | Q39: 退出重报（取消班/合班/延转/选班/扩科等） | AB39: 开课前退费】学生刘筱汤米，为了更好效果，退出班课，续费转入1v1. | AC39: 31000 | AF39: 2025-12-31 | AG39: 犹他州立大学 | AH39: 金融 | AI39: 大四 | AJ39: 国际金融与贸易 | AK39: 退费 | AL39: 罗志勇1 | AM39: 转项目/转班/退出重报等未产生实际退费 | AN39: 刘筱汤米 | AO39: XDF122122110720592 | AP39: 5382 | AQ39: 5382 | AR39: 2025 | AS39: 12 | AT39: 31 | AU39: 退至学员账户 | AZ39: TRUE
A40: 2025/12/31 | B40: 2025121701108 | C40: 徐岩91 | E40: 田一禾 | G40: 学管续费推荐 | H40: 未知 | I40: 四六级项目-VIP | K40: 开课后退费 | M40: 学员意愿转变_开课后 | Z40: 认为课程用处不大/不适合自己 | AB40: 孩子实在是没时间学习一对一，之前又报了大班课，孩子学校事物多，没时间学习，所以就想看大班课回放自己复习复习，已经劝说很多次了，也说过考研或者等考试出成绩再退费，家长说到时候在说吧，坚持退费～。 | AF40: 2025-12-31 | AG40: 重庆师范大学 | AH40: 化学学院 | AI40: 大一 | AJ40: 化学 | AK40: 退费 | AL40: 徐岩91 | AM40: 真实产生的退费 | AN40: 于芯懿 | AO40: BJWY0648546751 | AP40: 28800 | AQ40: 28800 | AR40: 2025 | AS40: 12 | AT40: 31 | AU40: 微信退回 | AZ40: TRUE
...

Sheet q2绩效
A1: 国内顾问业绩汇总（9月） | L1: 国内顾问业绩汇总（Q2）
A2: 排名 | B2: 组别 | C2: 顾问 | D2: 月度数据 | L2: 排名 | M2: 组别 | N2: 顾问 | O2: 月度数据
D3: 本月目标 | E3: 总进账 | F3: 线下退费 | G3: 手动加 | H3: 综合业绩 | I3: 月度完成率 | O3: 季度目标 | P3: 总进账 | Q3: 线下退费 | R3: 手动加 | S3: 综合业绩 | T3: 月度完成率
A4: 四六级 | C4: 刘晓娟 | D4: 480000 | E4: 810505.15 | F4: 188387.8 | G4: 2730 | H4: =E4-F4+G4 -> 624847.35 | I4: =H4/D4 -> 1.3017653 | L4: 四六级 | N4: 刘晓娟 | O4: =D4+D18+D30 -> 1164500 | P4: =E4+E18+E30 -> 1687531.6 | Q4: =F4+F18+F30 -> 324513.9 | R4: 2730 | S4: =P4-Q4+R4 -> 1365747.8 | T4: =S4/O4 -> 1.172819
C5: 房国超 | D5: 480000 | E5: 705889 | F5: 111034 | H5: =E5-F5 -> 594855 | I5: =H5/D5 -> 1.2392812 | N5: 房国超 | O5: =D5+D19+D31 -> 1187000 | P5: =E5+E19+E31 -> 1131319.6 | Q5: =F5+F19+F31 -> 165457.9 | S5: =P5-Q5+R5 -> 965861.75 | T5: =S5/O5 -> 0.81369987
C6: 宋增辉 | D6: 480000 | E6: 565662.5 | F6: 27310 | H6: =E6-F6 -> 538352.5 | I6: =H6/D6 -> 1.1215677 | N6: 宋增辉 | O6: =D6+D20+D32 -> 1187000 | P6: =E6+E20+E32 -> 870210.5 | Q6: =F6+F20+F32 -> 90252 | S6: =P6-Q6+R6 -> 779958.5 | T6: =S6/O6 -> 0.65708382
C7: 田一禾 | D7: 480000 | E7: 617994 | F7: 32802.8 | H7: =E7-F7 -> 585191.2 | I7: =H7/D7 -> 1.2191483 | N7: 田一禾 | O7: =D7+D21+D33 -> 1164500 | P7: =E7+E21+E33 -> 1312919.1 | Q7: =F7+F21+F33 -> 81535.1 | S7: =P7-Q7+R7 -> 1231384 | T7: =S7/O7 -> 1.0574358
C8: 黄智超 | D8: 480000 | E8: 790137 | F8: 95780 | H8: =E8-F8 -> 694357 | I8: =H8/D8 -> 1.4465771 | N8: 黄智超 | O8: =D8+D22+D34 -> 1164500 | P8: =E8+E22+E34 -> 1686870.6 | Q8: =F8+F22+F34 -> 176598 | S8: =P8-Q8+R8 -> 1510272.6 | T8: =S8/O8 -> 1.296928
C9: 徐一城 | D9: 240000 | E9: 440432 | F9: 79000 | H9: =E9-F9 -> 361432 | I9: =H9/D9 -> 1.5059667 | N9: 徐一城 | O9: =D9+D23+D35 -> 822500 | P9: =E9+E23+E35 -> 767284 | Q9: =F9+F23+F35 -> 149516.3 | S9: =P9-Q9+R9 -> 617767.7 | T9: =S9/O9 -> 0.75108535
C10: 刘文君 | E10: 5680 | H10: =E10-F10 -> 5680
C11: 小组合计 | D11: =SUM(D4:D10) -> 2640000 | E11: =SUM(E4:E10) -> 3936299.6 | F11: =SUM(F4:F10) -> 534314.6 | G11: =SUM(G4:G7) -> 2730 | H11: =SUM(H4:H10) -> 3404715 | I11: =H11/D11 -> 1.2896648 | N11: 小组合计 | O11: =SUM(O4:O10) -> 6690000 | P11: =SUM(P4:P10) -> 7456135.6 | Q11: =SUM(Q4:Q10) -> 987873.2 | R11: =SUM(R4:R7) -> 2730 | S11: =SUM(S4:S10) -> 6470992.4 | T11: =S11/O11 -> 0.96726343
A15: 国内顾问业绩汇总（10月）
A16: 排名 | B16: 组别 | C16: 顾问 | D16: 月度数据
D17: 本月目标 | E17: 总进账 | F17: 线下退费 | G17: 手动加 | H17: 综合业绩 | I17: 月度完成率
A18: 四六级 | C18: 刘晓娟 | D18: 417000 | E18: 419155 | F18: 28054.6 | H18: =E18-F18+G18 -> 391100.4 | I18: =H18/D18 -> 0.93789065
C19: 房国超 | D19: 417000 | E19: 187612.5 | F19: 51200.9 | H19: =E19-F19+G19 -> 136411.6 | I19: =H19/D19 -> 0.32712614
C20: 宋增辉 | D20: 417000 | E20: 216170 | F20: 56820 | H20: =E20-F20+G20 -> 159350 | I20: =H20/D20 -> 0.38213429
C21: 田一禾 | D21: 417000 | E21: 396955.1 | F21: 36111.3 | H21: =E21-F21+G21 -> 360843.8 | I21: =H21/D21 -> 0.86533285
C22: 黄智超 | D22: 417000 | E22: 493295.5 | F22: 23447 | H22: =E22-F22+G22 -> 469848.5 | I22: =H22/D22 -> 1.126735
C23: 徐一城 | D23: 315000 | E23: 223580 | F23: 66824.3 | H23: =E23-F23+G23 -> 156755.7 | I23: =H23/D23 -> 0.49763714
C24: 刘文君 | E24: 5680 | H24: =E24-F24+G24 -> 5680
C25: 小组合计 | D25: =SUM(D18:D24) -> 2400000 | E25: =SUM(E18:E24) -> 1942448.1 | F25: =SUM(F18:F24) -> 262458.1 | G25: =SUM(G18:G21) -> 0 | H25: =H18+H19+H20+H21+H22+H23 -> 1674310 | I25: =H25/D25 -> 0.69762917
A27: 国内顾问业绩汇总（11月）
A28: 排名 | B28: 组别 | C28: 顾问 | D28: 月度数据
D29: 本月目标 | E29: 总进账 | F29: 线下退费 | G29: 综合业绩 | H29: 月度完成率
A30: 四六级 | C30: 刘晓娟 | D30: 267500 | E30: 457871.5 | F30: 108071.5 | G30: 349800 | H30: =G30/D30 -> 1.3076636
C31: 房国超 | D31: 290000 | E31: 237818.15 | F31: 3223 | G31: 234595.15 | H31: =G31/D31 -> 0.80894879
C32: 宋增辉 | D32: 290000 | E32: 88378 | F32: 6122 | G32: 82256 | H32: =G32/D32 -> 0.28364138
C33: 田一禾 | D33: 267500 | E33: 297970 | F33: 12621 | G33: 285349 | H33: =G33/D33 -> 1.0667252
C34: 黄智超 | D34: 267500 | E34: 403438.15 | F34: 57371 | G34: 346067.15 | H34: =G34/D34 -> 1.293709
C35: 徐一城 | D35: 267500 | E35: 103272 | F35: 3692 | G35: 99580 | H35: =G35/D35 -> 0.37226168
C36: 小组合计 | D36: =SUM(D30:D35) -> 1650000 | E36: =SUM(E30:E35) -> 1588747.8 | F36: =SUM(F30:F35) -> 191100.5 | G36: =G30+G31+G32+G33+G34+G35 -> 1397647.3 | H36: =G36/D36 -> 0.84705897

Sheet 刘文君q2季度绩效
B2: Q2现金
B3: 月度 | C3: 顾问团队现金目标 | D3: 顾问团队实际完成 | E3: 现金完成率
B4: 9月 | C4: 3120000 | D4: 3421974 | E4: =D4/C4 -> 1.0967865
B5: 10月 | C5: 2400000 | D5: 1674310 | E5: =D5/C5 -> 0.69762917
B6: 汇总 | C6: =SUM(C4:C5) -> 5520000 | D6: =SUM(D4:D5) -> 5096284 | E6: =D6/C6 -> 0.92323985
B9: Q2转介绍业绩
B10: 月度 | C10: 转介绍现金目标 | D10: 转介绍实际完成 | E10: 转介绍完成率
B11: 9月 | C11: 325000 | D11: 146647 | E11: =D11/C11 -> 0.45122154
B12: 10月 | C12: 290000 | D12: 114664 | E12: =D12/C12 -> 0.3953931
B13: 汇总 | C13: =SUM(C11:C12) -> 615000 | D13: =SUM(D11:D12) -> 261311 | E13: =D13/C13 -> 0.42489593
B16: Q2签约率
B17: 月度 | C17: 新增工单量 | D17: 新增签约量 | E17: 新增资源签约率
B18: 9月 | C18: 1345 | D18: 309 | E18: =D18/C18 -> 0.22973978
B19: 10月 | C19: 716 | D19: 167 | E19: =D19/C19 -> 0.23324022
B20: 汇总 | C20: =SUM(C18:C19) -> 2061 | D20: =SUM(D18:D19) -> 476 | E20: =D20/C20 -> 0.23095585
B23: 指标 | C23: 目标 | D23: 占比 | E23: 实际完成 | F23: 完成率 | G23: 得分
B24: 现金 | C24: 5520000 | D24: 0.5 | E24: 5096284 | F24: =E24/C24 -> 0.92323986 | G24: 34
B25: 签约率 | C25: 0.29 | D25: 0.3 | E25: 0.23 | F25: 0.79 | G25: 12
B26: 转介绍业绩 | C26: 615000 | D26: 0.2 | E26: 210504 | F26: =E26/C26 -> 0.34228293 | G26: 0
B27: 汇总 | G27: =SUM(G24:G26) -> 46
