Workbook

Sheet 集训营
A1: 年月（自然月） | B1: 顾问姓名 | C1: 二级部门 | D1: 三级部门 | E1: 岗位 | F1: 奖金 | G1: 实发绩效 | H1: 实发提成 | I1: 月度业绩 | X1: 月度绩效
I2: 目标 | J2: 线下目标 | K2: 线下进账 | L2: 线下退费表 | M2: 线下主动调整 | N2: 线下净业绩 | O2: 线下完成率 | P2: 网课进账 | Q2: 网课退费 | R2: 网课净业绩 | S2: 转介绍目标 | T2: 转介绍业绩 | U2: 转介绍完成率 | V2: 提点 | W2: 提成 | X2: 合计得分 | Y2: 发放比例 | Z2: 月度绩效标准 | AA2: 月绩效应发
A3: 45809 | B3: 苏乾楠 | C3: 集训营 | D3: 考研项目部 | E3: B级学习顾问 | F3: =G3+H3 | G3: =AA3 | H3: =W3 | I3: 1276000 | K3: 1330516.6 | L3: -256375.1 | M3: -252202.2 | N3: 1078314.4 | P3: 21361.51 | Q3: 0 | R3: 21361.51 | S3: 150000 | T3: 63450 | U3: 0.423 | V3: 0.018 | W3: 19794.166 | X3: 83 | Y3: 0.83 | Z3: 2000 | AA3: 1660
A4: 45809 | B4: 陈伟钰 | C4: 集训营 | D4: 考研项目部 | E4: B级学习顾问 | F4: =G4+H4 | G4: 0 | H4: 6771.5612 | I4: 1276000 | K4: 946489.8 | L4: -130620.05 | M4: 28600 | N4: 844469.75 | P4: 1975.4 | Q4: 0 | R4: 1975.4 | S4: 150000 | T4: 28300 | U4: 0.18866667 | V4: 0.008 | W4: 6771.5612 | X4: 47 | Y4: 0 | Z4: 2000 | AA4: 0
A5: 45809 | B5: 杨晓超 | C5: 集训营 | D5: 考研项目部 | E5: B级学习顾问 | F5: =G5+H5 | G5: 2000 | H5: 35659.008 | I5: 1160000 | K5: 1505395.1 | L5: -370737.55 | M5: 0 | N5: 1134657.6 | P5: 57510.5 | Q5: -3534.5 | R5: 53976 | S5: 150000 | T5: 228120 | U5: 1.5208 | V5: 0.03 | W5: 35659.008 | X5: 107 | Y5: 1 | Z5: 2000 | AA5: 2000
A6: 45809 | B6: 钱雪冰 | C6: 集训营 | D6: 考研项目部 | E6: B级学习顾问 | F6: =G6+H6 | G6: 1600 | H6: 56704.008 | I6: 1160000 | K6: 1742439.8 | L6: -353710.9 | M6: 4880 | N6: 1393608.9 | P6: 25966.7 | Q6: -1975.4 | R6: 23991.3 | S6: 150000 | T6: 77480 | U6: 0.51653333 | V6: 0.04 | W6: 56704.008 | X6: 80 | Y6: 0.8 | Z6: 2000 | AA6: 1600
A7: 45809 | B7: 张乐 | C7: 集训营 | D7: 考研项目部 | E7: B级学习顾问 | F7: =G7+H7 | G7: 0 | H7: 4970.7504 | I7: 1276000 | K7: 1027042.3 | L7: -405698.55 | M7: 0 | N7: 621343.8 | P7: 0 | Q7: 0 | R7: 0 | S7: 150000 | T7: 45618.5 | U7: 0.30412333 | V7: 0.008 | W7: 4970.7504 | X7: 45 | Y7: 0 | Z7: 2000 | AA7: 0
A8: 45809 | B8: 陈露 | C8: 集训营 | D8: 考研项目部 | E8: B级学习顾问 | F8: =G8+H8 | G8: 0 | H8: 0 | I8: 1276000 | K8: 649070 | L8: -176315.5 | M8: 66134 | N8: 538888.5 | P8: 13827.9 | Q8: 0 | R8: 13827.9 | S8: 150000 | T8: 0 | U8: 0 | V8: 0 | W8: 0 | X8: 0 | Y8: 0 | Z8: 2000 | AA8: 0
A9: 45809 | B9: 刘创 | C9: 集训营 | D9: 考研项目部 | E9: B级学习顾问 | F9: =G9+H9 | G9: 0 | H9: 89263.095 | I9: 1160000 | K9: 2178352 | L9: -374422.5 | M9: -43100 | N9: 1760829.5 | P9: 24432.4 | Q9: 0 | R9: 24432.4 | S9: 150000 | T9: 81769.3 | U9: 0.54512867 | V9: 0.05 | W9: 89263.095 | X9: 68 | Y9: 0 | Z9: 2000 | AA9: 0
A10: 45809 | B10: 高龙明 | C10: 集训营 | D10: 考研项目部 | E10: A级学习顾问 | F10: =G10+H10 | G10: 1000 | H10: 36266.084 | I10: 1160000 | K10: 1832731 | L10: -711320.45 | M10: 21500 | N10: 1142910.6 | P10: 66237.9 | Q10: -279 | R10: 65958.9 | S10: 150000 | T10: 337186.8 | U10: 2.247912 | V10: 0.03 | W10: 36266.084 | X10: 115 | Y10: 1 | Z10: 1000 | AA10: 1000
A11: 45809 | B11: 张俊旺 | C11: 集训营 | D11: 考研项目部 | E11: A级学习顾问 | F11: =G11+H11 | G11: 0 | H11: 16832.236 | I11: 1160000 | K11: 928247.4 | L11: -70362.4 | M11: 0 | N11: 857885 | P11: 91700.6 | Q11: -14461.38 | R11: 77239.22 | S11: 80000 | T11: 5980 | U11: 0.07475 | V11: 0.018 | W11: 16832.236 | X11: 60 | Y11: 0 | Z11: 1000 | AA11: 0
A12: 45809 | B12: 王钦 | C12: 集训营 | D12: 考研项目部 | E12: B级学习顾问 | F12: =G12+H12 | G12: 2000 | H12: 11514 | I12: 60000 | K12: 230280 | L12: 0 | M12: 0 | N12: 230280 | P12: 0 | Q12: 0 | R12: 0 | S12: 0 | T12: 35300 | V12: 0.05 | W12: 11514 | X12: 100 | Y12: 1 | Z12: 2000 | AA12: 2000
A13: 45809 | B13: 王泽森 | C13: 集训营 | D13: 考研项目部 | E13: B级学习顾问 | F13: =G13+H13 | G13: 923.07692 | H13: 0 | S13: 0 | T13: 0 | U13: 0 | X13: 0 | Y13: 0 | Z13: 2000 | AA13: 923.07692
A14: 45839 | B14: 苏乾楠 | C14: 集训营 | D14: 考研项目部 | E14: B级学习顾问 | F14: =G14+H14 | G14: =AA14 | H14: =W14 | I14: 1120000 | K14: 644772 | L14: -481046 | M14: -502148 | N14: 142624 | P14: 24115 | Q14: 0 | R14: 24115 | S14: 150000 | T14: 72230 | U14: 0.48 | V14: 0 | W14: 0 | X14: 87 | Y14: 0.87 | Z14: 2000 | AA14: 1740
A15: 45839 | B15: 张乐 | C15: 集训营 | D15: 考研项目部 | E15: B级学习顾问 | F15: =G15+H15 | G15: 1460 | H15: 37057.98 | I15: 1232000 | K15: 1571381 | L15: -338710 | M15: 5265 | N15: 1237937 | P15: 1097 | Q15: -3767 | R15: -2671 | S15: 4 | T15: 2 | U15: 0.5 | V15: 0.03 | W15: 0.03 | X15: 73 | Y15: 0.73 | Z15: 2000 | AA15: 1460
A16: 45839 | B16: 张俊旺 | C16: 集训营 | D16: 考研项目部 | E16: A级学习顾问 | F16: =G16+H16 | G16: 1000 | H16: 0 | I16: 1120000 | K16: 417500 | L16: -137518 | M16: 0 | N16: 279982 | P16: 49497 | Q16: -23863 | R16: 25635 | S16: 2 | T16: 1 | U16: 0.5 | V16: 0 | W16: 0 | X16: 61 | Y16: 1 | Z16: 1000 | AA16: 1000
A17: 45839 | B17: 杨晓超 | C17: 集训营 | D17: 考研项目部 | E17: B级学习顾问 | F17: =G17+H17 | G17: 1780 | H17: 54267.32 | I17: 1120000 | K17: 1696550 | L17: -403918 | M17: 9750 | N17: 1302382 | P17: 82071 | Q17: -27770 | R17: 54302 | S17: 4 | T17: 2 | U17: 0.5 | V17: 0.04 | W17: 0.04 | X17: 89 | Y17: 0.89 | Z17: 2000 | AA17: 1780
A18: 45839 | B18: 王志远 | C18: 集训营 | D18: 考研项目部 | E18: B级学习顾问 | F18: =G18+H18 | G18: 363.63636 | H18: 0 | S18: 0 | T18: 0 | U18: 0 | X18: 0 | Y18: 1 | Z18: 2000 | AA18: 363.63636
A19: 45839 | B19: 王泽森 | C19: 集训营 | D19: 考研项目部 | E19: B级学习顾问 | F19: =G19+H19 | G19: 2000 | H19: 0 | S19: 0 | T19: 0 | U19: 0 | X19: 0 | Y19: 1 | Z19: 2000 | AA19: 2000
A20: 45839 | B20: 王钦 | C20: 集训营 | D20: 考研项目部 | E20: B级学习顾问 | F20: =G20+H20 | G20: 2000 | H20: 18024.84 | I20: 560000 | K20: 578904 | L20: -31680 | M20: 26000 | N20: 573224 | P20: 27605 | Q20: 0 | R20: 27605 | S20: 1 | T20: 0 | U20: 0 | V20: 0.03 | W20: 0.03 | X20: 100 | Y20: 1 | Z20: 2000 | AA20: 2000
A21: 45839 | B21: 钱雪冰 | C21: 集训营 | D21: 考研项目部 | E21: A级学习顾问 | F21: =G21+H21 | G21: 1000 | H21: 111109.35 | I21: 1120000 | K21: 2645146 | L21: -500735 | M21: 11300 | N21: 2155711 | P21: 66476 | Q21: 0 | R21: 66476 | S21: 4 | T21: 9 | U21: 2.25 | V21: 0.05 | W21: 0.05 | X21: 127 | Y21: 1 | Z21: 1000 | AA21: 1000
A22: 45839 | B22: 刘创 | C22: 集训营 | D22: 考研项目部 | E22: B级学习顾问 | F22: =G22+H22 | G22: 0 | H22: 0 | I22: 1120000 | K22: 344367 | L22: -341191 | M22: 0 | N22: 3175 | P22: 0 | Q22: 0 | R22: 0 | S22: 4 | T22: 1 | U22: 0.25 | V22: 0 | W22: 0 | X22: 35 | Y22: 0 | Z22: 2000 | AA22: 0
A23: 45839 | B23: 高龙明 | C23: 集训营 | D23: 考研项目部 | E23: A级学习顾问 | F23: =G23+H23 | G23: 0 | H23: 35357.1 | I23: 1120000 | K23: 1777684 | L23: -634404 | M23: 0 | N23: 1143279 | P23: 35291 | Q23: 0 | R23: 35291 | S23: 4 | T23: 3 | U23: 0.75 | V23: 0.03 | W23: 0.03 | X23: 69 | Y23: 0 | Z23: 1000 | AA23: 0
A24: 45839 | B24: 陈伟钰 | C24: 集训营 | D24: 考研项目部 | E24: B级学习顾问 | F24: =G24+H24 | G24: 2000 | H24: 5903.048 | I24: 1232000 | K24: 994027 | L24: -329229 | M24: 73084 | N24: 737881 | P24: 0 | Q24: 0 | R24: 0 | S24: 4 | T24: 3 | U24: 0.75 | V24: 0.008 | W24: 0.008 | X24: 105 | Y24: 1 | Z24: 2000 | AA24: 2000
A25: 45839 | B25: 陈露 | C25: 集训营 | D25: 考研项目部 | E25: B级学习顾问 | F25: =G25+H25 | G25: 0 | H25: 5941.416 | I25: 1232000 | K25: 825613 | L25: -162506 | M25: 0 | N25: 663107 | P25: 79570 | Q25: 0 | R25: 79570 | S25: 4 | T25: 1 | U25: 0.25 | V25: 0.008 | W25: 0.008 | X25: 42 | Y25: 0 | Z25: 2000 | AA25: 0
A26: 45870 | B26: 苏乾楠 | C26: 集训营 | D26: 考研项目部 | E26: B级学习顾问 | F26: =G26+H26 | G26: =AA26 | H26: =W26 | I26: 594000 | K26: 997762.2 | L26: -253999.4 | N26: =K26+L26+M26 | P26: 0 | Q26: 0 | R26: 0 | S26: 35000 | T26: 87176.8 | U26: =T26/S26 | V26: 0.04 | W26: 29750.512 | X26: 115 | Y26: 1 | Z26: 2000 | AA26: 2000
A27: 45870 | B27: 张乐 | C27: 集训营 | D27: 考研项目部 | E27: B级学习顾问 | F27: =G27+H27 | G27: =AA27 | H27: =W27 | I27: 540000 | K27: 508000 | L27: -421159.3 | M27: -495201 | N27: 0 | P27: -88775.8 | Q27: -0.17475551 | R27: 135400 | S27: =_xlfn.XLOOKUP(B27,'[1]8月老带新'!$B$15:$B$23,'[1]8月老带新'!$N$15:$N$23,0,0) | T27: =_xlfn.XLOOKUP(B27,'[1]8月老带新'!$B$15:$B$23,'[1]8月老带新'!$O$15:$O$23,0,0) | U27: =T27/S27 | V27: =_xlfn.XLOOKUP(B27,[1]顾问业绩奖金及绩效!$B$18:$B$28,[1]顾问业绩奖金及绩效!$AM$18:$AM$28,0,0) | W27: =_xlfn.XLOOKUP(B27,[1]顾问业绩奖金及绩效!$B$18:$B$28,[1]顾问业绩奖金及绩效!$AN$18:$AN$28,0,0) | X27: 100 | Y27: 1 | Z27: 2000 | AA27: 2000
A28: 45870 | B28: 张俊旺 | C28: 集训营 | D28: 考研项目部 | E28: A级学习顾问 | F28: =G28+H28 | G28: =AA28 | H28: =W28 | I28: 594000 | K28: 562000 | L28: -195333.1 | M28: -189520.1 | N28: 0 | P28: 718728.35 | Q28: 1.2788761 | R28: 0 | S28: =_xlfn.XLOOKUP(B28,'[1]8月老带新'!$B$15:$B$23,'[1]8月老带新'!$N$15:$N$23,0,0) | T28: =_xlfn.XLOOKUP(B28,'[1]8月老带新'!$B$15:$B$23,'[1]8月老带新'!$O$15:$O$23,0,0) | U28: =T28/S28 | V28: =_xlfn.XLOOKUP(B28,[1]顾问业绩奖金及绩效!$B$18:$B$28,[1]顾问业绩奖金及绩效!$AM$18:$AM$28,0,0) | W28: =_xlfn.XLOOKUP(B28,[1]顾问业绩奖金及绩效!$B$18:$B$28,[1]顾问业绩奖金及绩效!$AN$18:$AN$28,0,0) | X28: 40 | Y28: 0 | Z28: 1000 | AA28: 0
A29: 45870 | B29: 杨晓超 | C29: 集训营 | D29: 考研项目部 | E29: B级学习顾问 | F29: =G29+H29 | G29: =AA29 | H29: =W29 | I29: 540000 | K29: 508000 | L29: -628247.2 | M29: -604346.25 | N29: 54300 | P29: 789744.57 | Q29: 1.5546153 | R29: 96909.8 | S29: =_xlfn.XLOOKUP(B29,'[1]8月老带新'!$B$15:$B$23,'[1]8月老带新'!$N$15:$N$23,0,0) | T29: =_xlfn.XLOOKUP(B29,'[1]8月老带新'!$B$15:$B$23,'[1]8月老带新'!$O$15:$O$23,0,0) | U29: =T29/S29 | V29: =_xlfn.XLOOKUP(B29,[1]顾问业绩奖金及绩效!$B$18:$B$28,[1]顾问业绩奖金及绩效!$AM$18:$AM$28,0,0) | W29: =_xlfn.XLOOKUP(B29,[1]顾问业绩奖金及绩效!$B$18:$B$28,[1]顾问业绩奖金及绩效!$AN$18:$AN$28,0,0) | X29: 120 | Y29: 1 | Z29: 2000 | AA29: 2000
A30: 45870 | B30: 王志远 | C30: 集训营 | D30: 考研项目部 | E30: B级学习顾问 | F30: =G30+H30 | G30: =AA30 | H30: =W30 | S30: =_xlfn.XLOOKUP(B30,'[1]8月老带新'!$B$15:$B$23,'[1]8月老带新'!$N$15:$N$23,0,0) | T30: =_xlfn.XLOOKUP(B30,'[1]8月老带新'!$B$15:$B$23,'[1]8月老带新'!$O$15:$O$23,0,0) | V30: =_xlfn.XLOOKUP(B30,[1]顾问业绩奖金及绩效!$B$18:$B$28,[1]顾问业绩奖金及绩效!$AM$18:$AM$28,0,0) | W30: =_xlfn.XLOOKUP(B30,[1]顾问业绩奖金及绩效!$B$18:$B$28,[1]顾问业绩奖金及绩效!$AN$18:$AN$28,0,0) | X30: 0 | Y30: 1 | Z30: 2000 | AA30: 2000
A31: 45870 | B31: 王钦 | C31: 集训营 | D31: 考研项目部 | E31: B级学习顾问 | F31: =G31+H31 | G31: =AA31 | H31: =W31 | I31: 432000 | K31: 400000 | L31: -145975.2 | M31: -169464.8 | N31: 0 | P31: 365307.4 | Q31: 0.9132685 | R31: 6130 | S31: =_xlfn.XLOOKUP(B31,'[1]8月老带新'!$B$15:$B$23,'[1]8月老带新'!$N$15:$N$23,0,0) | T31: =_xlfn.XLOOKUP(B31,'[1]8月老带新'!$B$15:$B$23,'[1]8月老带新'!$O$15:$O$23,0,0) | U31: =T31/S31 | V31: =_xlfn.XLOOKUP(B31,[1]顾问业绩奖金及绩效!$B$18:$B$28,[1]顾问业绩奖金及绩效!$AM$18:$AM$28,0,0) | W31: =_xlfn.XLOOKUP(B31,[1]顾问业绩奖金及绩效!$B$18:$B$28,[1]顾问业绩奖金及绩效!$AN$18:$AN$28,0,0) | X31: 100 | Y31: 1 | Z31: 2000 | AA31: 2000
A32: 45870 | B32: 钱雪冰 | C32: 集训营 | D32: 考研项目部 | E32: B级学习顾问 | F32: =G32+H32 | G32: =AA32 | H32: =W32 | I32: 540000 | K32: 508000 | L32: -512931.85 | M32: -473267.05 | N32: 0 | P32: 760336.85 | Q32: 1.4967261 | R32: 18388.8 | S32: =_xlfn.XLOOKUP(B32,'[1]8月老带新'!$B$15:$B$23,'[1]8月老带新'!$N$15:$N$23,0,0) | T32: =_xlfn.XLOOKUP(B32,'[1]8月老带新'!$B$15:$B$23,'[1]8月老带新'!$O$15:$O$23,0,0) | U32: =T32/S32 | V32: =_xlfn.XLOOKUP(B32,[1]顾问业绩奖金及绩效!$B$18:$B$28,[1]顾问业绩奖金及绩效!$AM$18:$AM$28,0,0) | W32: =_xlfn.XLOOKUP(B32,[1]顾问业绩奖金及绩效!$B$18:$B$28,[1]顾问业绩奖金及绩效!$AN$18:$AN$28,0,0) | X32: 95 | Y32: 1 | Z32: 1000 | AA32: 1000
A33: 45870 | B33: 刘创 | C33: 集训营 | D33: 考研项目部 | E33: B级学习顾问 | F33: =G33+H33 | G33: =AA33 | H33: =W33 | I33: 594000 | K33: 562000 | L33: -474810.65 | M33: -440995.75 | N33: 0 | P33: 852644.9 | Q33: 1.5171617 | R33: 80301.9 | S33: =_xlfn.XLOOKUP(B33,'[1]8月老带新'!$B$15:$B$23,'[1]8月老带新'!$N$15:$N$23,0,0) | T33: =_xlfn.XLOOKUP(B33,'[1]8月老带新'!$B$15:$B$23,'[1]8月老带新'!$O$15:$O$23,0,0) | U33: =T33/S33 | V33: =_xlfn.XLOOKUP(B33,[1]顾问业绩奖金及绩效!$B$18:$B$28,[1]顾问业绩奖金及绩效!$AM$18:$AM$28,0,0) | W33: =_xlfn.XLOOKUP(B33,[1]顾问业绩奖金及绩效!$B$18:$B$28,[1]顾问业绩奖金及绩效!$AN$18:$AN$28,0,0) | X33: 100 | Y33: 1 | Z33: 2000 | AA33: 2000
A34: 45870 | B34: 高龙明 | C34: 集训营 | D34: 考研项目部 | E34: A级学习顾问 | F34: =G34+H34 | G34: =AA34 | H34: =W34 | I34: 540000 | K34: 508000 | L34: -661390.05 | M34: -707562.15 | N34: 14625.5 | P34: 843016.55 | Q34: 1.6594814 | R34: 100803 | S34: =_xlfn.XLOOKUP(B34,'[1]8月老带新'!$B$15:$B$23,'[1]8月老带新'!$N$15:$N$23,0,0) | T34: =_xlfn.XLOOKUP(B34,'[1]8月老带新'!$B$15:$B$23,'[1]8月老带新'!$O$15:$O$23,0,0) | U34: =T34/S34 | V34: =_xlfn.XLOOKUP(B34,[1]顾问业绩奖金及绩效!$B$18:$B$28,[1]顾问业绩奖金及绩效!$AM$18:$AM$28,0,0) | W34: =_xlfn.XLOOKUP(B34,[1]顾问业绩奖金及绩效!$B$18:$B$28,[1]顾问业绩奖金及绩效!$AN$18:$AN$28,0,0) | X34: 105 | Y34: 1 | Z34: 1000 | AA34: 1000
A35: 45870 | B35: 陈伟钰 | C35: 集训营 | D35: 考研项目部 | E35: B级学习顾问 | F35: =G35+H35 | G35: =AA35 | H35: =W35 | S35: =_xlfn.XLOOKUP(B35,'[1]8月老带新'!$B$15:$B$23,'[1]8月老带新'!$N$15:$N$23,0,0) | T35: =_xlfn.XLOOKUP(B35,'[1]8月老带新'!$B$15:$B$23,'[1]8月老带新'!$O$15:$O$23,0,0) | V35: =_xlfn.XLOOKUP(B35,[1]顾问业绩奖金及绩效!$B$18:$B$28,[1]顾问业绩奖金及绩效!$AM$18:$AM$28,0,0) | W35: =_xlfn.XLOOKUP(B35,[1]顾问业绩奖金及绩效!$B$18:$B$28,[1]顾问业绩奖金及绩效!$AN$18:$AN$28,0,0)
A36: 45870 | B36: 陈露 | C36: 集训营 | D36: 考研项目部 | E36: B级学习顾问 | F36: =G36+H36 | G36: =AA36 | H36: =W36 | I36: 594000 | K36: 562000 | L36: -251159.55 | M36: -277508.8 | N36: 36125.6 | P36: 336072 | Q36: 0.59799288 | R36: 0 | S36: =_xlfn.XLOOKUP(B36,'[1]8月老带新'!$B$15:$B$23,'[1]8月老带新'!$N$15:$N$23,0,0) | T36: =_xlfn.XLOOKUP(B36,'[1]8月老带新'!$B$15:$B$23,'[1]8月老带新'!$O$15:$O$23,0,0) | U36: 0 | V36: =_xlfn.XLOOKUP(B36,[1]顾问业绩奖金及绩效!$B$18:$B$28,[1]顾问业绩奖金及绩效!$AM$18:$AM$28,0,0) | W36: =_xlfn.XLOOKUP(B36,[1]顾问业绩奖金及绩效!$B$18:$B$28,[1]顾问业绩奖金及绩效!$AN$18:$AN$28,0,0) | X36: 40 | Y36: 0 | Z36: 2000 | AA36: 0
A37: 45901 | B37: 苏乾楠 | C37: 集训营 | D37: 考研项目部 | E37: B级学习顾问 | F37: =G37+H37 | G37: =AA37 | H37: =W37 | I37: 700000 | J37: 680000 | K37: 902001.15 | L37: -80250 | N37: =K37+L37+M37 | O37: =N37/J37 | P37: 22448.6 | Q37: -1332.44 | R37: 21116.16 | S37: 35000 | T37: 202262.8 | U37: 5.7789371 | V37: 0.04 | W37: 33714.692 | X37: 100 | Y37: 1 | Z37: 2000 | AA37: 2000
A38: 45901 | B38: 张乐 | C38: 集训营 | D38: 考研项目部 | E38: B级学习顾问 | F38: =G38+H38 | G38: 2000 | H38: 12144.645 | I38: 831124 | J38: 811124 | K38: 833431.95 | L38: -168876.95 | M38: 0 | N38: 664555 | O38: 0.81930136 | P38: 10147.5 | Q38: 0 | R38: 10147.5 | S38: 35000 | T38: 90600 | U38: 2.5885714 | V38: 0.018 | W38: 12144.645 | X38: 96 | Y38: 1 | Z38: 2000 | AA38: 2000
A39: 45901 | B39: 张俊旺 | C39: 集训营 | D39: 考研项目部 | E39: 集训营顾问组长 | F39: =G39+H39 | G39: 4000 | H39: 0 | I39: 350000 | J39: 340000 | K39: 195800 | L39: -84312.6 | M39: 0 | N39: 111487.4 | O39: 0.32790412 | P39: 0 | Q39: 0 | R39: 0 | S39: 70000 | T39: 97299 | U39: 1.39 | V39: 0 | W39: 0 | X39: 100 | Y39: 1 | Z39: 4000 | AA39: 4000
A40: 45901 | B40: 杨晓超 | C40: 集训营 | D40: 考研项目部 | E40: B级学习顾问 | F40: =G40+H40 | G40: 1600 | H40: 24143.832 | I40: 700000 | J40: 680000 | K40: 999784.5 | L40: -213079.8 | M40: 0 | N40: 786704.7 | O40: 1.1569187 | P40: 18159.7 | Q40: -70 | R40: 18089.7 | S40: 35000 | T40: 97298.5 | U40: 2.7799571 | V40: 0.03 | W40: 24143.832 | X40: 80 | Y40: 0.8 | Z40: 2000 | AA40: 1600
...

Sheet 走读
A1: 年月（自然月） | B1: 顾问姓名 | C1: 二级部门 | D1: 三级部门 | E1: 岗位 | F1: 奖金 | G1: 实发绩效 | H1: 实发提成 | I1: 月度业绩 | X1: 月度绩效
I2: 目标 | J2: 线下目标 | K2: 线下进账 | L2: 线下退费表 | M2: 线下主动调整 | N2: 线下净业绩 | O2: 线下完成率 | P2: 网课进账 | Q2: 网课退费 | R2: 网课净业绩 | S2: 转介绍目标 | T2: 转介绍业绩 | U2: 转介绍完成率 | V2: 提点 | W2: 提成 | X2: 合计得分 | Y2: 发放比例 | Z2: 月度绩效标准 | AA2: 月绩效应发
A3: 45809 | B3: 刘海玲 | C3: 无忧/走读 | D3: 考研项目部 | E3: B级学习顾问 | F3: =G3+H3 | G3: 0 | H3: 0 | I3: 880000 | K3: 417141.5 | L3: -356767.3 | M3: 0 | N3: 60374.2 | P3: 20827.8 | Q3: -10054.83 | R3: 10772.97 | S3: 6 | T3: 1 | U3: 0.1667 | V3: 0 | W3: 0 | X3: 25 | Y3: 0 | Z3: 2000 | AA3: 0
A4: 45809 | B4: 徐铁 | C4: 无忧/走读 | D4: 考研项目部 | E4: B级学习顾问 | F4: =G4+H4 | G4: 0 | H4: 49805.696 | I4: 880000 | K4: 1403968.5 | L4: -223913.6 | M4: 0 | N4: 1180054.9 | P4: 75118.85 | Q4: -10031.35 | R4: 65087.5 | S4: 6 | T4: 6 | U4: 1 | V4: 0.04 | W4: 49805.696 | X4: 67 | Y4: 0 | Z4: 2000 | AA4: 0
A5: 45809 | B5: 刘欢 | C5: 无忧/走读 | D5: 考研项目部 | E5: A级学习顾问 | F5: =G5+H5 | G5: 810 | H5: 79101.78 | I5: 880000 | K5: 1741966 | L5: -296213.8 | M5: 54150 | N5: 1499902.2 | P5: 88315.1 | Q5: -6181.7 | R5: 82133.4 | S5: 6 | T5: 9 | U5: 1.5 | V5: 0.05 | W5: 79101.78 | X5: 81 | Y5: 0.81 | Z5: 1000 | AA5: 810
A6: 45809 | B6: 汪宇萌 | C6: 无忧/走读 | D6: 考研项目部 | E6: B级学习顾问 | F6: =G6+H6 | G6: 1720 | H6: 44222.501 | I6: 880000 | K6: 1228006 | L6: -184301.1 | M6: 0 | N6: 1043704.9 | P6: 111974.2 | Q6: -50116.58 | R6: 61857.62 | S6: 6 | T6: 6 | U6: 1 | V6: 0.04 | W6: 44222.501 | X6: 86 | Y6: 0.86 | Z6: 2000 | AA6: 1720
A7: 45809 | B7: 李婧 | C7: 无忧/走读 | D7: 考研项目部 | E7: B级学习顾问 | F7: =G7+H7 | G7: 1500 | H7: 16237.534 | I7: 968000 | K7: 999495.9 | L7: -116128.8 | M7: 0 | N7: 883367.1 | P7: 28918.1 | Q7: -10200 | R7: 18718.1 | S7: 6 | T7: 5 | U7: 0.8333 | V7: 0.018 | W7: 16237.534 | X7: 75 | Y7: 0.75 | Z7: 2000 | AA7: 1500
A8: 45809 | B8: 李崇宇 | C8: 无忧/走读 | D8: 考研项目部 | E8: B级学习顾问 | F8: =G8+H8 | G8: 0 | H8: 0 | I8: 968000 | K8: 197700 | L8: -69190.8 | M8: 0 | N8: 128509.2 | P8: 12682.9 | Q8: 0 | R8: 12682.9 | S8: 4 | T8: 0 | U8: 0 | V8: 0 | W8: 0 | X8: 0 | Y8: 0 | Z8: 2000 | AA8: 0
A9: 45809 | B9: 王秋雨 | C9: 无忧/走读 | D9: 考研项目部 | E9: B级学习顾问 | F9: =G9+H9 | G9: 0 | H9: 12986.145 | I9: 880000 | K9: 749621.2 | L9: -67974.8 | M9: 0 | N9: 681646.4 | P9: 39806.1 | Q9: 0 | R9: 39806.1 | S9: 4 | T9: 2 | U9: 0.5 | V9: 0.018 | W9: 12986.145 | X9: 45 | Y9: 0 | Z9: 2000 | AA9: 0
A10: 45809 | B10: 田源 | C10: 无忧/走读 | D10: 考研项目部 | E10: B级学习顾问 | F10: =G10+H10 | G10: 818.18182 | H10: 0 | I10: 0 | K10: 0 | L10: 0 | M10: 0 | N10: 0 | P10: 0 | Q10: 0 | R10: 0 | S10: 0 | T10: 0 | U10: 0 | V10: 0 | W10: 0 | X10: 0 | Y10: 0.40909091 | Z10: 2000 | AA10: 818.18182
A11: 45809 | B11: 卢晓飞 | C11: 无忧/走读 | D11: 考研项目部 | E11: B级学习顾问 | F11: =G11+H11 | G11: 2000 | H11: 544.36 | I11: 0 | K11: 125500 | L11: 0 | M11: -88200 | N11: 37300 | P11: 17136 | Q11: 0 | R11: 17136 | S11: 0 | T11: 0 | U11: 0 | V11: 0.01 | W11: 544.36 | X11: 0 | Y11: 1 | Z11: 2000 | AA11: 2000
A12: 45809 | B12: 田志伟 | C12: 无忧/走读 | D12: 考研项目部 | E12: B级学习顾问 | F12: =G12+H12 | G12: 2000 | H12: 230 | I12: 0 | K12: 23000 | L12: 0 | M12: 0 | N12: 23000 | P12: 0 | Q12: 0 | R12: 0 | S12: 0 | T12: 0 | U12: 0 | V12: 0.01 | W12: 230 | X12: 0 | Y12: 1 | Z12: 2000 | AA12: 2000
A13: 45809 | B13: 金民民 | C13: 无忧/走读 | D13: 考研项目部 | E13: B级学习顾问 | F13: =G13+H13 | G13: 2000 | H13: 0 | I13: 0 | K13: 0 | L13: 0 | M13: 0 | N13: 0 | P13: 0 | Q13: 0 | R13: 0 | S13: 0 | T13: 0 | U13: 0 | V13: 0 | W13: 0 | X13: 0 | Y13: 1 | Z13: 2000 | AA13: 2000
A14: 45809 | B14: 寇源 | C14: 无忧/走读 | D14: 考研项目部 | E14: B级学习顾问 | F14: =G14+H14 | G14: 0 | H14: 0 | I14: 0 | K14: 0 | L14: 0 | M14: 0 | N14: 0 | P14: 0 | Q14: 0 | R14: 0 | S14: 0 | T14: 0 | U14: 0 | V14: 0 | W14: 0 | X14: 0 | Y14: 0 | Z14: 0 | AA14: 0
... A26: 45839 | B26: 堕朕 | C26: 无忧/走读 | D26: 考研项目部 | E26: 走读项目部-销售管理部-O1学习顾问 | F26: =G26+H26 | G26: 363.63636 | H26: 0 | I26: 0 | K26: 0 | L26: 0 | M26: 0 | N26: 0 | P26: 0 | Q26: 0 | R26: 0 | S26: 0 | T26: 0 | U26: 0 | V26: 0 | W26: 0 | X26: 0 | Y26: 0.18181818 | Z26: 2000 | AA26: 363.63636
A27: 45870 | B27: 刘海玲 | C27: 无忧/走读 | D27: 考研项目部 | E27: 走读项目部-销售管理部-O1学习顾问 | F27: =G27+H27 | G27: 0 | H27: 10461.939 | I27: 705000 | J27: 670000 | K27: 944937.8 | L27: -365741.95 | M27: 0 | N27: 579195.85 | O27: 0.86447142 | P27: 2023 | Q27: 0 | R27: 2023 | S27: 90000 | T27: 31123 | U27: 0.34581111 | V27: 0.018 | W27: 10461.939 | X27: 20 | Y27: 0 | Z27: 2000 | AA27: 0
A28: 45870 | B28: 徐铁 | C28: 无忧/走读 | D28: 考研项目部 | E28: 走读项目部-销售管理部-O1学习顾问 | F28: =G28+H28 | G28: 0 | H28: 35873.076 | I28: 705000 | J28: 670000 | K28: 969162.5 | L28: -147704.25 | M28: 0 | N28: 821458.25 | O28: 1.2260571 | P28: 75368.65 | Q28: 0 | R28: 75368.65 | S28: 90000 | T28: 49055.9 | U28: 0.54506556 | V28: 0.04 | W28: 35873.076 | X28: 20 | Y28: 0 | Z28: 2000 | AA28: 0
A29: 45870 | B29: 刘欢 | C29: 无忧/走读 | D29: 考研项目部 | E29: 走读项目部-销售管理部-O3学习顾问 | F29: =G29+H29 | G29: 0 | H29: 56684.624 | I29: 705000 | J29: 670000 | K29: 1415085.4 | L29: -343524.05 | M29: 0 | N29: 1071561.4 | O29: 1.5993454 | P29: 76275.75 | Q29: -14144.68 | R29: 62131.07 | S29: 90000 | T29: 128995.7 | U29: 1.4332856 | V29: 0.05 | W29: 56684.624 | X29: 88 | Y29: 0.88 | Z29: 0 | AA29: 0
A30: 45870 | B30: 汪宇萌 | C30: 无忧/走读 | D30: 考研项目部 | E30: 走读项目部-销售管理部-O1学习顾问 | F30: =G30+H30 | G30: 0 | H30: 37202.274 | I30: 705000 | J30: 670000 | K30: 1214290 | L30: -348563.75 | M30: 0 | N30: 865726.25 | O30: 1.2921287 | P30: 68367.5 | Q30: -4036.89 | R30: 64330.61 | S30: 90000 | T30: 43250 | U30: 0.48055556 | V30: 0.04 | W30: 37202.274 | X30: 20 | Y30: 0 | Z30: 2000 | AA30: 0
A31: 45870 | B31: 李婧 | C31: 无忧/走读 | D31: 考研项目部 | E31: 走读项目部-销售管理部-O1学习顾问 | F31: =G31+H31 | G31: 2000 | H31: 43811.619 | I31: 775500 | J31: 740500 | K31: 1261818.3 | L31: -201755.85 | M31: 0 | N31: 1060062.4 | O31: 1.4315496 | P31: 42455.5 | Q31: -7227.48 | R31: 35228.02 | S31: 90000 | T31: 115206 | U31: 1.2800667 | V31: 0.04 | W31: 43811.619 | X31: 100 | Y31: 1 | Z31: 2000 | AA31: 2000
A32: 45870 | B32: 王秋雨 | C32: 无忧/走读 | D32: 考研项目部 | E32: 走读项目部-销售管理部-O1学习顾问 | F32: =G32+H32 | G32: 0 | H32: 22612.435 | I32: 705000 | J32: 670000 | K32: 817555 | L32: -110820.9 | M32: 0 | N32: 706734.1 | O32: 1.054827 | P32: 65435 | Q32: -18421.28 | R32: 47013.72 | S32: 90000 | T32: 22100 | U32: 0.24555556 | V32: 0.03 | W32: 22612.435 | X32: 20 | Y32: 0 | Z32: 2000 | AA32: 0
A33: 45870 | B33: 田志伟 | C33: 无忧/走读 | D33: 考研项目部 | E33: 走读项目部-销售管理部-O1学习顾问 | F33: =G33+H33 | G33: 2000 | H33: 8462.805 | I33: 352500 | J33: 335000 | K33: 343629.75 | L33: 0 | M33: 0 | N33: 343629.75 | O33: 1.0257604 | P33: 79610.5 | Q33: -100 | R33: 79510.5 | S33: 30000 | T33: 0 | U33: 0 | V33: 0.02 | W33: 8462.805 | X33: 20 | Y33: 1 | Z33: 2000 | AA33: 2000
A34: 45870 | B34: 卢晓飞 | C34: 无忧/走读 | D34: 考研项目部 | E34: 走读项目部-销售管理部-O1学习顾问 | F34: =G34+H34 | G34: 2000 | H34: 5188.248 | I34: 352500 | J34: 335000 | K34: 301332.8 | L34: -41406.7 | M34: 8997.9 | N34: 268924 | O34: 0.80275821 | P34: 19312 | Q34: 0 | R34: 19312 | S34: 30000 | T34: 0 | U34: 0 | V34: 0.018 | W34: 5188.248 | X34: 0 | Y34: 1 | Z34: 2000 | AA34: 2000
A35: 45870 | B35: 金民民 | C35: 无忧/走读 | D35: 考研项目部 | E35: 走读项目部-销售管理部-O1学习顾问 | F35: =G35+H35 | G35: 2000 | H35: 0 | I35: 352500 | J35: 335000 | K35: 89626.5 | L35: -30188 | M35: 0 | N35: 59438.5 | O35: 0.17742836 | P35: 18725.5 | Q35: 0 | R35: 18725.5 | S35: 30000 | T35: 0 | U35: 0 | V35: 0 | W35: 0 | X35: 0 | Y35: 1 | Z35: 2000 | AA35: 2000
A36: 45870 | B36: 王一鸣 | C36: 无忧/走读 | D36: 考研项目部 | E36: 走读项目部-销售管理部-O1学习顾问 | F36: =G36+H36 | G36: 2000 | H36: 27093.8 | I36: 211500 | J36: 201000 | K36: 538493 | L36: 0 | M36: 0 | N36: 538493 | O36: 2.6790697 | P36: 3383 | Q36: 0 | R36: 3383 | S36: 30000 | T36: 129000 | U36: 4.3 | V36: 0.05 | W36: 27093.8 | X36: 70 | Y36: 1 | Z36: 2000 | AA36: 2000
A37: 45870 | B37: 堕朕 | C37: 无忧/走读 | D37: 考研项目部 | E37: 走读项目部-销售管理部-O1学习顾问 | F37: =G37+H37 | G37: 2000 | H37: 0 | I37: 0 | J37: 0 | K37: 0 | L37: 0 | M37: 0 | N37: 0 | O37: 0 | P37: 0 | Q37: 0 | R37: 0 | S37: 0 | T37: 0 | U37: 0 | V37: 0 | W37: 0 | X37: 0 | Y37: 1 | Z37: 2000 | AA37: 2000
A38: 45901 | B38: 汪宇萌 | C38: 无忧/走读 | D38: 考研项目部 | E38: 走读顾问组长 | F38: =G38+H38 | G38: 2880 | H38: 29807.76 | I38: 365000 | J38: 350000 | K38: 1101732.3 | L38: -166811.4 | M38: 9900 | N38: 944820.9 | O38: 2.6994883 | P38: 48991 | Q38: -220 | R38: 48771 | S38: 55000 | T38: 50800 | U38: 0 | V38: 0.03 | W38: 29807.757 | X38: 75.97311 | Y38: 0.7597 | Z38: 4000 | AA38: 2880
... A58: 45931 | B58: 堕朕 | C58: 无忧/走读 | D58: 考研项目部 | E58: 走读项目部-销售管理部-O1学习顾问 | F58: =G58+H58 | G58: 2000 | H58: 18091.42 | I58: 360000 | J58: 345000 | K58: 558781 | L58: -136660 | M58: 0 | N58: 422121 | O58: 1.22 | P58: 31068 | Q58: -904 | R58: 30164 | S58: 35000 | T58: 106100 | U58: 3.03 | V58: 0.04 | W58: 18091.42 | X58: 76 | Y58: 1 | Z58: 2000 | AA58: 2000
A59: 45962 | B59: 汪宇萌 | C59: 无忧/走读 | D59: 考研项目部 | E59: 走读顾问组长 | F59: =G59+H59 | G59: 3600 | H59: 14447.91 | I59: 332500 | J59: 330000 | K59: 618836 | L59: -175808.9 | M59: 12220 | N59: 455247.1 | O59: 1.3795367 | P59: 26449.4 | Q59: -100 | R59: 26349.4 | V59: 0.03 | W59: 14447.9 | X59: 84.731504 | Y59: 0.8473 | Z59: 4000 | AA59: 3600
A60: 45962 | B60: 刘海玲 | C60: 无忧/走读 | D60: 考研项目部 | E60: 走读项目部-销售管理部-O1学习顾问 | F60: =G60+H60 | G60: 0 | H60: 9865.49 | I60: 599000 | J60: 594000 | K60: 620080 | L60: -83800 | M60: 0 | N60: 536280 | O60: 0.90282828 | P60: 11902.8 | Q60: -100 | R60: 11802.8 | S60: 80000 | T60: 14200 | U60: 0.18 | V60: 0.018 | W60: 9865.49 | X60: 28 | Y60: 0 | Z60: 2000 | AA60: 0
A61: 45962 | B61: 徐铁 | C61: 无忧/走读 | D61: 考研项目部 | E61: 走读项目部-销售管理部-O1学习顾问 | F61: =G61+H61 | G61: 2000 | H61: 27152.8 | I61: 555000 | J61: 550000 | K61: 836268 | L61: -214452.5 | M61: 17100 | N61: 638915.5 | O61: 1.1616645 | P61: 40004.4 | Q61: -100 | R61: 39904.4 | S61: 80000 | T61: 106100 | U61: 1.33 | V61: 0.04 | W61: 27152.8 | X61: 90 | Y61: 1 | Z61: 2000 | AA61: 2000
A62: 45962 | B62: 刘欢 | C62: 无忧/走读 | D62: 考研项目部 | E62: 走读项目部-销售管理部-O3学习顾问 | F62: =G62+H62 | G62: 0 | H62: 8239.41 | I62: 555000 | J62: 550000 | K62: 648333.7 | L62: -193109.1 | M62: -6400 | N62: 448824.6 | O62: 0.81604473 | P62: 18470.6 | Q62: -9550 | R62: 8920.6 | S62: 80000 | T62: 3366 | U62: 0.04 | V62: 0.018 | W62: 8239.41 | X62: 20 | Y62: 0 | Z62: 0 | AA62: 0
A63: 45962 | B63: 李婧 | C63: 无忧/走读 | D63: 考研项目部 | E63: 走读项目部-销售管理部-O1学习顾问 | F63: =G63+H63 | G63: 0 | H63: 0 | I63: 555000 | J63: 550000 | K63: 183650 | L63: -37829 | M63: 0 | N63: 145821 | O63: 0.26512909 | P63: 8263.1 | Q63: -100 | R63: 8163.1 | S63: 80000 | T63: 54800 | U63: 0.69 | V63: 0 | W63: 0 | X63: 50 | Y63: 0 | Z63: 2000 | AA63: 0
A64: 45962 | B64: 王秋雨 | C64: 无忧/走读 | D64: 考研项目部 | E64: 走读项目部-销售管理部-O1学习顾问 | F64: =G64+H64 | G64: 0 | H64: 22992.59 | I64: 478000 | J64: 473000 | K64: 696219.1 | L64: -133486.1 | M64: 0 | N64: 562733 | O64: 1.1897104 | P64: 12181.85 | Q64: -100 | R64: 12081.85 | S64: 40000 | T64: 0 | U64: 0 | V64: 0.04 | W64: 22992.59 | X64: 30 | Y64: 0 | Z64: 2000 | AA64: 0
A65: 45962 | B65: 卢晓飞 | C65: 无忧/走读 | D65: 考研项目部 | E65: 走读项目部-销售管理部-O1学习顾问 | F65: =G65+H65 | G65: 0 | H65: 0 | I65: 522000 | J65: 517000 | K65: 203322 | L65: -39000 | M65: 0 | N65: 164322 | O65: 0.31783752 | P65: 4286.4 | Q65: -1415.39 | R65: 2871.01 | S65: 40000 | T65: 0 | U65: 0 | V65: 0 | W65: 0 | X65: 20 | Y65: 0 | Z65: 2000 | AA65: 0
A66: 45962 | B66: 王一鸣 | C66: 无忧/走读 | D66: 考研项目部 | E66: 走读项目部-销售管理部-O1学习顾问 | F66: =G66+H66 | G66: 0 | H66: 22951.78 | I66: 478000 | J66: 473000 | K66: 602381.6 | L66: -54321.6 | M66: 0 | N66: 548060 | O66: 1.1586892 | P66: 25814.4 | Q66: -80 | R66: 25734.4 | S66: 40000 | T66: 14856 | U66: 0.37 | V66: 0.04 | W66: 22951.78 | X66: 38 | Y66: 0 | Z66: 2000 | AA66: 0
A67: 45962 | B67: 堕朕 | C67: 无忧/走读 | D67: 考研项目部 | E67: 走读项目部-销售管理部-O1学习顾问 | F67: =G67+H67 | G67: 2000 | H67: 10686.34 | I67: 356000 | J67: 352000 | K67: 373299.5 | L67: -81040.3 | M67: 17100 | N67: 309359.2 | O67: 0.87886136 | P67: 46952.05 | Q67: -100 | R67: 46852.05 | S67: 40000 | T67: 70300 | U67: 1.76 | V67: 0.03 | W67: 10686.34 | X67: 90 | Y67: 1 | Z67: 2000 | AA67: 2000
A68: 45992 | B68: 汪宇萌 | C68: 无忧/走读 | D68: 考研项目部 | E68: 走读顾问组长 | F68: =G68+H68 | G68: 0 | H68: 10311.3 | I68: 262000 | J68: 255000 | K68: 439100 | L68: -139285 | M68: 0 | N68: 299816 | O68: 1.18 | P68: 44144 | Q68: -250 | R68: 43894 | V68: 0.04 | W68: 13748.4 | X68: 30 | Y68: 0.3 | Z68: 4000 | AA68: 0
A69: 45992 | B69: 刘海玲 | C69: 无忧/走读 | D69: 考研项目部 | E69: 走读项目部-销售管理部-O1学习顾问 | F69: =G69+H69 | G69: 0 | H69: 2795.71 | I69: 474000 | J69: 460000 | K69: 446520 | L69: -111760 | M69: 0 | N69: 334760 | O69: 0.72773913 | P69: 14703.6 | Q69: 0 | R69: 14703.6 | S69: 100000 | T69: 42300 | U69: 0.42 | V69: 0.008 | W69: 2795.71 | X69: 22 | Y69: 0 | Z69: 2000 | AA69: 0
A70: 45992 | B70: 徐铁 | C70: 无忧/走读 | D70: 考研项目部 | E70: 走读项目部-销售管理部-O1学习顾问 | F70: =G70+H70 | G70: 0 | H70: 22924.08 | I70: 474000 | J70: 460000 | K70: 602497 | L70: -38991 | M70: 0 | N70: 563506 | O70: 1.225013 | P70: 9596.1 | Q70: 0 | R70: 9596.1 | S70: 100000 | T70: 0 | U70: 0 | V70: 0.04 | W70: 22924.08 | X70: 8 | Y70: 0 | Z70: 2000 | AA70: 0
...

Sheet 四六级
A1: 年月（自然月） | B1: 顾问姓名 | C1: 二级部门 | D1: 三级部门 | E1: 岗位 | F1: 奖金 | G1: 实发绩效 | H1: 实发提成 | I1: 月度业绩 | P1: 月度绩效
I2: 资源处理时效数据 | J2: 资源处理时效得分 | K2: 老带新完成人头 | L2: 老带新得分 | M2: 新增签约完成情况 | N2: 新增签约完成率 | O2: 新增签约得分 | P2: 合计得分 | Q2: 发放比例 | R2: 月度绩效标准 | S2: 月绩效应发
A3: 45962 | B3: 刘晓娟 | C3: 四六级 | D3: 四六级项目部 | E3: B级学习顾问 | F3: =G3+H3 | G3: 2000 | H3: 14556.105 | I3: 12.89 | J3: 10 | K3: 5 | L3: 30 | M3: 0.3 | N3: 1.0714286 | O3: 60 | P3: 100 | Q3: 1 | R3: 2000 | S3: 2000
A4: 45962 | B4: 房国超 | C4: 四六级 | D4: 四六级项目部 | E4: B级学习顾问 | F4: =G4+H4 | G4: 1400 | H4: 4170.9927 | I4: 4.5 | J4: 10 | K4: 3 | L4: 18 | M4: 0.194 | N4: 0.69285714 | O4: 41.571429 | P4: 69.571429 | Q4: 0.7 | R4: 2000 | S4: 1400
A5: 45962 | B5: 宋增辉 | C5: 四六级 | D5: 四六级项目部 | E5: B级学习顾问 | F5: =G5+H5 | G5: 0 | H5: 0 | I5: 25.83 | J5: 10 | K5: 0 | L5: 0 | M5: 0.11 | N5: 0.39285714 | O5: 23.571429 | P5: 33.571429 | Q5: 0 | R5: 2000 | S5: 0
A6: 45962 | B6: 田一禾 | C6: 四六级 | D6: 四六级项目部 | E6: B级学习顾问 | F6: =G6+H6 | G6: 1440 | H6: 8662 | I6: 30.36 | J6: 10 | K6: 0 | L6: 0 | M6: 0.3 | N6: 1.0714286 | O6: 60 | P6: 70 | Q6: 0.7 | R6: 2000 | S6: 1400
A7: 45962 | B7: 黄智超 | C7: 四六级 | D7: 四六级项目部 | E7: B级学习顾问 | F7: =G7+H7 | G7: 1520 | H7: 15076 | I7: 5.15 | J7: 10 | K7: 3 | L7: 18 | M7: 0.22 | N7: 0.78571429 | O7: 48 | P7: 76 | Q7: 0.76 | R7: 2000 | S7: 1520
A8: 45962 | B8: 徐一城 | C8: 四六级 | D8: 四六级项目部 | E8: B级学习顾问 | F8: =G8+H8 | G8: 1480 | H8: 0 | I8: 新人第三个月保护期打满 | J8: 10 | K8: 1 | L8: 6 | M8: 0.27 | N8: 0.96428571 | O8: 58 | P8: 74 | Q8: 0.74 | R8: 2000 | S8: 1480

Sheet 个性化
A1: 年月（自然月） | B1: 顾问姓名 | C1: 二级部门 | D1: 三级部门 | E1: 岗位 | F1: 奖金 | G1: 实发绩效 | H1: 基本提成 | I1: 基本提成 | Q1: 转介绍提成 | U1: 月度绩效
I2: 地面现金目标 | J2: 地面净现金 | K2: 在线现金目标 | L2: 在线净现金 | M2: 总现金完成-退费后 | N2: 现金完成率 | O2: 提点系数 | P2: 基本提成 | Q2: 转介绍目标 | R2: 转介绍业绩 | S2: 提点 | T2: 转介绍提成 | U2: 总得分 | V2: 绩效基数 | W2: 发放比例 | X2: 发放金额
A3: 45962 | B3: 赵星火 | C3: 个性化 | D3: 考研个性化 | E3: 学习顾问 | F3: =G3+H3 | G3: 600 | H3: =P3 | I3: 510000 | J3: 120749.5 | K3: 5000 | L3: 53054.4 | M3: 173803.9 | N3: 0.3374833 | O3: 0.008 | P3: 1390.4312 | Q3: 50000 | R3: 0 | S3: -0.002 | T3: 0 | U3: 70 | V3: 1000 | W3: 0.6 | X3: 600
A4: 45962 | B4: 谭悦 | C4: 个性化 | D4: 考研个性化 | E4: 学习顾问 | F4: =G4+H4 | G4: 0 | H4: 27810.468 | I4: 510000 | J4: 640893.2 | K4: 5000 | L4: 56051 | M4: 696944.2 | N4: 1.3532897 | O4: 0.04 | P4: 27877.768 | Q4: 50000 | R4: 33650 | S4: -0.002 | T4: -67.3 | U4: 70 | V4: 0 | W4: 0.6 | X4: 0
A5: 45962 | B5: 李涛 | C5: 个性化 | D5: 考研个性化 | E5: 学习顾问 | F5: =G5+H5 | G5: 1200 | H5: 0 | I5: 510000 | J5: 77710 | K5: 4000 | L5: -8366.45 | M5: 69343.55 | N5: 0.13490963 | O5: 0 | P5: 0 | Q5: 40000 | R5: 0 | S5: -0.002 | T5: 0 | U5: 70 | V5: 2000 | W5: 0.6 | X5: 1200

Sheet 在职研
A1: 年月（自然月） | B1: 顾问姓名 | C1: 二级部门 | D1: 三级部门 | E1: 岗位 | F1: 奖金 | G1: 实发绩效 | H1: 实发提成 | I1: 月度业绩 | S1: 月度绩效
I2: 本月目标 | J2: 线下进账 | K2: 线下退费 | L2: 线下净业绩 | M2: 月度完成率 | N2: 网课进账 | O2: 网课退费 | P2: 网课净业绩 | Q2: 提点 | R2: 奖金合计 | S2: 总分 | T2: 发放比例 | U2: 绩效满额 | V2: 应发绩效 | W2: 2+3绩效满额 | X2: 2+3应发绩效
A3: 2+3 | B3: 杨明 | C3: 在职研 | D3: 在职研项目部 | E3: B级学习顾问 | F3: =G3+H3 | G3: 2000 | H3: =R3 | I3: 617700 | J3: 574550 | K3: 36279.15 | L3: 538270.85 | M3: 0.87141145 | N3: 41810 | O3: 0 | P3: 41810 | Q3: 0.035 | R3: 19257.58 | S3: 92.203375 | T3: 1 | U3: 2000 | V3: 2000 | W3: 4000 | X3: 2000
A4: 2+3 | B4: 刘津玲 | C4: 在职研 | D4: 在职研项目部 | E4: A级学习顾问 | F4: =G4+H4 | G4: 2220 | H4: =R4 | I4: 617700 | J4: 810280 | K4: 60524.85 | L4: 749755.15 | M4: 1.2137853 | N4: 84091.6 | O4: 30046 | P4: 54045.6 | Q4: 0.06 | R4: 45525.765 | S4: 86.5 | T4: 0.87 | U4: 3000 | V4: 2610 | W4: 6000 | X4: 2220
A5: 2+3 | B5: 王沛贤 | C5: 在职研 | D5: 在职研项目部 | E5: B级学习顾问 | F5: =G5+H5 | G5: 8295 | H5: =R5 | I5: 217500 | J5: 195550 | K5: 0 | L5: 195550 | M5: 0.89908046 | N5: 13064.2 | O5: 0 | P5: 13064.2 | Q5: 0.035 | R5: 6974.892 | S5: 83 | T5: 0.83 | U5: 2000 | V5: 1660 | W5: 4000 | X5: 1320
A6: 46113 | B6: 杨明 | C6: 在职研 | D6: 在职研项目部 | E6: B级学习顾问 | F6: =G6+H6 | G6: 2000 | H6: =R6 | I6: 211000 | J6: 421680 | K6: 167916.1 | L6: 253763.9 | M6: 1.2026725 | N6: 4117.5 | O6: 0 | P6: 4117.5 | Q6: 0.06 | R6: 15267.009 | S6: 100 | T6: 1 | U6: 2000 | V6: 2000
A7: 46113 | B7: 刘津玲 | C7: 在职研 | D7: 在职研项目部 | E7: A级学习顾问 | F7: =G7+H7 | G7: 3000 | H7: =R7 | I7: 211000 | J7: 558372.3 | K7: 132642 | L7: 425730.3 | M7: 2.0176791 | N7: 32205 | O7: 8459.72 | P7: 23745.28 | Q7: 0.065 | R7: 27909.922 | S7: 100 | T7: 1 | U7: 3000 | V7: 3000
A8: 46113 | B8: 王沛贤 | C8: 在职研 | D8: 在职研项目部 | E8: B级学习顾问 | F8: =G8+H8 | G8: 1600 | H8: =R8 | I8: 150000 | J8: 204180 | K8: 0 | L8: 204180 | M8: 1.3612 | N8: 15350.7 | O8: 0 | P8: 15350.7 | Q8: 0.06 | R8: 12404.307 | S8: 80 | T8: 0.8 | U8: 2000 | V8: 1600
A9: 46143 | B9: 杨明 | C9: 在职研 | D9: 在职研项目部 | E9: B级学习顾问 | F9: =G9+H9 | G9: 2000 | H9: =R9 | I9: 230000 | J9: 283350 | K9: 0 | L9: 283350 | M9: 1.2319565 | N9: 31801.7 | O9: 20885 | P9: 10916.7 | Q9: 0.06 | R9: 17110.167 | S9: 100 | T9: 1 | U9: 2000 | V9: 2000
A10: 46143 | B10: 刘津玲 | C10: 在职研 | D10: 在职研项目部 | E10: A级学习顾问 | F10: =G10+H10 | G10: 3000 | H10: =R10 | I10: 230000 | J10: 366530 | K10: 0 | L10: 366530 | M10: 1.5936087 | N10: 42700.1 | O10: 37291.3 | P10: 5408.8 | Q10: 0.065 | R10: 23878.538 | S10: 92.250431 | T10: 1 | U10: 3000 | V10: 3000
A11: 46143 | B11: 王沛贤 | C11: 在职研 | D11: 在职研项目部 | E11: B级学习顾问 | F11: =G11+H11 | G11: 0 | H11: =R11 | I11: 230000 | J11: 36400 | K11: 0 | L11: 36400 | M11: 0.15826087 | N11: 10509 | O11: 0 | P11: 10509 | Q11: 0 | R11: 105.09 | S11: 38.575 | T11: 0 | U11: 2000 | V11: 0
A12: 46023 | B12: 杨明 | C12: 在职研 | D12: 在职研项目部 | E12: B级学习顾问 | F12: =G12+H12 | G12: 2000 | H12: =R12 | I12: 250000 | J12: 179279.8 | K12: 40529.8 | L12: 138750 | M12: 0.824718 | N12: 70215.5 | O12: 2786 | P12: 67429.5 | Q12: 0.035 | R12: 7216.2825 | S12: 98 | T12: 1 | U12: 2000 | V12: 2000
A13: 46023 | B13: 刘津玲 | C13: 在职研 | D13: 在职研项目部 | E13: A级学习顾问 | F13: =G13+H13 | G13: 3000 | H13: =R13 | I13: 250000 | J13: 187350 | K13: 30100 | L13: 157250 | M13: 1.0546631 | N13: 125915.78 | O13: 19500 | P13: 106415.78 | Q13: 0.05 | R13: 13183.289 | S13: 100 | T13: 1 | U13: 3000 | V13: 3000
A14: 46023 | B14: 王沛贤 | C14: 在职研 | D14: 在职研项目部 | E14: B级学习顾问 | F14: =G14+H14 | G14: 4000 | H14: =R14 | I14: 50000 | J14: 28800 | K14: 0 | L14: 28800 | M14: 0.576 | N14: 0 | O14: 0 | P14: 0 | Q14: 0 | R14: 0 | S14: —— | T14: 1 | U14: 4000 | V14: 4000

Sheet 英学
A1: 年月（自然月） | B1: 顾问姓名 | C1: 二级部门 | D1: 三级部门 | E1: 岗位 | F1: 奖金 | G1: 新签提成 | H1: 续费提成 | I1: 月度绩效 | J1: 新签提成 | Q1: 续费提成 | W1: 月度绩效
J2: 业绩目标 | K2: 个人新签 | L2: 退费金额 | M2: 新签净业绩 | N2: 新签完成率 | O2: 提点 | P2: 新签提成 | Q2: 续费总计 | R2: 退费总计 | S2: 退费金额 | T2: 续费业绩 | U2: 提点 | V2: 续费提成 | W2: 月度评分 | X2: 月度绩效
